weight=20
embed_into_distance=1
acceptable_target_blocks=stone,grass,dirt,sand,gravel
dimensions=12,15,11
max_leveling=1
leveling_buffer=0
preserve_water=0
preserve_lava=0
preserve_plants=1

rule1=0,100,preserveBlock
rule2=0,100,log
rule3=0,95,cobblestone
rule4=0,20,wooden_door
rule5=0,20,wooden_door-2
rule6=0,100,air
rule7=0,90,fence
rule8=0,100,oak_stairs-2
rule9=0,80,planks
rule10=0,50,glass_pane
rule11=0,25,wooden_door-8
rule12=0,25,wooden_door-9
rule13=0,100,oak_stairs-1
rule14=0,70,oak_stairs-2
rule15=0,70,oak_stairs-3
rule16=0,70,planks
rule17=0,85,planks
rule18=0,100,fence
rule19=0,80,oak_stairs-7
rule20=0,80,oak_stairs-6
rule21=0,70,stone_slab-2
rule22=0,70,oak_stairs
rule23=0,70,oak_stairs-1
rule24=0,70,iron_bars


layer
1,1,1,1,1,1,1,1,1,1,1
1,1,1,1,1,1,1,1,1,1,1
1,2,3,3,3,3,3,3,3,2,1
1,3,3,3,3,3,3,3,3,3,1
1,3,3,3,3,3,3,3,3,3,1
1,3,3,3,3,3,3,3,3,3,1
1,3,3,3,3,3,3,3,3,3,1
1,3,3,3,3,3,3,3,3,3,1
1,3,3,3,3,3,3,3,3,3,1
1,3,3,3,3,3,3,3,3,3,1
1,3,3,3,3,3,3,3,3,3,1
1,3,3,3,3,3,3,3,3,3,1
1,2,3,3,3,3,3,3,3,2,1
1,1,1,1,1,1,1,1,1,1,1
1,1,1,1,1,1,1,1,1,1,1
endlayer

layer
0,0,0,0,0,0,0,0,0,0,0
0,0,0,0,0,0,0,0,0,0,0
0,2,3,3,3,3,4,4,3,2,0
0,3,0,0,6,0,0,0,0,3,0
0,3,7,7,7,0,0,0,0,3,0
0,3,0,0,6,0,0,0,0,3,0
0,3,7,7,7,0,0,0,0,3,0
0,3,0,0,6,0,0,0,0,3,0
0,3,7,7,7,0,0,0,0,3,0
0,3,0,0,6,0,0,0,0,3,0
0,3,9,9,7,0,0,0,0,3,0
0,3,9,9,8,0,0,0,0,3,0
0,2,3,3,3,3,5,5,3,2,0
0,0,0,0,0,0,0,0,0,0,0
0,0,0,0,0,0,0,0,0,0,0
endlayer

layer
0,0,0,0,0,0,0,0,0,0,0
0,0,0,0,0,0,0,0,0,0,0
0,2,9,10,10,9,12,11,9,2,0
0,9,0,0,0,0,0,0,0,9,0
0,9,0,0,0,0,0,0,0,10,0
0,10,0,0,0,0,0,0,0,10,0
0,10,0,0,0,0,0,0,0,9,0
0,10,0,0,0,0,0,0,0,9,0
0,9,0,0,0,0,0,0,0,9,0
0,9,0,0,0,0,0,0,0,10,0
0,9,9,9,0,0,0,0,0,10,0
0,9,9,8,0,0,0,0,0,9,0
0,2,9,9,9,9,11,12,9,2,0
0,0,0,0,0,0,0,0,0,0,0
0,0,0,0,0,0,0,0,0,0,0
endlayer

layer
0,0,0,0,0,0,0,0,0,0,0
0,0,0,0,0,0,0,0,0,0,0
0,2,9,9,9,9,9,9,9,2,0
0,9,0,0,0,0,0,0,0,9,0
0,9,0,0,0,0,0,0,0,9,0
0,9,0,0,0,0,0,0,0,9,0
0,9,0,0,0,0,0,0,0,9,0
0,9,0,0,0,0,0,0,0,9,0
0,9,0,0,0,0,0,0,0,9,0
0,9,0,0,0,0,0,0,0,9,0
0,9,13,9,0,0,0,0,0,9,0
0,9,0,0,0,0,0,0,0,9,0
0,2,9,9,9,9,9,9,9,2,0
0,0,0,0,0,0,0,0,0,0,0
0,0,0,0,0,0,0,0,0,0,0
endlayer

layer
0,0,0,0,0,0,0,0,0,0,0
15,0,0,0,0,0,0,0,0,0,14
15,2,2,2,2,2,2,2,2,2,14
15,2,9,9,9,9,9,9,9,2,14
15,2,9,9,9,9,9,9,9,2,14
15,2,9,9,9,9,9,9,9,2,14
15,2,9,9,9,9,9,9,9,2,14
15,2,9,9,9,9,9,9,9,2,14
15,2,9,9,9,9,9,9,9,2,14
15,2,13,9,9,9,9,9,9,2,14
15,2,0,9,9,9,9,9,9,2,14
15,2,0,0,0,9,9,9,9,2,14
15,2,2,2,2,2,2,2,2,2,14
15,0,0,0,0,0,0,0,0,0,14
0,0,0,0,0,0,0,0,0,0,0
endlayer

layer
0,0,0,0,0,0,0,0,0,0,0
0,16,0,0,0,0,0,0,0,16,0
0,16,17,17,2,0,2,17,17,16,0
0,16,0,0,0,0,0,0,0,16,0
0,16,0,0,0,0,0,0,0,16,0
0,16,0,0,0,0,0,0,0,16,0
0,16,0,0,0,0,0,0,0,16,0
0,16,0,0,0,0,0,0,0,16,0
0,16,0,0,0,0,0,0,0,16,0
0,16,0,0,0,0,0,0,0,16,0
0,16,0,0,0,0,0,0,0,16,0
0,16,0,0,0,0,0,0,0,16,0
0,16,17,17,2,17,2,17,17,16,0
0,16,0,0,0,0,0,0,0,16,0
0,0,0,0,0,0,0,0,0,0,0
endlayer

layer
0,0,0,0,0,0,0,0,0,0,0
0,15,0,0,0,0,0,0,0,14,0
0,15,17,17,2,0,2,17,17,14,0
0,15,0,0,0,0,0,0,0,14,0
0,15,0,0,0,0,0,0,0,14,0
0,15,0,0,0,0,0,0,0,14,0
0,15,0,0,0,0,0,0,0,14,0
0,15,0,0,0,0,0,0,0,14,0
0,15,0,0,0,0,0,0,0,14,0
0,15,0,0,0,0,0,0,0,14,0
0,15,0,0,0,0,0,0,0,14,0
0,15,0,0,0,0,0,0,0,14,0
0,15,17,17,2,17,2,17,17,14,0
0,15,0,0,0,0,0,0,0,14,0
0,0,0,0,0,0,0,0,0,0,0
endlayer

layer
0,0,0,0,0,18,0,0,0,0,0
0,0,16,0,0,18,0,0,16,0,0
0,0,16,17,17,2,17,17,16,0,0
0,0,16,0,0,0,0,0,16,0,0
0,0,16,0,0,0,0,0,16,0,0
0,0,16,0,0,0,0,0,16,0,0
0,0,16,0,0,0,0,0,16,0,0
0,0,16,0,0,0,0,0,16,0,0
0,0,16,0,0,0,0,0,16,0,0
0,0,16,0,0,0,0,0,16,0,0
0,0,16,0,0,0,0,0,16,0,0
0,0,16,0,0,0,0,0,16,0,0
0,0,16,17,17,0,17,17,16,0,0
0,0,16,0,0,0,0,0,16,0,0
0,0,0,0,0,0,0,0,0,0,0
endlayer

layer
0,0,0,0,0,0,0,0,0,0,0
0,0,15,0,0,0,0,0,14,0,0
0,0,15,17,17,2,17,17,14,0,0
0,0,15,20,0,0,0,19,14,0,0
0,0,15,20,0,0,0,19,14,0,0
0,0,15,20,0,0,0,19,14,0,0
0,0,15,20,0,0,0,19,14,0,0
0,0,15,20,0,0,0,19,14,0,0
0,0,15,20,0,0,0,19,14,0,0
0,0,15,20,0,0,0,19,14,0,0
0,0,15,20,0,0,0,19,14,0,0
0,0,15,20,0,0,0,19,14,0,0
0,0,15,17,17,2,17,17,14,0,0
0,0,15,0,0,0,0,0,14,0,0
0,0,0,0,0,0,0,0,0,0,0
endlayer

layer
0,0,0,0,0,0,0,0,0,0,0
0,0,0,15,16,0,16,14,0,0,0
0,0,0,15,16,17,16,14,0,0,0
0,0,0,15,16,0,16,14,0,0,0
0,0,0,15,16,0,16,14,0,0,0
0,0,0,15,16,0,16,14,0,0,0
0,0,0,15,16,0,16,14,0,0,0
0,0,0,15,16,0,16,14,0,0,0
0,0,0,15,16,0,16,14,0,0,0
0,0,0,15,16,0,16,14,0,0,0
0,0,0,15,16,0,16,14,0,0,0
0,0,0,15,16,0,16,14,0,0,0
0,0,0,15,16,17,16,14,0,0,0
0,0,0,15,16,0,16,14,0,0,0
0,0,0,0,0,0,0,0,0,0,0
endlayer

layer
0,0,0,0,0,21,0,0,0,0,0
0,0,0,0,0,21,0,0,0,0,0
0,0,0,0,0,21,0,0,0,0,0
0,0,0,0,0,21,0,0,0,0,0
0,0,0,0,0,21,0,0,0,0,0
0,0,0,0,0,21,0,0,0,0,0
0,0,0,0,0,22,0,0,0,0,0
0,0,0,0,0,16,0,0,0,0,0
0,0,0,0,0,23,0,0,0,0,0
0,0,0,0,0,21,0,0,0,0,0
0,0,0,0,0,21,0,0,0,0,0
0,0,0,0,0,21,0,0,0,0,0
0,0,0,0,0,21,0,0,0,0,0
0,0,0,0,0,21,0,0,0,0,0
0,0,0,0,0,21,0,0,0,0,0
endlayer

layer
0,0,0,0,0,0,0,0,0,0,0
0,0,0,0,0,0,0,0,0,0,0
0,0,0,0,0,0,0,0,0,0,0
0,0,0,0,0,0,0,0,0,0,0
0,0,0,0,0,0,0,0,0,0,0
0,0,0,0,0,0,0,0,0,0,0
0,0,0,0,0,0,0,0,0,0,0
0,0,0,0,0,24,0,0,0,0,0
0,0,0,0,0,0,0,0,0,0,0
0,0,0,0,0,0,0,0,0,0,0
0,0,0,0,0,0,0,0,0,0,0
0,0,0,0,0,0,0,0,0,0,0
0,0,0,0,0,0,0,0,0,0,0
0,0,0,0,0,0,0,0,0,0,0
0,0,0,0,0,0,0,0,0,0,0
endlayer

