# Author: d00dv4d3r
# From: Default Template

weight=10
embed_into_distance=5
unacceptable_target_blocks=flowing_water,water,flowing_lava,lava
dimensions=9,7,7
allowable_overhang=2
max_leveling=2
leveling_buffer=1
preserve_water=0
preserve_lava=0
preserve_plants=0

rule1=0,100,air,double_stone_slab,stone_slab
rule2=0,100,cobblestone,mossy_cobblestone
rule3=1,50,cobblestone,mossy_cobblestone
rule4=1,50,planks
rule5=2,33,planks
rule6=0,100,stone_stairs-1,air

layer
2,2,2,2,2,2,2
2,2,2,2,2,2,2
2,2,2,2,2,2,2
2,2,2,2,2,2,2
2,2,2,2,2,2,2
2,2,2,2,2,2,2
2,2,2,2,2,2,2
endlayer

layer
2,2,2,2,2,2,2
2,0,0,0,0,0,2
2,0,0,0,0,0,2
2,0,0,0,0,0,2
2,0,0,0,0,6,2
2,0,0,0,0,0,2
2,2,2,2,2,2,2
endlayer

layer
2,2,2,2,2,2,2
2,0,0,0,0,0,2
2,0,0,0,0,0,2
2,0,0,0,0,6,2
2,0,0,0,0,0,2
2,0,0,0,0,0,2
2,2,2,2,2,2,2
endlayer

layer
2,2,2,2,2,2,2
2,0,0,0,0,0,2
2,0,0,0,0,6,2
2,0,0,0,0,0,2
2,0,0,0,0,0,2
2,0,0,0,0,0,2
2,2,2,2,2,2,2
endlayer

layer
2,2,2,2,2,2,2
2,1,1,1,1,6,2
2,1,1,1,1,0,2
2,1,1,1,1,0,2
2,1,1,1,1,0,2
2,1,1,1,1,1,2
2,2,2,2,2,2,2
endlayer

layer
3,3,3,3,3,3,3
3,0,0,0,0,0,3
3,0,0,0,0,0,3
3,0,0,0,0,0,3
3,0,0,0,0,0,3
3,0,0,0,0,0,3
3,3,3,3,3,3,3
endlayer

layer
3,3,3,3,3,3,3
3,0,0,0,0,0,3
3,0,0,0,0,0,3
3,0,0,0,0,0,3
3,0,0,0,0,0,3
3,0,0,0,0,0,3
3,3,3,3,3,3,3
endlayer

layer
3,3,3,3,3,3,3
3,0,0,0,0,0,3
3,0,0,0,0,0,3
3,0,0,0,0,0,3
3,0,0,0,0,0,3
3,0,0,0,0,0,3
3,3,3,3,3,3,3
endlayer

layer
4,5,0,0,0,5,4
5,0,0,0,0,0,5
0,0,0,0,0,0,0
0,0,0,0,0,0,0
0,0,0,0,0,0,0
5,0,0,0,0,0,5
4,5,0,0,0,5,4
endlayer
