
weight=20
embed_into_distance=1
unacceptable_target_blocks=flowing_water,water,flowing_lava,lava,snow,snow_layer
dimensions=5,11,7
max_leveling=1
leveling_buffer=0
preserve_water=0
preserve_lava=0
preserve_plants=1


rule1=0,50,cobblestone,mossy_cobblestone
rule2=0,30,cobblestone,cobblestone,mossy_cobblestone,planks
rule3=0,100,brick_block
rule4=0,20,cobblestone,mossy_cobblestone,stone_slab-3
rule5=0,0,preserveBlock
rule6=0,100,brick_stairs-1


layer
1,1,3,3,3,1,1
1,1,3,3,3,1,1
1,2,2,2,2,2,1
1,2,2,2,2,2,1
1,2,2,2,2,2,1
1,2,2,2,2,2,1
1,2,2,2,2,2,1
1,2,2,2,2,2,1
1,2,2,2,2,2,1
1,2,2,2,2,2,1
1,1,1,1,1,1,1
endlayer

layer
4,4,3,3,3,4,4
4,5,3,5,3,5,4
4,5,5,5,5,5,4
4,5,5,5,5,5,4
4,5,5,5,5,5,4
4,5,5,5,5,5,4
4,5,5,5,5,5,4
4,5,5,5,5,5,4
4,5,5,5,5,5,4
4,5,5,5,5,5,4
4,4,4,4,4,4,4
endlayer

layer
0,0,3,3,3,0,0
0,0,6,6,6,0,0
0,0,0,0,0,0,0
0,0,0,0,0,0,0
0,0,0,0,0,0,0
0,0,0,0,0,0,0
0,0,0,0,0,0,0
0,0,0,0,0,0,0
0,0,0,0,0,0,0
0,0,0,0,0,0,0
0,0,0,0,0,0,0
endlayer

layer
0,0,0,3,0,0,0
0,0,0,0,0,0,0
0,0,0,0,0,0,0
0,0,0,0,0,0,0
0,0,0,0,0,0,0
0,0,0,0,0,0,0
0,0,0,0,0,0,0
0,0,0,0,0,0,0
0,0,0,0,0,0,0
0,0,0,0,0,0,0
0,0,0,0,0,0,0
endlayer

layer
0,0,0,3,0,0,0
0,0,0,0,0,0,0
0,0,0,0,0,0,0
0,0,0,0,0,0,0
0,0,0,0,0,0,0
0,0,0,0,0,0,0
0,0,0,0,0,0,0
0,0,0,0,0,0,0
0,0,0,0,0,0,0
0,0,0,0,0,0,0
0,0,0,0,0,0,0
endlayer

