weight=20
embed_into_distance=5
unacceptable_target_blocks=flowing_water,water,flowing_lava,lava
dimensions=5,8,8
max_leveling=0
leveling_buffer=0
preserve_water=0
preserve_lava=0
preserve_plants=0


rule1=0,100,preserveBlock
rule2=0,100,cobblestone
rule3=0,100,gravel
rule4=0,50,cobblestone,mossy_cobblestone
rule5=0,100,stone_stairs-3
rule6=0,100,stone_slab-3
rule7=0,100,stone_stairs-1
rule8=0,100,stone_stairs
rule9=0,100,stone_stairs-2


layer
1,1,1,2,2,1,1,1
1,1,2,2,2,2,1,1
1,2,2,3,3,2,2,1
2,2,3,3,3,3,2,2
2,2,3,3,3,3,2,2
1,2,2,3,3,2,2,1
1,1,2,2,2,2,1,1
1,1,1,2,2,1,1,1
endlayer

layer
1,1,1,2,2,1,1,1
1,1,2,2,2,2,1,1
1,2,2,0,0,2,2,1
2,2,0,0,0,0,2,2
2,2,0,0,0,0,2,2
1,2,2,0,0,2,2,1
1,1,2,2,2,2,1,1
1,1,1,2,2,1,1,1
endlayer

layer
1,1,1,2,2,1,1,1
1,1,2,0,0,2,1,1
1,2,2,0,0,2,2,1
2,0,0,0,0,0,0,2
2,0,0,0,0,0,0,2
1,2,2,0,0,2,2,1
1,1,2,0,0,2,1,1
1,1,1,2,2,1,1,1
endlayer

layer
1,1,1,1,1,1,1,1
1,1,2,2,2,2,1,1
1,2,2,0,0,2,2,1
1,2,0,0,0,0,2,1
1,2,0,0,0,0,2,1
1,2,2,0,0,2,2,1
1,1,2,2,2,2,1,1
1,1,1,1,1,1,1,1
endlayer

layer
1,1,4,4,4,4,1,1
1,4,2,7,7,2,4,1
4,2,6,0,0,6,2,4
4,9,0,0,0,0,5,4
4,9,0,0,0,0,5,4
4,2,6,0,0,6,2,4
1,4,2,8,8,2,4,1
1,1,4,4,4,4,1,1
endlayer

