# Author: d00dv4d3r
# From: Default Template
weight=20
embed_into_distance=1
unacceptable_target_blocks=flowing_water,water,flowing_lava,lava,Natura:Cloud
dimensions=5,7,7
allowable_overhang=2
max_leveling=2
leveling_buffer=1
preserve_water=0
preserve_lava=0
preserve_plants=1

rule1=0,100,air,cobblestone,mossy_cobblestone,stone_slab-3
rule2=0,100,cobblestone,mossy_cobblestone
rule3=1,50,cobblestone,mossy_cobblestone
rule4=2,50,cobblestone,mossy_cobblestone
rule5=0,100,preserveBlock

layer
5,5,2,2,2,5,5
5,2,1,1,1,2,5
2,1,1,1,1,1,2
2,1,1,1,1,1,2
2,1,1,1,1,1,2
5,2,1,1,1,2,5
5,5,2,2,2,5,5
endlayer

layer
0,0,3,3,3,0,0
0,3,0,0,0,3,0
3,0,0,0,0,0,3
3,0,0,0,0,0,3
3,0,0,0,0,0,3
0,3,0,0,0,3,0
0,0,3,3,3,0,0
endlayer

layer
0,0,3,3,3,0,0
0,3,0,0,0,3,0
3,0,0,0,0,0,3
3,0,0,0,0,0,3
3,0,0,0,0,0,3
0,3,0,0,0,3,0
0,0,3,3,3,0,0
endlayer

layer
0,0,3,3,3,0,0
0,3,0,0,0,3,0
3,0,0,0,0,0,3
3,0,0,0,0,0,3
3,0,0,0,0,0,3
0,3,0,0,0,3,0
0,0,3,3,3,0,0
endlayer

layer
0,0,3,3,3,0,0
0,3,4,4,4,3,0
3,4,4,4,4,4,3
3,4,4,4,4,4,3
3,4,4,4,4,4,3
0,3,4,4,4,3,0
0,0,3,3,3,0,0
endlayer
