# Converted from schematic
# THIS TEMPLATE USES DEFAULTS!  Please edit for corrections.
# If you need help, consult template_rules.txt
weight=5
embed_into_distance=2
unacceptable_target_blocks=flowing_water,water,flowing_lava,lava
dimensions=11,9,8
allowable_overhang=0
max_leveling=2
leveling_buffer=1
preserve_water=0
preserve_lava=0
preserve_plants=0


rule1=0,100,dirt
rule2=0,100,grass
rule3=0,100,stonebrick
rule4=0,100,stonebrick-1
rule5=0,100,stone_brick_stairs-2
rule6=0,100,stone_brick_stairs-3
rule7=0,100,stone_brick_stairs
rule8=0,100,stone_brick_stairs-1
rule9=0,100,glass
rule10=0,100,stonebrick-2
rule11=2,100,torch-3
rule12=0,100,lapis_block
rule13=2,100,torch-4
rule14=2,100,torch-1
rule15=0,100,lever-11
rule16=0,100,unlit_redstone_torch-5


layer
1,1,1,1,1,1,1,1
1,1,1,1,1,1,1,1
1,1,1,1,1,1,1,1
1,1,1,1,1,1,1,1
1,1,1,1,1,1,1,2
1,1,1,1,1,1,1,1
1,1,1,1,1,1,1,1
1,1,1,1,1,1,1,1
1,1,1,1,1,1,1,1
endlayer

layer
2,2,2,1,0,2,2,2
2,2,1,1,1,1,2,2
2,1,1,3,3,1,1,2
1,1,3,3,4,3,1,1
4,4,3,3,3,3,1,0
1,1,3,3,4,3,1,1
2,1,1,3,3,1,1,2
2,2,1,1,1,1,2,2
2,2,2,1,1,2,2,2
endlayer

layer
0,0,0,7,7,0,0,0
0,0,6,3,3,5,0,0
0,6,3,4,3,3,5,0
6,3,5,0,0,6,3,5
0,0,0,0,0,6,3,5
6,3,5,0,0,6,3,5
0,6,3,4,3,3,5,0
0,0,6,3,3,5,0,0
0,0,0,8,8,0,0,0
endlayer

layer
0,0,0,0,0,0,0,0
0,0,0,3,3,0,0,0
0,0,3,0,0,3,0,0
0,3,0,0,0,0,3,0
0,0,0,0,0,0,9,0
0,3,0,0,0,0,3,0
0,0,10,0,0,3,0,0
0,0,0,3,3,0,0,0
0,0,0,0,0,0,0,0
endlayer

layer
0,0,0,0,0,0,0,0
0,0,0,9,9,0,0,0
0,0,3,0,0,3,0,0
0,3,0,0,0,11,3,0
0,12,0,0,0,0,9,0
0,3,0,0,0,11,3,0
0,0,10,0,0,3,0,0
0,0,0,9,9,0,0,0
0,0,0,0,0,0,0,0
endlayer

layer
0,0,0,0,0,0,0,0
0,0,0,3,3,0,0,0
0,0,3,0,0,3,0,0
0,3,13,0,0,0,3,0
0,12,0,0,0,0,3,0
0,3,13,0,0,0,3,0
0,0,3,0,0,3,0,0
0,0,0,3,3,0,0,0
0,0,0,0,0,0,0,0
endlayer

layer
0,0,0,0,0,0,0,0
0,0,0,3,3,0,0,0
0,0,3,14,14,3,0,0
0,3,0,0,0,0,3,0
0,3,0,0,0,0,3,0
0,3,0,0,0,0,3,0
0,0,3,0,15,3,0,0
0,0,0,3,3,0,0,0
0,0,0,0,0,0,0,0
endlayer

layer
0,0,0,12,12,0,0,0
0,0,12,12,12,12,0,0
0,12,12,12,12,12,12,0
12,12,12,12,12,12,12,12
12,12,12,12,12,12,12,12
12,12,12,12,12,12,12,12
0,12,12,12,12,16,12,0
0,0,12,0,12,12,0,0
0,0,0,12,12,0,0,0
endlayer

layer
0,0,0,0,0,0,0,0
0,0,0,12,12,0,0,0
0,0,12,0,0,12,0,0
0,12,0,0,0,0,12,0
0,12,0,0,0,0,12,0
0,12,0,0,0,12,12,0
0,0,12,0,0,12,0,0
0,0,0,12,12,0,0,0
0,0,0,0,0,0,0,0
endlayer

layer
0,0,0,0,0,0,0,0
0,0,0,0,0,0,0,0
0,0,0,12,12,0,0,0
0,0,12,0,0,12,0,0
0,0,12,0,0,12,0,0
0,0,12,0,12,12,0,0
0,0,0,12,12,0,0,0
0,0,0,0,0,0,0,0
0,0,0,0,0,0,0,0
endlayer

layer
0,0,0,0,0,0,0,0
0,0,0,0,0,0,0,0
0,0,0,0,0,0,0,0
0,0,0,12,12,0,0,0
0,0,0,12,12,0,0,0
0,0,0,12,12,0,0,0
0,0,0,0,0,0,0,0
0,0,0,0,0,0,0,0
0,0,0,0,0,0,0,0
endlayer

