# Author: GnomeWorks
# From: Minecraft Forums

weight=1
embed_into_distance=1
unacceptable_target_blocks=flowing_water,water,flowing_lava,lava,Natura:Cloud,sand,gravel
dimensions=35,11,18
allowable_overhang=0
max_cut_in=2
cut_in_buffer=1
max_leveling=2
leveling_buffer=1
preserve_water=0
preserve_lava=0
preserve_plants=0

rule1=1,90,cobblestone,mossy_cobblestone,mossy_cobblestone,mossy_cobblestone
rule2=1,20,iron_block
rule3=1,20,lapis_block
rule4=2,80,cobblestone,mossy_cobblestone,mossy_cobblestone,mossy_cobblestone
rule5=0,100,air
rule6=1,80,cobblestone,mossy_cobblestone,mossy_cobblestone,mossy_cobblestone
rule7=2,20,iron_block

layer
1,1,1,1,1,1,1,1,1,1,1,1,1,1,1,1,1,1
1,1,1,1,1,1,1,1,1,1,1,1,1,1,1,1,1,1
1,1,1,1,1,1,1,1,1,1,1,1,1,1,1,1,1,1
1,1,1,1,1,1,1,1,1,1,1,1,1,1,1,1,1,1
1,1,1,1,1,1,1,1,1,1,1,1,1,1,1,1,1,1
1,1,1,1,1,1,1,1,1,1,1,1,1,1,1,1,1,1
1,1,1,1,1,1,1,1,1,1,1,1,1,1,1,1,1,1
1,1,1,1,1,1,1,1,1,1,1,1,1,1,1,1,1,1
1,1,1,1,1,1,1,1,1,1,1,1,1,1,1,1,1,1
1,1,1,1,1,1,1,1,1,1,1,1,1,1,1,1,1,1
1,1,1,1,1,1,1,1,1,1,1,1,1,1,1,1,1,1
endlayer

layer
1,1,1,1,1,1,1,1,1,1,1,1,1,1,1,1,1,1
1,1,1,1,1,1,1,1,1,1,1,1,1,1,1,1,1,1
1,1,1,1,1,1,1,1,1,1,1,1,1,1,1,1,1,1
1,1,1,1,1,1,1,1,1,1,1,1,1,1,1,1,1,1
1,1,1,1,1,1,1,1,1,1,1,1,1,1,1,1,1,1
1,1,1,1,1,1,1,1,1,1,1,1,1,1,1,1,1,1
1,1,1,1,1,1,1,1,1,1,1,1,1,1,1,1,1,1
1,1,1,1,1,1,1,1,1,1,1,1,1,1,1,1,1,1
1,1,1,1,1,1,1,1,1,1,1,1,1,1,1,1,1,1
1,1,1,1,1,1,1,1,1,1,1,1,1,1,1,1,1,1
1,1,1,1,1,1,1,1,1,1,1,1,1,1,1,1,1,1
endlayer

layer
5,5,5,5,5,5,5,5,5,5,5,5,5,5,5,5,5,5
5,5,5,5,5,5,5,5,5,5,5,5,5,5,5,5,5,5
5,5,5,5,5,6,6,6,6,6,6,6,6,5,5,5,5,5
5,5,5,5,5,6,6,6,6,6,6,6,6,5,5,5,5,5
5,5,5,5,5,6,6,6,6,6,6,6,6,5,5,5,5,5
5,5,5,5,5,6,6,6,6,6,6,6,6,5,5,5,5,5
5,5,5,5,5,5,5,5,5,5,5,5,5,5,5,5,5,5
5,5,6,6,5,5,5,5,5,5,5,5,5,5,5,5,5,5
5,5,6,6,5,5,5,5,5,5,5,5,5,5,5,5,5,5
5,5,5,5,5,5,5,5,5,5,5,5,5,5,5,5,5,5
5,5,5,5,5,5,5,5,5,5,5,5,5,5,5,5,5,5
endlayer

layer
5,5,5,5,5,5,5,5,5,5,5,5,5,5,5,5,5,5
5,5,5,5,5,5,5,5,5,5,5,5,5,5,5,5,5,5
5,5,5,5,5,6,6,6,6,6,6,6,6,5,5,5,5,5
5,5,5,5,5,6,6,6,6,6,6,6,6,5,5,5,5,5
5,5,5,5,5,6,6,6,6,6,6,6,6,5,5,5,5,5
5,5,5,5,5,6,6,6,6,6,6,6,6,5,5,5,5,5
5,5,5,5,5,5,5,5,5,5,5,5,5,5,5,5,5,5
5,5,6,6,5,5,5,5,5,5,5,5,5,5,5,5,5,5
5,5,6,6,5,5,5,5,5,5,5,5,5,5,5,5,5,5
5,5,5,5,5,5,5,5,5,5,5,5,5,5,5,5,5,5
5,5,5,5,5,5,5,5,5,5,5,5,5,5,5,5,5,5
endlayer

layer
5,5,5,5,5,5,5,5,5,5,5,5,5,5,5,5,5,5
5,5,5,5,5,5,5,5,5,5,5,5,5,5,5,5,5,5
5,5,5,5,5,6,6,6,6,6,6,6,6,5,5,5,5,5
5,5,5,5,5,6,6,6,6,6,6,6,6,5,5,5,5,5
5,5,5,5,5,6,6,6,6,6,6,6,6,5,5,5,5,5
5,5,5,5,5,6,6,6,6,6,6,6,6,5,5,5,5,5
5,5,5,5,5,5,5,5,5,5,5,5,5,5,5,5,5,5
5,5,6,6,5,5,5,5,5,5,5,5,5,5,5,5,5,5
5,5,6,6,5,5,5,5,5,5,5,5,5,5,5,5,5,5
5,5,5,5,5,5,5,5,5,5,5,5,5,5,5,5,5,5
5,5,5,5,5,5,5,5,5,5,5,5,5,5,5,5,5,5
endlayer

layer
5,5,5,5,5,5,5,5,5,5,5,5,5,5,5,5,5,5
5,5,5,5,5,5,5,5,5,5,5,5,5,5,5,5,5,5
5,5,5,5,5,6,6,6,6,6,6,6,6,5,5,5,5,5
5,5,5,5,5,6,6,6,6,6,6,6,6,5,5,5,5,5
5,5,5,5,5,6,6,6,6,6,6,6,6,5,5,5,5,5
5,5,5,5,5,6,6,6,6,6,6,6,6,5,5,5,5,5
5,5,5,5,5,5,5,5,5,5,5,5,5,5,5,5,5,5
5,5,6,6,5,5,5,5,5,5,5,5,5,5,5,5,5,5
5,5,6,6,5,5,5,5,5,5,5,5,5,5,5,5,5,5
5,5,5,5,5,5,5,5,5,5,5,5,5,5,5,5,5,5
5,5,5,5,5,5,5,5,5,5,5,5,5,5,5,5,5,5
endlayer

layer
5,5,5,5,5,5,5,5,5,5,5,5,5,5,5,5,5,5
5,5,5,5,5,5,5,5,5,5,5,5,5,5,5,5,5,5
5,5,5,5,5,6,6,6,6,6,6,6,6,5,5,5,5,5
5,5,5,5,5,6,6,6,6,6,6,6,6,5,5,5,5,5
5,5,5,5,5,6,6,6,6,6,6,6,6,5,5,5,5,5
5,5,5,5,5,6,6,6,6,6,6,6,6,5,5,5,5,5
5,5,5,5,5,5,5,5,5,5,5,5,5,5,5,5,5,5
5,5,6,6,5,5,5,5,5,5,5,5,5,5,5,5,5,5
5,5,6,6,5,5,5,5,5,5,5,5,5,5,5,5,5,5
5,5,5,5,5,5,5,5,5,5,5,5,5,5,5,5,5,5
5,5,5,5,5,5,5,5,5,5,5,5,5,5,5,5,5,5
endlayer

layer
5,5,5,5,5,5,5,5,5,5,5,5,5,5,5,5,5,5
5,5,5,5,5,5,5,5,5,5,5,5,5,5,5,5,5,5
5,5,5,5,5,6,6,6,6,6,6,6,6,5,5,5,5,5
5,5,5,5,5,6,6,6,6,6,6,6,6,5,5,5,5,5
5,5,5,5,5,6,6,6,6,6,6,6,6,5,5,5,5,5
5,5,5,5,5,6,6,6,6,6,6,6,6,5,5,5,5,5
5,5,5,5,5,5,5,5,5,5,5,5,5,5,5,5,5,5
5,5,6,6,5,5,5,5,5,5,5,5,5,5,5,5,5,5
5,5,6,6,5,5,5,5,5,5,5,5,5,5,5,5,5,5
5,5,5,5,5,5,5,5,5,5,5,5,5,5,5,5,5,5
5,5,5,5,5,5,5,5,5,5,5,5,5,5,5,5,5,5
endlayer

layer
5,5,5,5,5,5,5,5,5,5,5,5,5,5,5,5,5,5
5,5,5,5,5,5,5,5,5,5,5,5,5,5,5,5,5,5
5,5,5,5,5,6,6,6,6,6,6,6,6,5,5,5,5,5
5,5,5,5,5,6,6,6,6,6,6,6,6,5,5,5,5,5
5,5,5,5,5,6,6,6,6,6,6,6,6,5,5,5,5,5
5,5,5,5,5,6,6,6,6,6,6,6,6,5,5,5,5,5
5,5,5,5,5,5,5,5,5,5,5,5,5,5,5,5,5,5
5,5,6,6,5,5,5,5,5,5,5,5,5,5,5,5,5,5
5,5,6,6,5,5,5,5,5,5,5,5,5,5,5,5,5,5
5,5,5,5,5,5,5,5,5,5,5,5,5,5,5,5,5,5
5,5,5,5,5,5,5,5,5,5,5,5,5,5,5,5,5,5
endlayer

layer
5,5,5,5,5,5,5,5,5,5,5,5,5,5,5,5,5,5
5,5,5,5,5,5,5,5,5,5,5,5,5,5,5,5,5,5
5,5,5,5,5,6,6,6,6,6,6,6,6,5,5,5,5,5
5,5,5,5,5,6,6,6,6,6,6,6,6,5,5,5,5,5
5,5,5,5,5,6,6,6,6,6,6,6,6,5,5,5,5,5
5,5,5,5,5,6,6,6,6,6,6,6,6,5,5,5,5,5
5,5,5,5,5,5,5,5,5,5,5,5,5,5,5,5,5,5
5,5,6,6,5,5,5,5,5,5,5,5,5,5,5,5,5,5
5,5,6,6,5,5,5,5,5,5,5,5,5,5,5,5,5,5
5,5,5,5,5,5,5,5,5,5,5,5,5,5,5,5,5,5
5,5,5,5,5,5,5,5,5,5,5,5,5,5,5,5,5,5
endlayer

layer
5,5,5,5,5,5,5,5,5,5,5,5,5,5,5,5,5,5
5,5,5,5,5,5,5,5,5,5,5,5,5,5,5,5,5,5
5,5,5,5,5,6,6,6,6,6,6,6,6,4,4,4,4,5
5,5,5,5,5,6,6,6,6,6,6,6,6,4,4,4,4,5
5,5,5,5,5,6,6,6,6,6,6,6,6,4,4,4,4,5
5,5,5,5,5,6,6,6,6,6,6,6,6,4,4,4,4,5
5,5,5,5,5,5,5,5,5,5,5,5,5,5,5,5,5,5
5,5,6,6,5,5,5,5,5,5,5,5,5,5,5,5,5,5
5,5,6,6,5,5,5,5,5,5,5,5,5,5,5,5,5,5
5,5,5,5,5,5,5,5,5,5,5,5,5,5,5,5,5,5
5,5,5,5,5,5,5,5,5,5,5,5,5,5,5,5,5,5
endlayer

layer
5,5,5,5,5,5,5,5,5,5,5,5,5,5,5,5,5,5
5,5,5,5,5,5,5,5,5,5,5,5,5,5,5,5,5,5
5,5,5,5,5,6,6,6,6,6,6,6,6,4,4,4,4,5
5,5,5,5,5,6,6,6,6,6,6,6,6,4,4,4,4,5
5,5,5,5,5,6,6,6,6,6,6,6,6,4,4,4,4,5
5,5,5,5,5,6,6,6,6,6,6,6,6,4,4,4,4,5
5,5,5,5,5,5,5,5,5,5,5,5,5,5,5,5,5,5
5,5,6,6,5,5,5,5,5,5,5,5,5,5,5,5,5,5
5,5,6,6,5,5,5,5,5,5,5,5,5,5,5,5,5,5
5,5,5,5,5,5,5,5,5,5,5,5,5,5,5,5,5,5
5,5,5,5,5,5,5,5,5,5,5,5,5,5,5,5,5,5
endlayer

layer
5,5,5,5,5,5,5,5,5,5,5,5,5,5,5,5,5,5
5,5,5,5,5,5,5,5,5,5,5,5,5,5,5,5,5,5
5,5,5,5,5,6,6,6,6,6,6,6,6,4,4,4,4,5
5,5,5,5,5,6,6,6,6,6,6,6,6,4,4,4,4,5
5,5,5,5,5,6,6,6,6,6,6,6,6,4,4,4,4,5
5,5,5,5,5,6,6,6,6,6,6,6,6,4,4,4,4,5
5,5,5,5,5,5,5,5,5,5,5,5,5,5,5,5,5,5
5,5,6,6,5,5,5,5,5,5,5,5,5,5,5,5,5,5
5,5,6,6,5,5,5,5,5,5,5,5,5,5,5,5,5,5
5,5,5,5,5,5,5,5,5,5,5,5,5,5,5,5,5,5
5,5,5,5,5,5,5,5,5,5,5,5,5,5,5,5,5,5
endlayer

layer
5,5,5,5,5,5,5,5,5,5,5,5,5,5,5,5,5,5
5,5,5,5,5,5,5,5,5,5,5,5,5,5,5,5,5,5
5,5,5,5,5,6,6,6,6,6,6,6,6,4,4,4,4,5
5,5,5,5,5,6,6,6,6,6,6,6,6,4,4,4,4,5
5,5,5,5,5,6,6,6,6,6,6,6,6,4,4,4,4,5
5,5,5,5,5,6,6,6,6,6,6,6,6,4,4,4,4,5
5,5,5,5,5,5,5,5,5,5,5,5,5,5,5,5,5,5
5,5,6,6,5,5,5,5,5,5,5,5,5,5,5,5,5,5
5,5,6,6,5,5,5,5,5,5,5,5,5,5,5,5,5,5
5,5,5,5,5,5,5,5,5,5,5,5,5,5,5,5,5,5
5,5,5,5,5,5,5,5,5,5,5,5,5,5,5,5,5,5
endlayer

layer
5,5,5,5,5,5,5,5,5,5,5,5,5,5,5,5,5,5
5,5,5,5,5,5,5,5,5,5,5,5,5,5,5,5,5,5
5,4,4,4,4,6,6,6,6,6,6,6,6,4,4,4,4,5
5,4,4,4,4,6,6,6,6,6,6,6,6,4,4,4,4,5
5,4,4,4,4,6,6,6,6,6,6,6,6,4,4,4,4,5
5,4,4,4,4,6,6,6,6,6,6,6,6,4,4,4,4,5
5,4,4,4,4,5,5,5,5,5,5,5,5,5,5,5,5,5
5,4,6,6,4,5,5,5,5,5,5,5,5,5,5,5,5,5
5,4,6,6,4,5,5,5,5,5,5,5,5,5,5,5,5,5
5,4,4,4,4,5,5,5,5,5,5,5,5,5,5,5,5,5
5,5,5,5,5,5,5,5,5,5,5,5,5,5,5,5,5,5
endlayer

layer
5,5,5,5,5,5,5,5,5,5,5,5,5,5,5,5,5,5
5,5,5,5,5,5,5,5,5,5,5,5,5,5,5,5,5,5
5,4,4,4,4,6,6,6,6,6,6,6,6,4,4,4,4,5
5,4,4,4,4,6,6,6,6,6,6,6,6,4,4,4,4,5
5,4,4,4,4,6,6,6,6,6,6,6,6,4,4,4,4,5
5,4,4,4,4,6,6,6,6,6,6,6,6,4,4,4,4,5
5,4,4,4,4,5,5,5,5,5,5,5,5,5,5,5,5,5
5,4,6,6,4,5,5,5,5,5,5,5,5,5,5,5,5,5
5,4,6,6,4,5,5,5,5,5,5,5,5,5,5,5,5,5
5,4,4,4,4,5,5,5,5,5,5,5,5,5,5,5,5,5
5,5,5,5,5,5,5,5,5,5,5,5,5,5,5,5,5,5
endlayer

layer
5,5,5,5,5,5,5,5,5,5,5,5,5,5,5,5,5,5
5,5,5,5,5,5,5,5,5,5,5,5,5,5,5,5,5,5
5,4,4,4,4,6,6,6,6,6,6,6,6,4,4,4,4,5
5,4,4,4,4,6,6,6,6,6,6,6,6,4,4,4,4,5
5,4,4,4,4,6,6,6,6,6,6,6,6,4,4,4,4,5
5,4,4,4,4,6,6,6,6,6,6,6,6,4,4,4,4,5
5,4,4,4,4,5,5,5,5,5,5,5,5,5,5,5,5,5
5,4,6,6,4,5,5,5,5,5,5,5,5,5,5,5,5,5
5,4,6,6,4,5,5,5,5,5,5,5,5,5,5,5,5,5
5,4,4,4,4,5,5,5,5,5,5,5,5,5,5,5,5,5
5,5,5,5,5,5,5,5,5,5,5,5,5,5,5,5,5,5
endlayer

layer
5,5,5,5,5,5,5,5,5,5,5,5,5,5,5,5,5,5
5,5,5,5,5,5,5,5,5,5,5,5,5,5,5,5,5,5
5,4,4,4,4,6,6,6,6,6,6,6,6,4,4,4,4,5
5,4,4,4,4,6,6,6,6,6,6,6,6,4,4,4,4,5
5,4,4,4,4,6,6,6,6,6,6,6,6,4,4,4,4,5
5,4,4,4,4,6,6,6,6,6,6,6,6,4,4,4,4,5
5,4,4,4,4,5,5,5,5,5,5,5,5,5,5,5,5,5
5,4,6,6,4,5,5,5,5,5,5,5,5,5,5,5,5,5
5,4,6,6,4,5,5,5,5,5,5,5,5,5,5,5,5,5
5,4,4,4,4,5,5,5,5,5,5,5,5,5,5,5,5,5
5,5,5,5,5,5,5,5,5,5,5,5,5,5,5,5,5,5
endlayer

layer
5,5,5,5,5,5,5,5,5,5,5,5,5,5,5,5,5,5
5,5,5,5,5,5,5,5,5,5,5,5,5,5,5,5,5,5
5,5,5,5,5,6,6,6,6,6,6,6,6,5,5,5,5,5
5,5,5,5,5,6,6,6,6,6,6,6,6,5,5,5,5,5
5,5,5,5,5,6,6,6,6,6,6,6,6,5,5,5,5,5
5,5,5,5,5,6,6,6,6,6,6,6,6,5,5,5,5,5
5,5,5,5,5,5,5,5,5,5,5,5,5,5,5,5,5,5
5,5,6,6,5,5,5,5,5,5,5,5,5,5,5,5,5,5
5,5,6,6,5,5,5,5,5,5,5,5,5,5,5,5,5,5
5,5,5,5,5,5,5,5,5,5,5,5,5,5,5,5,5,5
5,5,5,5,5,5,5,5,5,5,5,5,5,5,5,5,5,5
endlayer

layer
5,5,5,5,5,4,4,4,4,4,4,4,4,5,5,5,5,5
5,5,5,5,5,4,4,4,4,4,4,4,4,5,5,5,5,5
5,5,5,5,5,6,6,6,6,6,6,6,6,5,5,5,5,5
5,5,5,5,5,6,6,6,6,6,6,6,6,5,5,5,5,5
5,5,5,5,5,6,6,6,6,6,6,6,6,5,5,5,5,5
5,5,5,5,5,6,6,6,6,6,6,6,6,5,5,5,5,5
5,5,5,5,5,4,4,4,4,4,4,4,4,5,5,5,5,5
5,5,6,6,5,4,4,4,4,4,4,4,4,5,5,5,5,5
5,5,6,6,5,5,5,5,5,5,5,5,5,5,5,5,5,5
5,5,5,5,5,5,5,5,5,5,5,5,5,5,5,5,5,5
5,5,5,5,5,5,5,5,5,5,5,5,5,5,5,5,5,5
endlayer

layer
5,5,5,5,5,4,4,4,4,4,4,4,4,5,5,5,5,5
5,5,5,5,5,4,4,4,4,4,4,4,4,5,5,5,5,5
5,5,5,5,5,4,4,6,6,6,6,6,4,5,5,5,5,5
5,5,5,5,5,4,4,6,6,6,6,4,4,5,5,5,5,5
5,5,5,5,5,4,4,6,6,6,6,4,4,5,5,5,5,5
5,5,5,5,5,4,4,6,6,6,6,4,4,5,5,5,5,5
5,5,5,5,5,4,4,4,4,4,4,4,4,5,5,5,5,5
5,5,6,6,5,4,4,4,4,4,4,4,4,5,5,5,5,5
5,5,6,6,5,5,5,5,5,5,5,5,5,5,5,5,5,5
5,5,5,5,5,5,5,5,5,5,5,5,5,5,5,5,5,5
5,5,5,5,5,5,5,5,5,5,5,5,5,5,5,5,5,5
endlayer

layer
5,5,5,5,5,4,4,4,4,4,4,4,4,5,5,5,5,5
5,5,5,5,5,4,4,4,4,4,4,4,4,5,5,5,5,5
5,5,5,5,5,4,4,6,6,6,6,6,4,5,5,5,5,5
5,5,5,5,5,4,4,6,6,6,6,4,4,5,5,5,5,5
5,5,5,5,5,4,4,6,6,6,6,4,4,5,5,5,5,5
5,5,5,5,5,4,4,6,6,6,6,4,4,5,5,5,5,5
5,5,5,5,5,4,4,4,4,4,4,4,4,5,5,5,5,5
5,5,6,6,5,4,4,4,4,4,4,4,4,5,5,5,5,5
5,5,6,6,5,5,5,5,5,5,5,5,5,5,5,5,5,5
5,5,5,5,5,5,5,5,5,5,5,5,5,5,5,5,5,5
5,5,5,5,5,5,5,5,5,5,5,5,5,5,5,5,5,5
endlayer

layer
5,5,5,5,5,4,4,4,4,4,4,4,4,5,5,5,5,5
5,5,5,5,5,4,4,4,4,4,4,4,4,5,5,5,5,5
5,5,5,5,5,4,4,6,6,6,6,6,4,5,5,5,5,5
5,5,5,5,5,4,4,6,6,6,6,4,4,5,5,5,5,5
5,5,5,5,5,4,4,6,6,6,6,4,4,5,5,5,5,5
5,5,5,5,5,4,4,6,6,6,6,4,4,5,5,5,5,5
5,5,5,5,5,4,4,4,4,4,4,4,4,5,5,5,5,5
5,5,6,6,5,4,4,3,4,4,3,4,4,5,5,5,5,5
5,5,6,6,5,5,5,5,5,5,5,5,5,5,5,5,5,5
5,5,5,5,5,5,5,5,5,5,5,5,5,5,5,5,5,5
5,5,5,5,5,5,5,5,5,5,5,5,5,5,5,5,5,5
endlayer

layer
5,5,5,5,5,4,4,4,4,4,4,4,4,5,5,5,5,5
5,5,5,5,5,4,4,4,4,4,4,4,4,5,5,5,5,5
5,5,5,5,5,4,4,6,6,6,6,6,4,5,5,5,5,5
5,5,5,5,5,4,4,6,6,6,6,4,4,5,5,5,5,5
5,5,5,5,5,4,4,6,6,6,6,4,4,5,5,5,5,5
5,5,5,5,5,4,4,6,6,6,6,4,4,5,5,5,5,5
5,5,5,5,5,4,4,4,4,4,4,4,4,5,5,5,5,5
5,5,6,6,5,4,4,4,4,4,4,4,4,5,5,5,5,5
5,5,6,6,5,5,5,5,5,5,5,5,5,5,5,5,5,5
5,5,5,5,5,5,5,5,5,5,5,5,5,5,5,5,5,5
5,5,5,5,5,5,5,5,5,5,5,5,5,5,5,5,5,5
endlayer

layer
5,5,5,5,5,4,4,4,4,4,4,4,4,5,5,5,5,5
5,5,5,5,5,4,4,4,4,4,4,4,4,5,5,5,5,5
5,5,5,5,5,4,4,6,6,6,6,6,4,5,5,5,5,5
5,5,5,5,5,4,4,6,6,6,6,4,4,5,5,5,5,5
5,5,5,5,5,4,4,6,6,6,6,4,4,5,5,5,5,5
5,5,5,5,5,4,4,6,6,6,6,4,4,5,5,5,5,5
5,5,5,5,5,4,4,4,4,4,4,4,4,5,5,5,5,5
5,5,6,6,5,4,4,4,4,4,4,4,4,5,5,5,5,5
5,5,6,6,5,5,5,5,5,5,5,5,5,5,5,5,5,5
5,5,5,5,5,5,5,5,5,5,5,5,5,5,5,5,5,5
5,5,5,5,5,5,5,5,5,5,5,5,5,5,5,5,5,5
endlayer

layer
5,5,5,5,5,4,4,4,4,4,4,4,4,5,5,5,5,5
5,5,5,5,5,4,4,4,4,4,4,4,4,5,5,5,5,5
5,5,5,5,5,4,4,6,6,6,6,6,4,5,5,5,5,5
5,5,5,5,5,4,4,6,6,6,6,4,4,5,5,5,5,5
5,5,5,5,5,4,4,6,6,6,6,4,4,5,5,5,5,5
5,5,5,5,5,4,4,6,6,6,6,4,4,5,5,5,5,5
5,5,5,5,5,4,4,4,4,4,4,4,4,5,5,5,5,5
5,5,6,6,5,4,4,4,4,4,4,4,4,5,5,5,5,5
5,5,6,6,5,5,5,5,5,5,5,5,5,5,5,5,5,5
5,5,5,5,5,5,5,5,5,5,5,5,5,5,5,5,5,5
5,5,5,5,5,5,5,5,5,5,5,5,5,5,5,5,5,5
endlayer

layer
5,5,5,5,5,4,4,4,4,4,4,4,4,5,5,5,5,5
5,5,5,5,5,4,4,4,4,4,4,4,4,5,5,5,5,5
5,5,5,5,5,4,4,6,6,6,6,6,4,5,5,5,5,5
5,5,5,5,5,4,4,6,6,6,6,4,4,5,5,5,5,5
5,5,5,5,5,4,4,6,6,6,6,4,4,5,5,5,5,5
5,5,5,5,5,4,4,6,6,6,6,4,4,5,5,5,5,5
5,5,5,5,5,4,4,4,4,4,4,4,4,5,5,5,5,5
5,5,6,6,5,4,4,4,4,4,4,4,4,5,5,5,5,5
5,5,6,6,5,5,5,5,5,5,5,5,5,5,5,5,5,5
5,5,5,5,5,5,5,5,5,5,5,5,5,5,5,5,5,5
5,5,5,5,5,5,5,5,5,5,5,5,5,5,5,5,5,5
endlayer

layer
5,5,5,5,5,5,5,5,5,5,5,5,5,5,5,5,5,5
5,5,5,5,5,5,5,5,5,5,5,5,5,5,5,5,5,5
5,5,5,5,5,5,5,5,5,5,5,5,5,5,5,5,5,5
5,5,5,5,5,5,5,5,5,5,5,5,5,5,5,5,5,5
5,5,5,5,5,5,5,5,5,5,5,5,5,5,5,5,5,5
5,5,5,5,5,5,5,5,5,5,5,5,5,5,5,5,5,5
5,5,5,5,5,5,5,5,5,5,5,5,5,5,5,5,5,5
5,5,6,6,5,5,5,5,5,5,5,5,5,5,5,5,5,5
5,5,6,6,5,5,5,5,5,5,5,5,5,5,5,5,5,5
5,5,5,5,5,5,5,5,5,5,5,5,5,5,5,5,5,5
5,5,5,5,5,5,5,5,5,5,5,5,5,5,5,5,5,5
endlayer

layer
5,5,5,5,5,5,5,5,5,5,5,5,5,5,5,5,5,5
5,5,5,5,5,5,5,5,5,5,5,5,5,5,5,5,5,5
5,5,5,5,5,5,5,5,5,5,5,5,5,5,5,5,5,5
5,5,5,5,5,5,5,5,5,5,5,5,5,5,5,5,5,5
5,5,5,5,5,5,5,5,5,5,5,5,5,5,5,5,5,5
5,5,5,5,5,5,5,5,5,5,5,5,5,5,5,5,5,5
5,5,7,7,5,5,5,5,5,5,5,5,5,5,5,5,5,5
5,7,6,6,7,5,5,5,5,5,5,5,5,5,5,5,5,5
5,7,6,6,7,5,5,5,5,5,5,5,5,5,5,5,5,5
5,5,7,7,5,5,5,5,5,5,5,5,5,5,5,5,5,5
5,5,5,5,5,5,5,5,5,5,5,5,5,5,5,5,5,5
endlayer

layer
5,5,5,5,5,5,5,5,5,5,5,5,5,5,5,5,5,5
5,5,5,5,5,5,5,5,5,5,5,5,5,5,5,5,5,5
5,5,5,5,5,5,5,5,5,5,5,5,5,5,5,5,5,5
5,5,5,5,5,5,5,5,5,5,5,5,5,5,5,5,5,5
5,5,5,5,5,5,5,5,5,5,5,5,5,5,5,5,5,5
5,5,5,5,5,5,5,5,5,5,5,5,5,5,5,5,5,5
5,5,7,7,5,5,5,5,5,5,5,5,5,5,5,5,5,5
5,7,6,6,7,5,5,5,5,5,5,5,5,5,5,5,5,5
5,7,6,6,7,5,5,5,5,5,5,5,5,5,5,5,5,5
5,5,7,7,5,5,5,5,5,5,5,5,5,5,5,5,5,5
5,5,5,5,5,5,5,5,5,5,5,5,5,5,5,5,5,5
endlayer

layer
5,5,5,5,5,5,5,5,5,5,5,5,5,5,5,5,5,5
5,5,5,5,5,5,5,5,5,5,5,5,5,5,5,5,5,5
5,5,5,5,5,5,5,5,5,5,5,5,5,5,5,5,5,5
5,5,5,5,5,5,5,5,5,5,5,5,5,5,5,5,5,5
5,5,5,5,5,5,5,5,5,5,5,5,5,5,5,5,5,5
5,5,5,5,5,5,5,5,5,5,5,5,5,5,5,5,5,5
5,5,7,7,5,5,5,5,5,5,5,5,5,5,5,5,5,5
5,7,6,6,7,5,5,5,5,5,5,5,5,5,5,5,5,5
5,7,6,6,7,5,5,5,5,5,5,5,5,5,5,5,5,5
5,5,7,7,5,5,5,5,5,5,5,5,5,5,5,5,5,5
5,5,5,5,5,5,5,5,5,5,5,5,5,5,5,5,5,5
endlayer

layer
5,5,5,5,5,5,5,5,5,5,5,5,5,5,5,5,5,5
5,5,5,5,5,5,5,5,5,5,5,5,5,5,5,5,5,5
5,5,5,5,5,5,5,5,5,5,5,5,5,5,5,5,5,5
5,5,5,5,5,5,5,5,5,5,5,5,5,5,5,5,5,5
5,5,5,5,5,5,5,5,5,5,5,5,5,5,5,5,5,5
5,5,5,5,5,5,5,5,5,5,5,5,5,5,5,5,5,5
5,5,5,5,5,5,5,5,5,5,5,5,5,5,5,5,5,5
5,5,3,3,5,5,5,5,5,5,5,5,5,5,5,5,5,5
5,5,3,3,5,5,5,5,5,5,5,5,5,5,5,5,5,5
5,5,5,5,5,5,5,5,5,5,5,5,5,5,5,5,5,5
5,5,5,5,5,5,5,5,5,5,5,5,5,5,5,5,5,5
endlayer

layer
5,5,5,5,5,5,5,5,5,5,5,5,5,5,5,5,5,5
5,5,5,5,5,5,5,5,5,5,5,5,5,5,5,5,5,5
5,5,5,5,5,5,5,5,5,5,5,5,5,5,5,5,5,5
5,5,5,5,5,5,5,5,5,5,5,5,5,5,5,5,5,5
5,5,5,5,5,5,5,5,5,5,5,5,5,5,5,5,5,5
5,5,5,5,5,5,5,5,5,5,5,5,5,5,5,5,5,5
5,5,5,5,5,5,5,5,5,5,5,5,5,5,5,5,5,5
5,5,3,3,5,5,5,5,5,5,5,5,5,5,5,5,5,5
5,5,3,3,5,5,5,5,5,5,5,5,5,5,5,5,5,5
5,5,5,5,5,5,5,5,5,5,5,5,5,5,5,5,5,5
5,5,5,5,5,5,5,5,5,5,5,5,5,5,5,5,5,5
endlayer

layer
5,5,5,5,5,5,5,5,5,5,5,5,5,5,5,5,5,5
5,5,5,5,5,5,5,5,5,5,5,5,5,5,5,5,5,5
5,5,5,5,5,5,5,5,5,5,5,5,5,5,5,5,5,5
5,5,5,5,5,5,5,5,5,5,5,5,5,5,5,5,5,5
5,5,5,5,5,5,5,5,5,5,5,5,5,5,5,5,5,5
5,5,5,5,5,5,5,5,5,5,5,5,5,5,5,5,5,5
5,5,5,5,5,5,5,5,5,5,5,5,5,5,5,5,5,5
5,5,3,3,5,5,5,5,5,5,5,5,5,5,5,5,5,5
5,5,3,3,5,5,5,5,5,5,5,5,5,5,5,5,5,5
5,5,5,5,5,5,5,5,5,5,5,5,5,5,5,5,5,5
5,5,5,5,5,5,5,5,5,5,5,5,5,5,5,5,5,5
endlayer

layer
5,5,5,5,5,5,5,5,5,5,5,5,5,5,5,5,5,5
5,5,5,5,5,5,5,5,5,5,5,5,5,5,5,5,5,5
5,5,5,5,5,5,5,5,5,5,5,5,5,5,5,5,5,5
5,5,5,5,5,5,5,5,5,5,5,5,5,5,5,5,5,5
5,5,5,5,5,5,5,5,5,5,5,5,5,5,5,5,5,5
5,5,5,5,5,5,5,5,5,5,5,5,5,5,5,5,5,5
5,5,5,5,5,5,5,5,5,5,5,5,5,5,5,5,5,5
5,5,3,3,5,5,5,5,5,5,5,5,5,5,5,5,5,5
5,5,3,3,5,5,5,5,5,5,5,5,5,5,5,5,5,5
5,5,5,5,5,5,5,5,5,5,5,5,5,5,5,5,5,5
5,5,5,5,5,5,5,5,5,5,5,5,5,5,5,5,5,5
endlayer