# Converted from schematic
# THIS TEMPLATE USES DEFAULTS!  Please edit for corrections.
# If you need help, consult template_rules.txt
weight=20
embed_into_distance=1
unacceptable_target_blocks=flowing_water,water,flowing_lava,lava,Natura:Cloud
dimensions=8,12,11
allowable_overhang=0
max_leveling=2
leveling_buffer=1
preserve_water=0
preserve_lava=0
preserve_plants=1


rule1=0,100,sandstone
rule2=0,100,stone
rule3=0,100,dirt
rule4=0,100,sandstone-2
rule5=0,100,cobblestone
rule6=0,100,stone_slab
rule7=0,100,stone_slab-3
rule8=0,100,double_stone_slab


layer
5,1,1,1,5,0,0,1,1,1,1
5,2,0,0,0,0,0,0,2,2,1
5,0,0,0,0,0,0,0,2,2,1
5,0,0,0,0,0,0,0,2,2,1
5,2,0,0,0,0,0,0,2,2,1
5,0,0,0,0,0,0,0,2,2,1
5,2,2,0,2,0,2,4,2,2,1
2,2,2,4,2,2,2,4,2,3,2
2,2,2,4,4,4,4,4,2,2,2
2,2,2,2,2,2,2,2,2,2,2
2,2,2,2,2,2,2,2,2,2,2
2,2,2,2,2,2,2,2,2,2,2
endlayer

layer
6,6,6,6,0,0,0,6,6,6,6
6,0,0,0,0,0,0,2,2,2,6
6,0,0,0,0,0,0,0,0,2,6
6,0,0,0,0,0,0,0,0,2,6
0,0,0,0,0,0,0,0,0,2,6
0,0,0,0,0,0,0,0,0,2,6
0,2,0,0,0,0,0,0,0,2,6
6,2,0,0,0,0,0,0,0,2,6
6,2,0,0,0,0,0,0,0,2,6
6,2,0,0,0,0,0,0,0,0,6
0,0,2,2,2,2,0,0,2,0,6
0,0,6,0,6,6,0,0,0,6,6
endlayer

layer
0,0,0,0,0,0,0,0,0,0,0
0,0,0,0,0,0,0,0,0,2,0
0,0,0,0,0,0,0,0,0,2,0
0,0,0,0,0,0,0,0,0,0,0
0,0,0,0,0,0,0,0,0,0,0
0,0,0,0,0,0,0,0,0,2,0
0,2,0,0,0,0,0,0,0,2,0
0,2,0,0,0,0,0,0,0,2,0
0,2,0,0,0,0,0,0,0,2,0
0,2,0,0,0,0,0,0,0,0,0
0,0,2,0,0,2,0,0,2,0,0
0,0,0,0,0,0,0,0,0,0,0
endlayer

layer
0,0,0,0,0,0,0,0,0,0,0
0,0,0,0,0,0,0,0,0,2,0
0,0,0,0,0,0,0,0,0,2,0
0,0,0,0,0,0,0,0,0,0,0
0,0,0,0,0,0,0,0,0,0,0
0,0,0,0,0,0,0,0,0,2,0
0,2,0,0,0,0,0,0,0,2,0
0,2,0,0,0,0,0,0,0,2,0
0,2,0,0,0,0,0,0,0,0,0
0,2,0,0,0,0,0,0,0,0,0
0,0,0,0,0,2,0,0,2,0,0
0,0,0,0,0,0,0,0,0,0,0
endlayer

layer
0,0,0,0,0,0,0,0,0,0,0
0,0,0,0,0,2,2,2,2,2,0
0,0,0,0,0,0,0,0,2,2,0
0,0,0,0,0,0,0,2,2,2,7
0,0,0,0,0,0,0,2,2,2,7
0,2,2,0,0,0,0,2,2,2,0
0,2,2,2,0,2,0,2,2,2,0
0,2,2,2,0,0,0,2,2,2,0
0,2,2,2,2,2,2,2,2,2,0
0,2,2,2,2,0,2,2,2,0,0
0,0,0,2,2,0,0,2,2,0,0
0,0,0,0,0,0,0,0,0,0,0
endlayer

layer
0,0,0,0,0,6,6,6,6,6,0
0,0,0,0,0,0,8,8,8,6,6
0,0,0,0,0,0,0,8,0,8,6
0,0,0,0,0,0,0,8,8,8,6
0,0,0,0,0,0,0,8,8,8,6
6,8,8,8,0,0,8,8,8,8,6
6,8,8,8,8,0,8,8,8,8,6
6,8,8,8,8,8,8,8,8,8,6
6,0,8,8,8,8,8,8,8,8,6
6,8,8,8,8,0,8,8,8,8,6
0,0,8,8,0,0,8,0,8,6,6
0,0,6,6,6,0,6,6,6,6,0
endlayer

layer
0,0,0,0,0,0,0,0,0,0,0
0,0,0,0,0,0,0,0,0,0,0
0,0,0,0,0,0,0,0,0,0,0
0,0,0,0,0,0,0,6,6,0,0
0,0,0,0,0,0,0,0,6,0,0
0,0,6,6,0,0,8,6,6,0,0
0,0,6,6,8,8,8,6,6,0,0
0,0,0,6,0,8,8,6,0,0,0
0,0,6,6,0,8,0,6,6,0,0
0,0,0,6,0,0,6,0,0,0,0
0,0,0,0,0,0,0,0,0,0,0
0,0,0,0,0,0,0,0,0,0,0
endlayer

layer
0,0,0,0,0,0,0,0,0,0,0
0,0,0,0,0,0,0,0,0,0,0
0,0,0,0,0,0,0,0,0,0,0
0,0,0,0,0,0,0,0,0,0,0
0,0,0,0,0,0,0,0,0,0,0
0,0,0,0,0,0,0,0,0,0,0
0,0,0,0,0,6,0,0,0,0,0
0,0,0,0,0,0,0,0,0,0,0
0,0,0,0,0,0,0,0,0,0,0
0,0,0,0,0,0,0,0,0,0,0
0,0,0,0,0,0,0,0,0,0,0
0,0,0,0,0,0,0,0,0,0,0
endlayer

