weight=10
embed_into_distance=1
unacceptable_target_blocks=flowing_water,water,flowing_lava,lava,Natura:Cloud
dimensions=6,6,5
max_leveling=2
leveling_buffer=1
preserve_water=0
preserve_lava=0
preserve_plants=0

rule1=0,100,preserveBlock
rule2=0,100,gravel
rule3=0,100,cobblestone
rule4=0,100,stone_stairs-1
rule5=0,100,planks
rule6=0,100,glass_pane
rule7=2,100,torch-2
rule8=0,100,log


layer
1,1,1,1,1
1,1,1,1,1
1,1,1,1,1
1,1,1,1,1
1,1,1,1,1
2,2,2,2,2
endlayer

layer
3,3,3,3,3
3,3,3,3,3
3,3,3,3,3
3,3,3,3,3
3,3,3,3,3
0,0,4,0,0
endlayer

layer
3,5,5,5,3
5,0,0,0,5
5,0,0,0,5
5,0,0,0,5
3,5,0,5,3
0,0,0,0,0
endlayer

layer
3,5,6,5,3
5,0,0,0,5
6,0,0,0,6
5,0,0,0,5
3,5,0,5,3
0,0,0,0,0
endlayer

layer
3,5,5,5,3
5,0,0,0,5
5,0,0,0,5
5,0,7,0,5
3,5,5,5,3
0,0,0,0,0
endlayer

layer
8,8,8,8,8
8,5,5,5,8
8,5,5,5,8
8,5,5,5,8
8,8,8,8,8
0,0,0,0,0
endlayer

