weight=20
embed_into_distance=11
unacceptable_target_blocks=flowing_water,water,flowing_lava,lava,Natura:Cloud
dimensions=16,6,6
max_leveling=2
leveling_buffer=0
preserve_water=0
preserve_lava=0
preserve_plants=0


rule1=0,100,preserveBlock
rule2=0,100,cobblestone
rule3=0,100,water
rule4=0,100,gravel
rule5=0,100,fence


layer
1,1,1,1,1,1
1,2,2,2,2,1
1,2,2,2,2,1
1,2,2,2,2,1
1,2,2,2,2,1
1,1,1,1,1,1
endlayer

layer
1,1,1,1,1,1
1,2,2,2,2,1
1,2,3,3,2,1
1,2,3,3,2,1
1,2,2,2,2,1
1,1,1,1,1,1
endlayer

layer
1,1,1,1,1,1
1,2,2,2,2,1
1,2,3,3,2,1
1,2,3,3,2,1
1,2,2,2,2,1
1,1,1,1,1,1
endlayer

layer
1,1,1,1,1,1
1,2,2,2,2,1
1,2,3,3,2,1
1,2,3,3,2,1
1,2,2,2,2,1
1,1,1,1,1,1
endlayer

layer
1,1,1,1,1,1
1,2,2,2,2,1
1,2,3,3,2,1
1,2,3,3,2,1
1,2,2,2,2,1
1,1,1,1,1,1
endlayer

layer
1,1,1,1,1,1
1,2,2,2,2,1
1,2,3,3,2,1
1,2,3,3,2,1
1,2,2,2,2,1
1,1,1,1,1,1
endlayer

layer
1,1,1,1,1,1
1,2,2,2,2,1
1,2,3,3,2,1
1,2,3,3,2,1
1,2,2,2,2,1
1,1,1,1,1,1
endlayer

layer
1,1,1,1,1,1
1,2,2,2,2,1
1,2,3,3,2,1
1,2,3,3,2,1
1,2,2,2,2,1
1,1,1,1,1,1
endlayer

layer
1,1,1,1,1,1
1,2,2,2,2,1
1,2,3,3,2,1
1,2,3,3,2,1
1,2,2,2,2,1
1,1,1,1,1,1
endlayer

layer
4,4,4,4,4,4
4,2,2,2,2,4
4,2,3,3,2,4
4,2,3,3,2,4
4,2,2,2,2,4
4,4,4,4,4,4
endlayer

layer
4,4,4,4,4,4
4,2,2,2,2,4
4,2,3,3,2,4
4,2,3,3,2,4
4,2,2,2,2,4
4,4,4,4,4,4
endlayer

layer
4,4,4,4,4,4
4,2,2,2,2,4
4,2,3,3,2,4
4,2,3,3,2,4
4,2,2,2,2,4
4,4,4,4,4,4
endlayer

layer
0,0,0,0,0,0
0,2,2,2,2,0
0,2,0,0,2,0
0,2,0,0,2,0
0,2,2,2,2,0
0,0,0,0,0,0
endlayer

layer
0,0,0,0,0,0
0,5,0,0,5,0
0,0,0,0,0,0
0,0,0,0,0,0
0,5,0,0,5,0
0,0,0,0,0,0
endlayer

layer
0,0,0,0,0,0
0,5,0,0,5,0
0,0,0,0,0,0
0,0,0,0,0,0
0,5,0,0,5,0
0,0,0,0,0,0
endlayer

layer
0,0,0,0,0,0
0,2,2,2,2,0
0,2,2,2,2,0
0,2,2,2,2,0
0,2,2,2,2,0
0,0,0,0,0,0
endlayer

