weight=10
embed_into_distance=1
unacceptable_target_blocks=flowing_water,water,flowing_lava,lava,Natura:Cloud
dimensions=7,12,9
max_leveling=2
leveling_buffer=1
preserve_water=0
preserve_lava=0
preserve_plants=0


rule1=0,100,preserveBlock
rule2=0,100,cobblestone
rule3=0,100,gravel
rule4=0,100,planks
rule5=0,100,dirt
rule6=0,100,double_stone_slab
rule7=0,100,oak_stairs-3
rule8=0,100,fence
rule9=0,100,oak_stairs-1
rule10=0,100,wooden_door-2
rule11=0,100,log
rule12=0,100,glass_pane
rule13=0,100,wooden_pressure_plate
rule14=0,100,wooden_door-8
rule15=0,100,oak_stairs
rule16=2,100,torch-2
rule17=2,100,torch-1


layer
5,5,5,5,5,5,5,1,1
5,5,5,5,5,5,5,1,1
5,5,5,5,5,5,5,1,1
5,5,5,5,5,5,5,1,1
5,5,2,5,5,5,5,1,1
2,2,2,2,2,2,2,2,2
2,4,4,4,4,4,4,4,2
2,6,6,6,4,4,4,4,2
2,6,6,6,4,4,4,4,2
2,6,6,6,4,4,4,4,2
2,2,2,2,2,2,2,2,2
3,3,3,3,3,3,3,3,3
endlayer

layer
8,8,8,8,8,8,8,0,0
8,0,0,0,0,0,8,0,0
8,0,0,0,0,0,8,0,0
8,0,0,0,0,0,8,0,0
8,0,0,0,0,0,8,0,0
2,2,10,2,2,2,2,2,2
2,0,0,0,0,0,9,4,2
2,0,0,0,0,0,8,7,2
2,0,6,0,0,0,0,0,2
2,0,6,0,0,0,0,0,2
2,2,2,2,2,2,10,2,2
0,0,0,0,0,0,0,0,0
endlayer

layer
0,0,0,0,0,0,0,0,0
0,0,0,0,0,0,0,0,0
0,0,0,0,0,0,0,0,0
0,0,0,0,0,0,0,0,0
0,0,0,0,0,0,0,0,0
2,4,14,4,4,12,12,4,2
11,0,0,0,0,0,0,0,11
12,0,0,0,0,0,13,0,12
12,0,0,0,0,0,0,0,12
11,0,0,0,0,0,0,0,11
2,4,4,12,4,4,14,4,2
0,0,0,0,0,0,0,0,0
endlayer

layer
0,0,0,0,0,0,0,0,0
0,0,0,0,0,0,0,0,0
0,0,0,0,0,0,0,0,0
0,0,0,0,0,0,0,0,0
15,15,15,15,15,15,15,15,15
2,4,4,4,4,4,4,4,2
2,0,17,0,0,0,0,0,2
2,0,0,0,0,0,0,0,2
2,0,0,0,0,0,0,0,2
2,0,0,0,0,0,16,0,2
2,4,4,4,4,4,4,4,2
9,9,9,9,9,9,9,9,9
endlayer

layer
0,0,0,0,0,0,0,0,0
0,0,0,0,0,0,0,0,0
0,0,0,0,0,0,0,0,0
0,0,0,0,0,0,0,0,0
0,0,0,0,0,0,0,0,0
15,15,15,15,15,15,15,15,15
4,4,4,4,4,4,4,4,4
4,0,0,0,0,0,0,0,4
4,0,0,0,0,0,0,0,4
4,4,4,4,4,4,4,4,4
9,9,9,9,9,9,9,9,9
0,0,0,0,0,0,0,0,0
endlayer

layer
0,0,0,0,0,0,0,0,0
0,0,0,0,0,0,0,0,0
0,0,0,0,0,0,0,0,0
0,0,0,0,0,0,0,0,0
0,0,0,0,0,0,0,0,0
0,0,0,0,0,0,0,0,0
15,15,15,15,15,15,15,15,15
4,4,4,4,4,4,4,4,4
4,4,4,4,4,4,4,4,4
9,9,9,9,9,9,9,9,9
0,0,0,0,0,0,0,0,0
0,0,0,0,0,0,0,0,0
endlayer

layer
0,0,0,0,0,0,0,0,0
0,0,0,0,0,0,0,0,0
0,0,0,0,0,0,0,0,0
0,0,0,0,0,0,0,0,0
0,0,0,0,0,0,0,0,0
0,0,0,0,0,0,0,0,0
0,0,0,0,0,0,0,0,0
15,15,15,15,15,15,15,15,15
9,9,9,9,9,9,9,9,9
0,0,0,0,0,0,0,0,0
0,0,0,0,0,0,0,0,0
0,0,0,0,0,0,0,0,0
endlayer

