weight=20
embed_into_distance=1
unacceptable_target_blocks=flowing_water,water,flowing_lava,lava,Natura:Cloud
dimensions=7,8,10
max_leveling=2
leveling_buffer=1
preserve_water=0
preserve_lava=0
preserve_plants=1


rule1=0,100,preserveBlock
rule2=0,90,cobblestone,cobblestone,cobblestone,mossy_cobblestone,monster_egg-1
rule3=0,50,stone_stairs-1
rule4=0,50,cobblestone,cobblestone,cobblestone,mossy_cobblestone,monster_egg-1
rule5=0,100,double_stone_slab
rule6=0,80,planks
rule7=0,80,log
rule8=0,50,iron_bars
rule9=0,50,furnace-5
rule10=0,10,glass_pane
rule11=1,80,stone_slab


layer
1,1,1,1,1,1,1,1,1,1
1,1,1,1,1,1,1,1,1,1
1,1,1,1,1,1,1,1,1,1
1,1,1,1,1,1,1,1,1,1
1,1,1,1,1,1,1,1,1,1
1,1,1,1,1,1,1,1,1,1
1,1,1,1,1,1,1,1,1,1
1,1,1,1,1,1,1,1,1,1
endlayer

layer
2,2,2,2,2,2,2,2,2,2
2,2,2,2,2,2,2,2,2,2
2,2,2,2,2,2,2,2,2,2
2,2,2,2,2,2,2,2,2,2
2,2,2,2,2,2,2,2,2,2
2,2,2,2,2,2,2,2,2,2
2,2,2,2,2,2,2,2,2,2
0,0,0,0,0,0,3,3,3,0
endlayer

layer
7,6,6,6,6,6,2,2,2,2
6,0,0,0,0,0,2,0,0,2
6,0,0,0,0,0,2,2,2,2
6,0,0,0,6,6,2,0,0,0
6,0,0,6,0,0,0,0,4,4
6,0,0,0,0,0,4,4,5,4
7,6,6,7,0,4,4,4,4,4
0,0,0,0,0,0,0,0,0,0
endlayer

layer
7,6,10,6,10,6,2,2,2,2
6,0,0,0,0,0,2,0,0,8
10,0,0,0,0,0,2,0,0,8
6,0,0,0,6,6,9,0,0,0
10,0,0,6,0,0,0,0,0,0
6,0,0,0,0,0,0,0,4,0
7,6,6,7,0,0,0,0,0,0
0,0,0,0,0,0,0,0,0,0
endlayer

layer
7,6,6,6,6,6,2,2,2,2
6,0,0,0,0,0,2,2,2,2
6,0,0,0,0,0,2,2,2,2
6,0,0,0,6,6,9,0,0,0
6,0,0,6,0,0,0,0,0,0
6,0,0,6,0,0,0,0,0,0
7,6,6,7,0,0,0,0,0,0
0,0,0,0,0,0,0,0,0,0
endlayer

layer
7,4,4,4,4,4,4,4,4,4
4,4,4,4,4,4,4,4,4,4
4,4,4,4,4,4,4,4,4,4
4,4,4,4,4,4,4,4,4,4
4,4,4,4,4,4,4,4,0,0
4,4,4,4,4,4,0,0,0,0
7,4,4,7,4,0,0,0,0,0
0,0,0,0,0,0,0,0,0,0
endlayer

layer
11,11,11,11,11,11,11,11,11,11
11,0,0,0,0,0,0,0,0,11
11,0,0,0,0,0,0,0,0,11
11,0,0,0,0,0,0,0,0,11
11,0,0,0,0,0,0,0,0,0
11,0,0,0,0,0,0,0,0,0
11,11,11,11,11,0,0,0,0,0
0,0,0,0,0,0,0,0,0,0
endlayer

