weight=20
embed_into_distance=1
unacceptable_target_blocks=flowing_water,water,flowing_lava,lava,Natura:Cloud
dimensions=6,6,5
max_leveling=2
leveling_buffer=1
preserve_water=0
preserve_lava=0
preserve_plants=1

rule1=0,100,preserveBlock
rule2=0,90,cobblestone,cobblestone,cobblestone,cobblestone,mossy_cobblestone,monster_egg-1
rule3=0,50,stone_stairs-1
rule4=0,90,planks
rule5=0,10,glass_pane
rule6=0,60,log
rule7=2,50,planks


layer
1,1,1,1,1
1,1,1,1,1
1,1,1,1,1
1,1,1,1,1
1,1,1,1,1
1,1,1,1,1
endlayer

layer
2,2,2,2,2
2,2,2,2,2
2,2,2,2,2
2,2,2,2,2
2,2,2,2,2
0,0,3,0,0
endlayer

layer
2,4,4,4,2
4,0,0,0,4
4,0,0,0,4
4,0,0,0,4
2,4,0,4,2
0,0,0,0,0
endlayer

layer
2,4,5,4,2
4,0,0,0,4
5,0,0,0,5
4,0,0,0,4
2,4,0,4,2
0,0,0,0,0
endlayer

layer
2,4,4,4,2
4,0,0,0,4
4,0,0,0,4
4,0,0,0,4
2,4,4,4,2
0,0,0,0,0
endlayer

layer
6,6,6,6,6
6,7,7,7,6
6,7,7,7,6
6,7,7,7,6
6,6,6,6,6
0,0,0,0,0
endlayer

