weight=10
embed_into_distance=1
unacceptable_target_blocks=flowing_water,water,flowing_lava,lava,Natura:Cloud
dimensions=9,8,9
max_leveling=2
leveling_buffer=1
preserve_water=0
preserve_lava=0
preserve_plants=0


rule1=0,100,preserveBlock
rule2=0,100,cobblestone
rule3=0,100,gravel
rule4=0,100,planks
rule5=0,100,oak_stairs-3
rule6=0,100,crafting_table
rule7=0,100,oak_stairs-1
rule8=0,100,fence
rule9=0,100,wooden_door
rule10=0,100,glass_pane
rule11=0,100,wooden_pressure_plate
rule12=0,100,wooden_door-8
rule13=0,100,bookshelf
rule14=0,100,oak_stairs


layer
1,1,1,1,1,1,1,1,1
2,2,2,2,2,2,2,2,2
2,2,2,2,2,2,2,2,2
2,2,2,2,2,2,2,2,2
2,2,2,2,2,2,2,2,2
2,2,2,2,2,2,2,2,2
2,2,2,2,2,2,2,2,2
3,3,3,3,3,3,3,3,3
endlayer

layer
0,0,0,0,0,0,0,0,0
2,2,2,2,2,2,2,2,2
2,0,0,7,7,7,7,4,2
2,0,0,0,8,0,8,5,2
2,0,0,0,0,0,0,0,2
2,0,0,0,0,0,0,6,2
2,9,2,2,2,2,2,2,2
0,0,0,0,0,0,0,0,0
endlayer

layer
0,0,0,0,0,0,0,0,0
2,4,10,10,4,10,10,4,2
4,0,0,0,0,0,0,0,4
10,0,0,0,11,0,11,0,10
10,0,0,0,0,0,0,0,10
4,0,0,0,0,0,0,0,4
2,12,4,4,10,10,10,4,2
0,0,0,0,0,0,0,0,0
endlayer

layer
0,0,0,0,0,0,0,0,0
2,4,4,4,4,4,4,4,2
4,13,13,13,13,13,13,13,4
10,0,0,0,0,0,0,0,10
10,0,0,0,0,0,0,0,10
4,0,0,0,0,0,0,0,4
2,4,4,4,10,10,10,4,2
0,0,0,0,0,0,0,0,0
endlayer

layer
0,0,0,0,0,0,0,0,0
2,4,4,4,4,4,4,4,2
4,4,4,4,4,4,4,4,4
4,0,0,0,0,0,0,0,4
4,0,0,0,0,0,0,0,4
4,4,4,4,4,4,4,4,4
2,4,4,4,4,4,4,4,2
0,0,0,0,0,0,0,0,0
endlayer

layer
14,14,14,14,14,14,14,14,14
2,2,2,2,2,2,2,2,2
2,2,2,2,2,2,2,2,2
2,2,2,2,2,2,2,2,2
2,2,2,2,2,2,2,2,2
2,2,2,2,2,2,2,2,2
2,2,2,2,2,2,2,2,2
7,7,7,7,7,7,7,7,7
endlayer

layer
0,0,0,0,0,0,0,0,0
14,14,14,14,14,14,14,14,14
2,2,2,2,2,2,2,2,2
2,2,2,2,2,2,2,2,2
2,2,2,2,2,2,2,2,2
2,2,2,2,2,2,2,2,2
7,7,7,7,7,7,7,7,7
0,0,0,0,0,0,0,0,0
endlayer

layer
0,0,0,0,0,0,0,0,0
0,0,0,0,0,0,0,0,0
14,14,14,14,14,14,14,14,14
2,2,2,2,2,2,2,2,2
2,2,2,2,2,2,2,2,2
7,7,7,7,7,7,7,7,7
0,0,0,0,0,0,0,0,0
0,0,0,0,0,0,0,0,0
endlayer

layer
0,0,0,0,0,0,0,0,0
0,0,0,0,0,0,0,0,0
0,0,0,0,0,0,0,0,0
14,14,14,14,14,14,14,14,14
7,7,7,7,7,7,7,7,7
0,0,0,0,0,0,0,0,0
0,0,0,0,0,0,0,0,0
0,0,0,0,0,0,0,0,0
endlayer

