weight=10
embed_into_distance=1
unacceptable_target_blocks=flowing_water,water,flowing_lava,lava,Natura:Cloud
dimensions=7,8,10
max_leveling=2
leveling_buffer=1
preserve_water=0
preserve_lava=0
preserve_plants=0


rule1=0,100,preserveBlock
rule2=0,100,gravel
rule3=0,100,cobblestone
rule4=0,100,stone_stairs-1
rule5=0,100,fence
rule6=0,100,lava
rule7=0,100,double_stone_slab
rule8=0,100,planks
rule9=0,100,MediumChest
rule10=0,100,log
rule11=0,100,oak_stairs-1
rule12=0,100,oak_stairs-2
rule13=0,100,iron_bars
rule14=0,100,furnace-5
rule15=0,100,glass_pane
rule16=0,100,wooden_pressure_plate
rule17=0,100,stone_slab


layer
1,1,1,1,1,1,1,1,1,1
1,1,1,1,1,1,1,1,1,1
1,1,1,1,1,1,1,1,1,1
1,1,1,1,1,1,1,1,1,1
1,1,1,1,1,1,1,1,1,1
1,1,1,1,1,1,1,1,1,1
1,1,1,1,1,1,1,1,1,1
2,2,2,2,2,2,2,2,2,2
endlayer

layer
3,3,3,3,3,3,3,3,3,3
3,3,3,3,3,3,3,3,3,3
3,3,3,3,3,3,3,3,3,3
3,3,3,3,3,3,3,3,3,3
3,3,3,3,3,3,3,3,3,3
3,3,3,3,3,3,3,3,3,3
3,3,3,3,3,3,3,3,3,3
0,0,0,0,0,0,4,4,4,0
endlayer

layer
10,8,8,8,8,8,3,3,3,3
8,8,11,0,0,9,3,6,6,3
8,12,5,0,0,0,3,3,3,3
8,0,0,0,8,8,3,0,0,0
8,0,0,8,0,0,0,0,0,0
8,0,0,0,0,0,0,0,7,0
10,8,8,10,0,5,0,0,0,5
0,0,0,0,0,0,0,0,0,0
endlayer

layer
10,8,15,8,15,8,3,3,3,3
8,0,0,0,0,0,3,0,0,13
15,0,16,0,0,0,3,0,0,13
8,0,0,0,8,8,14,0,0,0
15,0,0,8,0,0,0,0,0,0
8,0,0,0,0,0,0,0,0,0
10,8,8,10,0,5,0,0,0,5
0,0,0,0,0,0,0,0,0,0
endlayer

layer
10,8,8,8,8,8,3,3,3,3
8,0,0,0,0,0,3,3,3,3
8,0,0,0,0,0,3,3,3,3
8,0,0,0,8,8,14,0,0,0
8,0,0,8,0,0,0,0,0,0
8,0,0,8,0,0,0,0,0,0
10,8,8,10,0,5,0,0,0,5
0,0,0,0,0,0,0,0,0,0
endlayer

layer
10,3,3,3,3,3,3,3,3,3
3,3,3,3,3,3,3,3,3,3
3,3,3,3,3,3,3,3,3,3
3,3,3,3,3,3,3,3,3,3
3,3,3,3,3,3,3,3,3,3
3,3,3,3,3,3,3,3,3,3
10,3,3,10,3,3,3,3,3,3
0,0,0,0,0,0,0,0,0,0
endlayer

layer
17,17,17,17,17,17,17,17,17,17
17,0,0,0,0,0,0,0,0,17
17,0,0,0,0,0,0,0,0,17
17,0,0,0,0,0,0,0,0,17
17,0,0,0,0,0,0,0,0,17
17,0,0,0,0,0,0,0,0,17
17,17,17,17,17,17,17,17,17,17
0,0,0,0,0,0,0,0,0,0
endlayer

