# Author: Gantz
# From: Minecraft Forums

weight=1
uniqueMinDistance=1000
embed_into_distance=1
unacceptable_target_blocks=flowing_water,water,flowing_lava,lava,Natura:Cloud
dimensions=5,5,8
allowable_overhang=2
max_leveling=2
leveling_buffer=1
preserve_water=0
preserve_lava=0
preserve_plants=0

rule1=0,100,obsidian
rule2=0,20,cobblestone
rule3=1,80,cobblestone,cobblestone,mossy_cobblestone
rule4=0,100,preserveBlock,preserveBlock,cobblestone

layer
4,3,4,4,4,4,3,4
3,3,3,3,3,3,3,3
4,3,1,1,1,1,3,4
3,3,3,3,3,3,3,3
4,3,4,4,4,4,3,4
endlayer

layer
0,0,0,0,0,0,0,0
0,3,3,0,0,3,3,0
0,3,1,2,2,1,3,0
0,3,3,0,0,3,3,0
0,0,0,0,0,0,0,0
endlayer

layer
0,0,0,0,0,0,0,0
0,3,0,0,0,0,3,0
0,3,1,0,0,1,3,0
0,3,0,0,0,0,3,0
0,0,0,0,0,0,0,0
endlayer

layer
0,0,0,0,0,0,0,0
0,0,0,0,0,0,0,0
0,3,1,0,0,1,3,0
0,0,0,0,0,0,0,0
0,0,0,0,0,0,0,0
endlayer

layer
0,0,0,0,0,0,0,0
0,0,0,0,0,0,0,0
0,0,1,1,1,1,0,0
0,0,0,0,0,0,0,0
0,0,0,0,0,0,0,0
endlayer