
# Created by Ruins mod version 14.5 Ingame Parser
# authoring Player: Sinhika

weight=20
embed_into_distance=1
acceptable_target_blocks=
unacceptable_target_blocks=flowing_water,water,flowing_lava,lava,Natura:Cloud
dimensions=9,7,7
allowable_overhang=0
max_leveling=1
leveling_buffer=1
preserve_water=0
preserve_lava=0

rule1=0,100,preserveBlock
rule2=0,100,minecraft:stone-0
rule3=0,100,preserveBlock
rule4=0,100,minecraft:stone_stairs-0
rule5=0,100,minecraft:stone_stairs-3
rule6=0,100,minecraft:stone_stairs-2
rule7=0,100,minecraft:cobblestone-0
rule8=0,100,minecraft:stone_stairs-1
rule9=0,100,minecraft:stone_stairs-7
rule10=0,100,minecraft:stone_stairs-6
rule11=0,100,minecraft:stone_stairs-5
rule12=0,100,minecraft:stone_stairs-4
rule13=0,100,minecraft:stone_slab-3

layer
1,1,2,2,2,1,1
1,3,2,2,2,3,1
2,2,2,2,2,2,2
2,2,2,2,2,2,2
2,2,2,2,2,2,2
1,3,2,2,2,3,1
1,1,2,2,2,1,1
endlayer

layer
5,4,0,0,0,4,4
5,7,0,0,0,7,6
0,0,0,0,0,0,0
0,0,0,0,0,0,0
0,0,0,0,0,0,0
5,7,0,0,0,7,6
8,8,0,0,0,8,6
endlayer

layer
0,0,0,0,0,0,0
0,7,10,0,9,7,0
0,11,0,0,0,11,0
0,0,0,0,0,0,0
0,12,0,0,0,12,0
0,7,10,0,9,7,0
0,0,0,0,0,0,0
endlayer

layer
0,0,0,0,0,0,0
0,4,4,4,4,4,0
0,5,7,0,7,6,0
0,5,7,0,0,6,0
0,5,0,0,0,6,0
0,5,8,8,8,6,0
0,0,0,0,0,0,0
endlayer

layer
0,0,0,0,0,0,0
0,0,0,0,0,0,0
0,0,7,7,7,0,0
0,0,7,0,7,0,0
0,0,7,7,7,0,0
0,0,0,0,0,0,0
0,0,0,0,0,0,0
endlayer

layer
0,0,0,0,0,0,0
0,0,0,0,0,0,0
0,0,7,7,7,0,0
0,0,7,0,7,0,0
0,0,7,7,7,0,0
0,0,0,0,0,0,0
0,0,0,0,0,0,0
endlayer

layer
0,0,0,0,0,0,0
0,0,0,0,0,0,0
0,0,7,7,7,0,0
0,0,7,0,7,0,0
0,0,7,7,7,0,0
0,0,0,0,0,0,0
0,0,0,0,0,0,0
endlayer

layer
0,0,0,0,0,0,0
0,0,0,0,0,0,0
0,0,13,7,13,0,0
0,0,7,0,7,0,0
0,0,13,7,13,0,0
0,0,0,0,0,0,0
0,0,0,0,0,0,0
endlayer

layer
0,0,0,0,0,0,0
0,0,0,0,0,0,0
0,0,0,4,0,0,0
0,0,5,0,6,0,0
0,0,0,8,0,0,0
0,0,0,0,0,0,0
0,0,0,0,0,0,0
endlayer

