# Author: Arrrg
# From: Minecraft Forums

weight=1
embed_into_distance=12
acceptable_target_blocks=water
dimensions=30,30,30
allowable_overhang=900
uniqueMinDistance=2000
max_leveling=0
leveling_buffer=0
preserve_water=0
preserve_lava=0
preserve_plants=0

rule1=0,100,preserveBlock
rule2=0,100,dirt
rule3=0,100,log-0
rule4=0,100,mossy_cobblestone
rule5=0,100,planks
rule6=0,100,standing_sign
rule7=0,100,glass
rule8=0,100,fence
rule9=0,100,ladder-5
rule10=0,100,ladder-4
rule11=0,100,ladder-2
rule12=0,100,ladder-3
rule13=2,100,torch-0
rule14=0,100,redstone_torch-1
rule15=0,100,redstone_torch-2
rule16=0,100,redstone_torch-3
rule17=0,100,redstone_torch-4
rule18=0,100,redstone_torch-5

layer
1,1,1,1,1,1,1,1,1,1,1,1,1,1,1,1,1,1,1,1,1,1,1,1,1,1,1,1,1,1
1,1,1,1,1,1,1,1,1,1,1,1,1,1,1,1,1,1,1,1,1,1,1,1,1,1,1,1,1,1
1,1,1,1,1,1,1,1,1,1,1,1,1,1,1,1,1,1,1,1,1,1,1,1,1,1,1,1,1,1
1,1,1,1,1,1,1,1,1,1,1,1,1,1,1,1,1,1,1,1,1,1,1,1,1,1,1,1,1,1
1,1,1,1,1,1,1,1,1,1,1,1,1,1,1,1,1,1,1,1,1,1,1,1,1,1,1,1,1,1
1,1,1,1,1,1,1,1,1,1,1,1,1,1,1,1,1,1,1,1,1,1,1,1,1,1,1,1,1,1
1,1,1,1,1,1,1,1,1,1,1,1,1,1,1,1,1,1,1,1,1,1,1,1,1,1,1,1,1,1
1,1,1,1,1,1,1,1,1,1,1,1,1,1,1,1,1,1,1,1,1,1,1,1,1,1,1,1,1,1
1,1,1,1,1,1,1,1,1,1,1,1,1,1,1,1,1,1,1,1,1,1,1,1,1,1,1,1,1,1
1,1,1,1,1,1,1,1,1,1,1,1,1,1,1,1,1,1,1,1,1,1,1,1,1,1,1,1,1,1
1,1,1,1,1,1,1,1,1,1,1,1,1,1,1,1,1,1,1,1,1,1,1,1,1,1,1,1,1,1
1,1,1,1,1,1,1,1,1,1,1,1,1,1,1,1,1,1,1,1,1,1,1,1,1,1,1,1,1,1
1,1,1,1,1,1,1,1,1,1,1,1,7,7,7,7,7,7,1,1,1,1,1,1,1,1,1,1,1,1
1,1,1,1,1,1,1,1,1,1,1,1,7,7,7,7,7,7,1,1,1,1,1,1,1,1,1,1,1,1
1,1,1,1,1,1,1,1,1,1,1,1,7,7,7,7,7,7,1,1,1,1,1,1,1,1,1,1,1,1
1,1,1,1,1,1,1,1,1,1,1,1,7,7,7,7,7,7,1,1,1,1,1,1,1,1,1,1,1,1
1,1,1,1,1,1,1,1,1,1,1,1,7,7,7,7,7,7,1,1,1,1,1,1,1,1,1,1,1,1
1,1,1,1,1,1,1,1,1,1,1,1,7,7,7,7,7,7,1,1,1,1,1,1,1,1,1,1,1,1
1,1,1,1,1,1,1,1,1,1,1,1,1,1,1,1,1,1,1,1,1,1,1,1,1,1,1,1,1,1
1,1,1,1,1,1,1,1,1,1,1,1,1,1,1,1,1,1,1,1,1,1,1,1,1,1,1,1,1,1
1,1,1,1,1,1,1,1,1,1,1,1,1,1,1,1,1,1,1,1,1,1,1,1,1,1,1,1,1,1
1,1,1,1,1,1,1,1,1,1,1,1,1,1,1,1,1,1,1,1,1,1,1,1,1,1,1,1,1,1
1,1,1,1,1,1,1,1,1,1,1,1,1,1,1,1,1,1,1,1,1,1,1,1,1,1,1,1,1,1
1,1,1,1,1,1,1,1,1,1,1,1,1,1,1,1,1,1,1,1,1,1,1,1,1,1,1,1,1,1
1,1,1,1,1,1,1,1,1,1,1,1,1,1,1,1,1,1,1,1,1,1,1,1,1,1,1,1,1,1
1,1,1,1,1,1,1,1,1,1,1,1,1,1,1,1,1,1,1,1,1,1,1,1,1,1,1,1,1,1
1,1,1,1,1,1,1,1,1,1,1,1,1,1,1,1,1,1,1,1,1,1,1,1,1,1,1,1,1,1
1,1,1,1,1,1,1,1,1,1,1,1,1,1,1,1,1,1,1,1,1,1,1,1,1,1,1,1,1,1
1,1,1,1,1,1,1,1,1,1,1,1,1,1,1,1,1,1,1,1,1,1,1,1,1,1,1,1,1,1
1,1,1,1,1,1,1,1,1,1,1,1,1,1,1,1,1,1,1,1,1,1,1,1,1,1,1,1,1,1
endlayer

layer
1,1,1,1,1,1,1,1,1,1,1,1,1,1,1,1,1,1,1,1,1,1,1,1,1,1,1,1,1,1
1,1,1,1,1,1,1,1,1,1,1,1,1,1,1,1,1,1,1,1,1,1,1,1,1,1,1,1,1,1
1,1,1,1,1,1,1,1,1,1,1,1,1,1,1,1,1,1,1,1,1,1,1,1,1,1,1,1,1,1
1,1,1,1,1,1,1,1,1,1,1,1,1,1,1,1,1,1,1,1,1,1,1,1,1,1,1,1,1,1
1,1,1,1,1,1,1,1,1,1,1,1,1,1,1,1,1,1,1,1,1,1,1,1,1,1,1,1,1,1
1,1,1,1,1,1,1,1,1,1,1,1,1,1,1,1,1,1,1,1,1,1,1,1,1,1,1,1,1,1
1,1,1,1,1,1,1,1,1,1,1,1,1,1,1,1,1,1,1,1,1,1,1,1,1,1,1,1,1,1
1,1,1,1,1,1,1,1,1,1,1,1,1,1,1,1,1,1,1,1,1,1,1,1,1,1,1,1,1,1
1,1,1,1,1,1,1,1,1,1,1,1,1,1,1,1,1,1,1,1,1,1,1,1,1,1,1,1,1,1
1,1,1,1,1,1,1,1,1,1,1,1,7,7,7,7,7,7,1,1,1,1,1,1,1,1,1,1,1,1
1,1,1,1,1,1,1,1,1,1,1,7,7,7,7,7,7,7,7,1,1,1,1,1,1,1,1,1,1,1
1,1,1,1,1,1,1,1,1,1,7,7,7,7,7,7,7,7,7,7,1,1,1,1,1,1,1,1,1,1
1,1,1,1,1,1,1,1,1,7,7,7,0,0,0,0,0,0,7,7,7,1,1,1,1,1,1,1,1,1
1,1,1,1,1,1,1,1,1,7,7,7,0,0,0,0,0,0,7,7,7,1,1,1,1,1,1,1,1,1
1,1,1,1,1,1,1,1,1,7,7,7,0,0,0,0,0,0,7,7,7,1,1,1,1,1,1,1,1,1
1,1,1,1,1,1,1,1,1,7,7,7,0,0,0,0,0,0,7,7,7,1,1,1,1,1,1,1,1,1
1,1,1,1,1,1,1,1,1,7,7,7,0,0,0,0,0,0,7,7,7,1,1,1,1,1,1,1,1,1
1,1,1,1,1,1,1,1,1,7,7,7,0,0,0,0,0,0,7,7,7,1,1,1,1,1,1,1,1,1
1,1,1,1,1,1,1,1,1,1,7,7,7,7,7,7,7,7,7,7,1,1,1,1,1,1,1,1,1,1
1,1,1,1,1,1,1,1,1,1,1,7,7,7,7,7,7,7,7,1,1,1,1,1,1,1,1,1,1,1
1,1,1,1,1,1,1,1,1,1,1,1,7,7,7,7,7,7,1,1,1,1,1,1,1,1,1,1,1,1
1,1,1,1,1,1,1,1,1,1,1,1,1,1,1,1,1,1,1,1,1,1,1,1,1,1,1,1,1,1
1,1,1,1,1,1,1,1,1,1,1,1,1,1,1,1,1,1,1,1,1,1,1,1,1,1,1,1,1,1
1,1,1,1,1,1,1,1,1,1,1,1,1,1,1,1,1,1,1,1,1,1,1,1,1,1,1,1,1,1
1,1,1,1,1,1,1,1,1,1,1,1,1,1,1,1,1,1,1,1,1,1,1,1,1,1,1,1,1,1
1,1,1,1,1,1,1,1,1,1,1,1,1,1,1,1,1,1,1,1,1,1,1,1,1,1,1,1,1,1
1,1,1,1,1,1,1,1,1,1,1,1,1,1,1,1,1,1,1,1,1,1,1,1,1,1,1,1,1,1
1,1,1,1,1,1,1,1,1,1,1,1,1,1,1,1,1,1,1,1,1,1,1,1,1,1,1,1,1,1
1,1,1,1,1,1,1,1,1,1,1,1,1,1,1,1,1,1,1,1,1,1,1,1,1,1,1,1,1,1
1,1,1,1,1,1,1,1,1,1,1,1,1,1,1,1,1,1,1,1,1,1,1,1,1,1,1,1,1,1
endlayer

layer
1,1,1,1,1,1,1,1,1,1,1,1,1,1,1,1,1,1,1,1,1,1,1,1,1,1,1,1,1,1
1,1,1,1,1,1,1,1,1,1,1,1,1,1,1,1,1,1,1,1,1,1,1,1,1,1,1,1,1,1
1,1,1,1,1,1,1,1,1,1,1,1,1,1,1,1,1,1,1,1,1,1,1,1,1,1,1,1,1,1
1,1,1,1,1,1,1,1,1,1,1,1,1,1,1,1,1,1,1,1,1,1,1,1,1,1,1,1,1,1
1,1,1,1,1,1,1,1,1,1,1,1,1,1,1,1,1,1,1,1,1,1,1,1,1,1,1,1,1,1
1,1,1,1,1,1,1,1,1,1,1,1,1,1,1,1,1,1,1,1,1,1,1,1,1,1,1,1,1,1
1,1,1,1,1,1,1,1,1,1,1,1,1,1,1,1,1,1,1,1,1,1,1,1,1,1,1,1,1,1
1,1,1,1,1,1,1,1,1,1,1,1,7,7,7,7,7,7,1,1,1,1,1,1,1,1,1,1,1,1
1,1,1,1,1,1,1,1,1,1,7,7,7,7,7,7,7,7,7,7,1,1,1,1,1,1,1,1,1,1
1,1,1,1,1,1,1,1,1,7,7,7,0,0,0,0,0,0,7,7,7,1,1,1,1,1,1,1,1,1
1,1,1,1,1,1,1,1,7,7,7,0,0,0,0,0,0,0,0,7,7,7,1,1,1,1,1,1,1,1
1,1,1,1,1,1,1,1,7,7,0,0,0,0,0,0,0,0,0,0,7,7,1,1,1,1,1,1,1,1
1,1,1,1,1,1,1,7,7,0,0,0,0,0,0,0,0,0,0,0,0,7,7,1,1,1,1,1,1,1
1,1,1,1,1,1,1,7,7,0,0,0,0,0,0,0,0,0,0,0,0,7,7,1,1,1,1,1,1,1
1,1,1,1,1,1,1,7,7,0,0,0,0,0,0,0,0,0,0,0,0,7,7,1,1,1,1,1,1,1
1,1,1,1,1,1,1,7,7,0,0,0,0,0,0,0,0,0,0,0,0,7,7,1,1,1,1,1,1,1
1,1,1,1,1,1,1,7,7,0,0,0,0,0,0,0,0,0,0,0,0,7,7,1,1,1,1,1,1,1
1,1,1,1,1,1,1,7,7,0,0,0,0,0,0,0,0,0,0,0,0,7,7,1,1,1,1,1,1,1
1,1,1,1,1,1,1,1,7,7,0,0,0,0,0,0,0,0,0,0,7,7,1,1,1,1,1,1,1,1
1,1,1,1,1,1,1,1,7,7,7,0,0,0,0,0,0,0,0,7,7,7,1,1,1,1,1,1,1,1
1,1,1,1,1,1,1,1,1,7,7,7,0,0,0,0,0,0,7,7,7,1,1,1,1,1,1,1,1,1
1,1,1,1,1,1,1,1,1,1,7,7,7,7,7,7,7,7,7,7,1,1,1,1,1,1,1,1,1,1
1,1,1,1,1,1,1,1,1,1,1,1,7,7,7,7,7,7,1,1,1,1,1,1,1,1,1,1,1,1
1,1,1,1,1,1,1,1,1,1,1,1,1,1,1,1,1,1,1,1,1,1,1,1,1,1,1,1,1,1
1,1,1,1,1,1,1,1,1,1,1,1,1,1,1,1,1,1,1,1,1,1,1,1,1,1,1,1,1,1
1,1,1,1,1,1,1,1,1,1,1,1,1,1,1,1,1,1,1,1,1,1,1,1,1,1,1,1,1,1
1,1,1,1,1,1,1,1,1,1,1,1,1,1,1,1,1,1,1,1,1,1,1,1,1,1,1,1,1,1
1,1,1,1,1,1,1,1,1,1,1,1,1,1,1,1,1,1,1,1,1,1,1,1,1,1,1,1,1,1
1,1,1,1,1,1,1,1,1,1,1,1,1,1,1,1,1,1,1,1,1,1,1,1,1,1,1,1,1,1
1,1,1,1,1,1,1,1,1,1,1,1,1,1,1,1,1,1,1,1,1,1,1,1,1,1,1,1,1,1
endlayer

layer
1,1,1,1,1,1,1,1,1,1,1,1,1,1,1,1,1,1,1,1,1,1,1,1,1,1,1,1,1,1
1,1,1,1,1,1,1,1,1,1,1,1,1,1,1,1,1,1,1,1,1,1,1,1,1,1,1,1,1,1
1,1,1,1,1,1,1,1,1,1,1,1,1,1,1,1,1,1,1,1,1,1,1,1,1,1,1,1,1,1
1,1,1,1,1,1,1,1,1,1,1,1,1,1,1,1,1,1,1,1,1,1,1,1,1,1,1,1,1,1
1,1,1,1,1,1,1,1,1,1,1,1,1,1,1,1,1,1,1,1,1,1,1,1,1,1,1,1,1,1
1,1,1,1,1,1,1,1,1,1,1,1,1,1,1,1,1,1,1,1,1,1,1,1,1,1,1,1,1,1
1,1,1,1,1,1,1,1,1,1,1,1,7,7,7,7,7,7,1,1,1,1,1,1,1,1,1,1,1,1
1,1,1,1,1,1,1,1,1,1,7,7,0,0,0,0,0,0,7,7,1,1,1,1,1,1,1,1,1,1
1,1,1,1,1,1,1,1,1,7,0,0,0,0,0,0,0,0,0,0,7,1,1,1,1,1,1,1,1,1
1,1,1,1,1,1,1,1,7,0,0,0,0,0,0,0,0,0,0,0,0,7,1,1,1,1,1,1,1,1
1,1,1,1,1,1,1,7,0,0,0,0,0,0,0,0,0,0,0,0,0,0,7,1,1,1,1,1,1,1
1,1,1,1,1,1,1,7,0,0,0,0,0,0,0,0,0,0,0,0,0,0,7,1,1,1,1,1,1,1
1,1,1,1,1,1,7,0,0,0,0,0,0,0,0,0,0,0,0,0,0,0,0,7,1,1,1,1,1,1
1,1,1,1,1,1,7,0,0,0,0,0,0,0,0,0,0,0,0,0,0,0,0,7,1,1,1,1,1,1
1,1,1,1,1,1,7,0,0,0,0,0,0,0,0,0,0,0,0,0,0,0,0,7,1,1,1,1,1,1
1,1,1,1,1,1,7,0,0,0,0,0,0,0,0,0,0,0,0,0,0,0,0,7,1,1,1,1,1,1
1,1,1,1,1,1,7,0,0,0,0,0,0,0,0,0,0,0,0,0,0,0,0,7,1,1,1,1,1,1
1,1,1,1,1,1,7,0,0,0,0,0,0,0,0,0,0,0,0,0,0,0,0,7,1,1,1,1,1,1
1,1,1,1,1,1,1,7,0,0,0,0,0,0,0,0,0,0,0,0,0,0,7,1,1,1,1,1,1,1
1,1,1,1,1,1,1,7,0,0,0,0,0,0,0,0,0,0,0,0,0,0,7,1,1,1,1,1,1,1
1,1,1,1,1,1,1,1,7,0,0,0,0,0,0,0,0,0,0,0,0,7,1,1,1,1,1,1,1,1
1,1,1,1,1,1,1,1,1,7,0,0,0,0,0,0,0,0,0,0,7,1,1,1,1,1,1,1,1,1
1,1,1,1,1,1,1,1,1,1,7,7,0,0,0,0,0,0,7,7,1,1,1,1,1,1,1,1,1,1
1,1,1,1,1,1,1,1,1,1,1,1,7,7,7,7,7,7,1,1,1,1,1,1,1,1,1,1,1,1
1,1,1,1,1,1,1,1,1,1,1,1,1,1,1,1,1,1,1,1,1,1,1,1,1,1,1,1,1,1
1,1,1,1,1,1,1,1,1,1,1,1,1,1,1,1,1,1,1,1,1,1,1,1,1,1,1,1,1,1
1,1,1,1,1,1,1,1,1,1,1,1,1,1,1,1,1,1,1,1,1,1,1,1,1,1,1,1,1,1
1,1,1,1,1,1,1,1,1,1,1,1,1,1,1,1,1,1,1,1,1,1,1,1,1,1,1,1,1,1
1,1,1,1,1,1,1,1,1,1,1,1,1,1,1,1,1,1,1,1,1,1,1,1,1,1,1,1,1,1
1,1,1,1,1,1,1,1,1,1,1,1,1,1,1,1,1,1,1,1,1,1,1,1,1,1,1,1,1,1
endlayer

layer
1,1,1,1,1,1,1,1,1,1,1,1,1,1,1,1,1,1,1,1,1,1,1,1,1,1,1,1,1,1
1,1,1,1,1,1,1,1,1,1,1,1,1,1,1,1,1,1,1,1,1,1,1,1,1,1,1,1,1,1
1,1,1,1,1,1,1,1,1,1,1,1,1,1,1,1,1,1,1,1,1,1,1,1,1,1,1,1,1,1
1,1,1,1,1,1,1,1,1,1,1,1,1,1,1,1,1,1,1,1,1,1,1,1,1,1,1,1,1,1
1,1,1,1,1,1,1,1,1,1,1,1,1,1,1,1,1,1,1,1,1,1,1,1,1,1,1,1,1,1
1,1,1,1,1,1,1,1,1,1,1,1,7,7,7,7,7,7,1,1,1,1,1,1,1,1,1,1,1,1
1,1,1,1,1,1,1,1,1,1,7,7,0,0,0,0,0,0,7,7,1,1,1,1,1,1,1,1,1,1
1,1,1,1,1,1,1,1,1,7,0,0,0,0,0,0,0,0,0,0,7,1,1,1,1,1,1,1,1,1
1,1,1,1,1,1,1,1,7,0,0,0,0,0,0,0,0,0,0,0,0,7,1,1,1,1,1,1,1,1
1,1,1,1,1,1,1,7,0,0,0,0,0,0,0,0,0,0,0,0,0,0,7,1,1,1,1,1,1,1
1,1,1,1,1,1,7,0,0,0,0,0,0,0,0,0,0,0,0,0,0,0,0,7,1,1,1,1,1,1
1,1,1,1,1,1,7,0,0,0,0,0,0,0,0,0,0,0,0,0,0,0,0,7,1,1,1,1,1,1
1,1,1,1,1,7,0,0,0,0,0,0,0,0,0,0,0,0,0,0,0,0,0,0,7,1,1,1,1,1
1,1,1,1,1,7,0,0,0,0,0,0,0,0,0,0,0,0,0,0,0,0,0,0,7,1,1,1,1,1
1,1,1,1,1,7,0,0,0,0,0,0,0,0,0,0,0,0,0,0,0,0,0,0,7,1,1,1,1,1
1,1,1,1,1,7,0,0,0,0,0,0,0,0,0,0,0,0,0,0,0,0,0,0,7,1,1,1,1,1
1,1,1,1,1,7,0,0,0,0,0,0,0,0,0,0,0,0,0,0,0,0,0,0,7,1,1,1,1,1
1,1,1,1,1,7,0,0,0,0,0,0,0,0,0,0,0,0,0,0,0,0,0,0,7,1,1,1,1,1
1,1,1,1,1,1,7,0,0,0,0,0,0,0,0,0,0,0,0,0,0,0,0,7,1,1,1,1,1,1
1,1,1,1,1,1,7,0,0,0,0,0,0,0,0,0,0,0,0,0,0,0,0,7,1,1,1,1,1,1
1,1,1,1,1,1,1,7,0,0,0,0,0,0,0,0,0,0,0,0,0,0,7,1,1,1,1,1,1,1
1,1,1,1,1,1,1,1,7,0,0,0,0,0,0,0,0,0,0,0,0,7,1,1,1,1,1,1,1,1
1,1,1,1,1,1,1,1,1,7,0,0,0,0,0,0,0,0,0,0,7,1,1,1,1,1,1,1,1,1
1,1,1,1,1,1,1,1,1,1,7,7,0,0,0,0,0,0,7,7,1,1,1,1,1,1,1,1,1,1
1,1,1,1,1,1,1,1,1,1,1,1,7,7,7,7,7,7,1,1,1,1,1,1,1,1,1,1,1,1
1,1,1,1,1,1,1,1,1,1,1,1,1,1,1,1,1,1,1,1,1,1,1,1,1,1,1,1,1,1
1,1,1,1,1,1,1,1,1,1,1,1,1,1,1,1,1,1,1,1,1,1,1,1,1,1,1,1,1,1
1,1,1,1,1,1,1,1,1,1,1,1,1,1,1,1,1,1,1,1,1,1,1,1,1,1,1,1,1,1
1,1,1,1,1,1,1,1,1,1,1,1,1,1,1,1,1,1,1,1,1,1,1,1,1,1,1,1,1,1
1,1,1,1,1,1,1,1,1,1,1,1,1,1,1,1,1,1,1,1,1,1,1,1,1,1,1,1,1,1
endlayer

layer
1,1,1,1,1,1,1,1,1,1,1,1,1,1,1,1,1,1,1,1,1,1,1,1,1,1,1,1,1,1
1,1,1,1,1,1,1,1,1,1,1,1,1,1,1,1,1,1,1,1,1,1,1,1,1,1,1,1,1,1
1,1,1,1,1,1,1,1,1,1,1,1,1,1,1,1,1,1,1,1,1,1,1,1,1,1,1,1,1,1
1,1,1,1,1,1,1,1,1,1,1,1,1,1,1,1,1,1,1,1,1,1,1,1,1,1,1,1,1,1
1,1,1,1,1,1,1,1,1,1,1,1,7,7,7,7,7,7,1,1,1,1,1,1,1,1,1,1,1,1
1,1,1,1,1,1,1,1,1,1,7,7,0,0,0,0,0,0,7,7,1,1,1,1,1,1,1,1,1,1
1,1,1,1,1,1,1,1,7,7,0,0,0,0,0,0,0,0,0,0,7,7,1,1,1,1,1,1,1,1
1,1,1,1,1,1,1,7,7,0,0,0,0,0,0,0,0,0,0,0,0,7,7,1,1,1,1,1,1,1
1,1,1,1,1,1,7,7,0,0,0,0,0,0,0,0,0,0,0,0,0,0,7,7,1,1,1,1,1,1
1,1,1,1,1,1,7,0,0,0,0,0,0,0,0,0,0,0,0,0,0,0,0,7,1,1,1,1,1,1
1,1,1,1,1,7,0,0,0,0,0,0,0,0,0,0,0,0,0,0,0,0,0,0,7,1,1,1,1,1
1,1,1,1,1,7,0,0,0,0,0,0,0,0,0,0,0,0,0,0,0,0,0,0,7,1,1,1,1,1
1,1,1,1,7,0,0,0,0,0,0,0,0,0,0,0,0,0,0,0,0,0,0,0,0,7,1,1,1,1
1,1,1,1,7,0,0,0,0,0,0,0,0,0,0,0,0,0,0,0,0,0,0,0,0,7,1,1,1,1
1,1,1,1,7,0,0,0,0,0,0,0,0,0,0,0,0,0,0,0,0,0,0,0,0,7,1,1,1,1
1,1,1,1,7,0,0,0,0,0,0,0,0,0,0,0,0,0,0,0,0,0,0,0,0,7,1,1,1,1
1,1,1,1,7,0,0,0,0,0,0,0,0,0,0,0,0,0,0,0,0,0,0,0,0,7,1,1,1,1
1,1,1,1,7,0,0,0,0,0,0,0,0,0,0,0,0,0,0,0,0,0,0,0,0,7,1,1,1,1
1,1,1,1,1,7,0,0,0,0,0,0,0,0,0,0,0,0,0,0,0,0,0,0,7,1,1,1,1,1
1,1,1,1,1,7,0,0,0,0,0,0,0,0,0,0,0,0,0,0,0,0,0,0,7,1,1,1,1,1
1,1,1,1,1,1,7,0,0,0,0,0,0,0,0,0,0,0,0,0,0,0,0,7,1,1,1,1,1,1
1,1,1,1,1,1,7,7,0,0,0,0,0,0,0,0,0,0,0,0,0,0,7,7,1,1,1,1,1,1
1,1,1,1,1,1,1,7,7,0,0,0,0,0,0,0,0,0,0,0,0,7,7,1,1,1,1,1,1,1
1,1,1,1,1,1,1,1,7,7,0,0,0,0,0,0,0,0,0,0,7,7,1,1,1,1,1,1,1,1
1,1,1,1,1,1,1,1,1,1,7,7,0,0,0,0,0,0,7,7,1,1,1,1,1,1,1,1,1,1
1,1,1,1,1,1,1,1,1,1,1,1,7,7,7,7,7,7,1,1,1,1,1,1,1,1,1,1,1,1
1,1,1,1,1,1,1,1,1,1,1,1,1,1,1,1,1,1,1,1,1,1,1,1,1,1,1,1,1,1
1,1,1,1,1,1,1,1,1,1,1,1,1,1,1,1,1,1,1,1,1,1,1,1,1,1,1,1,1,1
1,1,1,1,1,1,1,1,1,1,1,1,1,1,1,1,1,1,1,1,1,1,1,1,1,1,1,1,1,1
1,1,1,1,1,1,1,1,1,1,1,1,1,1,1,1,1,1,1,1,1,1,1,1,1,1,1,1,1,1
endlayer

layer
1,1,1,1,1,1,1,1,1,1,1,1,1,1,1,1,1,1,1,1,1,1,1,1,1,1,1,1,1,1
1,1,1,1,1,1,1,1,1,1,1,1,1,1,1,1,1,1,1,1,1,1,1,1,1,1,1,1,1,1
1,1,1,1,1,1,1,1,1,1,1,1,1,1,1,1,1,1,1,1,1,1,1,1,1,1,1,1,1,1
1,1,1,1,1,1,1,1,1,1,1,1,7,7,7,7,7,7,1,1,1,1,1,1,1,1,1,1,1,1
1,1,1,1,1,1,1,1,1,7,7,7,0,0,0,0,0,0,7,7,7,1,1,1,1,1,1,1,1,1
1,1,1,1,1,1,1,7,7,7,0,0,0,0,0,0,0,0,0,0,7,7,7,1,1,1,1,1,1,1
1,1,1,1,1,1,7,7,0,0,0,0,0,0,0,0,0,0,0,0,0,0,7,7,1,1,1,1,1,1
1,1,1,1,1,7,7,0,0,0,0,0,0,0,0,0,0,0,0,0,0,0,0,7,7,1,1,1,1,1
1,1,1,1,1,7,0,0,0,0,0,0,0,0,0,0,0,0,0,0,0,0,0,0,7,1,1,1,1,1
1,1,1,1,7,7,0,0,0,0,0,0,0,0,0,0,0,0,0,0,0,0,0,0,7,7,1,1,1,1
1,1,1,1,7,0,0,0,0,0,0,0,0,0,0,0,0,0,0,0,0,0,0,0,0,7,1,1,1,1
1,1,1,1,7,0,0,0,0,0,0,0,0,0,0,0,0,0,0,0,0,0,0,0,0,7,1,1,1,1
1,1,1,7,0,0,0,0,0,0,0,0,0,0,0,0,0,0,0,0,0,0,0,0,0,0,7,1,1,1
1,1,1,7,0,0,0,0,0,0,0,0,0,0,0,0,0,0,0,0,0,0,0,0,0,0,7,1,1,1
1,1,1,7,0,0,0,0,0,0,0,0,0,0,0,0,0,0,0,0,0,0,0,0,0,0,7,1,1,1
1,1,1,7,0,0,0,0,0,0,0,0,0,0,0,0,0,0,0,0,0,0,0,0,0,0,7,1,1,1
1,1,1,7,0,0,0,0,0,0,0,0,0,0,0,0,0,0,0,0,0,0,0,0,0,0,7,1,1,1
1,1,1,7,0,0,0,0,0,0,0,0,0,0,0,0,0,0,0,0,0,0,0,0,0,0,7,1,1,1
1,1,1,1,7,0,0,0,0,0,0,0,0,0,0,0,0,0,0,0,0,0,0,0,0,7,1,1,1,1
1,1,1,1,7,0,0,0,0,0,0,0,0,0,0,0,0,0,0,0,0,0,0,0,0,7,1,1,1,1
1,1,1,1,7,7,0,0,0,0,0,0,0,0,0,0,0,0,0,0,0,0,0,0,7,7,1,1,1,1
1,1,1,1,1,7,0,0,0,0,0,0,0,0,0,0,0,0,0,0,0,0,0,0,7,1,1,1,1,1
1,1,1,1,1,7,7,0,0,0,0,0,0,0,0,0,0,0,0,0,0,0,0,7,7,1,1,1,1,1
1,1,1,1,1,1,7,7,0,0,0,0,0,0,0,0,0,0,0,0,0,0,7,7,1,1,1,1,1,1
1,1,1,1,1,1,1,7,7,7,0,0,0,0,0,0,0,0,0,0,7,7,7,1,1,1,1,1,1,1
1,1,1,1,1,1,1,1,1,7,7,7,0,0,0,0,0,0,7,7,7,1,1,1,1,1,1,1,1,1
1,1,1,1,1,1,1,1,1,1,1,1,7,7,7,7,7,7,1,1,1,1,1,1,1,1,1,1,1,1
1,1,1,1,1,1,1,1,1,1,1,1,1,1,1,1,1,1,1,1,1,1,1,1,1,1,1,1,1,1
1,1,1,1,1,1,1,1,1,1,1,1,1,1,1,1,1,1,1,1,1,1,1,1,1,1,1,1,1,1
1,1,1,1,1,1,1,1,1,1,1,1,1,1,1,1,1,1,1,1,1,1,1,1,1,1,1,1,1,1
endlayer

layer
1,1,1,1,1,1,1,1,1,1,1,1,1,1,1,1,1,1,1,1,1,1,1,1,1,1,1,1,1,1
1,1,1,1,1,1,1,1,1,1,1,1,1,1,1,1,1,1,1,1,1,1,1,1,1,1,1,1,1,1
1,1,1,1,1,1,1,1,1,1,1,1,7,7,7,7,7,7,1,1,1,1,1,1,1,1,1,1,1,1
1,1,1,1,1,1,1,1,1,7,7,7,0,0,0,0,0,0,7,7,7,1,1,1,1,1,1,1,1,1
1,1,1,1,1,1,1,7,7,0,0,0,0,0,0,0,0,0,0,0,0,7,7,1,1,1,1,1,1,1
1,1,1,1,1,1,7,0,0,0,0,0,0,0,0,0,0,0,0,0,0,0,0,7,1,1,1,1,1,1
1,1,1,1,1,7,0,0,0,0,0,0,0,0,0,0,0,0,0,0,0,0,0,0,7,1,1,1,1,1
1,1,1,1,7,0,0,0,0,0,0,0,0,0,0,0,0,0,0,0,0,0,0,0,0,7,1,1,1,1
1,1,1,1,7,0,0,0,0,0,0,0,0,0,0,0,0,0,0,0,0,0,0,0,0,7,1,1,1,1
1,1,1,7,0,0,0,0,0,0,0,0,0,0,0,0,0,0,0,0,0,0,0,0,0,0,7,1,1,1
1,1,1,7,0,0,0,0,0,0,0,0,0,0,0,0,0,0,0,0,0,0,0,0,0,0,7,1,1,1
1,1,1,7,0,0,0,0,0,0,0,0,0,0,0,0,0,0,0,0,0,0,0,0,0,0,7,1,1,1
1,1,7,0,0,0,0,0,0,0,0,0,0,0,0,0,0,0,0,0,0,0,0,0,0,0,0,7,1,1
1,1,7,0,0,0,0,0,0,0,0,0,0,0,0,0,0,0,0,0,0,0,0,0,0,0,0,7,1,1
1,1,7,0,0,0,0,0,0,0,0,0,0,0,0,0,0,0,0,0,0,0,0,0,0,0,0,7,1,1
1,1,7,0,0,0,0,0,0,0,0,0,0,0,0,0,0,0,0,0,0,0,0,0,0,0,0,7,1,1
1,1,7,0,0,0,0,0,0,0,0,0,0,0,0,0,0,0,0,0,0,0,0,0,0,0,0,7,1,1
1,1,7,0,0,0,0,0,0,0,0,0,0,0,0,0,0,0,0,0,0,0,0,0,0,0,0,7,1,1
1,1,1,7,0,0,0,0,0,0,0,0,0,0,0,0,0,0,0,0,0,0,0,0,0,0,7,1,1,1
1,1,1,7,0,0,0,0,0,0,0,0,0,0,0,0,0,0,0,0,0,0,0,0,0,0,7,1,1,1
1,1,1,7,0,0,0,0,0,0,0,0,0,0,0,0,0,0,0,0,0,0,0,0,0,0,7,1,1,1
1,1,1,1,7,0,0,0,0,0,0,0,0,0,0,0,0,0,0,0,0,0,0,0,0,7,1,1,1,1
1,1,1,1,7,0,0,0,0,0,0,0,0,0,0,0,0,0,0,0,0,0,0,0,0,7,1,1,1,1
1,1,1,1,1,7,0,0,0,0,0,0,0,0,0,0,0,0,0,0,0,0,0,0,7,1,1,1,1,1
1,1,1,1,1,1,7,0,0,0,0,0,0,0,0,0,0,0,0,0,0,0,0,7,1,1,1,1,1,1
1,1,1,1,1,1,1,7,7,0,0,0,0,0,0,0,0,0,0,0,0,7,7,1,1,1,1,1,1,1
1,1,1,1,1,1,1,1,1,7,7,7,0,0,0,0,0,0,7,7,7,1,1,1,1,1,1,1,1,1
1,1,1,1,1,1,1,1,1,1,1,1,7,7,7,7,7,7,1,1,1,1,1,1,1,1,1,1,1,1
1,1,1,1,1,1,1,1,1,1,1,1,1,1,1,1,1,1,1,1,1,1,1,1,1,1,1,1,1,1
1,1,1,1,1,1,1,1,1,1,1,1,1,1,1,1,1,1,1,1,1,1,1,1,1,1,1,1,1,1
endlayer

layer
1,1,1,1,1,1,1,1,1,1,1,1,1,1,1,1,1,1,1,1,1,1,1,1,1,1,1,1,1,1
1,1,1,1,1,1,1,1,1,1,1,1,1,1,1,1,1,1,1,1,1,1,1,1,1,1,1,1,1,1
1,1,1,1,1,1,1,1,1,1,1,1,7,7,7,7,7,7,1,1,1,1,1,1,1,1,1,1,1,1
1,1,1,1,1,1,1,1,1,7,7,7,0,0,0,0,0,0,7,7,7,1,1,1,1,1,1,1,1,1
1,1,1,1,1,1,1,7,7,0,0,0,0,0,0,0,0,0,0,0,0,7,7,1,1,1,1,1,1,1
1,1,1,1,1,1,7,0,0,0,0,0,0,0,0,0,0,0,0,0,0,0,0,7,1,1,1,1,1,1
1,1,1,1,1,7,0,0,0,0,0,0,0,0,0,0,0,0,0,0,0,0,0,0,7,1,1,1,1,1
1,1,1,1,7,0,0,0,0,0,0,0,0,0,0,0,0,0,0,0,0,0,0,0,0,7,1,1,1,1
1,1,1,1,7,0,0,0,0,0,0,0,0,0,0,0,0,0,0,0,0,0,0,0,0,7,1,1,1,1
1,1,1,7,0,0,0,0,0,0,0,0,0,0,0,0,0,0,0,0,0,0,0,0,0,0,7,1,1,1
1,1,1,7,0,0,0,0,0,0,0,0,0,0,0,0,0,0,0,0,0,0,0,0,0,0,7,1,1,1
1,1,1,7,0,0,0,0,0,0,0,0,0,0,0,0,0,0,0,0,0,0,0,0,0,0,7,1,1,1
1,1,7,0,0,0,0,0,0,0,0,0,0,0,0,0,0,0,0,0,0,0,0,0,0,0,0,7,1,1
1,1,7,0,0,0,0,0,0,0,0,0,0,0,0,0,0,0,0,0,0,0,0,0,0,0,0,7,1,1
1,1,7,0,0,0,0,0,0,0,0,0,0,0,0,0,0,0,0,0,0,0,0,0,0,0,0,7,1,1
1,1,7,0,0,0,0,0,0,0,0,0,0,0,0,0,0,0,0,0,0,0,0,0,0,0,0,7,1,1
1,1,7,0,0,0,0,0,0,0,0,0,0,0,0,0,0,0,0,0,0,0,0,0,0,0,0,7,1,1
1,1,7,0,0,0,0,0,0,0,0,0,0,0,0,0,0,0,0,0,0,0,0,0,0,0,0,7,1,1
1,1,1,7,0,0,0,0,0,0,0,0,0,0,0,0,0,0,0,0,0,0,0,0,0,0,7,1,1,1
1,1,1,7,0,0,0,0,0,0,0,0,0,0,0,0,0,0,0,0,0,0,0,0,0,0,7,1,1,1
1,1,1,7,0,0,0,0,0,0,0,0,0,0,0,0,0,0,0,0,0,0,0,0,0,0,7,1,1,1
1,1,1,1,7,0,0,0,0,0,0,0,0,0,0,0,0,0,0,0,0,0,0,0,0,7,1,1,1,1
1,1,1,1,7,0,0,0,0,0,0,0,0,0,0,0,0,0,0,0,0,0,0,0,0,7,1,1,1,1
1,1,1,1,1,7,0,0,0,0,0,0,0,0,0,0,0,0,0,0,0,0,0,0,7,1,1,1,1,1
1,1,1,1,1,1,7,0,0,0,0,0,0,0,0,0,0,0,0,0,0,0,0,7,1,1,1,1,1,1
1,1,1,1,1,1,1,7,7,0,0,0,0,0,0,0,0,0,0,0,0,7,7,1,1,1,1,1,1,1
1,1,1,1,1,1,1,1,1,7,7,7,0,0,0,0,0,0,7,7,7,1,1,1,1,1,1,1,1,1
1,1,1,1,1,1,1,1,1,1,1,1,7,7,7,7,7,7,1,1,1,1,1,1,1,1,1,1,1,1
1,1,1,1,1,1,1,1,1,1,1,1,1,1,1,1,1,1,1,1,1,1,1,1,1,1,1,1,1,1
1,1,1,1,1,1,1,1,1,1,1,1,1,1,1,1,1,1,1,1,1,1,1,1,1,1,1,1,1,1
endlayer

layer
1,1,1,1,1,1,1,1,1,1,1,1,1,1,1,1,1,1,1,1,1,1,1,1,1,1,1,1,1,1
1,1,1,1,1,1,1,1,1,1,1,1,7,7,7,7,7,7,1,1,1,1,1,1,1,1,1,1,1,1
1,1,1,1,1,1,1,1,1,7,7,7,0,0,0,0,0,0,7,7,7,1,1,1,1,1,1,1,1,1
1,1,1,1,1,1,1,7,7,0,0,0,0,0,0,0,0,0,0,0,0,7,7,1,1,1,1,1,1,1
1,1,1,1,1,1,7,0,0,0,0,0,0,0,0,0,0,0,0,0,0,0,0,7,1,1,1,1,1,1
1,1,1,1,1,7,0,0,0,0,0,0,0,0,0,0,0,0,0,0,0,0,0,0,7,1,1,1,1,1
1,1,1,1,7,0,0,0,0,0,0,0,0,0,0,0,0,0,0,0,0,0,0,0,0,7,1,1,1,1
1,1,1,7,0,0,0,0,0,0,0,0,0,0,0,0,0,0,0,0,0,0,0,0,0,0,7,1,1,1
1,1,1,7,0,0,0,0,0,0,0,0,0,0,0,0,0,0,0,0,0,0,0,0,0,0,7,1,1,1
1,1,7,0,0,0,0,0,0,0,0,0,0,0,0,0,0,0,0,0,0,0,0,0,0,0,0,7,1,1
1,1,7,0,0,0,0,0,0,0,0,0,0,0,0,0,0,0,0,0,0,0,0,0,0,0,0,7,1,1
1,1,7,0,0,0,0,0,0,0,0,0,0,0,0,0,0,0,0,0,0,0,0,0,0,0,0,7,1,1
1,7,0,0,0,0,0,0,0,0,0,0,0,0,0,0,0,0,0,0,0,0,0,0,0,0,0,0,7,1
1,7,0,0,0,0,0,0,0,0,0,0,0,0,0,0,0,0,0,0,0,0,0,0,0,0,0,0,7,1
1,7,0,0,0,0,0,0,0,0,0,0,0,0,0,0,0,0,0,0,0,0,0,0,0,0,0,0,7,1
1,7,0,0,0,0,0,0,0,0,0,0,0,0,0,0,0,0,0,0,0,0,0,0,0,0,0,0,7,1
1,7,0,0,0,0,0,0,0,0,0,0,0,0,0,0,0,0,0,0,0,0,0,0,0,0,0,0,7,1
1,7,0,0,0,0,0,0,0,0,0,0,0,0,0,0,0,0,0,0,0,0,0,0,0,0,0,0,7,1
1,1,7,0,0,0,0,0,0,0,0,0,0,0,0,0,0,0,0,0,0,0,0,0,0,0,0,7,1,1
1,1,7,0,0,0,0,0,0,0,0,0,0,0,0,0,0,0,0,0,0,0,0,0,0,0,0,7,1,1
1,1,7,0,0,0,0,0,0,0,0,0,0,0,0,0,0,0,0,0,0,0,0,0,0,0,0,7,1,1
1,1,1,7,0,0,0,0,0,0,0,0,0,0,0,0,0,0,0,0,0,0,0,0,0,0,7,1,1,1
1,1,1,7,0,0,0,0,0,0,0,0,0,0,0,0,0,0,0,0,0,0,0,0,0,0,7,1,1,1
1,1,1,1,7,0,0,0,0,0,0,0,0,0,0,0,0,0,0,0,0,0,0,0,0,7,1,1,1,1
1,1,1,1,1,7,0,0,0,0,0,0,0,0,0,0,0,0,0,0,0,0,0,0,7,1,1,1,1,1
1,1,1,1,1,1,7,0,0,0,0,0,0,0,0,0,0,0,0,0,0,0,0,7,1,1,1,1,1,1
1,1,1,1,1,1,1,7,7,0,0,0,0,0,0,0,0,0,0,0,0,7,7,1,1,1,1,1,1,1
1,1,1,1,1,1,1,1,1,7,7,7,0,0,0,0,0,0,7,7,7,1,1,1,1,1,1,1,1,1
1,1,1,1,1,1,1,1,1,1,1,1,7,7,7,7,7,7,1,1,1,1,1,1,1,1,1,1,1,1
1,1,1,1,1,1,1,1,1,1,1,1,1,1,1,1,1,1,1,1,1,1,1,1,1,1,1,1,1,1
endlayer

layer
1,1,1,1,1,1,1,1,1,1,1,1,1,1,1,1,1,1,1,1,1,1,1,1,1,1,1,1,1,1
1,1,1,1,1,1,1,1,1,1,1,1,7,7,7,7,7,7,1,1,1,1,1,1,1,1,1,1,1,1
1,1,1,1,1,1,1,1,1,7,7,7,0,0,0,0,0,0,7,7,7,1,1,1,1,1,1,1,1,1
1,1,1,1,1,1,1,7,7,0,0,0,0,0,0,0,0,0,0,0,0,7,7,1,1,1,1,1,1,1
1,1,1,1,1,1,7,0,0,0,0,0,0,0,0,0,0,0,0,0,0,0,0,7,1,1,1,1,1,1
1,1,1,1,1,7,0,0,0,0,0,0,0,0,0,0,0,0,0,0,0,0,0,0,7,1,1,1,1,1
1,1,1,1,7,0,0,0,0,0,0,0,0,0,0,0,0,0,0,0,0,0,0,0,0,7,1,1,1,1
1,1,1,7,0,0,0,0,0,0,0,0,0,0,0,0,0,0,0,0,0,0,0,0,0,0,7,1,1,1
1,1,1,7,0,0,0,0,0,0,0,0,0,0,0,0,0,0,0,0,0,0,0,0,0,0,7,1,1,1
1,1,7,0,0,0,0,0,0,0,0,0,0,0,0,0,0,0,0,0,0,0,0,0,0,0,0,7,1,1
1,1,7,0,0,0,0,0,0,0,0,0,0,0,0,0,0,0,0,0,0,0,0,0,0,0,0,7,1,1
1,1,7,0,0,0,0,0,0,0,0,0,0,0,0,0,0,0,0,0,0,0,0,0,0,0,0,7,1,1
1,7,0,0,0,0,0,0,0,0,0,0,0,0,0,0,0,0,0,0,0,0,0,0,0,0,0,0,7,1
1,7,0,0,0,0,0,0,0,0,0,0,0,0,0,0,0,0,0,0,0,0,0,0,0,0,0,0,7,1
1,7,0,0,0,0,0,0,0,0,0,0,0,0,0,0,0,0,0,0,0,0,0,0,0,0,0,0,7,1
1,7,0,0,0,0,0,0,0,0,0,0,0,0,0,0,0,0,0,0,0,0,0,0,0,0,0,0,7,1
1,7,0,0,0,0,0,0,0,0,0,0,0,0,0,0,0,0,0,0,0,0,0,0,0,0,0,0,7,1
1,7,0,0,0,0,0,0,0,0,0,0,0,0,0,0,0,0,0,0,0,0,0,0,0,0,0,0,7,1
1,1,7,0,0,0,0,0,0,0,0,0,0,0,0,0,0,0,0,0,0,0,0,0,0,0,0,7,1,1
1,1,7,0,0,0,0,0,0,0,0,0,0,0,0,0,0,0,0,0,0,0,0,0,0,0,0,7,1,1
1,1,7,0,0,0,0,0,0,0,0,0,0,0,0,0,0,0,0,0,0,0,0,0,0,0,0,7,1,1
1,1,1,7,0,0,0,0,0,0,0,0,0,0,0,0,0,0,0,0,0,0,0,0,0,0,7,1,1,1
1,1,1,7,0,0,0,0,0,0,0,0,0,0,0,0,0,0,0,0,0,0,0,0,0,0,7,1,1,1
1,1,1,1,7,0,0,0,0,0,0,0,0,0,0,0,0,0,0,0,0,0,0,0,0,7,1,1,1,1
1,1,1,1,1,7,0,0,0,0,0,0,0,0,0,0,0,0,0,0,0,0,0,0,7,1,1,1,1,1
1,1,1,1,1,1,7,0,0,0,0,0,0,0,0,0,0,0,0,0,0,0,0,7,1,1,1,1,1,1
1,1,1,1,1,1,1,7,7,0,0,0,0,0,0,0,0,0,0,0,0,7,7,1,1,1,1,1,1,1
1,1,1,1,1,1,1,1,1,7,7,7,0,0,0,0,0,0,7,7,7,1,1,1,1,1,1,1,1,1
1,1,1,1,1,1,1,1,1,1,1,1,7,7,7,7,7,7,1,1,1,1,1,1,1,1,1,1,1,1
1,1,1,1,1,1,1,1,1,1,1,1,1,1,1,1,1,1,1,1,1,1,1,1,1,1,1,1,1,1
endlayer

layer
1,1,1,1,1,1,1,1,1,1,1,1,1,4,4,4,4,1,1,1,1,1,1,1,1,1,1,1,1,1
1,1,1,1,1,1,1,1,1,1,1,1,7,7,4,4,7,7,1,1,1,1,1,1,1,1,1,1,1,1
1,1,1,1,1,1,1,1,1,7,7,7,0,0,4,4,0,0,7,7,7,1,1,1,1,1,1,1,1,1
1,1,1,1,1,1,1,7,7,0,0,0,0,0,4,4,0,0,0,0,0,7,7,1,1,1,1,1,1,1
1,1,1,1,1,1,7,0,0,0,0,0,0,0,4,4,0,0,0,0,0,0,0,7,1,1,1,1,1,1
1,1,1,1,1,7,0,0,0,0,0,0,0,0,4,4,0,0,0,0,0,0,0,0,7,1,1,1,1,1
1,1,1,1,7,0,0,0,0,0,0,0,0,0,4,4,0,0,0,0,0,0,0,0,0,7,1,1,1,1
1,1,1,7,0,0,0,0,0,0,0,0,0,0,4,4,0,0,0,0,0,0,0,0,0,0,7,1,1,1
1,1,1,7,0,0,0,0,0,0,0,0,0,0,4,4,0,0,0,0,0,0,0,0,0,0,7,1,1,1
1,1,7,0,0,0,0,0,0,0,0,0,0,0,4,4,0,0,0,0,0,0,0,0,0,0,0,7,1,1
1,1,7,0,0,0,0,0,0,0,0,0,0,0,4,4,0,0,0,0,0,0,0,0,0,0,0,7,1,1
1,1,7,0,0,0,0,0,0,0,0,0,0,0,4,4,0,0,0,0,0,0,0,0,0,0,0,7,1,1
1,7,0,0,0,0,0,0,0,0,0,0,0,0,4,4,0,0,0,0,0,0,0,0,0,0,0,0,7,1
4,7,0,0,0,0,0,0,0,0,0,0,0,0,4,4,0,0,0,0,0,0,0,0,0,0,0,0,7,4
4,4,4,4,4,4,4,4,4,4,4,4,4,4,4,4,4,4,4,4,4,4,4,4,4,4,4,4,4,4
4,4,4,4,4,4,4,4,4,4,4,4,4,4,4,4,4,4,4,4,4,4,4,4,4,4,4,4,4,4
4,7,0,0,0,0,0,0,0,0,0,0,0,0,4,4,0,0,0,0,0,0,0,0,0,0,0,0,7,4
1,7,0,0,0,0,0,0,0,0,0,0,0,0,4,4,0,0,0,0,0,0,0,0,0,0,0,0,7,1
1,1,7,0,0,0,0,0,0,0,0,0,0,0,4,4,0,0,0,0,0,0,0,0,0,0,0,7,1,1
1,1,7,0,0,0,0,0,0,0,0,0,0,0,4,4,0,0,0,0,0,0,0,0,0,0,0,7,1,1
1,1,7,0,0,0,0,0,0,0,0,0,0,0,4,4,0,0,0,0,0,0,0,0,0,0,0,7,1,1
1,1,1,7,0,0,0,0,0,0,0,0,0,0,4,4,0,0,0,0,0,0,0,0,0,0,7,1,1,1
1,1,1,7,0,0,0,0,0,0,0,0,0,0,4,4,0,0,0,0,0,0,0,0,0,0,7,1,1,1
1,1,1,1,7,0,0,0,0,0,0,0,0,0,4,4,0,0,0,0,0,0,0,0,0,7,1,1,1,1
1,1,1,1,1,7,0,0,0,0,0,0,0,0,4,4,0,0,0,0,0,0,0,0,7,1,1,1,1,1
1,1,1,1,1,1,7,0,0,0,0,0,0,0,4,4,0,0,0,0,0,0,0,7,1,1,1,1,1,1
1,1,1,1,1,1,1,7,7,0,0,0,0,0,4,4,0,0,0,0,0,7,7,1,1,1,1,1,1,1
1,1,1,1,1,1,1,1,1,7,7,7,0,0,4,4,0,0,7,7,7,1,1,1,1,1,1,1,1,1
1,1,1,1,1,1,1,1,1,1,1,1,7,7,4,4,7,7,1,1,1,1,1,1,1,1,1,1,1,1
1,1,1,1,1,1,1,1,1,1,1,1,1,4,4,4,4,1,1,1,1,1,1,1,1,1,1,1,1,1
endlayer

layer
1,1,1,1,1,1,1,1,1,1,1,1,7,4,0,0,4,7,1,1,1,1,1,1,1,1,1,1,1,1
1,1,1,1,1,1,1,1,1,7,7,7,0,0,0,0,0,0,7,7,7,1,1,1,1,1,1,1,1,1
1,1,1,1,1,1,1,7,7,0,0,0,0,0,0,0,0,0,0,0,0,7,7,1,1,1,1,1,1,1
1,1,1,1,1,1,7,0,0,0,0,0,0,0,0,0,0,0,0,0,0,0,0,7,1,1,1,1,1,1
1,1,1,1,1,7,0,0,0,0,0,0,0,0,0,0,0,0,0,0,0,0,0,0,7,1,1,1,1,1
1,1,1,1,7,0,0,0,0,0,0,0,0,0,0,0,0,0,0,0,0,0,0,0,0,7,1,1,1,1
1,1,1,7,0,0,0,0,0,0,0,0,0,0,0,0,0,0,0,0,0,0,0,0,0,0,7,1,1,1
1,1,7,0,0,0,0,0,0,0,0,0,0,0,0,0,0,0,0,0,0,0,0,0,0,0,0,7,1,1
1,1,7,0,0,0,0,0,0,0,0,0,0,0,0,0,0,0,0,0,0,0,0,0,0,0,0,7,1,1
1,7,0,0,0,0,0,0,0,0,0,0,0,0,0,0,0,0,0,0,0,0,0,0,0,0,0,0,7,1
1,7,0,0,0,0,0,0,0,0,0,0,0,0,0,0,0,0,0,0,0,0,0,0,0,0,0,0,7,1
1,7,0,0,0,0,0,0,0,0,0,0,0,0,0,0,0,0,0,0,0,0,0,0,0,0,0,0,7,1
7,0,0,0,0,0,0,0,0,0,0,0,0,0,0,0,0,0,0,0,0,0,0,0,0,0,0,0,0,7
4,0,0,0,0,0,0,0,0,0,0,0,0,0,0,0,0,0,0,0,0,0,0,0,0,0,0,0,0,4
0,0,0,0,0,0,0,0,0,0,0,0,0,0,0,0,0,0,0,0,0,0,0,0,0,0,0,0,0,0
0,0,0,0,0,0,0,0,0,0,0,0,0,0,0,0,0,0,0,0,0,0,0,0,0,0,0,0,0,0
4,0,0,0,0,0,0,0,0,0,0,0,0,0,0,0,0,0,0,0,0,0,0,0,0,0,0,0,0,4
7,0,0,0,0,0,0,0,0,0,0,0,0,0,0,0,0,0,0,0,0,0,0,0,0,0,0,0,0,7
1,7,0,0,0,0,0,0,0,0,0,0,0,0,0,0,0,0,0,0,0,0,0,0,0,0,0,0,7,1
1,7,0,0,0,0,0,0,0,0,0,0,0,0,0,0,0,0,0,0,0,0,0,0,0,0,0,0,7,1
1,7,0,0,0,0,0,0,0,0,0,0,0,0,0,0,0,0,0,0,0,0,0,0,0,0,0,0,7,1
1,1,7,0,0,0,0,0,0,0,0,0,0,0,0,0,0,0,0,0,0,0,0,0,0,0,0,7,1,1
1,1,7,0,0,0,0,0,0,0,0,0,0,0,0,0,0,0,0,0,0,0,0,0,0,0,0,7,1,1
1,1,1,7,0,0,0,0,0,0,0,0,0,0,0,0,0,0,0,0,0,0,0,0,0,0,7,1,1,1
1,1,1,1,7,0,0,0,0,0,0,0,0,0,0,0,0,0,0,0,0,0,0,0,0,7,1,1,1,1
1,1,1,1,1,7,0,0,0,0,0,0,0,0,0,0,0,0,0,0,0,0,0,0,7,1,1,1,1,1
1,1,1,1,1,1,7,0,0,0,0,0,0,0,0,0,0,0,0,0,0,0,0,7,1,1,1,1,1,1
1,1,1,1,1,1,1,7,7,0,0,0,0,0,0,0,0,0,0,0,0,7,7,1,1,1,1,1,1,1
1,1,1,1,1,1,1,1,1,7,7,7,0,0,0,0,0,0,7,7,7,1,1,1,1,1,1,1,1,1
1,1,1,1,1,1,1,1,1,1,1,1,7,4,0,0,4,7,1,1,1,1,1,1,1,1,1,1,1,1
endlayer

layer
1,1,1,1,1,1,1,1,1,1,1,1,7,4,0,0,4,7,1,1,1,1,1,1,1,1,1,1,1,1
1,1,1,1,1,1,1,1,1,7,7,7,0,0,0,0,0,0,7,7,7,1,1,1,1,1,1,1,1,1
1,1,1,1,1,1,1,7,7,0,0,0,0,0,0,0,0,0,0,0,0,7,7,1,1,1,1,1,1,1
1,1,1,1,1,1,7,0,0,0,0,0,0,0,0,0,0,0,0,0,0,0,0,7,1,1,1,1,1,1
1,1,1,1,1,7,0,0,0,0,0,0,0,0,0,0,0,0,0,0,0,0,0,0,7,1,1,1,1,1
1,1,1,1,7,0,0,0,0,0,0,0,0,0,0,0,0,0,0,0,0,0,0,0,0,7,1,1,1,1
1,1,1,7,0,0,0,0,0,0,0,0,0,0,0,0,0,0,0,0,0,0,0,0,0,0,7,1,1,1
1,1,7,0,0,0,0,0,0,0,0,0,0,0,0,0,0,0,0,0,0,0,0,0,0,0,0,7,1,1
1,1,7,0,0,0,0,0,0,0,0,0,0,0,0,0,0,0,0,0,0,0,0,0,0,0,0,7,1,1
1,7,0,0,0,0,0,0,0,0,0,0,0,0,0,0,0,0,0,0,0,0,0,0,0,0,0,0,7,1
1,7,0,0,0,0,0,0,0,0,0,0,0,0,0,0,0,0,0,0,0,0,0,0,0,0,0,0,7,1
1,7,0,0,0,0,0,0,0,0,0,0,0,0,0,0,0,0,0,0,0,0,0,0,0,0,0,0,7,1
7,0,0,0,0,0,0,0,0,0,0,0,0,0,0,0,0,0,0,0,0,0,0,0,0,0,0,0,0,7
4,0,0,0,0,0,0,0,0,0,0,0,0,0,0,0,0,0,0,0,0,0,0,0,0,0,0,0,0,4
0,0,0,0,0,0,0,0,0,0,0,0,0,0,0,0,0,0,0,0,0,0,0,0,0,0,0,0,0,0
0,0,0,0,0,0,0,0,0,0,0,0,0,0,0,0,0,0,0,0,0,0,0,0,0,0,0,0,0,0
4,0,0,0,0,0,0,0,0,0,0,0,0,0,0,0,0,0,0,0,0,0,0,0,0,0,0,0,0,4
7,0,0,0,0,0,0,0,0,0,0,0,0,0,0,0,0,0,0,0,0,0,0,0,0,0,0,0,0,7
1,7,0,0,0,0,0,0,0,0,0,0,0,0,0,0,0,0,0,0,0,0,0,0,0,0,0,0,7,1
1,7,0,0,0,0,0,0,0,0,0,0,0,0,0,0,0,0,0,0,0,0,0,0,0,0,0,0,7,1
1,7,0,0,0,0,0,0,0,0,0,0,0,0,0,0,0,0,0,0,0,0,0,0,0,0,0,0,7,1
1,1,7,0,0,0,0,0,0,0,0,0,0,0,0,0,0,0,0,0,0,0,0,0,0,0,0,7,1,1
1,1,7,0,0,0,0,0,0,0,0,0,0,0,0,0,0,0,0,0,0,0,0,0,0,0,0,7,1,1
1,1,1,7,0,0,0,0,0,0,0,0,0,0,0,0,0,0,0,0,0,0,0,0,0,0,7,1,1,1
1,1,1,1,7,0,0,0,0,0,0,0,0,0,0,0,0,0,0,0,0,0,0,0,0,7,1,1,1,1
1,1,1,1,1,7,0,0,0,0,0,0,0,0,0,0,0,0,0,0,0,0,0,0,7,1,1,1,1,1
1,1,1,1,1,1,7,0,0,0,0,0,0,0,0,0,0,0,0,0,0,0,0,7,1,1,1,1,1,1
1,1,1,1,1,1,1,7,7,0,0,0,0,0,0,0,0,0,0,0,0,7,7,1,1,1,1,1,1,1
1,1,1,1,1,1,1,1,1,7,7,7,0,0,0,0,0,0,7,7,7,1,1,1,1,1,1,1,1,1
1,1,1,1,1,1,1,1,1,1,1,1,7,4,0,0,4,7,1,1,1,1,1,1,1,1,1,1,1,1
endlayer

layer
1,1,1,1,1,1,1,1,1,1,1,1,7,4,0,0,4,7,1,1,1,1,1,1,1,1,1,1,1,1
1,1,1,1,1,1,1,1,1,7,7,7,0,0,0,0,0,0,7,7,7,1,1,1,1,1,1,1,1,1
1,1,1,1,1,1,1,7,7,0,0,0,0,0,0,0,0,0,0,0,0,7,7,1,1,1,1,1,1,1
1,1,1,1,1,1,7,0,0,0,0,0,0,0,0,0,0,0,0,0,0,0,0,7,1,1,1,1,1,1
1,1,1,1,1,7,0,0,0,0,0,0,0,0,0,0,0,0,0,0,0,0,0,0,7,1,1,1,1,1
1,1,1,1,7,0,0,0,0,0,0,0,0,0,0,0,0,0,0,0,0,0,0,0,0,7,1,1,1,1
1,1,1,7,0,0,0,0,0,0,0,0,0,0,0,0,0,0,0,0,0,0,0,0,0,0,7,1,1,1
1,1,7,0,0,0,0,0,0,0,0,0,0,0,0,0,0,0,0,0,0,0,0,0,0,0,0,7,1,1
1,1,7,0,0,0,0,0,0,0,0,0,0,0,0,0,0,0,0,0,0,0,0,0,0,0,0,7,1,1
1,7,0,0,0,0,0,0,0,0,0,0,0,0,0,0,0,0,0,0,0,0,0,0,0,0,0,0,7,1
1,7,0,0,0,0,0,0,0,0,0,0,0,0,0,0,0,0,0,0,0,0,0,0,0,0,0,0,7,1
1,7,0,0,0,0,0,0,0,0,0,0,0,0,0,0,0,0,0,0,0,0,0,0,0,0,0,0,7,1
7,0,0,0,0,0,0,0,0,0,0,0,0,0,0,0,0,0,0,0,0,0,0,0,0,0,0,0,0,7
4,0,0,0,0,0,0,0,0,0,0,0,0,0,0,0,0,0,0,0,0,0,0,0,0,0,0,0,0,4
0,0,0,0,0,0,0,0,0,0,0,0,0,0,0,0,0,0,0,0,0,0,0,0,0,0,0,0,0,0
0,0,0,0,0,0,0,0,0,0,0,0,0,0,0,0,0,0,0,0,0,0,0,0,0,0,0,0,0,0
4,0,0,0,0,0,0,0,0,0,0,0,0,0,0,0,0,0,0,0,0,0,0,0,0,0,0,0,0,4
7,0,0,0,0,0,0,0,0,0,0,0,0,0,0,0,0,0,0,0,0,0,0,0,0,0,0,0,0,7
1,7,0,0,0,0,0,0,0,0,0,0,0,0,0,0,0,0,0,0,0,0,0,0,0,0,0,0,7,1
1,7,0,0,0,0,0,0,0,0,0,0,0,0,0,0,0,0,0,0,0,0,0,0,0,0,0,0,7,1
1,7,0,0,0,0,0,0,0,0,0,0,0,0,0,0,0,0,0,0,0,0,0,0,0,0,0,0,7,1
1,1,7,0,0,0,0,0,0,0,0,0,0,0,0,0,0,0,0,0,0,0,0,0,0,0,0,7,1,1
1,1,7,0,0,0,0,0,0,0,0,0,0,0,0,0,0,0,0,0,0,0,0,0,0,0,0,7,1,1
1,1,1,7,0,0,0,0,0,0,0,0,0,0,0,0,0,0,0,0,0,0,0,0,0,0,7,1,1,1
1,1,1,1,7,0,0,0,0,0,0,0,0,0,0,0,0,0,0,0,0,0,0,0,0,7,1,1,1,1
1,1,1,1,1,7,0,0,0,0,0,0,0,0,0,0,0,0,0,0,0,0,0,0,7,1,1,1,1,1
1,1,1,1,1,1,7,0,0,0,0,0,0,0,0,0,0,0,0,0,0,0,0,7,1,1,1,1,1,1
1,1,1,1,1,1,1,7,7,0,0,0,0,0,0,0,0,0,0,0,0,7,7,1,1,1,1,1,1,1
1,1,1,1,1,1,1,1,1,7,7,7,0,0,0,0,0,0,7,7,7,1,1,1,1,1,1,1,1,1
1,1,1,1,1,1,1,1,1,1,1,1,7,4,0,0,4,7,1,1,1,1,1,1,1,1,1,1,1,1
endlayer

layer
1,1,1,1,1,1,1,1,1,1,1,1,7,4,4,4,4,7,1,1,1,1,1,1,1,1,1,1,1,1
1,1,1,1,1,1,1,1,1,7,7,7,0,0,0,0,0,0,7,7,7,1,1,1,1,1,1,1,1,1
1,1,1,1,1,1,1,7,7,0,0,0,0,0,0,0,0,0,0,0,0,7,7,1,1,1,1,1,1,1
1,1,1,1,1,1,7,0,0,0,0,0,0,0,0,0,0,0,0,0,0,0,0,7,1,1,1,1,1,1
1,1,1,1,1,7,0,0,0,0,0,0,0,0,0,0,0,0,0,0,0,0,0,0,7,1,1,1,1,1
1,1,1,1,7,0,0,0,0,0,0,0,0,0,0,0,0,0,0,0,0,0,0,0,0,7,1,1,1,1
1,1,1,7,0,0,0,0,0,0,0,0,0,0,0,0,0,0,0,0,0,0,0,0,0,0,7,1,1,1
1,1,7,0,0,0,0,0,0,0,0,0,0,0,0,0,0,0,0,0,0,0,0,0,0,0,0,7,1,1
1,1,7,0,0,0,0,0,0,0,0,0,0,0,0,0,0,0,0,0,0,0,0,0,0,0,0,7,1,1
1,7,0,0,0,0,0,0,0,0,0,0,0,0,0,0,0,0,0,0,0,0,0,0,0,0,0,0,7,1
1,7,0,0,0,0,0,0,0,0,0,0,0,0,0,0,0,0,0,0,0,0,0,0,0,0,0,0,7,1
1,7,0,0,0,0,0,0,0,0,0,0,0,0,0,0,0,0,0,0,0,0,0,0,0,0,0,0,7,1
7,0,0,0,0,0,0,0,0,0,0,0,0,0,0,0,0,0,0,0,0,0,0,0,0,0,0,0,0,7
4,0,0,0,0,0,0,0,0,0,0,0,0,0,0,0,0,0,0,0,0,0,0,0,0,0,0,0,0,4
4,0,0,0,0,0,0,0,0,0,0,0,0,0,0,0,0,0,0,0,0,0,0,0,0,0,0,0,0,4
4,0,0,0,0,0,0,0,0,0,0,0,0,0,0,0,0,0,0,0,0,0,0,0,0,0,0,0,0,4
4,0,0,0,0,0,0,0,0,0,0,0,0,0,0,0,0,0,0,0,0,0,0,0,0,0,0,0,0,4
7,0,0,0,0,0,0,0,0,0,0,0,0,0,0,0,0,0,0,0,0,0,0,0,0,0,0,0,0,7
1,7,0,0,0,0,0,0,0,0,0,0,0,0,0,0,0,0,0,0,0,0,0,0,0,0,0,0,7,1
1,7,0,0,0,0,0,0,0,0,0,0,0,0,0,0,0,0,0,0,0,0,0,0,0,0,0,0,7,1
1,7,0,0,0,0,0,0,0,0,0,0,0,0,0,0,0,0,0,0,0,0,0,0,0,0,0,0,7,1
1,1,7,0,0,0,0,0,0,0,0,0,0,0,0,0,0,0,0,0,0,0,0,0,0,0,0,7,1,1
1,1,7,0,0,0,0,0,0,0,0,0,0,0,0,0,0,0,0,0,0,0,0,0,0,0,0,7,1,1
1,1,1,7,0,0,0,0,0,0,0,0,0,0,0,0,0,0,0,0,0,0,0,0,0,0,7,1,1,1
1,1,1,1,7,0,0,0,0,0,0,0,0,0,0,0,0,0,0,0,0,0,0,0,0,7,1,1,1,1
1,1,1,1,1,7,0,0,0,0,0,0,0,0,0,0,0,0,0,0,0,0,0,0,7,1,1,1,1,1
1,1,1,1,1,1,7,0,0,0,0,0,0,0,0,0,0,0,0,0,0,0,0,7,1,1,1,1,1,1
1,1,1,1,1,1,1,7,7,0,0,0,0,0,0,0,0,0,0,0,0,7,7,1,1,1,1,1,1,1
1,1,1,1,1,1,1,1,1,7,7,7,0,0,0,0,0,0,7,7,7,1,1,1,1,1,1,1,1,1
1,1,1,1,1,1,1,1,1,1,1,1,7,4,4,4,4,7,1,1,1,1,1,1,1,1,1,1,1,1
endlayer

layer
1,1,1,1,1,1,1,1,1,1,1,1,7,7,4,4,7,7,1,1,1,1,1,1,1,1,1,1,1,1
1,1,1,1,1,1,1,1,1,7,7,7,0,0,0,0,0,0,7,7,7,1,1,1,1,1,1,1,1,1
1,1,1,1,1,1,1,7,7,0,0,0,0,0,0,0,0,0,0,0,0,7,7,1,1,1,1,1,1,1
1,1,1,1,1,1,7,0,0,0,0,0,0,0,0,0,0,0,0,0,0,0,0,7,1,1,1,1,1,1
1,1,1,1,1,7,0,0,0,0,0,0,0,0,0,0,0,0,0,0,0,0,0,0,7,1,1,1,1,1
1,1,1,1,7,0,0,0,0,0,0,0,0,0,0,0,0,0,0,0,0,0,0,0,0,7,1,1,1,1
1,1,1,7,0,0,0,0,0,0,0,0,0,0,0,0,0,0,0,0,0,0,0,0,0,0,7,1,1,1
1,1,7,0,0,0,0,0,0,0,0,0,0,0,0,0,0,0,0,0,0,0,0,0,0,0,0,7,1,1
1,1,7,0,0,0,0,0,0,0,0,0,0,0,0,0,0,0,0,0,0,0,0,0,0,0,0,7,1,1
1,7,0,0,0,0,0,0,0,0,0,0,0,0,0,0,0,0,0,0,0,0,0,0,0,0,0,0,7,1
1,7,0,0,0,0,0,0,0,0,0,0,0,0,0,0,0,0,0,0,0,0,0,0,0,0,0,0,7,1
1,7,0,0,0,0,0,0,0,0,0,0,0,0,0,0,0,0,0,0,0,0,0,0,0,0,0,0,7,1
7,0,0,0,0,0,0,0,0,0,0,0,0,0,0,0,0,0,0,0,0,0,0,0,0,0,0,0,0,7
7,0,0,0,0,0,0,0,0,0,0,0,0,0,0,0,0,0,0,0,0,0,0,0,0,0,0,0,0,7
4,0,0,0,0,0,0,0,0,0,0,0,0,0,0,0,0,0,0,0,0,0,0,0,0,0,0,0,0,4
4,0,0,0,0,0,0,0,0,0,0,0,0,0,0,0,0,0,0,0,0,0,0,0,0,0,0,0,0,4
7,0,0,0,0,0,0,0,0,0,0,0,0,0,0,0,0,0,0,0,0,0,0,0,0,0,0,0,0,7
7,0,0,0,0,0,0,0,0,0,0,0,0,0,0,0,0,0,0,0,0,0,0,0,0,0,0,0,0,7
1,7,0,0,0,0,0,0,0,0,0,0,0,0,0,0,0,0,0,0,0,0,0,0,0,0,0,0,7,1
1,7,0,0,0,0,0,0,0,0,0,0,0,0,0,0,0,0,0,0,0,0,0,0,0,0,0,0,7,1
1,7,0,0,0,0,0,0,0,0,0,0,0,0,0,0,0,0,0,0,0,0,0,0,0,0,0,0,7,1
1,1,7,0,0,0,0,0,0,0,0,0,0,0,0,0,0,0,0,0,0,0,0,0,0,0,0,7,1,1
1,1,7,0,0,0,0,0,0,0,0,0,0,0,0,0,0,0,0,0,0,0,0,0,0,0,0,7,1,1
1,1,1,7,0,0,0,0,0,0,0,0,0,0,0,0,0,0,0,0,0,0,0,0,0,0,7,1,1,1
1,1,1,1,7,0,0,0,0,0,0,0,0,0,0,0,0,0,0,0,0,0,0,0,0,7,1,1,1,1
1,1,1,1,1,7,0,0,0,0,0,0,0,0,0,0,0,0,0,0,0,0,0,0,7,1,1,1,1,1
1,1,1,1,1,1,7,0,0,0,0,0,0,0,0,0,0,0,0,0,0,0,0,7,1,1,1,1,1,1
1,1,1,1,1,1,1,7,7,0,0,0,0,0,0,0,0,0,0,0,0,7,7,1,1,1,1,1,1,1
1,1,1,1,1,1,1,1,1,7,7,7,0,0,0,0,0,0,7,7,7,1,1,1,1,1,1,1,1,1
1,1,1,1,1,1,1,1,1,1,1,1,7,7,4,4,7,7,1,1,1,1,1,1,1,1,1,1,1,1
endlayer

layer
1,1,1,1,1,1,1,1,1,1,1,1,7,7,7,7,7,7,1,1,1,1,1,1,1,1,1,1,1,1
1,1,1,1,1,1,1,1,1,7,7,7,0,0,0,0,0,0,7,7,7,1,1,1,1,1,1,1,1,1
1,1,1,1,1,1,1,7,7,0,0,0,0,0,0,0,0,0,0,0,0,7,7,1,1,1,1,1,1,1
1,1,1,1,1,1,7,0,0,0,0,0,0,0,0,0,0,0,0,0,0,0,0,7,1,1,1,1,1,1
1,1,1,1,1,7,0,0,0,0,0,0,0,0,0,0,0,0,0,0,0,0,0,0,7,1,1,1,1,1
1,1,1,1,7,0,0,0,0,0,0,0,0,0,0,0,0,0,0,0,0,0,0,0,0,7,1,1,1,1
1,1,1,7,0,0,0,0,0,0,0,0,0,0,0,0,0,0,0,0,0,0,0,0,0,0,7,1,1,1
1,1,7,0,0,0,0,0,0,0,0,0,0,0,0,0,0,0,0,0,0,0,0,0,0,0,0,7,1,1
1,1,7,0,0,0,0,0,0,0,0,0,0,0,0,0,0,0,0,0,0,0,0,0,0,0,0,7,1,1
1,7,0,0,0,0,0,0,0,0,0,0,0,0,0,0,0,0,0,0,0,0,0,0,0,0,0,0,7,1
1,7,0,0,0,0,0,0,0,0,0,0,0,0,0,0,0,0,0,0,0,0,0,0,0,0,0,0,7,1
1,7,0,0,0,0,0,0,0,0,0,0,0,0,0,0,0,0,0,0,0,0,0,0,0,0,0,0,7,1
7,0,0,0,0,0,0,0,0,0,0,0,0,0,0,0,0,0,0,0,0,0,0,0,0,0,0,0,0,7
7,0,0,0,0,0,0,0,0,0,0,0,0,0,0,0,0,0,0,0,0,0,0,0,0,0,0,0,0,7
7,0,0,0,0,0,0,0,0,0,0,0,0,0,0,0,0,0,0,0,0,0,0,0,0,0,0,0,0,7
7,0,0,0,0,0,0,0,0,0,0,0,0,0,0,0,0,0,0,0,0,0,0,0,0,0,0,0,0,7
7,0,0,0,0,0,0,0,0,0,0,0,0,0,0,0,0,0,0,0,0,0,0,0,0,0,0,0,0,7
7,0,0,0,0,0,0,0,0,0,0,0,0,0,0,0,0,0,0,0,0,0,0,0,0,0,0,0,0,7
1,7,0,0,0,0,0,0,0,0,0,0,0,0,0,0,0,0,0,0,0,0,0,0,0,0,0,0,7,1
1,7,0,0,0,0,0,0,0,0,0,0,0,0,0,0,0,0,0,0,0,0,0,0,0,0,0,0,7,1
1,7,0,0,0,0,0,0,0,0,0,0,0,0,0,0,0,0,0,0,0,0,0,0,0,0,0,0,7,1
1,1,7,0,0,0,0,0,0,0,0,0,0,0,0,0,0,0,0,0,0,0,0,0,0,0,0,7,1,1
1,1,7,0,0,0,0,0,0,0,0,0,0,0,0,0,0,0,0,0,0,0,0,0,0,0,0,7,1,1
1,1,1,7,0,0,0,0,0,0,0,0,0,0,0,0,0,0,0,0,0,0,0,0,0,0,7,1,1,1
1,1,1,1,7,0,0,0,0,0,0,0,0,0,0,0,0,0,0,0,0,0,0,0,0,7,1,1,1,1
1,1,1,1,1,7,0,0,0,0,0,0,0,0,0,0,0,0,0,0,0,0,0,0,7,1,1,1,1,1
1,1,1,1,1,1,7,0,0,0,0,0,0,0,0,0,0,0,0,0,0,0,0,7,1,1,1,1,1,1
1,1,1,1,1,1,1,7,7,0,0,0,0,0,0,0,0,0,0,0,0,7,7,1,1,1,1,1,1,1
1,1,1,1,1,1,1,1,1,7,7,7,0,0,0,0,0,0,7,7,7,1,1,1,1,1,1,1,1,1
1,1,1,1,1,1,1,1,1,1,1,1,7,7,7,7,7,7,1,1,1,1,1,1,1,1,1,1,1,1
endlayer

layer
1,1,1,1,1,1,1,1,1,1,1,1,1,1,1,1,1,1,1,1,1,1,1,1,1,1,1,1,1,1
1,1,1,1,1,1,1,1,1,1,1,1,7,7,7,7,7,7,1,1,1,1,1,1,1,1,1,1,1,1
1,1,1,1,1,1,1,1,1,7,7,7,0,0,0,0,0,0,7,7,7,1,1,1,1,1,1,1,1,1
1,1,1,1,1,1,1,7,7,0,0,0,0,0,0,0,0,0,0,0,0,7,7,1,1,1,1,1,1,1
1,1,1,1,1,1,7,0,0,0,0,0,0,0,0,0,0,0,0,0,0,0,0,7,1,1,1,1,1,1
1,1,1,1,1,7,0,0,0,0,0,0,0,0,0,0,0,0,0,0,0,0,0,0,7,1,1,1,1,1
1,1,1,1,7,0,0,0,0,0,0,0,0,0,0,0,0,0,0,0,0,0,0,0,0,7,1,1,1,1
1,1,1,7,0,0,0,0,0,0,0,0,0,0,0,0,0,0,0,0,0,0,0,0,0,0,7,1,1,1
1,1,1,7,0,0,0,0,0,0,0,0,0,0,0,0,0,0,0,0,0,0,0,0,0,0,7,1,1,1
1,1,7,0,0,0,0,0,0,0,0,0,0,0,0,0,0,0,0,0,0,0,0,0,0,0,0,7,1,1
1,1,7,0,0,0,0,0,0,0,0,0,0,0,0,0,0,0,0,0,0,0,0,0,0,0,0,7,1,1
1,1,7,0,0,0,0,0,0,0,0,0,0,0,0,0,0,0,0,0,0,0,0,0,0,0,0,7,1,1
1,7,0,0,0,0,0,0,0,0,0,0,0,0,0,0,0,0,0,0,0,0,0,0,0,0,0,0,7,1
1,7,0,0,0,0,0,0,0,0,0,0,0,0,0,0,0,0,0,0,0,0,0,0,0,0,0,0,7,1
1,7,0,0,0,0,0,0,0,0,0,0,0,0,0,0,0,0,0,0,0,0,0,0,0,0,0,0,7,1
1,7,0,0,0,0,0,0,0,0,0,0,0,0,0,0,0,0,0,0,0,0,0,0,0,0,0,0,7,1
1,7,0,0,0,0,0,0,0,0,0,0,0,0,0,0,0,0,0,0,0,0,0,0,0,0,0,0,7,1
1,7,0,0,0,0,0,0,0,0,0,0,0,0,0,0,0,0,0,0,0,0,0,0,0,0,0,0,7,1
1,1,7,0,0,0,0,0,0,0,0,0,0,0,0,0,0,0,0,0,0,0,0,0,0,0,0,7,1,1
1,1,7,0,0,0,0,0,0,0,0,0,0,0,0,0,0,0,0,0,0,0,0,0,0,0,0,7,1,1
1,1,7,0,0,0,0,0,0,0,0,0,0,0,0,0,0,0,0,0,0,0,0,0,0,0,0,7,1,1
1,1,1,7,0,0,0,0,0,0,0,0,0,0,0,0,0,0,0,0,0,0,0,0,0,0,7,1,1,1
1,1,1,7,0,0,0,0,0,0,0,0,0,0,0,0,0,0,0,0,0,0,0,0,0,0,7,1,1,1
1,1,1,1,7,0,0,0,0,0,0,0,0,0,0,0,0,0,0,0,0,0,0,0,0,7,1,1,1,1
1,1,1,1,1,7,0,0,0,0,0,0,0,0,0,0,0,0,0,0,0,0,0,0,7,1,1,1,1,1
1,1,1,1,1,1,7,0,0,0,0,0,0,0,0,0,0,0,0,0,0,0,0,7,1,1,1,1,1,1
1,1,1,1,1,1,1,7,7,0,0,0,0,0,0,0,0,0,0,0,0,7,7,1,1,1,1,1,1,1
1,1,1,1,1,1,1,1,1,7,7,7,0,0,0,0,0,0,7,7,7,1,1,1,1,1,1,1,1,1
1,1,1,1,1,1,1,1,1,1,1,1,7,7,7,7,7,7,1,1,1,1,1,1,1,1,1,1,1,1
1,1,1,1,1,1,1,1,1,1,1,1,1,1,1,1,1,1,1,1,1,1,1,1,1,1,1,1,1,1
endlayer

layer
1,1,1,1,1,1,1,1,1,1,1,1,1,1,1,1,1,1,1,1,1,1,1,1,1,1,1,1,1,1
1,1,1,1,1,1,1,1,1,1,1,1,7,7,7,7,7,7,1,1,1,1,1,1,1,1,1,1,1,1
1,1,1,1,1,1,1,1,1,7,7,7,0,0,0,0,0,0,7,7,7,1,1,1,1,1,1,1,1,1
1,1,1,1,1,1,1,7,7,0,0,0,0,0,0,0,0,0,0,0,0,7,7,1,1,1,1,1,1,1
1,1,1,1,1,1,7,0,0,0,0,0,0,0,0,0,0,0,0,0,0,0,0,7,1,1,1,1,1,1
1,1,1,1,1,7,0,0,0,0,0,0,0,0,0,0,0,0,0,0,0,0,0,0,7,1,1,1,1,1
1,1,1,1,7,0,0,0,0,0,0,0,0,0,0,0,0,0,0,0,0,0,0,0,0,7,1,1,1,1
1,1,1,7,0,0,0,0,0,0,0,0,0,0,0,0,0,0,0,0,0,0,0,0,0,0,7,1,1,1
1,1,1,7,0,0,0,0,0,0,0,0,0,0,0,0,0,0,0,0,0,0,0,0,0,0,7,1,1,1
1,1,7,0,0,0,0,0,0,0,0,0,0,0,0,0,0,0,0,0,0,0,0,0,0,0,0,7,1,1
1,1,7,0,0,0,0,0,0,0,0,0,0,0,0,0,0,0,0,0,0,0,0,0,0,0,0,7,1,1
1,1,7,0,0,0,0,0,0,0,0,0,0,0,0,0,0,0,0,0,0,0,0,0,0,0,0,7,1,1
1,7,0,0,0,0,0,0,0,0,0,0,0,0,0,0,0,0,0,0,0,0,0,0,0,0,0,0,7,1
1,7,0,0,0,0,0,0,0,0,0,0,0,0,0,0,0,0,0,0,0,0,0,0,0,0,0,0,7,1
1,7,0,0,0,0,0,0,0,0,0,0,0,0,0,0,0,0,0,0,0,0,0,0,0,0,0,0,7,1
1,7,0,0,0,0,0,0,0,0,0,0,0,0,0,0,0,0,0,0,0,0,0,0,0,0,0,0,7,1
1,7,0,0,0,0,0,0,0,0,0,0,0,0,0,0,0,0,0,0,0,0,0,0,0,0,0,0,7,1
1,7,0,0,0,0,0,0,0,0,0,0,0,0,0,0,0,0,0,0,0,0,0,0,0,0,0,0,7,1
1,1,7,0,0,0,0,0,0,0,0,0,0,0,0,0,0,0,0,0,0,0,0,0,0,0,0,7,1,1
1,1,7,0,0,0,0,0,0,0,0,0,0,0,0,0,0,0,0,0,0,0,0,0,0,0,0,7,1,1
1,1,7,0,0,0,0,0,0,0,0,0,0,0,0,0,0,0,0,0,0,0,0,0,0,0,0,7,1,1
1,1,1,7,0,0,0,0,0,0,0,0,0,0,0,0,0,0,0,0,0,0,0,0,0,0,7,1,1,1
1,1,1,7,0,0,0,0,0,0,0,0,0,0,0,0,0,0,0,0,0,0,0,0,0,0,7,1,1,1
1,1,1,1,7,0,0,0,0,0,0,0,0,0,0,0,0,0,0,0,0,0,0,0,0,7,1,1,1,1
1,1,1,1,1,7,0,0,0,0,0,0,0,0,0,0,0,0,0,0,0,0,0,0,7,1,1,1,1,1
1,1,1,1,1,1,7,0,0,0,0,0,0,0,0,0,0,0,0,0,0,0,0,7,1,1,1,1,1,1
1,1,1,1,1,1,1,7,7,0,0,0,0,0,0,0,0,0,0,0,0,7,7,1,1,1,1,1,1,1
1,1,1,1,1,1,1,1,1,7,7,7,0,0,0,0,0,0,7,7,7,1,1,1,1,1,1,1,1,1
1,1,1,1,1,1,1,1,1,1,1,1,7,7,7,7,7,7,1,1,1,1,1,1,1,1,1,1,1,1
1,1,1,1,1,1,1,1,1,1,1,1,1,1,1,1,1,1,1,1,1,1,1,1,1,1,1,1,1,1
endlayer

layer
1,1,1,1,1,1,1,1,1,1,1,1,1,1,1,1,1,1,1,1,1,1,1,1,1,1,1,1,1,1
1,1,1,1,1,1,1,1,1,1,1,1,7,7,7,7,7,7,1,1,1,1,1,1,1,1,1,1,1,1
1,1,1,1,1,1,1,1,1,7,7,7,0,0,0,0,0,0,7,7,7,1,1,1,1,1,1,1,1,1
1,1,1,1,1,1,1,7,7,0,0,0,0,0,0,0,0,0,0,0,0,7,7,1,1,1,1,1,1,1
1,1,1,1,1,1,7,0,0,0,0,0,0,0,0,0,0,0,0,0,0,0,0,7,1,1,1,1,1,1
1,1,1,1,1,7,0,0,0,0,0,0,0,0,0,0,0,0,0,0,0,0,0,0,7,1,1,1,1,1
1,1,1,1,7,0,0,0,0,0,0,0,0,0,0,0,0,0,0,0,0,0,0,0,0,7,1,1,1,1
1,1,1,7,0,0,0,0,0,0,0,0,0,0,0,0,0,0,0,0,0,0,0,0,0,0,7,1,1,1
1,1,1,7,0,0,0,0,0,0,0,0,0,0,0,0,0,0,0,0,0,0,0,0,0,0,7,1,1,1
1,1,7,0,0,0,0,0,0,0,0,0,0,0,0,0,0,0,0,0,0,0,0,0,0,0,0,7,1,1
1,1,7,0,0,0,0,0,0,0,0,0,0,0,0,0,0,0,0,0,0,0,0,0,0,0,0,7,1,1
1,1,7,0,0,0,0,0,0,0,0,0,0,0,0,0,0,0,0,0,0,0,0,0,0,0,0,7,1,1
1,7,0,0,0,0,0,0,0,0,0,0,0,0,0,0,0,0,0,0,0,0,0,0,0,0,0,0,7,1
1,7,0,0,0,0,0,0,0,0,0,0,0,0,0,0,0,0,0,0,0,0,0,0,0,0,0,0,7,1
1,7,0,0,0,0,0,0,0,0,0,0,0,0,0,0,0,0,0,0,0,0,0,0,0,0,0,0,7,1
1,7,0,0,0,0,0,0,0,0,0,0,0,0,0,0,0,0,0,0,0,0,0,0,0,0,0,0,7,1
1,7,0,0,0,0,0,0,0,0,0,0,0,0,0,0,0,0,0,0,0,0,0,0,0,0,0,0,7,1
1,7,0,0,0,0,0,0,0,0,0,0,0,0,0,0,0,0,0,0,0,0,0,0,0,0,0,0,7,1
1,1,7,0,0,0,0,0,0,0,0,0,0,0,0,0,0,0,0,0,0,0,0,0,0,0,0,7,1,1
1,1,7,0,0,0,0,0,0,0,0,0,0,0,0,0,0,0,0,0,0,0,0,0,0,0,0,7,1,1
1,1,7,0,0,0,0,0,0,0,0,0,0,0,0,0,0,0,0,0,0,0,0,0,0,0,0,7,1,1
1,1,1,7,0,0,0,0,0,0,0,0,0,0,0,0,0,0,0,0,0,0,0,0,0,0,7,1,1,1
1,1,1,7,0,0,0,0,0,0,0,0,0,0,0,0,0,0,0,0,0,0,0,0,0,0,7,1,1,1
1,1,1,1,7,0,0,0,0,0,0,0,0,0,0,0,0,0,0,0,0,0,0,0,0,7,1,1,1,1
1,1,1,1,1,7,0,0,0,0,0,0,0,0,0,0,0,0,0,0,0,0,0,0,7,1,1,1,1,1
1,1,1,1,1,1,7,0,0,0,0,0,0,0,0,0,0,0,0,0,0,0,0,7,1,1,1,1,1,1
1,1,1,1,1,1,1,7,7,0,0,0,0,0,0,0,0,0,0,0,0,7,7,1,1,1,1,1,1,1
1,1,1,1,1,1,1,1,1,7,7,7,0,0,0,0,0,0,7,7,7,1,1,1,1,1,1,1,1,1
1,1,1,1,1,1,1,1,1,1,1,1,7,7,7,7,7,7,1,1,1,1,1,1,1,1,1,1,1,1
1,1,1,1,1,1,1,1,1,1,1,1,1,1,1,1,1,1,1,1,1,1,1,1,1,1,1,1,1,1
endlayer

layer
1,1,1,1,1,1,1,1,1,1,1,1,1,1,1,1,1,1,1,1,1,1,1,1,1,1,1,1,1,1
1,1,1,1,1,1,1,1,1,1,1,1,1,1,1,1,1,1,1,1,1,1,1,1,1,1,1,1,1,1
1,1,1,1,1,1,1,1,1,1,1,1,7,7,7,7,7,7,1,1,1,1,1,1,1,1,1,1,1,1
1,1,1,1,1,1,1,1,1,7,7,7,0,0,0,0,0,0,7,7,7,1,1,1,1,1,1,1,1,1
1,1,1,1,1,1,1,7,7,0,0,0,0,0,0,0,0,0,0,0,0,7,7,1,1,1,1,1,1,1
1,1,1,1,1,1,7,0,0,0,0,0,0,0,0,0,0,0,0,0,0,0,0,7,1,1,1,1,1,1
1,1,1,1,1,7,0,0,0,0,0,0,0,0,0,0,0,0,0,0,0,0,0,0,7,1,1,1,1,1
1,1,1,1,7,0,0,0,0,0,0,0,0,0,0,0,0,0,0,0,0,0,0,0,0,7,1,1,1,1
1,1,1,1,7,0,0,0,0,0,0,0,0,0,0,0,0,0,0,0,0,0,0,0,0,7,1,1,1,1
1,1,1,7,0,0,0,0,0,0,0,0,0,0,0,0,0,0,0,0,0,0,0,0,0,0,7,1,1,1
1,1,1,7,0,0,0,0,0,0,0,0,0,0,0,0,0,0,0,0,0,0,0,0,0,0,7,1,1,1
1,1,1,7,0,0,0,0,0,0,0,0,0,0,0,0,0,0,0,0,0,0,0,0,0,0,7,1,1,1
1,1,7,0,0,0,0,0,0,0,0,0,0,0,0,0,0,0,0,0,0,0,0,0,0,0,0,7,1,1
1,1,7,0,0,0,0,0,0,0,0,0,0,0,0,0,0,0,0,0,0,0,0,0,0,0,0,7,1,1
1,1,7,0,0,0,0,0,0,0,0,0,0,0,0,0,0,0,0,0,0,0,0,0,0,0,0,7,1,1
1,1,7,0,0,0,0,0,0,0,0,0,0,0,0,0,0,0,0,0,0,0,0,0,0,0,0,7,1,1
1,1,7,0,0,0,0,0,0,0,0,0,0,0,0,0,0,0,0,0,0,0,0,0,0,0,0,7,1,1
1,1,7,0,0,0,0,0,0,0,0,0,0,0,0,0,0,0,0,0,0,0,0,0,0,0,0,7,1,1
1,1,1,7,0,0,0,0,0,0,0,0,0,0,0,0,0,0,0,0,0,0,0,0,0,0,7,1,1,1
1,1,1,7,0,0,0,0,0,0,0,0,0,0,0,0,0,0,0,0,0,0,0,0,0,0,7,1,1,1
1,1,1,7,0,0,0,0,0,0,0,0,0,0,0,0,0,0,0,0,0,0,0,0,0,0,7,1,1,1
1,1,1,1,7,0,0,0,0,0,0,0,0,0,0,0,0,0,0,0,0,0,0,0,0,7,1,1,1,1
1,1,1,1,7,0,0,0,0,0,0,0,0,0,0,0,0,0,0,0,0,0,0,0,0,7,1,1,1,1
1,1,1,1,1,7,0,0,0,0,0,0,0,0,0,0,0,0,0,0,0,0,0,0,7,1,1,1,1,1
1,1,1,1,1,1,7,0,0,0,0,0,0,0,0,0,0,0,0,0,0,0,0,7,1,1,1,1,1,1
1,1,1,1,1,1,1,7,7,0,0,0,0,0,0,0,0,0,0,0,0,7,7,1,1,1,1,1,1,1
1,1,1,1,1,1,1,1,1,7,7,7,0,0,0,0,0,0,7,7,7,1,1,1,1,1,1,1,1,1
1,1,1,1,1,1,1,1,1,1,1,1,7,7,7,7,7,7,1,1,1,1,1,1,1,1,1,1,1,1
1,1,1,1,1,1,1,1,1,1,1,1,1,1,1,1,1,1,1,1,1,1,1,1,1,1,1,1,1,1
1,1,1,1,1,1,1,1,1,1,1,1,1,1,1,1,1,1,1,1,1,1,1,1,1,1,1,1,1,1
endlayer

layer
1,1,1,1,1,1,1,1,1,1,1,1,1,1,1,1,1,1,1,1,1,1,1,1,1,1,1,1,1,1
1,1,1,1,1,1,1,1,1,1,1,1,1,1,1,1,1,1,1,1,1,1,1,1,1,1,1,1,1,1
1,1,1,1,1,1,1,1,1,1,1,1,7,7,7,7,7,7,1,1,1,1,1,1,1,1,1,1,1,1
1,1,1,1,1,1,1,1,1,7,7,7,0,0,0,0,0,0,7,7,7,1,1,1,1,1,1,1,1,1
1,1,1,1,1,1,1,7,7,0,0,0,0,0,0,0,0,0,0,0,0,7,7,1,1,1,1,1,1,1
1,1,1,1,1,1,7,0,0,0,0,0,0,0,0,0,0,0,0,0,0,0,0,7,1,1,1,1,1,1
1,1,1,1,1,7,0,0,0,0,0,0,0,0,0,0,0,0,0,0,0,0,0,0,7,1,1,1,1,1
1,1,1,1,7,0,0,0,0,0,0,0,0,0,0,0,0,0,0,0,0,0,0,0,0,7,1,1,1,1
1,1,1,1,7,0,0,0,0,0,0,0,0,0,0,0,0,0,0,0,0,0,0,0,0,7,1,1,1,1
1,1,1,7,0,0,0,0,0,0,0,0,0,0,0,0,0,0,0,0,0,0,0,0,0,0,7,1,1,1
1,1,1,7,0,0,0,0,0,0,0,0,0,0,0,0,0,0,0,0,0,0,0,0,0,0,7,1,1,1
1,1,1,7,0,0,0,0,0,0,0,0,0,0,0,0,0,0,0,0,0,0,0,0,0,0,7,1,1,1
1,1,7,0,0,0,0,0,0,0,0,0,0,0,0,0,0,0,0,0,0,0,0,0,0,0,0,7,1,1
1,1,7,0,0,0,0,0,0,0,0,0,0,0,0,0,0,0,0,0,0,0,0,0,0,0,0,7,1,1
1,1,7,0,0,0,0,0,0,0,0,0,0,0,0,0,0,0,0,0,0,0,0,0,0,0,0,7,1,1
1,1,7,0,0,0,0,0,0,0,0,0,0,0,0,0,0,0,0,0,0,0,0,0,0,0,0,7,1,1
1,1,7,0,0,0,0,0,0,0,0,0,0,0,0,0,0,0,0,0,0,0,0,0,0,0,0,7,1,1
1,1,7,0,0,0,0,0,0,0,0,0,0,0,0,0,0,0,0,0,0,0,0,0,0,0,0,7,1,1
1,1,1,7,0,0,0,0,0,0,0,0,0,0,0,0,0,0,0,0,0,0,0,0,0,0,7,1,1,1
1,1,1,7,0,0,0,0,0,0,0,0,0,0,0,0,0,0,0,0,0,0,0,0,0,0,7,1,1,1
1,1,1,7,0,0,0,0,0,0,0,0,0,0,0,0,0,0,0,0,0,0,0,0,0,0,7,1,1,1
1,1,1,1,7,0,0,0,0,0,0,0,0,0,0,0,0,0,0,0,0,0,0,0,0,7,1,1,1,1
1,1,1,1,7,0,0,0,0,0,0,0,0,0,0,0,0,0,0,0,0,0,0,0,0,7,1,1,1,1
1,1,1,1,1,7,0,0,0,0,0,0,0,0,0,0,0,0,0,0,0,0,0,0,7,1,1,1,1,1
1,1,1,1,1,1,7,0,0,0,0,0,0,0,0,0,0,0,0,0,0,0,0,7,1,1,1,1,1,1
1,1,1,1,1,1,1,7,7,0,0,0,0,0,0,0,0,0,0,0,0,7,7,1,1,1,1,1,1,1
1,1,1,1,1,1,1,1,1,7,7,7,0,0,0,0,0,0,7,7,7,1,1,1,1,1,1,1,1,1
1,1,1,1,1,1,1,1,1,1,1,1,7,7,7,7,7,7,1,1,1,1,1,1,1,1,1,1,1,1
1,1,1,1,1,1,1,1,1,1,1,1,1,1,1,1,1,1,1,1,1,1,1,1,1,1,1,1,1,1
1,1,1,1,1,1,1,1,1,1,1,1,1,1,1,1,1,1,1,1,1,1,1,1,1,1,1,1,1,1
endlayer

layer
1,1,1,1,1,1,1,1,1,1,1,1,1,1,1,1,1,1,1,1,1,1,1,1,1,1,1,1,1,1
1,1,1,1,1,1,1,1,1,1,1,1,1,1,1,1,1,1,1,1,1,1,1,1,1,1,1,1,1,1
1,1,1,1,1,1,1,1,1,1,1,1,1,1,1,1,1,1,1,1,1,1,1,1,1,1,1,1,1,1
1,1,1,1,1,1,1,1,1,1,1,1,7,7,7,7,7,7,1,1,1,1,1,1,1,1,1,1,1,1
1,1,1,1,1,1,1,1,1,7,7,7,0,0,0,0,0,0,7,7,7,1,1,1,1,1,1,1,1,1
1,1,1,1,1,1,1,7,7,7,0,0,0,0,0,0,0,0,0,0,7,7,7,1,1,1,1,1,1,1
1,1,1,1,1,1,7,7,0,0,0,0,0,0,0,0,0,0,0,0,0,0,7,7,1,1,1,1,1,1
1,1,1,1,1,7,7,0,0,0,0,0,0,0,0,0,0,0,0,0,0,0,0,7,7,1,1,1,1,1
1,1,1,1,1,7,0,0,0,0,0,0,0,0,0,0,0,0,0,0,0,0,0,0,7,1,1,1,1,1
1,1,1,1,7,7,0,0,0,0,0,0,0,0,0,0,0,0,0,0,0,0,0,0,7,7,1,1,1,1
1,1,1,1,7,0,0,0,0,0,0,0,0,0,0,0,0,0,0,0,0,0,0,0,0,7,1,1,1,1
1,1,1,1,7,0,0,0,0,0,0,0,0,0,0,0,0,0,0,0,0,0,0,0,0,7,1,1,1,1
1,1,1,7,0,0,0,0,0,0,0,0,0,0,0,0,0,0,0,0,0,0,0,0,0,0,7,1,1,1
1,1,1,7,0,0,0,0,0,0,0,0,0,0,0,0,0,0,0,0,0,0,0,0,0,0,7,1,1,1
1,1,1,7,0,0,0,0,0,0,0,0,0,0,0,0,0,0,0,0,0,0,0,0,0,0,7,1,1,1
1,1,1,7,0,0,0,0,0,0,0,0,0,0,0,0,0,0,0,0,0,0,0,0,0,0,7,1,1,1
1,1,1,7,0,0,0,0,0,0,0,0,0,0,0,0,0,0,0,0,0,0,0,0,0,0,7,1,1,1
1,1,1,7,0,0,0,0,0,0,0,0,0,0,0,0,0,0,0,0,0,0,0,0,0,0,7,1,1,1
1,1,1,1,7,0,0,0,0,0,0,0,0,0,0,0,0,0,0,0,0,0,0,0,0,7,1,1,1,1
1,1,1,1,7,0,0,0,0,0,0,0,0,0,0,0,0,0,0,0,0,0,0,0,0,7,1,1,1,1
1,1,1,1,7,7,0,0,0,0,0,0,0,0,0,0,0,0,0,0,0,0,0,0,7,7,1,1,1,1
1,1,1,1,1,7,0,0,0,0,0,0,0,0,0,0,0,0,0,0,0,0,0,0,7,1,1,1,1,1
1,1,1,1,1,7,7,0,0,0,0,0,0,0,0,0,0,0,0,0,0,0,0,7,7,1,1,1,1,1
1,1,1,1,1,1,7,7,0,0,0,0,0,0,0,0,0,0,0,0,0,0,7,7,1,1,1,1,1,1
1,1,1,1,1,1,1,7,7,7,0,0,0,0,0,0,0,0,0,0,7,7,7,1,1,1,1,1,1,1
1,1,1,1,1,1,1,1,1,7,7,7,0,0,0,0,0,0,7,7,7,1,1,1,1,1,1,1,1,1
1,1,1,1,1,1,1,1,1,1,1,1,7,7,7,7,7,7,1,1,1,1,1,1,1,1,1,1,1,1
1,1,1,1,1,1,1,1,1,1,1,1,1,1,1,1,1,1,1,1,1,1,1,1,1,1,1,1,1,1
1,1,1,1,1,1,1,1,1,1,1,1,1,1,1,1,1,1,1,1,1,1,1,1,1,1,1,1,1,1
1,1,1,1,1,1,1,1,1,1,1,1,1,1,1,1,1,1,1,1,1,1,1,1,1,1,1,1,1,1
endlayer

layer
1,1,1,1,1,1,1,1,1,1,1,1,1,1,1,1,1,1,1,1,1,1,1,1,1,1,1,1,1,1
1,1,1,1,1,1,1,1,1,1,1,1,1,1,1,1,1,1,1,1,1,1,1,1,1,1,1,1,1,1
1,1,1,1,1,1,1,1,1,1,1,1,1,1,1,1,1,1,1,1,1,1,1,1,1,1,1,1,1,1
1,1,1,1,1,1,1,1,1,1,1,1,1,1,1,1,1,1,1,1,1,1,1,1,1,1,1,1,1,1
1,1,1,1,1,1,1,1,1,1,1,1,7,7,7,7,7,7,1,1,1,1,1,1,1,1,1,1,1,1
1,1,1,1,1,1,1,1,1,1,7,7,0,0,0,0,0,0,7,7,1,1,1,1,1,1,1,1,1,1
1,1,1,1,1,1,1,1,7,7,0,0,0,0,0,0,0,0,0,0,7,7,1,1,1,1,1,1,1,1
1,1,1,1,1,1,1,7,7,0,0,0,0,0,0,0,0,0,0,0,0,7,7,1,1,1,1,1,1,1
1,1,1,1,1,1,7,7,0,0,0,0,0,0,0,0,0,0,0,0,0,0,7,7,1,1,1,1,1,1
1,1,1,1,1,1,7,0,0,0,0,0,0,0,0,0,0,0,0,0,0,0,0,7,1,1,1,1,1,1
1,1,1,1,1,7,0,0,0,0,0,0,0,0,0,0,0,0,0,0,0,0,0,0,7,1,1,1,1,1
1,1,1,1,1,7,0,0,0,0,0,0,0,0,0,0,0,0,0,0,0,0,0,0,7,1,1,1,1,1
1,1,1,1,7,0,0,0,0,0,0,0,0,0,0,0,0,0,0,0,0,0,0,0,0,7,1,1,1,1
1,1,1,1,7,0,0,0,0,0,0,0,0,0,0,0,0,0,0,0,0,0,0,0,0,7,1,1,1,1
1,1,1,1,7,0,0,0,0,0,0,0,0,0,0,0,0,0,0,0,0,0,0,0,0,7,1,1,1,1
1,1,1,1,7,0,0,0,0,0,0,0,0,0,0,0,0,0,0,0,0,0,0,0,0,7,1,1,1,1
1,1,1,1,7,0,0,0,0,0,0,0,0,0,0,0,0,0,0,0,0,0,0,0,0,7,1,1,1,1
1,1,1,1,7,0,0,0,0,0,0,0,0,0,0,0,0,0,0,0,0,0,0,0,0,7,1,1,1,1
1,1,1,1,1,7,0,0,0,0,0,0,0,0,0,0,0,0,0,0,0,0,0,0,7,1,1,1,1,1
1,1,1,1,1,7,0,0,0,0,0,0,0,0,0,0,0,0,0,0,0,0,0,0,7,1,1,1,1,1
1,1,1,1,1,1,7,0,0,0,0,0,0,0,0,0,0,0,0,0,0,0,0,7,1,1,1,1,1,1
1,1,1,1,1,1,7,7,0,0,0,0,0,0,0,0,0,0,0,0,0,0,7,7,1,1,1,1,1,1
1,1,1,1,1,1,1,7,7,0,0,0,0,0,0,0,0,0,0,0,0,7,7,1,1,1,1,1,1,1
1,1,1,1,1,1,1,1,7,7,0,0,0,0,0,0,0,0,0,0,7,7,1,1,1,1,1,1,1,1
1,1,1,1,1,1,1,1,1,1,7,7,0,0,0,0,0,0,7,7,1,1,1,1,1,1,1,1,1,1
1,1,1,1,1,1,1,1,1,1,1,1,7,7,7,7,7,7,1,1,1,1,1,1,1,1,1,1,1,1
1,1,1,1,1,1,1,1,1,1,1,1,1,1,1,1,1,1,1,1,1,1,1,1,1,1,1,1,1,1
1,1,1,1,1,1,1,1,1,1,1,1,1,1,1,1,1,1,1,1,1,1,1,1,1,1,1,1,1,1
1,1,1,1,1,1,1,1,1,1,1,1,1,1,1,1,1,1,1,1,1,1,1,1,1,1,1,1,1,1
1,1,1,1,1,1,1,1,1,1,1,1,1,1,1,1,1,1,1,1,1,1,1,1,1,1,1,1,1,1
endlayer

layer
1,1,1,1,1,1,1,1,1,1,1,1,1,1,1,1,1,1,1,1,1,1,1,1,1,1,1,1,1,1
1,1,1,1,1,1,1,1,1,1,1,1,1,1,1,1,1,1,1,1,1,1,1,1,1,1,1,1,1,1
1,1,1,1,1,1,1,1,1,1,1,1,1,1,1,1,1,1,1,1,1,1,1,1,1,1,1,1,1,1
1,1,1,1,1,1,1,1,1,1,1,1,1,1,1,1,1,1,1,1,1,1,1,1,1,1,1,1,1,1
1,1,1,1,1,1,1,1,1,1,1,1,1,1,1,1,1,1,1,1,1,1,1,1,1,1,1,1,1,1
1,1,1,1,1,1,1,1,1,1,1,1,7,7,7,7,7,7,1,1,1,1,1,1,1,1,1,1,1,1
1,1,1,1,1,1,1,1,1,1,7,7,0,0,0,0,0,0,7,7,1,1,1,1,1,1,1,1,1,1
1,1,1,1,1,1,1,1,1,7,0,0,0,0,0,0,0,0,0,0,7,1,1,1,1,1,1,1,1,1
1,1,1,1,1,1,1,1,7,0,0,0,0,0,0,0,0,0,0,0,0,7,1,1,1,1,1,1,1,1
1,1,1,1,1,1,1,7,0,0,0,0,0,0,0,0,0,0,0,0,0,0,7,1,1,1,1,1,1,1
1,1,1,1,1,1,7,0,0,0,0,0,0,0,0,0,0,0,0,0,0,0,0,7,1,1,1,1,1,1
1,1,1,1,1,1,7,0,0,0,0,0,0,0,0,0,0,0,0,0,0,0,0,7,1,1,1,1,1,1
1,1,1,1,1,7,0,0,0,0,0,0,0,0,0,0,0,0,0,0,0,0,0,0,7,1,1,1,1,1
1,1,1,1,1,7,0,0,0,0,0,0,0,0,0,0,0,0,0,0,0,0,0,0,7,1,1,1,1,1
1,1,1,1,1,7,0,0,0,0,0,0,0,0,0,0,0,0,0,0,0,0,0,0,7,1,1,1,1,1
1,1,1,1,1,7,0,0,0,0,0,0,0,0,0,0,0,0,0,0,0,0,0,0,7,1,1,1,1,1
1,1,1,1,1,7,0,0,0,0,0,0,0,0,0,0,0,0,0,0,0,0,0,0,7,1,1,1,1,1
1,1,1,1,1,7,0,0,0,0,0,0,0,0,0,0,0,0,0,0,0,0,0,0,7,1,1,1,1,1
1,1,1,1,1,1,7,0,0,0,0,0,0,0,0,0,0,0,0,0,0,0,0,7,1,1,1,1,1,1
1,1,1,1,1,1,7,0,0,0,0,0,0,0,0,0,0,0,0,0,0,0,0,7,1,1,1,1,1,1
1,1,1,1,1,1,1,7,0,0,0,0,0,0,0,0,0,0,0,0,0,0,7,1,1,1,1,1,1,1
1,1,1,1,1,1,1,1,7,0,0,0,0,0,0,0,0,0,0,0,0,7,1,1,1,1,1,1,1,1
1,1,1,1,1,1,1,1,1,7,0,0,0,0,0,0,0,0,0,0,7,1,1,1,1,1,1,1,1,1
1,1,1,1,1,1,1,1,1,1,7,7,0,0,0,0,0,0,7,7,1,1,1,1,1,1,1,1,1,1
1,1,1,1,1,1,1,1,1,1,1,1,7,7,7,7,7,7,1,1,1,1,1,1,1,1,1,1,1,1
1,1,1,1,1,1,1,1,1,1,1,1,1,1,1,1,1,1,1,1,1,1,1,1,1,1,1,1,1,1
1,1,1,1,1,1,1,1,1,1,1,1,1,1,1,1,1,1,1,1,1,1,1,1,1,1,1,1,1,1
1,1,1,1,1,1,1,1,1,1,1,1,1,1,1,1,1,1,1,1,1,1,1,1,1,1,1,1,1,1
1,1,1,1,1,1,1,1,1,1,1,1,1,1,1,1,1,1,1,1,1,1,1,1,1,1,1,1,1,1
1,1,1,1,1,1,1,1,1,1,1,1,1,1,1,1,1,1,1,1,1,1,1,1,1,1,1,1,1,1
endlayer

layer
1,1,1,1,1,1,1,1,1,1,1,1,1,1,1,1,1,1,1,1,1,1,1,1,1,1,1,1,1,1
1,1,1,1,1,1,1,1,1,1,1,1,1,1,1,1,1,1,1,1,1,1,1,1,1,1,1,1,1,1
1,1,1,1,1,1,1,1,1,1,1,1,1,1,1,1,1,1,1,1,1,1,1,1,1,1,1,1,1,1
1,1,1,1,1,1,1,1,1,1,1,1,1,1,1,1,1,1,1,1,1,1,1,1,1,1,1,1,1,1
1,1,1,1,1,1,1,1,1,1,1,1,1,1,1,1,1,1,1,1,1,1,1,1,1,1,1,1,1,1
1,1,1,1,1,1,1,1,1,1,1,1,1,1,1,1,1,1,1,1,1,1,1,1,1,1,1,1,1,1
1,1,1,1,1,1,1,1,1,1,1,1,7,7,7,7,7,7,1,1,1,1,1,1,1,1,1,1,1,1
1,1,1,1,1,1,1,1,1,1,7,7,0,0,0,0,0,0,7,7,1,1,1,1,1,1,1,1,1,1
1,1,1,1,1,1,1,1,1,7,0,0,0,0,0,0,0,0,0,0,7,1,1,1,1,1,1,1,1,1
1,1,1,1,1,1,1,1,7,0,0,0,0,0,0,0,0,0,0,0,0,7,1,1,1,1,1,1,1,1
1,1,1,1,1,1,1,7,0,0,0,0,0,0,0,0,0,0,0,0,0,0,7,1,1,1,1,1,1,1
1,1,1,1,1,1,1,7,0,0,0,0,0,0,0,0,0,0,0,0,0,0,7,1,1,1,1,1,1,1
1,1,1,1,1,1,7,0,0,0,0,0,0,0,0,0,0,0,0,0,0,0,0,7,1,1,1,1,1,1
1,1,1,1,1,1,7,0,0,0,0,0,0,0,0,0,0,0,0,0,0,0,0,7,1,1,1,1,1,1
1,1,1,1,1,1,7,0,0,0,0,0,0,0,0,0,0,0,0,0,0,0,0,7,1,1,1,1,1,1
1,1,1,1,1,1,7,0,0,0,0,0,0,0,0,0,0,0,0,0,0,0,0,7,1,1,1,1,1,1
1,1,1,1,1,1,7,0,0,0,0,0,0,0,0,0,0,0,0,0,0,0,0,7,1,1,1,1,1,1
1,1,1,1,1,1,7,0,0,0,0,0,0,0,0,0,0,0,0,0,0,0,0,7,1,1,1,1,1,1
1,1,1,1,1,1,1,7,0,0,0,0,0,0,0,0,0,0,0,0,0,0,7,1,1,1,1,1,1,1
1,1,1,1,1,1,1,7,0,0,0,0,0,0,0,0,0,0,0,0,0,0,7,1,1,1,1,1,1,1
1,1,1,1,1,1,1,1,7,0,0,0,0,0,0,0,0,0,0,0,0,7,1,1,1,1,1,1,1,1
1,1,1,1,1,1,1,1,1,7,0,0,0,0,0,0,0,0,0,0,7,1,1,1,1,1,1,1,1,1
1,1,1,1,1,1,1,1,1,1,7,7,0,0,0,0,0,0,7,7,1,1,1,1,1,1,1,1,1,1
1,1,1,1,1,1,1,1,1,1,1,1,7,7,7,7,7,7,1,1,1,1,1,1,1,1,1,1,1,1
1,1,1,1,1,1,1,1,1,1,1,1,1,1,1,1,1,1,1,1,1,1,1,1,1,1,1,1,1,1
1,1,1,1,1,1,1,1,1,1,1,1,1,1,1,1,1,1,1,1,1,1,1,1,1,1,1,1,1,1
1,1,1,1,1,1,1,1,1,1,1,1,1,1,1,1,1,1,1,1,1,1,1,1,1,1,1,1,1,1
1,1,1,1,1,1,1,1,1,1,1,1,1,1,1,1,1,1,1,1,1,1,1,1,1,1,1,1,1,1
1,1,1,1,1,1,1,1,1,1,1,1,1,1,1,1,1,1,1,1,1,1,1,1,1,1,1,1,1,1
1,1,1,1,1,1,1,1,1,1,1,1,1,1,1,1,1,1,1,1,1,1,1,1,1,1,1,1,1,1
endlayer

layer
1,1,1,1,1,1,1,1,1,1,1,1,1,1,1,1,1,1,1,1,1,1,1,1,1,1,1,1,1,1
1,1,1,1,1,1,1,1,1,1,1,1,1,1,1,1,1,1,1,1,1,1,1,1,1,1,1,1,1,1
1,1,1,1,1,1,1,1,1,1,1,1,1,1,1,1,1,1,1,1,1,1,1,1,1,1,1,1,1,1
1,1,1,1,1,1,1,1,1,1,1,1,1,1,1,1,1,1,1,1,1,1,1,1,1,1,1,1,1,1
1,1,1,1,1,1,1,1,1,1,1,1,1,1,1,1,1,1,1,1,1,1,1,1,1,1,1,1,1,1
1,1,1,1,1,1,1,1,1,1,1,1,1,1,1,1,1,1,1,1,1,1,1,1,1,1,1,1,1,1
1,1,1,1,1,1,1,1,1,1,1,1,1,1,1,1,1,1,1,1,1,1,1,1,1,1,1,1,1,1
1,1,1,1,1,1,1,1,1,1,1,1,7,7,7,7,7,7,1,1,1,1,1,1,1,1,1,1,1,1
1,1,1,1,1,1,1,1,1,1,7,7,7,7,7,7,7,7,7,7,1,1,1,1,1,1,1,1,1,1
1,1,1,1,1,1,1,1,1,7,7,7,0,0,0,0,0,0,7,7,7,1,1,1,1,1,1,1,1,1
1,1,1,1,1,1,1,1,7,7,7,0,0,0,0,0,0,0,0,7,7,7,1,1,1,1,1,1,1,1
1,1,1,1,1,1,1,1,7,7,0,0,0,0,0,0,0,0,0,0,7,7,1,1,1,1,1,1,1,1
1,1,1,1,1,1,1,7,7,0,0,0,0,0,0,0,0,0,0,0,0,7,7,1,1,1,1,1,1,1
1,1,1,1,1,1,1,7,7,0,0,0,0,0,0,0,0,0,0,0,0,7,7,1,1,1,1,1,1,1
1,1,1,1,1,1,1,7,7,0,0,0,0,0,0,0,0,0,0,0,0,7,7,1,1,1,1,1,1,1
1,1,1,1,1,1,1,7,7,0,0,0,0,0,0,0,0,0,0,0,0,7,7,1,1,1,1,1,1,1
1,1,1,1,1,1,1,7,7,0,0,0,0,0,0,0,0,0,0,0,0,7,7,1,1,1,1,1,1,1
1,1,1,1,1,1,1,7,7,0,0,0,0,0,0,0,0,0,0,0,0,7,7,1,1,1,1,1,1,1
1,1,1,1,1,1,1,1,7,7,0,0,0,0,0,0,0,0,0,0,7,7,1,1,1,1,1,1,1,1
1,1,1,1,1,1,1,1,7,7,7,0,0,0,0,0,0,0,0,7,7,7,1,1,1,1,1,1,1,1
1,1,1,1,1,1,1,1,1,7,7,7,0,0,0,0,0,0,7,7,7,1,1,1,1,1,1,1,1,1
1,1,1,1,1,1,1,1,1,1,7,7,7,7,7,7,7,7,7,7,1,1,1,1,1,1,1,1,1,1
1,1,1,1,1,1,1,1,1,1,1,1,7,7,7,7,7,7,1,1,1,1,1,1,1,1,1,1,1,1
1,1,1,1,1,1,1,1,1,1,1,1,1,1,1,1,1,1,1,1,1,1,1,1,1,1,1,1,1,1
1,1,1,1,1,1,1,1,1,1,1,1,1,1,1,1,1,1,1,1,1,1,1,1,1,1,1,1,1,1
1,1,1,1,1,1,1,1,1,1,1,1,1,1,1,1,1,1,1,1,1,1,1,1,1,1,1,1,1,1
1,1,1,1,1,1,1,1,1,1,1,1,1,1,1,1,1,1,1,1,1,1,1,1,1,1,1,1,1,1
1,1,1,1,1,1,1,1,1,1,1,1,1,1,1,1,1,1,1,1,1,1,1,1,1,1,1,1,1,1
1,1,1,1,1,1,1,1,1,1,1,1,1,1,1,1,1,1,1,1,1,1,1,1,1,1,1,1,1,1
1,1,1,1,1,1,1,1,1,1,1,1,1,1,1,1,1,1,1,1,1,1,1,1,1,1,1,1,1,1
endlayer

layer
1,1,1,1,1,1,1,1,1,1,1,1,1,1,1,1,1,1,1,1,1,1,1,1,1,1,1,1,1,1
1,1,1,1,1,1,1,1,1,1,1,1,1,1,1,1,1,1,1,1,1,1,1,1,1,1,1,1,1,1
1,1,1,1,1,1,1,1,1,1,1,1,1,1,1,1,1,1,1,1,1,1,1,1,1,1,1,1,1,1
1,1,1,1,1,1,1,1,1,1,1,1,1,1,1,1,1,1,1,1,1,1,1,1,1,1,1,1,1,1
1,1,1,1,1,1,1,1,1,1,1,1,1,1,1,1,1,1,1,1,1,1,1,1,1,1,1,1,1,1
1,1,1,1,1,1,1,1,1,1,1,1,1,1,1,1,1,1,1,1,1,1,1,1,1,1,1,1,1,1
1,1,1,1,1,1,1,1,1,1,1,1,1,1,1,1,1,1,1,1,1,1,1,1,1,1,1,1,1,1
1,1,1,1,1,1,1,1,1,1,1,1,1,1,1,1,1,1,1,1,1,1,1,1,1,1,1,1,1,1
1,1,1,1,1,1,1,1,1,1,1,1,1,1,1,1,1,1,1,1,1,1,1,1,1,1,1,1,1,1
1,1,1,1,1,1,1,1,1,1,1,1,7,7,7,7,7,7,1,1,1,1,1,1,1,1,1,1,1,1
1,1,1,1,1,1,1,1,1,1,1,7,7,7,7,7,7,7,7,1,1,1,1,1,1,1,1,1,1,1
1,1,1,1,1,1,1,1,1,1,7,7,7,7,7,7,7,7,7,7,1,1,1,1,1,1,1,1,1,1
1,1,1,1,1,1,1,1,1,7,7,7,0,0,0,0,0,0,7,7,7,1,1,1,1,1,1,1,1,1
1,1,1,1,1,1,1,1,1,7,7,7,0,0,0,0,0,0,7,7,7,1,1,1,1,1,1,1,1,1
1,1,1,1,1,1,1,1,1,7,7,7,0,0,0,0,0,0,7,7,7,1,1,1,1,1,1,1,1,1
1,1,1,1,1,1,1,1,1,7,7,7,0,0,0,0,0,0,7,7,7,1,1,1,1,1,1,1,1,1
1,1,1,1,1,1,1,1,1,7,7,7,0,0,0,0,0,0,7,7,7,1,1,1,1,1,1,1,1,1
1,1,1,1,1,1,1,1,1,7,7,7,0,0,0,0,0,0,7,7,7,1,1,1,1,1,1,1,1,1
1,1,1,1,1,1,1,1,1,1,7,7,7,7,7,7,7,7,7,7,1,1,1,1,1,1,1,1,1,1
1,1,1,1,1,1,1,1,1,1,1,7,7,7,7,7,7,7,7,1,1,1,1,1,1,1,1,1,1,1
1,1,1,1,1,1,1,1,1,1,1,1,7,7,7,7,7,7,1,1,1,1,1,1,1,1,1,1,1,1
1,1,1,1,1,1,1,1,1,1,1,1,1,1,1,1,1,1,1,1,1,1,1,1,1,1,1,1,1,1
1,1,1,1,1,1,1,1,1,1,1,1,1,1,1,1,1,1,1,1,1,1,1,1,1,1,1,1,1,1
1,1,1,1,1,1,1,1,1,1,1,1,1,1,1,1,1,1,1,1,1,1,1,1,1,1,1,1,1,1
1,1,1,1,1,1,1,1,1,1,1,1,1,1,1,1,1,1,1,1,1,1,1,1,1,1,1,1,1,1
1,1,1,1,1,1,1,1,1,1,1,1,1,1,1,1,1,1,1,1,1,1,1,1,1,1,1,1,1,1
1,1,1,1,1,1,1,1,1,1,1,1,1,1,1,1,1,1,1,1,1,1,1,1,1,1,1,1,1,1
1,1,1,1,1,1,1,1,1,1,1,1,1,1,1,1,1,1,1,1,1,1,1,1,1,1,1,1,1,1
1,1,1,1,1,1,1,1,1,1,1,1,1,1,1,1,1,1,1,1,1,1,1,1,1,1,1,1,1,1
1,1,1,1,1,1,1,1,1,1,1,1,1,1,1,1,1,1,1,1,1,1,1,1,1,1,1,1,1,1
endlayer

layer
1,1,1,1,1,1,1,1,1,1,1,1,1,1,1,1,1,1,1,1,1,1,1,1,1,1,1,1,1,1
1,1,1,1,1,1,1,1,1,1,1,1,1,1,1,1,1,1,1,1,1,1,1,1,1,1,1,1,1,1
1,1,1,1,1,1,1,1,1,1,1,1,1,1,1,1,1,1,1,1,1,1,1,1,1,1,1,1,1,1
1,1,1,1,1,1,1,1,1,1,1,1,1,1,1,1,1,1,1,1,1,1,1,1,1,1,1,1,1,1
1,1,1,1,1,1,1,1,1,1,1,1,1,1,1,1,1,1,1,1,1,1,1,1,1,1,1,1,1,1
1,1,1,1,1,1,1,1,1,1,1,1,1,1,1,1,1,1,1,1,1,1,1,1,1,1,1,1,1,1
1,1,1,1,1,1,1,1,1,1,1,1,1,1,1,1,1,1,1,1,1,1,1,1,1,1,1,1,1,1
1,1,1,1,1,1,1,1,1,1,1,1,1,1,1,1,1,1,1,1,1,1,1,1,1,1,1,1,1,1
1,1,1,1,1,1,1,1,1,1,1,1,1,1,1,1,1,1,1,1,1,1,1,1,1,1,1,1,1,1
1,1,1,1,1,1,1,1,1,1,1,1,1,1,1,1,1,1,1,1,1,1,1,1,1,1,1,1,1,1
1,1,1,1,1,1,1,1,1,1,1,1,1,1,1,1,1,1,1,1,1,1,1,1,1,1,1,1,1,1
1,1,1,1,1,1,1,1,1,1,1,1,1,1,1,1,1,1,1,1,1,1,1,1,1,1,1,1,1,1
1,1,1,1,1,1,1,1,1,1,1,1,7,7,7,7,7,7,1,1,1,1,1,1,1,1,1,1,1,1
1,1,1,1,1,1,1,1,1,1,1,1,7,7,7,7,7,7,1,1,1,1,1,1,1,1,1,1,1,1
1,1,1,1,1,1,1,1,1,1,1,1,7,7,7,7,7,7,1,1,1,1,1,1,1,1,1,1,1,1
1,1,1,1,1,1,1,1,1,1,1,1,7,7,7,7,7,7,1,1,1,1,1,1,1,1,1,1,1,1
1,1,1,1,1,1,1,1,1,1,1,1,7,7,7,7,7,7,1,1,1,1,1,1,1,1,1,1,1,1
1,1,1,1,1,1,1,1,1,1,1,1,7,7,7,7,7,7,1,1,1,1,1,1,1,1,1,1,1,1
1,1,1,1,1,1,1,1,1,1,1,1,1,1,1,1,1,1,1,1,1,1,1,1,1,1,1,1,1,1
1,1,1,1,1,1,1,1,1,1,1,1,1,1,1,1,1,1,1,1,1,1,1,1,1,1,1,1,1,1
1,1,1,1,1,1,1,1,1,1,1,1,1,1,1,1,1,1,1,1,1,1,1,1,1,1,1,1,1,1
1,1,1,1,1,1,1,1,1,1,1,1,1,1,1,1,1,1,1,1,1,1,1,1,1,1,1,1,1,1
1,1,1,1,1,1,1,1,1,1,1,1,1,1,1,1,1,1,1,1,1,1,1,1,1,1,1,1,1,1
1,1,1,1,1,1,1,1,1,1,1,1,1,1,1,1,1,1,1,1,1,1,1,1,1,1,1,1,1,1
1,1,1,1,1,1,1,1,1,1,1,1,1,1,1,1,1,1,1,1,1,1,1,1,1,1,1,1,1,1
1,1,1,1,1,1,1,1,1,1,1,1,1,1,1,1,1,1,1,1,1,1,1,1,1,1,1,1,1,1
1,1,1,1,1,1,1,1,1,1,1,1,1,1,1,1,1,1,1,1,1,1,1,1,1,1,1,1,1,1
1,1,1,1,1,1,1,1,1,1,1,1,1,1,1,1,1,1,1,1,1,1,1,1,1,1,1,1,1,1
1,1,1,1,1,1,1,1,1,1,1,1,1,1,1,1,1,1,1,1,1,1,1,1,1,1,1,1,1,1
1,1,1,1,1,1,1,1,1,1,1,1,1,1,1,1,1,1,1,1,1,1,1,1,1,1,1,1,1,1
endlayer
