# uses blocks from ExtrabiomesXL
# If you need help, consult template_rules.txt
biomesToSpawnIn=red rock mountains,lush desert,outback,mesa,mesa (bryce),mesa plateau, mesa plateau f m,
weight=10
embed_into_distance=1
unacceptable_target_blocks=flowing_water,water,flowing_lava,lava,Natura:Cloud
dimensions=6,7,11
allowable_overhang=0
max_leveling=2
leveling_buffer=1
preserve_water=0
preserve_lava=0
preserve_plants=0


rule1=0,100,preserveBlock
rule2=0,100,ExtrabiomesXL:terrain_blocks1-1
rule3=0,100,ExtrabiomesXL:slabRedRock-1
rule4=0,100,ExtrabiomesXL:door_cypress-3
rule5=0,100,iron_bars
rule6=2,100,torch-3
rule7=2,100,torch-4
rule8=0,100,ExtrabiomesXL:door_cypress-8
rule9=0,100,ExtrabiomesXL:slabRedRock-9


layer
1,1,1,1,1,1,1,1,1,1,1
1,1,1,1,1,1,1,1,1,1,1
1,1,1,1,1,1,1,1,1,1,1
1,1,1,1,1,1,1,1,1,1,1
1,1,1,1,1,1,1,1,1,1,1
1,1,1,1,1,1,1,1,1,1,1
1,1,1,1,1,1,1,1,1,1,1
endlayer

layer
2,2,2,2,2,2,2,2,2,2,2
3,2,2,2,2,2,2,2,2,1,2
3,2,2,2,2,2,2,2,2,1,2
3,2,2,2,2,2,2,2,2,2,2
3,2,2,2,2,2,2,2,2,2,2
3,2,2,2,2,2,2,2,2,2,2
2,2,2,2,2,2,2,2,2,2,2
endlayer

layer
0,3,3,3,2,2,2,2,2,2,2
0,0,0,0,2,0,0,0,0,0,2
0,0,0,0,2,0,0,0,0,0,2
0,0,0,0,4,0,0,0,0,0,2
0,0,0,0,2,0,0,0,0,0,2
0,0,0,0,2,0,0,0,0,0,2
0,3,3,3,2,2,2,2,2,2,2
endlayer

layer
0,0,0,0,2,2,5,2,5,2,2
0,0,0,0,5,0,0,0,0,0,2
0,0,0,0,2,7,0,0,0,6,2
0,0,0,0,8,0,0,0,0,0,5
0,0,0,0,2,7,0,0,0,6,2
0,0,0,0,5,0,0,0,0,0,2
0,0,0,0,2,2,5,2,5,2,2
endlayer

layer
0,0,0,0,2,2,2,2,2,2,2
0,0,0,3,2,9,9,9,9,9,2
0,0,0,0,2,9,9,9,9,9,2
0,0,0,3,2,9,9,9,9,9,2
0,0,0,0,2,9,9,9,9,9,2
0,0,0,3,2,9,9,9,9,9,2
0,0,0,0,2,2,2,2,2,2,2
endlayer

layer
0,0,0,0,3,3,3,3,3,3,3
0,0,0,0,3,0,0,0,0,0,3
0,0,0,0,3,0,0,0,0,0,3
0,0,0,0,3,0,0,0,0,0,3
0,0,0,0,3,0,0,0,0,0,3
0,0,0,0,3,0,0,0,0,0,3
0,0,0,0,3,3,3,3,3,3,3
endlayer

