
# Created by Ruins mod version 14.5 Ingame Parser
# authoring Player: Sinhika
# uses blocks from Simple Ores 2 Fusion plugin
#
weight=1
embed_into_distance=1
acceptable_target_blocks=
unacceptable_target_blocks=flowing_water,water,flowing_lava,lava,Natura:Cloud
dimensions=9,7,7
allowable_overhang=0
max_leveling=1
leveling_buffer=1
preserve_water=0
preserve_lava=0

rule1=0,100,preserveBlock
rule2=0,100,minecraft:stone-0
rule3=0,100,preserveBlock
rule4=0,100,minecraft:stone_stairs-0
rule5=0,100,minecraft:stone_stairs-3
rule6=0,100,minecraft:stone_stairs-2
rule7=0,100,minecraft:cobblestone-0
rule8=1,100,minecraft:torch-5
rule9=0,100,minecraft:hopper-5
rule10=0,100,minecraft:furnace-5
rule11=0,100,minecraft:stone_stairs-1
rule12=0,100,minecraft:stone_stairs-7
rule13=0,100,minecraft:stone_stairs-6
rule14=0,100,minecraft:stone_stairs-5
rule15=0,100,minecraft:hopper-3
rule16=0,100,fusionplugin:fusion_furnace-4
rule17=0,100,minecraft:hopper-2
rule18=0,100,minecraft:stone_stairs-4
rule19=0,100,minecraft:hopper-0
rule20=0,100,minecraft:stone_slab-3
rule21=0,100,minecraft:netherrack-0
rule22=0,100,minecraft:fire-15

layer
1,1,2,2,2,1,1
1,3,2,2,2,3,1
2,2,2,2,2,2,2
2,2,2,2,2,2,2
2,2,2,2,2,2,2
1,3,2,2,2,3,1
1,1,2,2,2,1,1
endlayer

layer
5,4,0,0,0,4,4
5,7,0,0,0,7,6
0,0,0,0,0,0,0
0,0,8,9,8,0,0
0,0,0,9,0,0,0
5,7,0,10,0,7,6
11,11,0,0,0,11,6
endlayer

layer
0,0,0,0,0,0,0
0,5,13,0,12,6,0
0,14,0,0,0,14,0
0,17,17,16,15,15,0
0,18,0,0,0,18,0
0,7,13,14,12,7,0
0,0,0,0,0,0,0
endlayer

layer
0,0,0,0,0,0,0
0,0,5,4,6,0,0
0,5,7,9,7,6,0
0,5,7,19,0,6,0
0,5,0,0,0,6,0
0,5,11,11,11,6,0
0,0,0,0,0,0,0
endlayer

layer
0,0,0,0,0,0,0
0,0,0,0,0,0,0
0,0,7,19,7,0,0
0,0,7,7,7,0,0
0,0,7,7,7,0,0
0,0,0,0,0,0,0
0,0,0,0,0,0,0
endlayer

layer
0,0,0,0,0,0,0
0,0,0,0,0,0,0
0,0,7,7,7,0,0
0,0,7,0,7,0,0
0,0,7,7,7,0,0
0,0,0,0,0,0,0
0,0,0,0,0,0,0
endlayer

layer
0,0,0,0,0,0,0
0,0,0,0,0,0,0
0,0,7,7,7,0,0
0,0,7,0,7,0,0
0,0,7,7,7,0,0
0,0,0,0,0,0,0
0,0,0,0,0,0,0
endlayer

layer
0,0,0,0,0,0,0
0,0,0,0,0,0,0
0,0,20,7,20,0,0
0,0,7,21,7,0,0
0,0,20,7,20,0,0
0,0,0,0,0,0,0
0,0,0,0,0,0,0
endlayer

layer
0,0,0,0,0,0,0
0,0,0,0,0,0,0
0,0,0,4,0,0,0
0,0,5,22,6,0,0
0,0,0,11,0,0,0
0,0,0,0,0,0,0
0,0,0,0,0,0,0
endlayer

