# Converted from schematic
# THIS TEMPLATE USES DEFAULTS!  Please edit for corrections.
# If you need help, consult template_rules.txt
uniqueMinDistance=2000
weight=1
embed_into_distance=5
acceptable_target_blocks=stone,grass,dirt,sand,gravel
dimensions=9,33,34
allowable_overhang=0
max_leveling=2
leveling_buffer=1
preserve_water=0
preserve_lava=0
preserve_plants=0
rule1=0,100,stone
rule2=0,100,dirt
rule3=0,100,coal_ore
rule4=1,100,gravel
rule5=1,100,redstone_wire-9
rule6=1,100,redstone_wire-10
rule7=1,100,redstone_wire-11
rule8=1,100,redstone_wire-12
rule9=1,100,redstone_wire-13
rule10=1,100,redstone_wire-14
rule11=1,100,redstone_wire-8
rule12=1,100,redstone_wire
rule13=1,100,redstone_wire-7
rule14=1,100,redstone_wire-6
rule15=1,100,powered_repeater-2
rule16=1,100,redstone_wire-15
rule17=1,100,unpowered_repeater
rule18=1,100,redstone_wire-5
rule19=1,100,redstone_wire-4
rule20=1,100,redstone_wire-3
rule21=1,100,powered_repeater-1
rule22=1,100,torch-5
rule23=0,100,stonebrick
rule24=2,100,torch-3
rule25=2,100,torch-2
rule26=0,100,wool
rule27=2,100,torch-4
rule28=0,100,grass
rule29=0,100,stone_brick_stairs-3
rule30=0,100,web
rule31=0,100,sticky_piston-13
rule32=0,100,piston_head-13
rule33=0,100,dispenser-4
rule34=1,100,stone_pressure_plate
rule35=1,100,lever-14
rule36=0,100,MobSpawner:Skeleton,MobSpawner:Zombie
rule37=1,100,lever-13
rule38=0,100,stonebrick-3
rule39=0,100,sticky_piston-5
rule40=0,100,ChestGenHook:dungeonChest:5-3
rule41=0,100,ChestGenHook:dungeonChest:6-5
rule42=0,100,ChestGenHook:dungeonChest:4-4
rule43=2,100,torch-1
rule44=0,100,piston_head-12
rule45=0,100,sticky_piston-12
rule46=1,100,lever-5
rule47=1,100,tallgrass-1
rule48=2,100,lever-11
# mage light
# rule49=0,100,-14-2
rule49=0,100,glowstone
rule50=0,100,stone_brick_stairs-6
rule51=0,100,stone_brick_stairs-7
rule52=0,100,stone_brick_stairs-4
rule53=0,100,stone_brick_stairs-5


layer
1,1,1,1,1,1,1,1,1,1,1,1,1,1,1,1,1,1,1,1,1,1,1,1,1,1,1,1,1,1,2,1,1,1
1,1,1,1,1,1,1,1,1,1,1,1,1,1,1,1,1,1,1,1,1,1,2,1,1,1,1,1,1,1,1,1,1,1
1,1,1,1,1,1,1,1,1,1,1,1,1,1,1,1,1,1,1,1,2,2,2,2,1,1,1,1,1,1,1,1,1,1
1,1,1,1,1,1,1,1,1,1,1,1,1,1,1,1,1,1,2,2,2,2,2,2,1,1,1,1,1,1,1,1,2,2
1,1,1,1,1,1,1,1,1,1,1,1,1,1,1,1,1,2,2,2,2,2,2,2,1,1,1,1,1,1,1,1,1,2
1,1,1,1,1,1,1,1,1,1,1,1,1,1,1,1,1,2,2,2,2,2,2,1,2,2,2,1,1,1,1,1,1,2
1,1,1,1,1,1,1,1,1,1,1,1,1,1,1,1,2,2,2,2,2,2,1,1,2,2,2,2,1,1,1,1,1,1
1,1,1,1,1,1,1,1,1,1,1,1,1,1,1,1,2,2,2,2,1,1,1,1,2,2,2,2,1,1,1,1,1,1
1,1,1,1,1,1,1,1,1,1,1,1,1,1,1,1,1,1,1,1,1,1,1,1,2,2,2,2,1,1,1,1,1,1
1,1,1,1,1,1,1,1,1,1,1,1,1,1,1,1,1,1,1,1,1,1,1,1,2,2,2,2,2,1,1,1,1,1
1,1,1,1,1,1,1,1,1,1,1,1,1,1,1,1,1,1,1,1,1,1,1,1,1,2,2,2,2,1,1,1,1,1
1,1,1,1,1,1,1,1,1,1,1,1,1,1,1,1,1,1,1,1,1,1,1,1,1,2,2,2,2,1,1,1,1,1
1,1,1,1,1,1,1,1,1,1,1,1,1,1,1,1,1,1,1,1,1,1,1,1,1,1,2,2,1,1,1,1,1,1
1,1,1,1,1,1,1,1,1,1,1,1,1,1,1,1,1,1,1,1,1,1,1,1,1,1,1,1,1,1,1,1,1,1
1,1,1,1,1,1,1,1,1,1,1,1,1,1,1,1,1,1,1,1,1,1,1,1,1,1,1,1,1,1,1,1,1,1
1,1,1,1,1,1,1,1,1,1,1,1,1,1,1,1,1,1,1,1,1,1,1,1,1,3,3,1,1,1,1,1,1,1
1,1,1,1,1,1,1,1,1,1,1,1,1,1,1,1,1,1,1,1,1,1,1,1,1,3,3,1,1,1,1,1,1,1
1,1,1,1,1,1,1,1,1,1,1,1,1,1,1,1,1,1,1,1,1,1,1,1,1,3,3,1,1,1,1,1,1,1
1,1,1,1,1,1,1,1,1,1,1,1,1,1,1,1,1,1,2,2,2,2,2,2,1,1,3,1,1,1,1,1,1,1
1,1,1,1,1,1,1,1,1,1,1,1,1,1,1,1,1,2,2,2,2,2,2,2,2,1,1,1,1,1,1,1,1,1
1,1,1,1,1,1,1,1,1,1,1,1,1,1,1,1,1,1,2,2,2,2,2,2,2,2,1,1,1,1,1,1,1,1
1,1,1,1,1,1,1,1,1,1,1,1,1,1,1,1,1,1,1,2,2,2,2,2,2,1,1,1,1,1,1,1,1,1
1,1,1,1,1,1,1,1,1,1,1,1,1,1,1,1,1,1,1,1,1,1,1,1,1,1,1,1,1,1,1,1,1,1
1,1,1,1,1,1,1,1,1,1,1,1,1,1,1,1,1,1,1,1,1,1,1,1,1,1,1,1,1,1,1,1,1,1
1,1,1,1,1,1,1,1,1,1,1,1,1,1,1,1,1,1,1,1,1,1,1,1,1,1,1,1,1,1,1,1,1,1
1,1,1,1,1,1,1,1,1,1,1,1,1,1,1,1,1,1,1,1,1,1,1,1,1,1,1,1,1,1,1,1,1,1
1,1,1,1,1,1,1,1,1,4,4,1,1,1,1,1,1,1,1,1,1,1,1,1,1,1,1,1,1,1,1,1,1,1
1,1,1,1,1,1,1,1,4,4,4,4,4,1,1,1,1,1,1,1,1,1,1,1,1,1,1,1,1,1,1,1,1,1
1,1,1,1,1,1,1,1,1,4,4,4,4,4,4,1,1,1,1,1,1,1,1,1,1,1,1,1,1,1,1,1,1,1
1,1,1,1,1,1,1,1,1,1,1,4,4,4,4,1,1,1,1,1,1,1,1,1,1,1,1,1,1,1,1,1,1,1
1,1,1,1,1,1,1,1,1,1,1,1,1,1,1,1,1,1,1,1,1,1,1,1,1,1,1,1,1,1,1,1,1,1
1,1,1,1,1,1,1,1,1,1,1,1,1,1,1,1,1,1,1,1,1,1,1,1,1,1,1,1,1,1,1,1,1,1
1,1,1,1,1,1,1,1,1,1,1,1,1,1,1,1,1,1,4,4,4,1,1,1,1,1,1,1,1,1,1,1,1,1
endlayer

layer
1,1,1,1,1,1,1,1,1,1,1,1,1,1,1,1,1,1,2,2,2,2,2,2,2,2,2,2,2,2,2,2,2,1
1,1,1,1,1,1,1,1,1,1,1,1,1,1,1,1,1,2,2,2,2,2,2,2,2,2,2,2,2,2,2,2,2,2
1,1,1,1,1,1,1,1,2,2,2,2,2,2,2,2,2,2,2,2,2,2,2,2,2,2,2,2,2,2,1,2,2,2
1,1,1,1,1,1,1,2,2,2,2,2,2,2,2,2,2,2,2,2,2,2,2,2,2,2,2,2,2,2,1,2,2,2
1,1,1,1,1,1,1,2,2,2,2,2,2,2,2,2,2,2,2,2,2,2,2,2,2,2,2,2,2,1,2,1,2,2
1,1,1,1,1,1,1,2,2,2,2,2,2,2,2,2,2,2,2,2,2,2,2,2,2,2,2,2,1,1,1,1,2,2
1,1,1,1,1,1,1,2,2,2,2,2,2,2,2,2,2,2,2,2,2,2,2,2,2,2,2,2,1,1,1,1,1,2
1,1,1,1,1,1,1,1,2,2,2,2,2,2,2,2,2,2,2,2,2,2,2,2,2,2,2,2,1,1,1,1,1,2
1,1,1,1,1,1,1,2,2,2,2,2,2,2,2,2,2,2,2,2,2,2,2,2,2,2,2,2,1,1,1,1,1,1
1,1,1,1,1,1,1,1,1,1,2,2,2,2,2,2,2,2,2,2,2,2,2,2,2,2,2,2,1,1,1,1,1,1
1,1,1,1,1,1,1,1,1,1,2,1,2,1,2,2,1,2,2,2,2,2,2,2,2,2,2,2,1,1,1,1,1,1
1,1,1,1,1,1,1,1,1,1,1,2,1,2,1,1,1,1,1,2,2,2,2,2,2,1,2,2,1,1,1,1,1,1
1,1,1,1,1,1,1,1,1,1,1,1,1,1,1,1,1,1,1,1,1,1,1,1,1,1,1,1,1,1,1,1,1,1
1,1,1,1,1,1,1,1,1,1,1,1,1,1,1,1,1,1,1,1,1,1,1,1,1,3,1,1,1,1,1,1,1,1
1,1,1,1,1,1,1,1,1,1,1,1,1,1,1,1,1,1,1,1,1,1,1,1,1,3,3,1,1,1,1,1,1,1
1,1,1,1,1,1,1,1,1,1,1,1,1,1,1,1,1,1,1,1,1,1,1,1,1,3,3,1,1,1,1,1,1,1
1,1,1,1,1,1,1,1,1,1,1,1,1,1,1,1,1,1,1,1,1,1,1,1,1,3,3,1,1,1,1,1,1,1
1,1,1,1,1,1,1,1,1,1,1,1,1,1,1,1,1,1,1,1,1,1,1,1,1,3,3,1,1,1,1,1,1,1
1,1,1,1,1,1,1,1,1,1,1,1,1,1,1,1,1,1,1,1,2,1,1,1,1,1,3,1,1,1,1,1,1,1
1,1,1,1,1,1,1,1,1,1,1,1,1,1,1,1,1,1,1,2,2,2,2,2,1,1,1,1,1,1,1,1,1,1
1,1,1,1,1,1,1,1,1,1,1,1,1,1,1,1,1,1,1,2,2,2,2,2,1,1,1,1,1,1,1,1,1,1
1,1,1,1,1,1,1,1,1,1,1,1,1,1,1,1,1,1,1,1,1,1,1,1,1,1,1,1,1,1,1,1,1,1
1,1,1,1,1,1,1,1,1,1,1,1,1,1,1,1,1,1,1,1,1,1,1,1,1,1,1,1,1,1,1,1,1,1
1,1,1,1,1,1,1,1,1,1,1,1,1,1,1,1,1,1,1,1,1,1,1,1,1,1,1,1,1,1,1,1,1,1
1,1,1,1,1,1,1,1,1,1,1,1,1,1,1,1,1,1,1,1,1,1,1,1,1,1,1,1,1,1,1,1,1,1
1,1,1,1,1,1,1,1,1,4,1,1,1,1,1,1,1,1,1,1,1,1,1,1,1,1,1,1,1,1,1,1,1,1
1,1,1,1,1,1,1,4,4,4,4,4,4,1,1,1,1,1,1,1,1,1,1,1,1,1,1,1,1,1,1,1,1,1
1,1,1,1,1,1,1,4,4,4,4,4,4,4,1,1,1,1,1,1,1,1,1,1,1,1,1,1,1,1,1,1,1,1
1,1,1,1,1,1,1,1,4,4,4,4,4,4,4,1,1,1,1,1,1,1,1,1,1,1,1,1,1,1,1,1,1,1
1,1,1,1,1,1,1,1,1,4,4,4,4,4,4,4,1,1,1,1,1,1,1,1,1,1,1,1,1,1,1,1,1,1
1,1,1,1,1,1,1,1,1,1,1,1,1,4,4,1,1,1,1,3,3,3,1,1,1,1,1,1,1,1,1,1,1,1
1,1,1,1,1,1,1,1,1,1,1,1,1,1,1,1,1,1,1,3,3,3,1,1,1,1,1,1,1,1,1,1,1,1
1,1,1,1,1,1,1,1,1,1,1,1,1,1,1,1,1,1,1,1,1,1,1,1,1,1,1,1,1,1,1,1,1,1
endlayer

layer
1,1,1,1,1,1,1,1,1,1,1,1,1,2,2,2,2,2,2,2,2,2,2,2,2,2,2,2,2,2,2,2,2,2
1,1,1,1,1,1,1,2,2,2,2,2,2,2,2,2,2,2,2,2,2,2,2,2,2,2,2,2,2,2,2,2,2,2
1,1,1,1,1,1,2,2,2,2,2,2,2,2,2,2,2,2,2,2,2,2,2,2,2,2,2,2,2,2,2,2,2,2
1,1,1,1,1,1,2,2,2,2,2,2,2,2,2,2,2,2,2,2,2,2,2,2,2,2,2,2,2,2,2,2,2,2
1,1,1,1,1,1,2,2,2,2,2,2,2,2,2,2,2,2,2,2,2,2,2,2,2,2,2,2,2,2,2,4,2,2
1,1,1,1,1,2,2,2,2,2,2,2,2,2,2,2,2,2,2,2,2,2,2,2,2,2,2,2,2,2,1,1,2,2
1,1,1,1,1,2,1,2,2,2,2,2,2,2,2,2,2,2,2,2,2,2,2,2,2,2,2,2,2,2,1,1,2,2
1,1,1,1,1,1,2,2,2,2,2,2,2,2,2,2,2,2,2,2,2,2,2,2,2,2,2,2,2,1,1,1,1,2
1,1,1,1,1,1,1,2,2,2,2,2,2,2,2,2,2,2,2,2,2,2,2,2,2,2,2,2,2,1,1,1,1,2
1,1,1,1,1,1,2,2,2,2,2,2,2,2,2,2,2,2,2,2,2,2,2,2,2,2,2,2,1,1,1,1,1,1
1,1,1,1,1,1,2,2,2,2,2,2,2,2,2,2,2,2,2,2,2,2,2,2,2,2,2,2,1,1,1,1,1,1
1,1,1,1,1,2,2,2,2,2,2,2,2,2,2,2,2,2,2,2,2,2,2,2,2,2,2,1,1,1,1,1,1,1
1,1,1,1,1,2,2,2,2,2,2,2,2,2,2,1,1,2,2,2,2,2,2,2,2,2,1,1,1,1,1,1,1,1
1,1,1,1,1,2,2,2,2,2,2,2,2,2,1,1,1,2,2,2,2,2,2,2,2,3,1,1,1,1,1,1,1,1
2,2,1,1,1,2,2,2,2,2,2,2,2,1,1,1,1,2,2,2,2,2,2,1,1,3,3,1,1,1,1,1,1,1
2,2,2,2,1,2,2,2,2,2,2,2,1,1,1,1,1,2,2,2,2,2,1,1,1,3,3,1,1,1,1,1,1,1
2,2,2,2,1,2,2,2,2,2,2,1,1,1,1,1,1,1,1,2,2,1,1,1,1,3,3,1,1,1,1,1,1,1
2,2,2,2,2,2,2,2,2,2,1,1,1,1,1,1,1,2,1,2,1,1,1,1,1,1,1,1,1,1,1,1,1,1
2,2,2,2,2,2,2,1,1,1,1,1,1,1,1,1,1,1,2,1,1,1,1,1,1,1,1,1,1,1,1,1,1,1
2,2,2,2,2,2,1,1,1,1,1,1,1,1,1,1,1,1,1,1,1,1,1,1,1,1,1,1,1,1,1,1,1,1
2,2,2,2,1,1,1,1,1,1,1,1,1,1,1,1,1,1,1,1,1,1,1,1,1,1,1,1,1,1,1,1,1,1
2,2,1,1,1,1,1,1,1,1,1,1,1,1,1,1,1,1,1,1,1,1,1,1,1,1,1,1,1,1,1,1,1,1
1,1,1,1,1,1,1,1,1,1,1,1,1,1,1,1,1,1,1,1,1,1,1,1,1,1,1,1,1,1,1,1,1,1
1,1,1,1,1,1,1,1,1,1,1,1,1,1,1,1,1,1,1,1,1,1,1,1,1,1,1,1,1,1,1,1,1,1
1,1,1,1,1,1,1,1,1,1,1,1,1,1,1,1,1,1,1,1,1,1,1,1,1,1,1,1,1,1,1,1,1,1
1,1,1,1,1,1,1,4,4,4,4,1,1,1,1,1,1,1,1,1,1,1,1,1,1,1,1,1,1,1,1,1,1,1
1,1,1,1,1,1,4,4,4,4,4,4,1,1,1,1,1,1,1,1,1,1,1,1,1,1,1,1,1,1,1,1,1,1
1,1,1,1,1,1,4,4,2,2,4,4,4,1,1,1,1,1,1,1,1,1,1,1,1,1,1,1,1,1,1,1,1,1
1,1,1,1,1,1,1,1,4,4,4,1,4,4,1,1,1,1,1,1,1,1,1,1,1,1,1,1,1,1,1,1,1,1
1,1,1,1,1,1,1,1,1,4,4,4,4,4,4,1,1,1,1,1,1,1,1,1,1,1,1,1,1,1,1,1,1,1
1,1,1,1,1,1,1,1,1,1,1,1,1,1,1,1,1,3,3,3,3,3,1,1,1,1,1,1,1,1,1,1,1,1
1,1,1,1,1,1,1,1,1,1,1,1,1,1,1,1,1,3,3,3,3,3,1,1,1,1,1,1,1,1,1,1,1,1
1,1,1,1,1,1,1,1,1,1,1,1,1,1,1,1,1,1,1,1,1,1,1,1,1,1,1,1,1,1,1,1,1,1
endlayer

layer
1,1,1,1,1,2,2,2,2,2,2,2,2,2,2,2,2,2,2,2,2,2,2,2,2,2,2,2,2,2,2,2,2,2
1,1,1,1,1,2,2,2,2,2,2,2,2,2,2,2,2,2,2,2,2,2,2,2,2,2,2,2,2,2,2,2,2,2
2,1,1,1,1,2,2,2,2,2,2,2,2,2,2,2,2,2,2,2,2,2,2,2,2,2,2,2,2,2,2,2,2,2
2,2,1,1,1,2,2,2,2,2,2,2,2,2,2,2,2,2,2,2,2,2,2,2,2,2,2,2,2,2,2,2,2,2
2,2,2,1,2,2,2,2,2,2,2,2,2,2,2,2,2,2,2,2,2,2,2,2,2,2,2,2,2,2,2,2,2,2
1,1,2,2,2,1,2,2,2,2,2,2,2,2,2,2,2,2,2,2,2,2,2,2,2,2,2,2,2,2,2,2,2,2
1,1,1,2,2,2,0,0,1,2,2,2,2,2,2,2,2,2,2,2,2,2,2,2,0,2,2,2,2,2,2,2,2,2
1,1,1,1,2,2,2,22,10,2,2,2,2,2,2,2,16,15,14,13,11,5,6,7,8,9,2,2,2,2,2,1,1,2
1,1,1,1,1,2,2,0,9,2,2,2,2,2,2,2,10,0,2,2,2,2,2,2,2,2,2,2,2,2,2,1,1,1
1,1,1,1,2,2,2,2,8,2,2,2,2,2,2,2,9,2,2,2,2,2,2,2,2,2,1,2,2,2,1,1,1,1
1,1,1,2,2,2,2,2,7,2,2,2,2,2,2,2,8,2,2,2,2,2,2,2,1,2,0,2,2,2,1,1,1,1
1,1,2,2,2,2,2,2,6,2,2,2,2,2,2,1,7,2,2,2,2,2,2,2,2,1,1,2,2,2,1,1,1,1
1,2,2,2,2,2,2,2,5,2,2,2,2,2,2,2,2,2,2,2,2,2,2,2,2,8,0,2,2,1,1,1,1,1
2,2,2,2,2,2,2,2,11,2,2,2,2,2,2,2,2,2,2,2,2,2,2,2,2,9,0,2,1,1,1,1,1,1
2,2,2,2,2,2,2,2,13,2,2,2,2,2,2,2,2,2,2,2,2,2,2,2,2,10,1,1,1,1,1,1,1,1
2,2,2,2,2,2,2,2,14,2,2,2,2,2,2,2,2,2,2,2,2,2,2,1,1,1,1,1,1,1,1,1,1,1
2,2,2,2,2,2,2,2,18,2,2,2,2,2,2,2,2,2,2,2,2,2,2,1,1,1,1,1,1,1,1,1,1,1
2,2,2,2,2,2,2,2,19,2,2,2,2,2,2,2,2,2,2,2,1,1,2,1,1,1,1,1,1,1,1,1,1,1
2,11,2,2,2,2,2,2,20,2,2,2,2,2,2,2,2,2,2,1,1,1,1,1,1,1,1,1,1,1,1,1,1,1
2,5,2,2,2,2,2,2,21,2,2,2,2,2,2,1,2,2,1,1,1,1,1,1,1,1,1,1,5,1,1,1,1,1
2,6,2,2,2,2,2,0,16,10,9,8,7,6,5,0,2,2,1,1,12,1,1,1,1,1,1,1,6,1,1,1,1,1
2,2,1,2,2,2,2,2,2,2,2,2,2,2,0,12,17,12,12,12,12,1,1,1,1,1,1,1,7,1,1,1,1,1
2,2,2,2,2,2,2,1,2,2,2,2,2,2,12,12,1,1,0,0,0,1,1,1,1,1,1,1,8,1,1,1,1,1
2,2,2,2,2,2,2,2,2,2,2,2,2,2,12,1,2,2,1,1,1,1,1,1,1,1,1,1,9,1,1,1,1,1
2,1,2,2,2,2,2,2,2,2,2,2,2,2,12,2,2,2,1,1,1,1,1,1,1,1,1,1,1,1,1,1,1,1
2,2,2,2,2,2,2,2,2,2,2,2,0,12,12,2,2,2,1,1,1,1,1,1,1,1,1,1,1,1,1,1,1,1
2,2,2,2,2,2,2,2,2,2,1,1,1,1,0,2,2,2,1,1,1,1,1,1,1,1,1,1,1,1,1,1,1,1
2,2,2,2,2,2,2,2,2,2,1,1,1,1,1,2,2,2,1,1,1,1,1,1,1,1,1,1,1,1,1,1,1,1
2,2,2,1,2,2,2,2,2,2,1,1,1,1,2,2,2,2,2,1,1,1,1,1,1,1,1,1,1,1,1,1,1,1
2,1,1,2,2,2,1,1,2,2,1,1,1,2,2,2,2,2,2,1,1,1,1,1,1,1,1,1,1,1,1,1,1,1
2,2,2,2,2,2,2,2,2,2,1,1,1,2,2,2,1,2,2,2,3,1,1,1,1,1,1,1,1,1,1,1,1,1
2,2,2,2,2,2,2,2,2,2,1,1,1,2,2,2,2,2,2,1,2,1,1,1,1,1,1,1,1,1,1,1,1,1
2,1,1,2,2,2,2,2,2,2,2,2,2,2,2,1,2,2,2,2,2,1,1,1,1,1,1,1,1,1,1,1,1,2
endlayer

layer
2,2,1,1,2,2,2,2,1,2,2,2,2,2,2,2,2,2,23,23,23,23,23,23,23,23,23,23,23,23,23,2,2,2
2,2,1,1,1,1,1,1,1,1,1,1,1,1,1,1,1,1,1,1,1,1,1,1,1,1,1,1,1,1,1,1,2,2
2,2,1,1,1,1,1,1,1,1,1,1,1,1,1,1,1,1,1,1,1,1,1,1,1,1,1,1,1,1,1,1,1,2
2,2,1,1,1,1,1,1,1,1,1,1,1,1,1,1,1,1,1,1,1,1,1,1,1,1,1,1,1,1,1,1,1,2
2,1,1,1,1,1,1,1,1,1,1,1,1,1,1,1,1,1,1,1,1,1,1,1,1,1,1,1,1,1,1,1,1,2
2,2,1,1,1,1,1,1,1,1,1,1,1,1,1,1,1,1,1,1,1,1,1,1,1,1,1,1,1,1,1,1,1,2
1,2,1,1,1,1,1,1,16,1,1,1,1,1,1,1,1,1,1,1,1,1,1,1,1,10,16,1,1,1,1,1,1,2
1,1,1,1,1,1,1,0,0,1,1,1,1,1,1,1,1,0,0,1,0,0,0,25,1,0,1,1,1,1,1,1,1,1
1,1,1,1,1,1,1,1,1,1,1,1,1,1,1,1,1,0,1,1,1,1,1,1,1,1,1,1,1,1,1,1,1,1
1,2,1,1,1,1,1,1,0,1,1,1,1,1,1,1,1,1,1,1,1,1,1,1,1,1,1,1,1,1,1,1,1,1
2,2,1,1,1,1,1,1,1,1,1,1,1,1,1,1,1,1,1,1,1,1,1,1,1,1,0,1,1,1,1,1,1,1
2,2,1,1,1,1,1,1,0,1,1,1,1,1,1,6,0,1,1,1,1,1,1,1,1,7,1,1,1,1,1,1,1,2
2,2,1,1,1,1,0,11,0,1,1,1,1,1,1,1,1,1,1,1,1,1,1,1,1,0,0,1,1,1,1,1,1,2
28,2,1,1,1,1,1,0,0,1,1,1,1,1,1,1,1,1,1,1,1,1,1,1,1,1,1,1,1,1,1,1,1,2
28,1,1,1,1,1,1,1,1,1,1,1,1,1,1,1,1,1,1,1,1,1,1,1,1,24,1,1,1,1,1,1,1,2
1,1,1,1,1,1,1,1,1,1,1,1,1,1,1,1,1,1,1,1,1,1,1,1,1,16,1,1,12,1,1,1,1,1
29,1,1,1,1,1,1,1,1,1,1,1,1,1,1,1,1,1,1,1,1,1,1,1,1,1,1,1,1,1,1,1,1,1
1,2,1,1,1,1,1,1,1,1,1,1,1,1,1,1,1,26,1,1,1,1,1,1,1,1,1,1,1,1,1,1,1,1
23,0,13,1,1,1,1,1,1,1,1,1,1,1,1,1,1,1,1,1,1,1,1,1,1,1,1,1,1,13,0,1,1,1
23,23,0,1,1,1,1,1,1,1,1,1,1,5,11,23,1,1,1,1,12,1,1,1,1,1,1,1,0,11,0,1,1,1
23,0,23,1,1,1,1,27,1,0,1,0,1,0,23,23,1,12,12,1,0,1,1,1,1,1,1,1,1,1,1,1,1,1
23,7,8,1,1,1,1,1,1,1,1,1,1,1,0,0,1,0,0,0,1,1,1,1,1,1,1,1,0,1,1,1,1,2
28,2,1,1,1,1,1,1,1,1,1,1,1,1,1,1,1,1,1,1,1,1,1,1,1,1,1,1,1,1,1,1,1,2
28,2,1,1,1,1,1,1,1,1,1,1,1,1,0,1,1,1,1,1,1,1,1,1,1,1,1,10,0,1,1,1,1,2
28,2,1,1,1,1,1,1,1,1,1,1,1,1,0,1,1,1,1,1,1,1,1,1,1,1,1,16,1,1,1,1,1,2
28,2,1,1,1,1,1,1,1,1,1,1,0,0,25,1,1,1,1,1,1,1,1,1,1,1,1,1,1,1,1,1,1,2
28,2,1,1,1,1,1,1,1,1,1,1,23,12,1,1,1,1,1,1,1,1,1,1,1,1,1,1,1,1,1,1,1,2
28,2,1,1,1,1,1,1,1,1,1,1,23,1,1,1,1,1,1,1,1,1,1,1,1,1,1,1,1,1,1,1,1,2
28,2,1,1,1,1,1,1,1,1,1,1,1,0,1,1,1,1,1,1,1,1,1,1,1,1,1,1,1,1,1,1,1,2
28,2,1,1,1,1,1,1,1,1,1,1,1,1,1,1,1,1,1,1,1,1,1,1,1,1,1,1,1,1,1,1,1,2
28,2,1,1,1,1,1,1,1,1,1,1,1,1,1,1,1,1,1,1,1,1,1,1,1,1,1,1,1,1,1,1,1,2
28,2,1,1,1,1,1,1,1,1,1,1,1,1,1,1,2,1,1,1,1,1,1,1,1,1,1,1,1,1,1,1,1,2
28,2,2,2,2,2,2,2,2,2,2,2,2,2,2,1,2,1,2,2,2,2,2,2,1,1,1,1,1,1,1,1,1,2
endlayer

layer
2,2,2,2,2,1,2,2,1,2,2,2,2,23,23,23,23,23,23,23,23,23,23,23,23,23,23,23,23,23,23,23,23,23
2,2,23,23,23,23,23,23,23,23,23,23,23,23,23,23,23,23,23,23,23,23,23,23,23,23,23,23,23,23,23,23,1,2
2,2,23,0,0,23,0,0,0,0,0,0,0,0,0,23,0,0,0,0,0,0,0,0,0,0,0,0,0,0,0,0,23,2
2,2,23,0,23,23,0,23,23,23,0,23,23,23,0,23,0,23,23,23,23,23,23,23,0,23,23,23,23,23,23,0,23,2
2,2,23,0,0,0,0,23,23,0,0,0,23,23,0,23,0,23,23,0,0,0,23,36,0,23,23,0,0,30,23,0,23,2
2,2,23,23,23,23,0,23,37,0,0,0,23,23,0,23,0,23,23,0,23,0,23,0,0,23,37,0,0,0,0,0,23,2
2,2,23,0,0,0,0,23,23,30,0,30,23,23,0,23,0,23,23,0,23,0,0,0,0,23,23,0,0,0,23,0,23,2
2,2,23,0,23,23,0,23,23,23,23,23,23,23,23,0,0,23,23,0,23,23,23,23,0,23,23,23,23,23,23,0,23,2
2,2,23,0,23,0,0,0,23,0,0,23,23,23,44,23,0,23,23,0,0,0,0,0,0,0,0,0,0,0,0,0,23,2
2,2,23,0,23,23,23,23,44,23,0,0,23,23,45,23,0,23,23,0,23,23,23,0,23,23,23,23,23,0,23,0,23,2
28,2,23,0,0,23,0,0,45,23,23,0,23,23,23,23,23,0,23,0,23,0,23,0,23,6,23,23,23,0,23,0,23,2
28,2,23,23,0,23,0,13,23,23,23,0,0,23,5,43,23,0,23,0,23,0,0,0,23,0,31,23,23,0,23,0,23,2
28,23,23,23,0,23,0,0,23,23,23,23,0,23,23,23,23,0,23,0,23,23,23,23,23,23,32,23,23,0,23,0,23,2
0,23,23,23,23,23,23,23,23,0,23,23,0,23,0,0,0,0,0,0,0,23,0,0,0,0,23,0,23,23,23,0,23,2
0,23,23,23,0,0,0,0,0,0,0,23,0,36,23,23,23,23,23,23,0,23,0,23,23,23,23,0,34,0,0,0,23,2
0,23,23,23,0,23,23,23,0,23,0,23,0,23,23,23,38,23,23,38,0,23,0,23,23,23,35,23,23,33,23,30,23,2
0,0,23,0,0,0,0,23,0,23,0,23,0,23,23,38,0,41,38,23,0,23,0,23,23,0,0,0,23,23,23,23,23,2
0,23,44,23,23,23,0,23,0,23,0,23,0,0,23,0,0,0,40,23,23,23,0,0,0,0,0,0,23,14,1,23,23,2
0,23,45,23,36,23,0,23,0,23,0,23,0,23,44,38,0,42,38,38,22,23,0,23,23,0,0,0,23,25,31,23,23,2
23,23,23,23,30,23,0,23,0,23,0,23,0,23,45,23,38,23,23,12,0,23,0,36,23,23,23,23,23,23,32,23,23,2
0,23,9,23,30,23,0,23,0,23,0,23,0,23,13,23,0,0,0,39,0,23,0,0,0,0,0,0,0,0,23,0,23,2
0,23,0,23,0,23,0,23,36,23,0,23,0,23,23,23,23,23,23,23,23,23,23,23,23,23,23,23,23,23,23,0,23,2
0,23,23,0,0,0,0,23,23,23,0,23,30,0,0,0,0,0,0,0,0,0,0,0,23,0,0,0,0,0,0,0,23,2
0,23,23,0,23,23,23,23,23,23,23,23,23,0,23,23,23,0,23,23,23,23,23,0,23,0,23,23,23,23,23,0,23,2
0,23,23,0,23,0,0,0,23,0,0,0,23,0,23,0,0,0,0,0,23,0,0,0,23,0,23,23,35,23,23,0,23,2
0,23,23,0,23,0,23,0,23,0,23,0,23,23,23,0,23,23,23,0,23,0,23,23,23,0,23,0,0,0,23,0,23,2
47,23,23,0,0,0,23,0,0,0,23,0,23,23,0,0,0,0,23,0,23,0,23,0,0,0,23,0,0,0,0,0,23,2
0,23,23,0,23,23,23,23,23,0,23,0,23,46,0,0,0,0,23,0,23,0,23,0,23,0,23,0,0,30,23,0,23,2
0,23,23,0,23,36,23,0,23,0,23,0,23,23,0,0,0,0,23,0,23,0,23,30,23,0,23,23,23,23,23,0,23,2
47,23,23,0,23,0,23,0,23,0,23,0,23,23,23,23,23,23,23,0,23,0,23,23,23,0,23,23,23,23,23,0,23,2
0,23,23,0,0,0,23,30,0,0,23,0,0,0,0,0,0,0,0,0,23,0,0,0,0,0,23,36,30,0,0,0,23,2
0,23,23,23,23,23,23,23,23,23,23,36,23,23,23,23,23,23,23,23,23,23,23,23,23,23,23,23,23,23,23,23,23,2
0,23,23,23,23,23,23,23,23,23,23,23,23,23,23,23,23,23,23,23,23,2,2,1,2,2,2,2,2,2,2,2,2,2
endlayer

layer
0,2,23,23,23,23,23,23,23,23,23,23,23,23,23,23,23,23,23,23,23,23,23,23,23,23,23,23,23,23,23,23,23,23
28,2,23,23,23,23,23,23,23,23,23,23,23,23,23,23,23,23,23,23,23,23,23,23,23,23,23,23,23,23,23,23,23,23
28,2,23,0,0,23,0,0,0,0,0,0,0,0,0,23,0,0,0,0,0,0,0,0,0,0,0,0,0,0,0,0,23,23
0,23,23,0,23,23,0,23,23,23,0,23,23,23,0,23,0,23,23,23,23,23,23,23,0,23,23,23,23,23,23,0,23,23
0,23,23,0,0,0,0,23,23,0,0,0,23,23,0,23,0,23,23,0,0,0,23,0,0,23,23,0,0,0,23,0,23,23
0,23,23,23,23,23,0,23,23,0,0,0,23,23,0,23,0,23,23,0,23,0,23,0,0,23,23,0,0,0,0,0,23,23
0,23,23,0,0,0,0,23,23,0,0,30,23,23,0,23,0,23,23,0,23,0,0,0,0,23,23,0,0,0,23,0,23,23
28,2,23,0,23,23,0,23,23,23,23,23,23,23,23,0,0,23,23,0,23,23,23,23,0,23,23,23,23,23,23,0,23,23
28,23,23,0,23,0,0,0,23,0,0,23,23,23,44,23,0,23,23,0,0,0,0,0,0,0,0,0,0,0,0,0,23,23
28,23,23,0,23,23,23,23,44,23,0,0,23,23,45,23,0,23,23,0,23,23,23,0,23,23,23,23,23,0,23,0,23,23
47,23,23,0,0,23,0,0,45,23,23,0,23,13,11,23,23,0,23,0,23,0,23,0,23,0,5,11,23,0,23,0,23,23
0,23,23,23,0,23,0,0,14,18,23,0,0,23,0,0,23,0,23,0,23,0,0,0,23,25,31,23,23,0,23,0,23,23
0,23,23,23,0,23,25,0,23,23,23,23,0,23,23,23,23,0,23,0,23,23,23,23,23,23,32,23,23,0,23,0,23,23
0,23,23,23,23,23,23,23,23,0,23,23,0,23,0,0,0,0,0,0,0,23,0,0,0,0,23,0,23,23,23,0,23,23
0,23,23,23,0,0,0,0,0,0,0,23,0,23,23,23,23,23,23,23,0,23,0,23,23,23,23,0,0,0,0,0,23,23
0,23,23,38,0,23,23,23,0,23,0,23,0,23,23,23,38,23,38,23,0,23,0,23,23,23,23,23,23,0,23,0,23,23
0,0,23,0,0,0,0,23,0,23,0,23,0,23,23,38,0,0,38,38,0,23,0,23,23,0,0,0,23,23,23,23,23,23
0,23,44,38,23,23,0,23,0,23,0,23,0,0,23,0,0,0,0,23,23,23,0,0,0,0,0,0,23,0,18,23,0,23
48,23,45,23,30,23,0,23,0,23,0,23,0,23,44,38,0,0,38,38,0,23,0,23,23,0,0,0,23,23,31,23,23,23
23,16,10,23,0,23,0,23,0,23,0,23,0,23,45,23,38,23,12,0,0,23,0,0,23,23,23,23,23,23,32,23,23,23
0,23,0,23,30,23,0,23,0,23,0,23,0,23,0,14,0,0,23,39,23,23,0,0,0,0,0,0,0,0,23,0,23,23
0,23,23,23,0,23,0,23,0,23,0,23,0,23,23,23,23,23,23,23,23,23,23,23,23,23,23,23,23,23,23,0,23,23
0,23,23,0,0,0,0,23,23,23,0,23,30,0,0,0,0,0,0,0,0,0,0,0,23,0,0,0,0,0,0,0,23,23
0,23,23,0,23,23,23,23,23,23,23,23,23,0,23,23,23,0,23,23,23,23,23,0,23,0,23,23,23,23,23,0,23,23
0,23,23,0,23,0,0,0,23,0,0,0,23,0,23,0,0,0,0,0,23,0,0,0,23,0,23,23,23,23,23,0,23,23
0,23,23,0,23,0,23,0,23,0,23,0,23,23,23,0,23,23,23,0,23,0,23,23,23,0,23,0,0,0,23,0,23,23
0,23,23,0,0,0,23,0,0,0,23,0,23,23,0,0,0,0,23,0,23,0,23,0,0,0,23,0,0,0,0,0,23,23
0,23,23,0,23,23,23,23,23,0,23,0,23,23,0,0,0,0,23,0,23,0,23,0,23,0,23,0,0,0,23,0,23,23
0,23,23,0,23,30,23,0,23,0,23,0,23,23,0,0,0,0,23,0,23,0,23,0,23,0,23,23,23,23,23,0,23,23
0,23,23,0,23,0,23,0,23,0,23,0,23,23,23,23,23,23,23,0,23,0,23,23,23,0,23,23,23,23,23,0,23,23
0,23,23,0,0,0,23,0,0,0,23,0,0,0,0,0,0,0,0,0,23,0,0,0,0,0,23,30,30,0,0,0,23,23
0,23,23,23,23,23,23,23,23,23,23,23,23,23,23,23,23,23,23,23,23,23,23,23,23,23,23,23,23,23,23,23,23,23
0,23,23,23,23,23,23,23,23,23,23,23,23,23,23,23,23,23,23,23,23,23,23,23,23,23,23,23,23,23,23,23,23,23
endlayer

layer
0,23,23,23,23,23,23,23,23,23,23,23,23,23,23,23,23,23,23,23,23,23,23,23,23,23,23,23,23,23,23,23,23,23
47,23,23,23,23,23,23,23,23,23,23,23,23,23,23,23,23,23,23,23,23,23,23,23,23,23,23,23,23,23,23,23,23,23
0,23,23,0,49,23,49,0,0,0,0,0,0,0,49,23,49,0,0,0,0,0,0,0,49,0,0,0,0,0,0,49,23,23
0,23,23,0,23,23,0,23,23,23,0,23,23,23,0,23,0,23,23,23,23,23,23,23,0,23,23,23,23,23,23,0,23,23
0,23,23,49,0,0,0,23,23,0,0,0,23,23,0,23,0,23,23,49,0,49,23,0,0,23,23,0,0,0,23,0,23,23
0,23,23,23,23,23,0,23,23,0,49,0,23,23,0,23,0,23,23,0,23,0,23,0,0,23,23,0,49,0,0,0,23,23
0,23,23,49,0,0,0,23,23,0,0,30,23,23,0,23,0,23,23,0,23,49,0,0,0,23,23,0,0,30,23,0,23,23
0,23,23,0,23,23,0,23,23,23,23,23,23,23,23,49,0,23,23,0,23,23,23,23,0,23,23,23,23,23,23,0,23,23
0,23,23,0,23,49,0,49,23,49,49,23,23,23,0,23,0,23,23,49,0,0,0,0,0,0,0,0,0,0,0,49,23,23
0,23,23,0,23,23,23,23,23,23,0,0,23,14,0,23,49,23,23,0,23,23,23,0,23,23,23,23,23,0,23,0,23,23
0,23,23,0,0,23,0,0,0,19,23,0,23,27,0,23,23,49,23,0,23,49,23,0,23,0,0,43,23,0,23,0,23,23
0,23,23,23,0,23,0,0,25,0,23,49,0,23,0,0,23,0,23,0,23,0,0,49,23,0,0,13,23,0,23,0,23,23
0,23,23,23,49,23,0,0,23,23,23,23,0,23,23,23,23,0,23,0,23,23,23,23,23,23,23,23,23,49,23,0,23,23
0,23,23,23,23,23,23,23,23,49,23,23,0,23,49,0,0,0,0,0,0,23,49,0,0,49,23,0,23,23,23,0,23,23
0,23,23,23,0,0,0,0,0,0,49,23,0,23,23,23,23,23,23,23,0,23,0,23,23,23,23,49,0,0,0,0,23,23
0,23,23,23,49,23,23,23,0,23,0,23,0,23,23,23,38,23,38,23,0,23,0,23,23,23,23,23,23,49,23,49,23,23
0,51,23,50,0,0,49,23,0,23,0,23,0,23,23,38,0,0,38,38,49,23,0,23,23,0,0,0,23,23,23,23,23,23
0,23,23,23,23,23,0,23,0,23,0,23,0,49,23,0,49,0,0,23,23,23,0,0,0,0,49,0,23,0,0,19,23,23
0,23,23,23,49,23,0,23,0,23,0,23,0,23,23,38,0,0,38,38,0,23,0,23,23,0,0,0,23,22,0,20,23,23
0,23,23,23,0,23,0,23,0,23,0,23,0,23,0,18,38,23,0,0,25,23,0,30,23,23,23,23,23,23,23,23,23,23
0,23,23,23,0,23,0,23,0,23,0,23,0,23,27,0,0,25,12,0,23,23,49,0,0,30,0,0,0,49,23,49,23,23
0,23,23,23,0,23,0,23,49,23,0,23,0,23,23,23,23,23,23,23,23,23,23,23,23,23,23,23,23,23,23,0,23,23
0,23,23,0,0,0,49,23,23,23,49,23,30,0,0,0,0,0,49,23,30,0,0,49,23,49,0,0,0,0,0,0,23,23
0,23,23,0,23,23,23,23,23,23,23,23,23,0,23,23,23,0,23,23,23,23,23,0,23,0,23,23,23,23,23,0,23,23
0,23,23,0,23,0,0,49,23,30,0,49,23,49,23,49,0,0,0,49,23,49,0,30,23,0,23,23,23,23,23,0,23,23
0,23,23,0,23,0,23,0,23,0,23,0,23,23,23,0,23,23,23,0,23,0,23,23,23,0,23,30,0,0,23,0,23,23
0,23,23,0,0,49,23,49,0,0,23,0,23,23,0,0,0,0,23,0,23,0,23,0,0,0,23,0,49,0,0,0,23,23
0,23,23,0,23,23,23,23,23,0,23,0,23,23,0,0,49,0,23,0,23,0,23,30,23,0,23,0,0,0,23,0,23,23
0,23,23,0,23,49,23,49,23,0,23,0,23,23,30,0,0,0,23,0,23,0,23,49,23,0,23,23,23,23,23,0,23,23
0,23,23,0,23,0,23,30,23,0,23,0,23,23,23,23,23,23,23,0,23,0,23,23,23,0,23,23,23,23,23,0,23,23
0,23,23,49,0,0,23,0,0,49,23,49,0,0,0,0,0,0,0,49,23,49,0,0,0,49,23,49,0,0,0,49,23,23
0,23,23,23,23,23,23,23,23,23,23,23,23,23,23,23,23,23,23,23,23,23,23,23,23,23,23,23,23,23,23,23,23,23
0,23,23,23,23,23,23,23,23,23,23,23,23,23,23,23,23,23,23,23,23,23,23,23,23,23,23,23,23,23,23,23,23,23
endlayer

layer
0,23,52,52,52,52,52,52,52,52,52,52,52,52,52,52,52,52,52,52,52,52,52,52,52,52,52,52,52,52,52,52,52,23
0,51,23,23,23,23,23,23,23,23,23,23,23,23,23,23,23,23,23,23,23,23,23,23,23,23,23,23,23,23,23,23,23,50
0,51,23,23,23,23,23,23,23,23,23,23,23,23,23,23,23,23,23,23,23,23,23,23,23,23,23,23,23,23,23,23,23,50
0,51,23,23,23,23,23,23,23,23,23,23,23,23,23,23,23,23,23,23,23,23,23,23,23,23,23,23,23,23,23,23,23,50
0,51,23,23,23,23,23,23,23,23,23,23,23,23,23,23,23,23,23,23,23,23,23,23,23,23,23,23,23,23,23,23,23,50
0,51,23,23,23,23,23,23,23,23,23,23,23,23,23,23,23,23,23,23,23,23,23,23,23,23,23,23,23,23,23,23,23,50
0,51,23,23,23,23,23,23,23,23,23,23,23,23,23,23,23,23,23,23,23,23,23,23,23,23,23,23,23,23,23,23,23,50
0,51,23,23,23,23,23,23,23,23,23,23,23,23,23,23,23,23,23,23,23,23,23,23,23,23,23,23,23,23,23,23,23,50
0,51,23,23,23,23,23,23,23,23,23,23,23,23,23,23,23,23,23,23,23,23,23,23,23,23,23,23,23,23,23,23,23,50
0,51,23,23,23,23,23,23,23,23,23,23,23,23,23,23,23,23,23,23,23,23,23,23,23,23,23,23,23,23,23,23,23,50
0,51,23,23,23,23,23,23,23,23,23,23,23,23,23,23,23,23,23,23,23,23,23,23,23,23,23,23,23,23,23,23,23,50
0,51,23,23,23,23,23,23,23,23,23,23,23,23,23,23,23,23,23,23,23,23,23,23,23,23,23,23,23,23,23,23,23,50
0,51,23,23,23,23,23,23,23,23,23,23,23,23,23,23,23,23,23,23,23,23,23,23,23,23,23,23,23,23,23,23,23,50
0,51,23,23,23,23,23,23,23,23,23,23,23,23,23,23,23,23,23,23,23,23,23,23,23,23,23,23,23,23,23,23,23,50
0,51,23,23,23,23,23,23,23,23,23,23,23,23,23,23,23,23,23,23,23,23,23,23,23,23,23,23,23,23,23,23,23,50
0,51,23,23,23,23,23,23,23,23,23,23,23,23,23,23,38,23,38,23,23,23,23,23,23,23,23,23,23,23,23,23,23,50
0,23,23,23,23,23,23,23,23,23,23,23,23,23,23,38,38,38,38,38,23,23,23,23,23,23,23,23,23,23,23,23,23,50
0,51,23,23,23,23,23,23,23,23,23,23,23,23,23,23,38,38,38,23,23,23,23,23,23,23,23,23,23,23,23,23,23,50
0,51,23,23,23,23,23,23,23,23,23,23,23,23,23,38,38,38,38,38,23,23,23,23,23,23,23,23,23,23,23,23,23,50
0,51,23,23,23,23,23,23,23,23,23,23,23,23,23,23,38,23,38,23,23,23,23,23,23,23,23,23,23,23,23,23,23,50
0,51,23,23,23,23,23,23,23,23,23,23,23,23,23,23,23,23,23,23,23,23,23,23,23,23,23,23,23,23,23,23,23,50
0,51,23,23,23,23,23,23,23,23,23,23,23,23,23,23,23,23,23,23,23,23,23,23,23,23,23,23,23,23,23,23,23,50
0,51,23,23,23,23,23,23,23,23,23,23,23,23,23,23,23,23,23,23,23,23,23,23,23,23,23,23,23,23,23,23,23,50
0,51,23,23,23,23,23,23,23,23,23,23,23,23,23,23,23,23,23,23,23,23,23,23,23,23,23,23,23,23,23,23,23,50
0,51,23,23,23,23,23,23,23,23,23,23,23,23,23,23,23,23,23,23,23,23,23,23,23,23,23,23,23,23,23,23,23,50
0,51,23,23,23,23,23,23,23,23,23,23,23,23,23,23,23,23,23,23,23,23,23,23,23,23,23,23,23,23,23,23,23,50
0,51,23,23,23,23,23,23,23,23,23,23,23,23,23,23,23,23,23,23,23,23,23,23,23,23,23,23,23,23,23,23,23,50
0,51,23,23,23,23,23,23,23,23,23,23,23,23,23,23,23,23,23,23,23,23,23,23,23,23,23,23,23,23,23,23,23,50
0,51,23,23,23,23,23,23,23,23,23,23,23,23,23,23,23,23,23,23,23,23,23,23,23,23,23,23,23,23,23,23,23,50
0,51,23,23,23,23,23,23,23,23,23,23,23,23,23,23,23,23,23,23,23,23,23,23,23,23,23,23,23,23,23,23,23,50
0,51,23,23,23,23,23,23,23,23,23,23,23,23,23,23,23,23,23,23,23,23,23,23,23,23,23,23,23,23,23,23,23,50
0,51,23,23,23,23,23,23,23,23,23,23,23,23,23,23,23,23,23,23,23,23,23,23,23,23,23,23,23,23,23,23,23,50
0,23,53,53,53,53,53,53,53,53,53,53,53,53,53,53,53,53,53,53,53,53,53,53,53,53,53,53,53,53,53,53,53,23
endlayer

