# Converted from schematic
# THIS TEMPLATE USES DEFAULTS!  Please edit for corrections.
# If you need help, consult template_rules.txt

weight=1
embed_into_distance=6
acceptable_target_blocks=stone,grass,dirt,sand,gravel
dimensions=10,8,9
allowable_overhang=0
max_leveling=6
leveling_buffer=0
preserve_water=0
preserve_lava=0
preserve_plants=0

rule1=0,100,stonebrick
rule2=0,100,stonebrick-2
rule3=0,100,stonebrick-1
rule4=0,100,fence
rule5=0,100,oak_stairs
rule6=0,100,bookshelf
rule7=0,100,oak_stairs-1
rule8=0,100,glass_pane
rule9=0,100,lava-8
rule10=0,100,chest-2
rule11=1,100,wooden_pressure_plate
rule12=0,100,lava
# placeholder for warding rune
rule13=0,100,MobSpawner:Skeleton
#illusionary walls
#rule14=0,100,-11-13
#rule15=0,100,-11-11
rule14=0,100,stonebrick, stonebrick-2,stonebrick-1
rule15=0,100,stonebrick, stonebrick-2,stonebrick-1
rule16=0,100,oak_stairs-2
rule17=0,100,oak_stairs-3
rule18=0,100,stonebrick-3
rule19=0,100,web
rule20=0,100,vine-1
rule21=0,100,chest-3
rule22=1,100,torch-5
rule23=0,100,vine-2
rule24=2,100,torch-2
rule25=0,100,vine-4
rule26=2,100,torch-1


layer
1,1,1,1,1,1,1,1,1
1,1,3,1,1,1,1,1,1
1,1,1,1,1,3,2,1,1
1,1,1,2,3,3,1,1,1
1,1,3,3,3,2,1,1,1
1,1,2,1,3,3,3,1,1
1,1,1,1,1,1,3,1,1
1,1,1,1,1,1,1,1,1
endlayer

layer
1,1,3,1,1,1,1,1,1
1,6,0,8,9,8,0,4,1
1,6,0,8,8,8,0,5,1
1,10,0,0,0,0,0,6,1
1,10,0,0,0,0,0,6,1
1,6,0,8,8,8,0,7,1
1,6,0,8,9,8,0,4,1
1,1,1,1,1,1,3,1,1
endlayer

layer
1,1,3,1,1,1,2,1,1
1,6,0,8,9,8,0,11,1
1,6,0,8,8,8,0,0,1
2,0,0,0,0,0,0,6,1
1,0,0,0,0,0,0,6,1
1,6,0,8,8,8,0,0,1
1,6,0,8,9,8,0,11,1
1,1,2,1,1,1,3,2,1
endlayer

layer
1,1,2,1,1,1,2,2,1
1,6,0,8,9,8,0,0,1
1,6,0,8,8,8,0,0,2
2,0,0,0,0,0,0,6,1
2,0,0,0,0,0,0,6,1
1,6,0,8,8,8,0,0,2
1,6,0,8,9,8,0,0,2
1,1,2,1,1,1,3,2,1
endlayer

layer
1,1,1,1,1,1,1,1,1
1,6,0,8,12,8,0,0,1
1,6,0,8,13,8,0,0,1
1,0,0,0,0,0,0,6,1
2,0,0,0,0,0,0,6,1
1,6,0,8,8,8,0,0,1
1,6,0,8,12,8,0,0,1
1,1,2,1,1,1,3,1,1
endlayer

layer
1,1,2,1,1,3,1,1,1
2,1,2,1,1,1,1,2,1
1,1,2,1,1,1,1,1,1
1,1,1,1,15,1,1,1,2
3,1,3,15,15,14,1,1,1
3,1,3,1,14,2,1,1,1
1,1,1,1,1,1,1,1,1
2,1,1,1,3,1,3,1,1
endlayer

layer
1,2,2,2,1,3,2,1,1
2,6,19,16,4,17,0,6,1
2,6,0,0,0,0,0,6,2
1,6,0,0,0,0,16,4,2
2,6,20,0,0,0,16,4,3
1,6,20,0,0,0,0,6,2
1,6,0,0,0,0,0,6,1
2,2,3,18,0,18,1,3,1
endlayer

layer
2,1,2,3,2,3,2,1,2
1,6,0,23,11,23,0,21,1
1,6,0,0,0,0,0,22,1
2,6,0,0,0,0,0,11,2
2,6,20,0,0,0,0,11,3
2,6,20,0,0,0,0,22,1
3,6,0,24,0,24,0,0,2
2,2,1,18,0,18,1,3,1
endlayer

layer
2,1,2,1,3,2,2,2,1
1,6,0,0,26,23,0,19,1
3,6,0,0,0,0,0,0,1
2,6,0,0,0,0,0,25,1
1,6,20,0,0,0,0,25,3
3,6,20,0,0,0,0,25,3
3,6,19,0,0,0,0,19,1
1,2,2,18,18,18,3,1,1
endlayer

layer
1,1,1,3,1,1,2,1,1
1,1,1,2,1,1,1,1,1
3,1,1,2,2,1,3,1,1
1,1,1,1,1,1,1,1,1
1,3,2,1,2,1,1,1,1
1,3,1,1,2,3,3,1,3
1,1,1,1,1,1,1,1,1
1,3,3,1,1,1,1,1,1
endlayer

