
# Created by Ruins mod version 14.4 Ingame Parser
# authoring Player: Sinhika

weight=1
uniqueMinDistance=1000
embed_into_distance=0
acceptable_target_blocks=
unacceptable_target_blocks=flowing_water,water,flowing_lava,lava,ice,snow
dimensions=14,12,16
allowable_overhang=0
max_leveling=2
leveling_buffer=0
preserve_water=0
preserve_lava=0

rule1=0,100,minecraft:oak_stairs-2
rule2=0,100,minecraft:oak_stairs-0
rule3=0,100,minecraft:oak_stairs-3
rule4=0,100,minecraft:stonebrick-0
rule5=0,100,minecraft:stone-0
rule6=0,100,minecraft:redstone_wire-0
rule7=0,100,minecraft:oak_stairs-1
rule8=0,100,minecraft:wooden_door-0
rule9=0,100,minecraft:ladder-5
rule10=0,100,minecraft:tripwire_hook-7
rule11=0,100,minecraft:bookshelf-0
rule12=0,100,minecraft:tripwire-4
rule13=0,100,minecraft:ladder-4
rule14=0,100,minecraft:tripwire_hook-5
rule15=0,100,minecraft:web-0
rule16=0,100,ChestGenHook:dungeonChest:5-4
rule17=0,100,minecraft:wooden_door-2
rule18=0,100,minecraft:glass_pane-0
rule19=0,100,minecraft:wooden_door-8
rule20=2,100,minecraft:torch-1
rule21=2,100,minecraft:torch-3
rule22=2,100,minecraft:torch-4
rule23=0,100,IInventory;minecraft:dispenser;minecraft:arrow#63#0#0+minecraft:arrow#2#0#1-3
rule24=0,100,IInventory;minecraft:dispenser;minecraft:arrow#60#0#0+minecraft:arrow#6#0#1-3
rule25=2,100,minecraft:torch-2
rule26=0,100,minecraft:planks-0
rule27=0,100,minecraft:log-0
rule28=0,100,MobSpawner:Zombie
rule29=0,100,ChestGenHook:dungeonChest:5-2
rule30=0,100,minecraft:wooden_slab-8
rule31=0,100,minecraft:wooden_slab-0

layer
0,0,3,2,1,0,0,0,0,0,0,0,0,0,0,0
4,4,5,5,5,4,4,0,0,0,0,0,0,0,0,0
4,5,5,5,5,5,4,4,4,4,4,4,4,4,4,4
5,5,5,5,5,5,5,6,6,6,6,6,6,6,6,4
5,5,5,5,5,5,5,5,5,5,5,5,5,5,4,4
4,5,5,5,5,5,5,5,5,5,5,5,5,5,4,4
4,5,5,5,5,5,5,5,5,5,5,5,5,5,4,4
5,5,5,5,5,5,5,5,5,5,4,5,5,5,4,4
5,5,5,5,5,5,5,6,6,6,6,6,6,6,6,4
4,5,5,5,5,5,4,4,4,4,4,4,4,4,4,4
4,4,5,5,5,4,4,0,0,0,0,0,0,0,0,0
0,0,3,7,1,0,0,0,0,0,0,0,0,0,0,0
endlayer

layer
0,0,0,0,0,0,0,0,0,0,0,0,0,0,0,0
4,5,5,8,5,5,4,0,0,0,0,0,0,0,0,0
5,0,0,0,0,0,5,4,4,4,4,4,4,4,4,4
5,0,0,0,0,0,5,5,5,4,4,5,5,5,0,4
5,0,0,0,0,0,11,10,5,5,5,0,9,5,6,4
5,0,0,0,0,0,11,12,0,0,0,0,0,0,4,5
5,0,0,0,0,0,11,12,0,0,0,0,0,0,4,5
5,0,0,0,0,0,11,14,5,5,5,0,13,5,6,4
5,0,0,0,0,0,5,5,5,4,4,5,5,5,0,4
5,16,0,0,0,15,5,4,4,4,4,4,4,4,4,4
4,5,5,17,5,5,4,0,0,0,0,0,0,0,0,0
0,0,0,0,0,0,0,0,0,0,0,0,0,0,0,0
endlayer

layer
0,0,0,0,0,0,0,0,0,0,0,0,0,0,0,0
5,18,5,19,5,18,5,0,0,0,0,0,0,0,0,0
5,0,20,0,20,0,5,0,0,0,0,0,0,0,0,0
5,22,0,0,0,21,5,5,5,4,4,5,5,5,4,0
18,0,0,0,0,0,11,0,5,5,5,0,9,0,5,0
18,0,0,0,0,0,11,0,0,0,0,0,0,0,23,5
18,0,0,0,0,0,11,0,0,0,0,0,0,0,24,5
18,0,0,0,0,0,11,25,5,5,5,0,13,0,5,0
5,22,0,0,0,21,5,5,5,4,4,5,5,5,4,0
5,0,25,0,25,0,5,0,0,0,0,0,0,0,0,0
5,18,5,19,5,18,5,0,0,0,0,0,0,0,0,0
0,0,0,0,0,0,0,0,0,0,0,0,0,0,0,0
endlayer

layer
0,0,0,0,0,0,0,0,0,0,0,0,0,0,0,0
4,18,5,5,5,18,5,0,0,0,0,0,0,0,0,0
5,15,0,0,0,15,5,0,0,0,0,0,0,0,0,0
5,0,0,0,0,0,5,5,5,4,4,5,5,5,0,0
18,0,0,0,0,0,11,0,5,5,5,0,9,0,5,0
18,0,0,0,0,0,11,0,0,0,0,0,0,0,0,5
18,0,0,0,0,0,11,0,0,0,0,0,0,0,0,5
18,0,0,0,0,0,11,0,5,5,5,0,13,0,5,0
5,0,0,0,0,0,5,5,5,4,4,5,5,5,0,0
5,0,0,0,0,0,5,0,0,0,0,0,0,0,0,0
4,18,5,5,5,18,5,0,0,0,0,0,0,0,0,0
0,0,0,0,0,0,0,0,0,0,0,0,0,0,0,0
endlayer

layer
0,0,0,0,0,0,0,0,0,0,0,0,0,0,0,0
4,4,5,5,5,4,4,0,0,0,0,0,0,0,0,0
4,5,5,5,5,5,4,0,0,0,0,0,0,0,0,0
5,5,5,5,5,5,5,5,4,4,4,5,5,5,0,0
5,5,5,5,5,5,5,5,5,5,5,0,9,0,5,0
5,5,5,5,5,5,5,5,5,5,0,0,0,0,0,5
5,5,5,5,5,5,5,5,5,5,0,0,0,0,0,5
5,5,5,5,5,5,5,5,5,5,5,0,13,0,5,0
5,5,5,5,5,5,5,5,4,4,4,5,5,5,0,0
4,5,5,5,5,5,4,0,0,0,0,0,0,0,0,0
4,4,5,5,5,4,4,0,0,0,0,0,0,0,0,0
0,0,0,0,0,0,0,0,0,0,0,0,0,0,0,0
endlayer

layer
0,0,0,0,0,0,0,0,0,0,0,0,0,0,0,0
0,0,0,0,0,0,0,0,0,0,0,0,0,0,0,0
0,0,0,0,0,0,0,0,0,0,0,0,0,0,0,0
0,0,0,0,0,0,0,0,0,0,0,5,5,5,0,0
0,0,0,0,0,0,0,0,0,0,5,20,9,20,5,0
0,0,0,0,0,0,0,0,0,5,0,0,0,0,0,5
0,0,0,0,0,0,0,0,0,5,0,0,0,0,0,5
0,0,0,0,0,0,0,0,0,0,5,25,13,25,5,0
0,0,0,0,0,0,0,0,0,0,0,5,5,5,0,0
0,0,0,0,0,0,0,0,0,0,0,0,0,0,0,0
0,0,0,0,0,0,0,0,0,0,0,0,0,0,0,0
0,0,0,0,0,0,0,0,0,0,0,0,0,0,0,0
endlayer

layer
0,0,0,0,0,0,0,0,0,0,0,0,0,0,0,0
0,0,0,0,0,0,0,0,0,0,0,0,0,0,0,0
0,0,0,0,0,0,0,0,0,0,0,0,0,0,0,0
0,0,0,0,0,0,0,0,0,0,0,4,4,4,0,0
0,0,0,0,0,0,0,0,0,0,4,0,9,0,4,0
0,0,0,0,0,0,0,0,0,4,0,0,0,0,0,4
0,0,0,0,0,0,0,0,0,4,0,0,0,0,0,4
0,0,0,0,0,0,0,0,0,0,4,0,13,0,4,0
0,0,0,0,0,0,0,0,0,0,0,4,4,4,0,0
0,0,0,0,0,0,0,0,0,0,0,0,0,0,0,0
0,0,0,0,0,0,0,0,0,0,0,0,0,0,0,0
0,0,0,0,0,0,0,0,0,0,0,0,0,0,0,0
endlayer

layer
0,0,0,0,0,0,0,0,0,0,0,0,0,0,0,0
0,0,0,0,0,0,0,0,0,0,0,0,0,0,0,0
0,0,0,0,0,0,0,0,0,0,0,0,0,0,0,0
0,0,0,0,0,0,0,0,0,0,0,5,5,5,0,0
0,0,0,0,0,0,0,0,0,0,5,0,9,0,5,0
0,0,0,0,0,0,0,0,0,5,0,0,0,0,0,5
0,0,0,0,0,0,0,0,0,5,0,0,0,0,0,5
0,0,0,0,0,0,0,0,0,0,5,0,13,0,5,0
0,0,0,0,0,0,0,0,0,0,0,5,5,5,0,0
0,0,0,0,0,0,0,0,0,0,0,0,0,0,0,0
0,0,0,0,0,0,0,0,0,0,0,0,0,0,0,0
0,0,0,0,0,0,0,0,0,0,0,0,0,0,0,0
endlayer

layer
0,0,0,0,0,0,0,0,0,0,0,0,0,0,0,0
0,0,0,0,0,0,0,0,0,0,0,0,0,0,0,0
0,0,0,0,0,0,0,0,0,0,0,0,0,0,0,0
0,0,0,0,0,0,0,0,0,0,0,5,5,5,0,0
0,0,0,0,0,0,0,0,0,0,5,0,9,0,5,0
0,0,0,0,0,0,0,0,0,5,0,0,0,0,0,5
0,0,0,0,0,0,0,0,0,5,0,0,0,0,0,5
0,0,0,0,0,0,0,0,0,0,5,0,13,0,5,0
0,0,0,0,0,0,0,0,0,0,0,5,5,5,0,0
0,0,0,0,0,0,0,0,0,0,0,0,0,0,0,0
0,0,0,0,0,0,0,0,0,0,0,0,0,0,0,0
0,0,0,0,0,0,0,0,0,0,0,0,0,0,0,0
endlayer

layer
0,0,0,0,0,0,0,0,0,0,0,0,0,0,0,0
0,0,0,0,0,0,0,0,0,0,0,0,0,0,0,0
0,0,0,0,0,0,0,0,0,0,0,0,0,0,0,0
0,0,0,0,0,0,0,0,0,0,0,5,5,5,0,0
0,0,0,0,0,0,0,0,0,0,5,5,9,5,5,0
0,0,0,0,0,0,0,0,0,5,5,5,5,5,5,5
0,0,0,0,0,0,0,0,0,5,5,5,5,5,5,5
0,0,0,0,0,0,0,0,0,0,5,5,13,5,5,0
0,0,0,0,0,0,0,0,0,0,0,5,5,5,0,0
0,0,0,0,0,0,0,0,0,0,0,0,0,0,0,0
0,0,0,0,0,0,0,0,0,0,0,0,0,0,0,0
0,0,0,0,0,0,0,0,0,0,0,0,0,0,0,0
endlayer

layer
0,0,0,0,0,0,0,0,0,0,0,0,0,0,0,0
0,0,0,0,0,0,0,0,0,0,0,0,0,0,0,0
0,0,0,0,0,0,0,0,0,0,0,0,0,0,0,0
0,0,0,0,0,0,0,0,0,0,0,26,26,26,0,0
0,0,0,0,0,0,0,0,0,0,27,0,9,0,27,0
0,0,0,0,0,0,0,0,0,26,29,0,0,0,28,26
0,0,0,0,0,0,0,0,0,26,29,0,0,0,0,26
0,0,0,0,0,0,0,0,0,0,27,0,13,0,27,0
0,0,0,0,0,0,0,0,0,0,0,26,26,26,0,0
0,0,0,0,0,0,0,0,0,0,0,0,0,0,0,0
0,0,0,0,0,0,0,0,0,0,0,0,0,0,0,0
0,0,0,0,0,0,0,0,0,0,0,0,0,0,0,0
endlayer

layer
0,0,0,0,0,0,0,0,0,0,0,0,0,0,0,0
0,0,0,0,0,0,0,0,0,0,0,0,0,0,0,0
0,0,0,0,0,0,0,0,0,0,0,0,0,0,0,0
0,0,0,0,0,0,0,0,0,0,0,26,18,26,0,0
0,0,0,0,0,0,0,0,0,0,27,0,0,0,27,0
0,0,0,0,0,0,0,0,0,26,0,0,0,0,0,26
0,0,0,0,0,0,0,0,0,26,0,0,0,0,0,26
0,0,0,0,0,0,0,0,0,0,27,0,0,0,27,0
0,0,0,0,0,0,0,0,0,0,0,26,18,26,0,0
0,0,0,0,0,0,0,0,0,0,0,0,0,0,0,0
0,0,0,0,0,0,0,0,0,0,0,0,0,0,0,0
0,0,0,0,0,0,0,0,0,0,0,0,0,0,0,0
endlayer

layer
0,0,0,0,0,0,0,0,0,0,0,0,0,0,0,0
0,0,0,0,0,0,0,0,0,0,0,0,0,0,0,0
0,0,0,0,0,0,0,0,0,0,0,30,30,30,0,0
0,0,0,0,0,0,0,0,0,0,30,26,26,26,30,0
0,0,0,0,0,0,0,0,0,30,27,0,0,0,27,30
0,0,0,0,0,0,0,0,30,26,0,0,0,0,0,26
0,0,0,0,0,0,0,0,30,26,0,0,0,0,0,26
0,0,0,0,0,0,0,0,0,30,27,0,0,0,27,30
0,0,0,0,0,0,0,0,0,0,30,26,26,26,30,0
0,0,0,0,0,0,0,0,0,0,0,30,30,30,0,0
0,0,0,0,0,0,0,0,0,0,0,0,0,0,0,0
0,0,0,0,0,0,0,0,0,0,0,0,0,0,0,0
endlayer

layer
0,0,0,0,0,0,0,0,0,0,0,0,0,0,0,0
0,0,0,0,0,0,0,0,0,0,0,0,0,0,0,0
0,0,0,0,0,0,0,0,0,0,0,0,0,0,0,0
0,0,0,0,0,0,0,0,0,0,0,0,0,0,0,0
0,0,0,0,0,0,0,0,0,0,31,31,31,31,31,0
0,0,0,0,0,0,0,0,0,0,31,30,30,30,31,0
0,0,0,0,0,0,0,0,0,0,31,30,30,30,31,0
0,0,0,0,0,0,0,0,0,0,31,31,31,31,0,0
0,0,0,0,0,0,0,0,0,0,0,0,0,0,0,0
0,0,0,0,0,0,0,0,0,0,0,0,0,0,0,0
0,0,0,0,0,0,0,0,0,0,0,0,0,0,0,0
0,0,0,0,0,0,0,0,0,0,0,0,0,0,0,0
endlayer

