# Converted from schematic
# THIS TEMPLATE USES DEFAULTS!  Please edit for corrections.
# If you need help, consult template_rules.txt
uniqueMinDistance=5000
weight=1
embed_into_distance=3
unacceptable_target_blocks=flowing_water,water,flowing_lava,lava,sand,sandstone
dimensions=30,43,26
allowable_overhang=0
max_leveling=0
leveling_buffer=0
preserve_water=0
preserve_lava=0
preserve_plants=0

rule1=0,100,stone
rule2=1,100,gravel
rule3=1,100,sand
rule4=0,100,dirt
rule5=0,100,stonebrick-3
rule6=0,100,bookshelf
rule7=0,100,enchanting_table
rule8=2,100,ladder-4
rule9=0,100,chest-2
rule10=0,100,grass
rule11=0,100,coal_ore
rule12=0,100,lit_redstone_lamp
rule13=1,100,redstone_wire-15
rule14=2,100,lever-10
rule15=0,100,log
rule16=0,100,leaves
rule17=1,100,tallgrass-1
rule18=1,100,powered_repeater-3
rule19=1,100,redstone_wire-8
rule20=1,100,redstone_wire-9
rule21=1,100,redstone_wire-10
rule22=1,100,redstone_wire-11
rule23=1,100,redstone_wire-12
rule24=1,100,redstone_wire-13
rule25=1,100,redstone_wire-14
rule26=0,100,leaves-4
rule27=0,100,log-2
rule28=1,100,redstone_wire-7
rule29=1,100,powered_repeater-1
rule30=0,100,log-4
rule31=0,100,log-8
rule32=0,100,leaves-2
rule33=0,100,sticky_piston-9
rule34=1,100,redstone_torch-5
rule35=0,100,leaves-12
rule36=2,100,trapdoor-1
rule37=0,100,piston_head-9
rule38=2,100,redstone_torch-2
rule39=0,100,chest-5
rule40=0,100,planks
rule41=0,100,oak_stairs-2
rule42=0,100,fence
rule43=1,100,wooden_pressure_plate
# placeholder for warding rune
rule44=0,100,MobSpawner:Spider,MobSpawner:Skeleton,MobSpawner:Zombie,MobSpawner:Spider
# illusionary wall
#rule45=0,100,-11-3
rule45=0,100,planks-2
rule46=2,100,lever-3
rule47=0,100,wooden_slab-8
rule48=2,100,torch-4
rule49=2,100,torch-1
rule50=0,100,oak_stairs-7
rule51=0,100,piston_head-8
rule52=0,100,oak_stairs-6
rule53=2,100,torch-2
rule54=0,100,oak_stairs
rule55=0,100,sticky_piston-8
rule56=0,100,glowstone
rule57=1,100,torch-5
rule58=0,100,oak_stairs-3
rule59=2,100,torch-3
rule60=2,100,ladder-3
# illusionary wall
#rule61=0,100,-11
rule61=0,100,planks-3
rule62=1,100,bed-3
rule63=1,100,bed-11
rule64=0,100,chest-4
rule65=0,100,glass_pane
rule66=0,100,wooden_slab
rule67=0,100,double_wooden_slab
rule68=2,100,ladder-5
rule69=0,100,brewing_stand
rule70=0,100,cauldron
rule71=1,100,wooden_door-2
rule72=0,100,oak_stairs-1
rule73=1,100,wooden_door-8
rule74=0,100,oak_stairs-4
rule75=0,100,oak_stairs-5
rule76=0,100,preserveBlock

layer
4,4,1,4,1,1,1,4,4,4,4,4,4,4,4,4,4,4,4,4,4,4,1,1,1,1
1,1,1,1,1,1,1,4,4,4,4,4,4,4,4,4,4,4,4,4,4,4,1,1,1,1
1,1,1,1,1,1,1,1,4,4,4,4,4,4,4,4,4,4,4,4,4,4,1,1,1,1
1,1,1,1,1,1,1,1,1,1,4,4,4,4,4,1,1,4,4,4,4,4,1,1,1,1
1,1,1,1,1,1,1,1,1,1,4,4,4,4,1,4,4,4,4,4,1,1,1,1,1,1
1,1,1,1,1,1,1,1,1,1,1,1,1,4,4,4,4,4,4,1,1,1,1,1,1,1
1,1,1,1,1,1,1,1,1,1,1,1,1,4,4,4,4,4,1,1,1,1,1,2,2,2
1,1,1,1,1,1,1,1,1,1,1,4,4,4,4,4,4,4,1,1,1,1,1,2,2,2
1,1,1,1,1,1,1,1,1,1,1,4,4,4,4,4,1,1,1,1,1,1,1,1,2,2
1,1,1,1,1,1,1,1,1,1,1,4,4,4,4,1,1,1,1,1,1,1,1,1,1,2
1,1,1,1,1,1,1,1,1,1,1,1,4,1,1,1,1,1,1,1,1,1,1,1,1,1
1,1,1,1,1,1,1,1,1,1,1,1,1,1,1,1,4,4,1,1,1,1,1,4,3,3
1,1,1,1,1,1,1,1,1,1,1,1,1,1,1,4,4,4,1,1,1,1,4,4,3,3
1,1,1,1,1,1,1,1,1,1,1,1,1,1,1,4,4,1,1,1,4,4,4,4,4,3
1,1,1,1,1,1,1,1,1,1,1,1,1,1,1,1,1,1,1,1,4,4,4,4,4,4
1,1,1,1,1,1,1,1,1,1,1,1,1,1,1,1,1,1,1,1,1,1,1,1,1,1
1,1,1,1,1,1,1,1,1,1,1,1,1,1,1,1,1,1,1,1,1,1,1,1,1,1
1,1,1,1,1,1,1,1,1,1,1,1,1,1,1,1,1,1,1,1,1,1,1,1,1,1
1,1,1,1,1,1,1,1,1,1,1,1,1,1,1,1,1,1,1,1,1,1,1,1,1,1
1,1,1,1,1,1,1,1,1,1,1,1,1,1,1,1,1,1,1,1,1,1,1,1,1,1
1,1,1,1,1,1,1,1,1,1,1,1,1,1,1,1,1,4,4,4,1,1,1,1,1,1
1,1,1,1,1,1,1,1,1,1,1,1,1,1,1,1,1,4,4,4,4,1,1,1,1,1
1,1,1,1,1,1,1,1,1,1,1,1,1,5,5,5,1,4,4,4,4,4,1,1,1,1
1,1,1,1,1,1,1,1,1,1,1,1,1,5,1,5,1,1,4,4,4,4,4,4,4,4
1,1,1,1,1,1,1,1,1,1,1,1,1,5,5,5,1,1,1,4,4,4,4,4,4,4
1,1,1,1,1,1,1,1,1,1,1,1,1,1,1,1,1,1,1,1,4,4,4,1,4,4
1,1,1,1,1,1,1,1,1,1,1,1,1,1,1,1,1,1,1,1,1,1,1,1,1,1
1,1,1,1,1,1,1,1,1,1,1,1,1,1,1,1,1,1,1,1,1,1,1,1,1,1
1,1,1,1,1,1,1,1,1,1,1,1,1,1,1,1,1,1,1,1,1,1,1,1,1,1
1,1,1,1,1,1,1,1,1,1,1,1,1,1,1,1,1,1,1,1,1,1,1,1,1,1
1,1,1,1,1,1,1,1,1,1,1,1,1,1,1,1,1,1,1,1,1,1,1,1,1,1
1,1,1,1,1,1,1,1,1,1,1,1,1,1,1,1,1,1,1,1,1,1,1,1,1,1
1,1,1,1,1,1,1,1,1,1,1,1,1,1,1,1,1,1,1,1,1,1,1,1,1,1
1,1,1,1,1,2,2,2,2,1,1,1,1,1,1,1,1,1,1,1,1,1,1,1,1,1
1,1,1,2,2,2,2,2,2,1,1,1,1,1,1,1,1,1,1,1,1,1,1,1,1,1
1,1,2,2,2,2,2,2,2,1,1,1,1,1,1,1,1,1,1,1,1,1,1,1,1,1
1,2,2,2,2,2,2,2,1,1,1,4,4,4,4,4,1,1,1,1,1,1,1,1,1,1
1,2,2,2,2,2,2,1,1,1,4,4,4,4,4,4,1,1,1,1,1,1,1,1,1,1
1,2,2,2,2,1,1,1,1,1,4,4,4,4,4,1,1,1,1,1,1,1,1,1,1,1
1,1,1,1,1,1,1,1,1,1,1,4,4,4,4,1,1,1,1,1,4,4,1,1,1,1
1,1,1,1,1,1,1,1,1,1,4,4,4,4,1,1,4,4,4,4,4,4,4,1,1,1
1,1,1,1,1,1,1,1,1,1,1,4,4,1,4,4,4,4,4,4,4,4,4,1,1,1
1,1,1,1,1,1,1,1,1,1,4,4,1,1,4,4,4,4,4,4,4,4,4,4,1,1
endlayer

layer
1,1,1,1,1,1,4,4,4,4,4,4,4,4,4,4,4,4,4,4,4,4,4,1,1,1
1,1,1,1,1,1,1,4,4,4,4,4,4,4,4,4,4,4,4,4,4,4,4,1,1,1
1,1,1,1,1,1,1,4,4,4,4,4,4,4,4,4,4,4,4,4,4,4,1,1,1,1
1,1,1,1,1,1,1,1,1,1,4,4,4,4,4,4,4,4,4,4,4,4,1,1,1,1
1,1,1,1,1,1,1,1,1,1,4,4,4,4,1,4,4,4,4,4,4,1,1,1,1,1
1,1,1,1,1,1,1,1,1,1,1,1,1,1,4,4,4,4,4,4,1,1,1,1,1,1
1,1,1,1,1,1,1,1,1,1,1,1,1,4,4,4,4,4,4,1,1,1,1,1,1,2
1,1,1,1,1,1,1,1,1,1,1,1,4,4,4,4,4,4,1,1,1,1,1,1,1,2
1,1,1,1,1,1,1,1,1,1,1,4,4,4,4,4,1,1,1,1,1,1,1,1,1,2
1,1,1,1,1,1,1,1,1,1,1,4,4,4,1,1,1,1,1,1,1,1,1,1,1,1
1,1,1,1,1,1,1,1,1,1,1,1,1,1,1,1,1,1,1,1,1,1,1,1,1,1
1,1,1,1,1,1,1,1,1,1,1,1,1,1,1,1,1,1,1,1,1,1,4,4,3,3
1,1,1,1,1,1,1,1,1,1,1,1,1,1,1,1,1,1,1,1,1,4,4,4,3,3
1,1,1,1,1,1,1,1,1,1,1,1,1,1,1,1,1,1,1,1,4,4,4,4,4,3
1,1,1,1,1,1,1,1,1,1,1,1,1,1,1,1,1,1,1,1,4,4,4,4,4,4
1,1,1,1,1,1,1,1,1,1,1,1,1,1,1,1,1,1,1,1,1,1,1,1,1,1
1,1,1,1,1,1,1,1,1,1,1,1,1,1,1,1,1,1,1,1,1,1,1,1,1,1
1,1,1,1,1,1,1,1,1,1,1,1,1,1,1,1,1,1,1,1,1,1,1,1,1,1
1,1,1,1,1,1,1,1,1,1,1,1,1,1,1,1,1,1,1,1,1,1,1,1,1,1
1,1,1,1,1,1,1,1,1,1,1,1,1,1,1,1,1,1,1,1,1,1,1,1,1,1
1,1,1,1,1,1,1,1,1,1,1,1,1,1,1,1,1,4,4,4,1,1,1,1,1,1
1,1,1,1,1,1,1,1,1,1,1,1,6,6,6,6,6,1,4,4,4,4,1,1,1,1
1,1,1,1,1,1,1,1,1,1,1,1,6,0,0,0,6,1,4,4,4,4,4,1,4,1
2,1,1,1,1,1,1,1,1,1,1,1,6,0,7,0,6,1,4,4,4,4,4,4,4,4
2,1,1,1,1,1,1,1,1,1,1,1,6,0,0,0,6,1,4,4,4,4,4,4,4,4
1,1,1,1,1,1,1,1,1,4,4,1,6,6,0,6,6,1,1,4,4,4,4,4,4,4
1,1,1,1,1,1,1,1,1,4,4,5,9,0,8,0,1,5,1,1,1,4,4,4,1,4
1,1,1,1,1,1,1,1,1,1,1,1,5,5,5,5,5,1,1,1,1,1,1,1,1,1
1,1,1,1,1,1,1,1,1,1,1,1,1,1,1,1,1,1,1,1,1,1,1,1,1,1
1,1,1,1,1,1,1,1,1,1,1,1,1,1,1,1,1,1,1,1,1,1,1,1,1,1
1,1,1,1,1,1,1,1,1,1,1,1,1,1,1,1,1,1,1,1,1,1,1,1,1,1
1,1,1,1,1,1,1,1,1,1,1,1,1,4,1,1,1,1,1,1,1,1,1,1,1,1
1,1,1,1,1,1,1,1,1,1,1,1,4,4,4,4,1,1,1,1,1,1,1,1,1,1
1,4,4,4,1,1,2,2,2,1,1,4,4,4,4,4,1,1,1,1,1,1,1,1,1,1
4,4,4,4,2,2,2,2,2,1,4,4,4,4,4,1,4,1,1,1,1,1,1,1,1,1
1,4,4,4,4,2,2,2,2,4,4,4,4,4,1,1,1,1,1,1,1,1,1,1,1,1
1,4,4,4,4,2,2,1,1,4,4,4,4,4,4,1,1,1,1,1,1,1,1,1,1,1
1,2,2,4,4,4,1,1,4,4,4,4,4,4,1,4,4,4,4,4,4,4,4,1,1,1
1,1,2,4,4,4,1,1,1,4,4,4,4,4,4,4,4,4,4,4,4,4,4,4,1,1
1,1,1,1,1,1,1,1,1,1,4,4,4,4,4,4,4,4,4,4,4,4,4,4,4,1
1,1,1,1,1,1,1,1,1,1,4,4,4,4,4,4,4,4,4,4,4,4,4,4,4,4
4,4,4,4,1,1,1,1,1,1,4,4,4,4,4,4,4,4,4,4,4,4,4,4,4,4
4,4,4,4,4,4,4,4,4,4,4,4,4,4,4,4,4,4,4,4,4,4,4,4,4,4
endlayer

layer
10,1,1,1,1,1,4,10,10,10,4,4,10,10,10,10,10,10,10,10,4,4,4,1,1,1
10,1,1,1,1,1,1,4,4,4,4,4,10,10,10,10,10,10,10,10,4,4,1,1,1,1
1,1,1,1,1,1,4,4,4,4,4,4,4,10,10,10,10,10,10,4,4,4,1,1,1,1
1,1,1,1,1,1,1,4,1,4,4,4,10,10,10,4,4,4,4,4,4,4,1,1,1,1
1,1,1,1,1,1,1,1,1,1,1,1,1,1,1,4,4,4,4,4,1,1,1,1,1,1
1,1,1,1,1,1,1,1,1,1,1,1,1,1,4,4,4,4,4,1,1,1,1,1,1,1
10,1,1,1,1,1,1,1,1,1,1,1,1,4,4,4,4,4,1,1,1,1,1,1,1,1
10,1,1,1,1,1,1,1,1,1,1,1,1,4,4,4,4,4,1,1,1,1,1,1,1,1
1,1,1,1,1,1,1,1,1,1,1,1,1,1,4,1,1,1,1,1,1,1,1,1,1,1
1,1,1,1,1,1,1,1,1,1,1,1,1,1,1,1,1,1,1,1,2,1,1,1,1,1
1,1,1,1,1,1,1,1,1,1,1,1,1,1,1,1,1,1,1,2,2,2,1,1,1,1
1,1,1,1,1,1,1,1,1,1,1,1,1,1,1,1,1,1,1,1,2,1,1,4,3,3
1,1,1,1,1,1,1,1,1,1,1,1,1,1,1,1,1,1,1,1,1,1,4,4,3,3
1,1,1,1,1,1,1,1,1,1,1,1,1,1,1,1,1,1,2,2,2,1,4,4,4,3
1,1,1,1,1,1,1,1,1,1,1,1,1,1,1,1,1,1,2,2,1,1,4,4,4,4
1,1,1,1,1,1,1,1,1,1,1,1,1,1,1,1,1,1,2,2,1,1,1,1,1,1
10,2,1,1,1,1,1,1,1,1,1,1,1,1,1,1,1,1,2,2,1,1,1,1,1,1
10,2,2,2,1,1,1,1,1,1,1,1,1,1,1,1,1,1,1,1,1,1,1,1,1,1
10,2,2,2,2,1,1,1,1,1,1,1,1,1,1,1,1,1,1,1,1,1,1,1,1,1
1,1,1,2,1,1,1,1,1,1,1,1,1,1,1,1,1,1,1,1,1,1,1,1,1,1
1,1,1,1,1,1,1,1,1,1,1,1,1,1,1,1,1,1,1,1,1,1,1,1,1,1
1,1,1,1,1,1,1,1,1,1,1,1,6,6,6,6,6,1,4,4,4,4,1,1,1,1
1,1,1,1,1,1,1,1,1,1,1,1,6,0,0,0,6,1,4,4,4,4,4,1,1,1
2,1,1,1,1,1,1,1,1,1,1,1,6,0,0,0,6,1,4,4,4,4,4,4,4,4
2,1,1,1,1,1,1,1,1,1,1,1,6,0,0,0,6,1,4,4,4,4,4,4,4,4
1,1,1,1,1,1,1,1,1,4,4,1,6,6,0,6,6,1,1,4,4,4,4,4,4,4
1,1,1,1,1,1,1,1,1,4,4,5,0,0,8,0,0,5,1,1,4,4,4,4,4,1
1,1,1,1,1,1,1,1,1,1,1,1,5,5,5,5,5,1,1,1,1,1,4,4,4,1
1,1,1,1,1,1,1,1,1,1,1,1,1,1,1,1,1,1,1,1,1,1,1,1,1,1
1,1,1,1,1,1,1,1,1,1,1,1,1,1,1,1,4,4,1,1,1,1,1,1,1,1
1,1,1,1,1,1,1,1,1,1,4,4,1,4,4,4,4,4,4,4,1,1,1,1,1,1
1,1,1,1,1,1,1,1,1,1,4,4,1,4,4,4,4,4,4,4,4,4,1,1,1,1
1,1,1,1,1,1,1,1,1,1,4,4,4,4,4,4,4,4,4,4,4,4,4,4,1,1
4,4,4,4,4,1,1,1,1,1,4,4,4,4,4,4,4,4,4,4,4,4,4,4,4,1
4,4,4,4,4,4,2,2,1,1,4,4,4,4,4,4,4,4,4,4,4,4,4,4,4,4
4,4,4,4,4,2,2,1,1,1,4,4,4,4,4,4,4,4,4,4,4,4,4,4,4,4
4,4,4,4,4,4,4,1,1,4,4,4,4,4,4,4,4,4,4,4,4,4,4,4,4,4
4,4,4,4,4,4,4,4,4,4,4,4,4,4,4,4,4,4,4,4,4,4,4,4,4,4
4,4,4,4,4,4,4,4,4,4,4,4,4,4,4,4,4,4,4,4,4,4,4,4,4,4
4,4,4,4,4,4,4,4,4,4,4,4,4,4,4,4,4,4,4,4,4,4,4,4,4,4
4,4,4,4,4,4,4,4,4,4,4,4,4,4,4,4,4,4,4,4,4,4,4,4,4,4
4,4,4,4,4,4,4,4,4,4,4,4,4,4,4,4,4,4,4,4,4,4,4,4,4,4
4,4,4,4,4,4,4,4,4,4,4,10,10,4,4,4,4,4,4,4,4,4,4,4,4,10
endlayer

layer
76,10,4,4,1,4,10,0,0,0,10,10,76,76,76,76,76,76,76,76,10,1,1,1,1,76
76,4,4,1,4,1,4,10,10,10,10,10,0,0,0,0,0,0,0,0,4,1,1,1,1,76
10,4,1,1,4,4,4,10,10,10,10,10,10,0,0,0,0,0,0,4,4,1,1,1,1,1
4,1,1,1,4,1,1,4,4,10,10,10,0,0,0,10,10,4,4,4,1,1,1,1,1,1
4,1,1,1,1,4,4,4,4,1,1,1,1,1,1,1,1,1,1,1,1,1,1,1,1,76
10,1,1,1,4,4,4,1,4,1,1,1,1,1,1,1,4,1,1,1,1,1,1,1,1,1
76,4,1,1,1,1,1,1,1,1,1,1,1,1,1,1,4,1,1,1,1,1,1,1,1,1
76,4,1,1,4,1,1,1,1,1,1,1,1,1,1,1,1,1,1,1,1,1,1,1,1,1
10,1,4,4,4,1,1,1,1,1,1,1,1,1,1,1,1,1,1,2,2,2,1,1,1,1
10,4,4,1,1,1,1,1,1,1,1,1,1,1,1,1,1,1,1,2,2,2,1,1,1,1
4,4,4,1,1,1,1,1,1,1,1,1,1,1,1,1,1,1,2,2,2,2,2,1,1,1
4,4,1,1,1,1,1,1,1,1,1,1,1,1,1,1,1,1,1,2,2,2,1,1,1,1
4,1,1,1,1,1,1,1,1,1,1,1,1,1,1,1,1,1,1,2,2,1,1,1,1,3
10,1,1,1,1,1,1,1,1,1,1,1,1,1,1,1,1,1,2,2,2,1,1,4,1,3
10,1,1,1,1,1,1,1,1,1,1,1,1,1,1,1,1,1,2,2,2,1,1,1,1,1
10,1,1,1,1,1,1,1,1,1,1,1,1,1,1,1,1,1,2,2,2,1,1,1,1,1
76,4,2,4,4,1,1,1,1,1,1,1,1,1,1,1,1,1,2,2,1,1,1,1,1,1
76,4,2,4,4,1,1,1,1,1,1,1,1,1,1,1,1,1,1,1,1,1,1,1,1,76
76,4,4,4,4,2,1,1,1,1,1,1,1,1,1,1,1,1,1,1,1,1,1,1,1,1
10,2,4,4,4,2,1,1,1,1,1,1,1,1,1,1,1,1,1,1,1,1,1,1,1,1
10,1,4,4,4,1,1,1,1,1,1,5,5,5,5,5,5,5,1,1,1,1,1,1,1,1
10,1,4,4,1,1,1,1,1,1,1,5,0,0,0,0,0,5,1,1,1,1,1,1,1,1
4,4,4,4,1,1,1,1,1,1,1,5,0,0,0,0,0,5,1,4,4,4,1,1,1,1
4,4,4,1,1,1,1,1,1,4,1,5,0,0,0,0,0,5,1,4,4,4,4,1,4,10
4,1,1,1,1,1,1,1,4,4,4,5,0,0,0,0,0,5,1,4,4,4,4,4,4,10
4,1,1,1,1,1,4,4,4,4,4,5,0,0,0,0,0,5,1,1,4,4,4,4,4,1
4,4,4,4,4,4,4,4,4,4,4,5,0,0,8,0,0,5,4,4,1,4,4,4,4,1
4,4,4,4,4,4,4,4,4,4,4,5,5,5,5,5,5,5,4,4,4,4,1,4,4,1
10,4,4,4,4,4,4,4,4,4,4,4,4,4,4,4,4,4,4,4,4,4,4,4,1,1
4,4,4,4,4,4,4,4,4,4,4,4,4,4,4,4,4,4,4,4,4,4,4,4,4,1
4,4,4,4,4,4,4,4,4,4,4,4,4,4,4,4,4,4,4,4,4,4,4,4,4,4
10,4,4,4,4,4,4,4,4,4,4,4,4,4,4,4,4,4,4,4,4,4,4,4,4,4
10,4,4,4,4,4,4,4,4,4,4,4,4,4,4,4,4,4,4,4,4,4,4,4,4,4
10,4,4,4,4,4,4,4,4,4,4,4,4,4,4,4,4,4,4,4,4,4,4,4,4,4
10,4,4,4,4,4,4,4,4,4,4,4,4,4,4,4,4,4,4,4,4,4,4,4,4,4
10,4,4,4,4,4,4,4,4,4,4,4,4,4,4,4,4,4,4,4,4,4,4,4,4,4
4,4,4,4,4,4,4,4,4,4,4,4,4,4,4,4,4,4,4,4,4,4,4,4,4,10
4,4,4,4,4,4,4,4,4,4,4,4,4,4,4,4,4,4,4,4,4,4,4,4,4,4
10,4,4,4,4,4,4,4,4,4,4,4,4,4,4,4,4,4,4,4,4,4,4,4,4,10
10,4,4,4,4,4,4,4,4,4,4,4,4,4,4,4,4,4,4,4,4,4,4,4,4,10
4,4,4,4,4,4,4,4,4,4,4,4,4,4,4,4,4,4,4,4,4,4,4,4,4,10
4,4,4,4,4,4,4,10,10,4,4,10,4,4,4,4,4,4,4,4,4,4,4,4,4,10
10,4,4,10,10,10,10,10,10,10,10,0,0,10,4,10,10,10,10,4,10,10,10,10,10,76
endlayer

layer
0,0,10,4,4,4,0,0,0,0,0,0,0,0,0,0,0,0,0,0,0,10,4,10,10,0
0,10,10,4,4,4,10,0,16,16,16,0,0,0,0,0,0,0,0,0,10,4,4,10,1,0
0,10,4,4,4,4,10,0,0,0,0,0,0,0,0,0,0,0,0,10,4,1,1,1,1,0
10,4,4,4,4,4,4,10,10,0,0,0,0,0,0,0,0,10,4,4,4,1,1,1,1,0
10,4,4,4,4,4,4,4,4,4,4,4,4,4,4,4,4,1,1,1,1,1,1,1,1,0
0,4,4,4,4,4,4,4,4,4,4,4,4,4,4,4,1,1,1,1,1,1,1,1,1,0
0,4,4,4,4,4,4,4,4,4,4,4,4,4,4,1,1,1,1,1,1,1,1,1,1,0
0,10,4,4,4,4,1,4,4,4,4,4,4,1,1,1,1,1,1,1,2,2,1,1,1,10
0,10,4,4,4,4,4,4,4,4,4,4,1,1,1,1,1,1,1,2,2,2,1,1,1,10
0,10,10,4,1,4,4,4,4,4,4,1,1,1,1,1,1,1,2,2,2,2,2,1,1,10
10,4,4,4,4,4,4,4,4,4,1,1,1,1,1,1,1,1,2,2,2,2,2,1,1,1
10,4,4,4,4,4,4,4,4,1,1,1,1,1,1,1,1,1,2,2,2,2,1,1,1,1
10,4,4,4,4,4,4,1,1,1,1,1,1,1,1,1,1,1,1,2,2,1,1,1,1,1
0,10,4,4,4,4,1,1,1,1,1,1,1,1,1,1,1,1,2,2,2,1,1,1,1,0
0,10,4,4,4,4,4,1,1,1,10,1,1,1,1,1,1,1,11,2,1,1,1,1,1,0
0,10,4,4,1,4,4,1,1,1,4,1,1,1,1,1,1,1,2,2,1,1,1,1,1,0
0,4,4,4,4,1,1,1,1,1,1,1,1,1,1,1,1,1,11,11,1,1,1,1,1,0
0,10,2,4,4,2,1,1,1,1,1,1,1,1,1,1,1,1,1,1,1,1,1,1,1,0
0,4,4,4,4,2,2,1,1,1,1,1,1,1,1,1,4,4,1,1,1,1,1,1,1,1
0,4,4,4,4,2,2,1,1,1,1,1,1,1,4,1,1,4,1,1,1,1,1,1,1,1
0,4,4,4,4,2,1,4,4,1,1,5,12,12,12,12,12,5,4,1,1,1,1,1,1,1
0,4,4,4,4,1,4,1,1,1,4,12,0,0,0,0,0,12,4,4,1,1,1,1,1,1
10,4,4,4,4,1,4,1,4,1,4,12,0,0,0,0,0,12,10,4,4,1,1,1,1,1
10,4,4,4,1,4,4,4,4,4,1,12,0,0,0,0,0,12,10,4,4,4,1,1,1,0
4,4,4,4,4,4,1,4,4,4,4,12,0,0,0,0,0,12,10,4,4,4,4,4,4,0
10,4,1,1,1,4,4,4,4,4,4,12,0,0,0,0,0,12,10,4,4,4,4,4,4,1
10,4,4,4,4,4,4,4,4,4,4,12,0,0,8,0,14,12,10,4,4,4,4,4,4,4
10,4,4,4,4,4,4,4,4,4,4,5,5,5,5,5,5,13,10,4,4,4,4,4,4,4
0,4,4,4,4,4,4,4,4,4,4,4,4,4,4,4,4,4,4,4,4,4,4,4,4,10
10,4,4,4,4,4,4,4,4,4,4,4,4,4,4,4,4,4,4,4,4,4,4,4,4,10
10,4,4,4,4,4,4,4,4,4,4,4,4,4,4,4,4,4,4,4,4,4,4,4,4,10
0,10,4,4,4,4,4,4,4,4,4,4,4,4,4,4,4,4,4,4,4,4,4,4,10,10
0,10,4,4,4,4,4,4,4,4,4,4,4,4,4,4,4,4,4,4,4,4,4,4,4,10
0,10,4,4,4,4,4,4,4,4,4,4,4,4,4,4,4,4,4,4,4,4,4,4,4,10
0,10,4,4,4,4,4,4,4,4,4,4,4,4,4,4,4,4,4,4,4,4,4,4,4,10
0,4,4,4,4,4,4,4,4,4,4,4,4,4,4,4,4,4,4,4,4,4,4,4,10,10
10,4,4,4,4,4,4,4,4,4,4,4,4,4,4,4,4,4,4,4,4,4,4,4,4,0
10,4,4,4,4,4,4,4,4,4,4,4,4,4,4,4,10,10,10,10,10,10,10,4,4,10
0,4,4,4,4,4,4,4,4,4,4,4,4,10,4,10,10,4,10,10,10,10,10,4,4,0
0,4,4,4,4,4,4,4,4,4,4,10,10,10,10,10,10,10,10,10,10,10,10,10,10,0
10,4,4,10,4,4,4,4,10,4,10,10,4,10,10,10,10,10,10,10,10,10,10,10,10,0
10,10,10,10,10,10,10,0,0,10,10,0,10,10,10,15,10,4,10,10,10,10,10,10,10,0
0,10,10,0,0,0,0,0,0,0,0,0,0,0,10,0,0,0,0,10,0,0,0,0,0,0
endlayer

layer
0,0,0,10,10,10,0,0,0,0,0,0,0,0,0,0,0,0,0,0,0,0,10,0,0,0
0,0,0,10,10,10,0,16,30,30,16,0,0,0,0,0,0,0,0,0,0,10,10,0,0,0
0,16,10,10,10,10,0,0,16,0,0,0,0,0,0,0,0,0,0,0,10,4,10,10,10,0
0,10,10,10,10,10,10,0,0,0,0,0,0,0,0,0,0,0,10,10,4,4,4,10,10,0
0,4,10,10,10,10,4,10,10,10,4,4,4,4,4,4,4,4,4,4,4,4,4,4,4,0
0,10,10,10,10,4,10,10,10,4,4,4,4,4,4,4,4,4,4,4,4,4,4,4,10,0
0,10,10,10,10,10,10,4,4,4,4,4,4,4,4,4,4,4,4,4,4,4,4,4,10,0
0,0,10,10,10,4,4,4,4,4,4,4,4,4,4,4,4,4,4,4,4,4,4,4,4,0
0,0,10,15,4,4,4,4,4,4,4,4,4,4,4,4,4,4,4,4,2,2,1,1,1,0
0,0,0,10,4,4,4,4,4,4,4,4,4,4,4,4,4,4,4,4,2,2,1,1,1,0
0,10,10,4,4,4,4,4,4,4,4,4,4,4,4,4,4,4,4,2,2,2,1,1,1,0
0,10,4,4,4,4,4,4,10,0,0,4,4,4,4,4,4,1,1,2,2,2,1,1,1,0
0,10,4,4,4,4,4,4,4,0,0,0,0,4,4,1,1,1,1,1,1,4,1,1,1,0
0,0,10,4,4,4,4,4,4,10,24,0,0,0,4,1,1,1,1,11,1,1,1,1,1,0
0,0,10,4,4,4,4,4,0,0,23,10,10,0,1,1,1,1,11,11,1,1,1,4,0,0
0,0,4,4,4,4,4,4,0,4,10,10,10,0,1,1,1,1,11,11,4,4,4,1,10,0
0,10,4,4,4,4,4,4,4,4,4,4,1,1,1,1,1,1,11,4,4,4,4,4,10,0
0,0,4,4,4,4,4,4,4,4,4,4,4,1,4,4,1,1,4,4,4,4,4,4,4,0
0,10,4,4,4,4,4,4,4,4,4,4,4,4,4,4,4,4,4,4,4,4,4,4,4,10
0,10,4,4,4,4,4,4,4,4,28,19,20,21,22,23,24,25,13,4,4,4,4,4,4,10
0,4,4,4,4,4,4,4,4,4,29,5,5,5,5,5,5,5,18,4,4,4,4,4,4,10
0,10,4,4,4,4,4,4,4,4,13,5,0,0,0,0,0,5,19,4,4,4,4,4,4,0
0,10,4,4,4,4,4,4,4,4,25,5,0,0,0,0,0,5,20,4,4,4,4,4,4,0
0,10,4,4,4,4,4,4,4,4,24,5,0,0,0,0,0,5,21,4,4,4,4,4,4,0
10,4,4,4,4,4,4,4,4,4,23,5,0,0,0,0,0,5,22,4,4,4,4,4,4,0
0,4,4,4,4,4,4,4,4,4,22,5,0,0,0,0,0,5,23,4,4,4,4,4,4,0
0,4,4,4,4,4,4,4,4,4,21,5,0,0,8,0,0,5,24,4,4,4,4,4,4,4
0,4,4,4,4,4,4,4,4,4,4,5,5,5,5,5,5,0,25,4,4,4,4,4,4,10
0,4,4,4,4,4,4,4,4,4,4,4,4,4,4,4,4,4,4,4,4,4,4,4,10,0
0,10,4,4,4,4,4,4,4,4,4,4,4,4,4,4,10,10,4,4,4,4,4,4,10,0
0,10,4,4,4,4,4,4,4,4,4,4,4,4,4,10,10,4,10,10,4,4,4,4,10,0
0,0,10,4,4,4,4,4,4,4,4,4,4,4,4,10,10,10,10,10,10,10,4,4,0,0
0,0,4,4,4,4,4,4,4,4,4,4,10,10,4,10,10,10,10,10,10,10,10,10,10,0
0,0,4,4,4,4,4,4,4,4,4,10,4,10,4,4,10,4,10,10,10,10,10,10,10,0
0,0,4,4,4,4,4,4,4,4,4,10,10,10,10,10,10,10,10,10,10,10,10,10,10,0
0,4,4,4,4,4,4,4,4,4,10,10,10,10,10,10,10,10,10,10,10,10,10,10,0,0
0,4,4,4,4,4,4,4,4,10,10,10,10,10,10,10,10,10,10,10,10,10,10,10,10,0
0,10,4,4,4,4,4,10,10,4,10,10,10,10,10,10,0,0,0,0,0,0,0,10,10,0
0,10,10,4,10,10,10,10,10,4,10,10,10,0,27,0,0,15,0,0,0,0,0,15,10,0
0,10,10,10,10,10,10,10,10,10,10,0,0,16,16,16,16,16,0,0,0,0,17,0,0,0
0,10,10,0,10,10,10,10,0,10,0,0,10,16,16,16,16,16,0,0,0,0,0,0,0,0
0,0,0,0,0,0,0,0,0,0,0,0,0,16,16,15,16,15,17,0,0,0,0,0,0,0
0,0,0,0,0,0,0,0,0,0,0,0,0,0,0,26,0,0,0,0,0,0,0,0,0,0
endlayer

layer
0,0,0,0,0,0,0,0,35,16,16,0,0,0,0,0,0,0,0,0,0,0,0,0,0,0
0,16,16,0,16,16,16,16,16,16,16,16,16,0,0,0,0,0,0,0,0,0,0,0,0,0
0,16,16,16,0,16,16,16,16,30,16,32,32,0,0,0,0,0,0,0,0,10,0,0,0,0
0,16,16,16,0,0,0,16,16,30,16,32,32,32,0,0,0,0,0,0,10,4,10,0,0,0
0,15,16,16,0,0,27,0,0,16,10,4,10,10,10,10,10,4,4,4,4,4,4,10,10,0
0,16,16,16,0,15,0,0,0,10,10,10,10,10,10,4,4,4,4,4,4,4,4,4,0,0
0,16,16,0,0,0,0,10,10,10,10,10,10,10,10,4,4,4,4,4,4,4,4,4,0,0
0,0,0,0,0,10,10,10,10,10,10,10,10,4,4,4,4,4,4,4,4,4,4,4,10,0
0,0,0,0,31,4,10,10,10,10,4,10,4,4,4,4,4,4,4,4,4,4,4,4,4,0
0,0,0,0,10,10,4,10,10,10,10,4,4,4,4,4,4,4,4,4,4,4,4,4,10,0
0,0,17,10,10,10,4,4,4,4,4,4,4,4,4,4,4,4,4,4,4,4,4,4,10,0
0,0,10,4,10,10,10,10,0,0,0,4,4,33,23,10,4,4,4,4,4,4,4,4,10,0
0,0,4,10,10,10,10,4,10,0,0,0,0,4,4,4,4,4,4,4,4,4,4,4,10,0
0,0,0,10,10,10,4,4,10,25,0,0,0,0,4,4,4,4,4,4,4,4,4,4,0,0
0,0,0,10,10,4,4,4,10,0,0,0,0,0,4,4,4,4,4,4,4,4,4,10,0,0
0,0,10,10,4,4,4,4,0,4,33,0,34,0,4,4,4,4,4,4,4,4,4,4,0,0
0,0,4,4,4,4,4,4,4,4,4,4,4,4,4,4,4,4,4,4,4,4,4,4,0,0
0,0,4,4,4,4,4,4,4,4,4,4,4,4,4,4,4,4,4,4,4,4,4,4,10,0
0,0,4,4,4,4,4,4,4,4,4,4,4,4,4,4,4,4,4,4,4,4,4,4,10,0
0,0,4,4,4,4,4,4,4,4,4,4,4,4,4,4,4,4,4,4,4,4,4,4,10,0
0,4,4,4,4,4,4,4,4,4,4,4,4,4,4,4,4,4,4,4,4,4,4,4,4,0
0,0,4,4,4,4,4,4,4,4,4,4,5,5,5,5,5,4,4,4,4,4,4,4,10,0
0,0,4,4,4,4,4,4,4,4,4,4,5,5,5,5,5,4,4,4,4,4,4,4,10,0
0,0,4,4,4,4,4,4,4,4,4,4,5,5,5,5,5,4,4,4,4,4,4,4,10,0
0,4,4,4,4,4,4,4,4,4,4,4,5,5,5,5,5,4,4,4,4,4,4,4,10,0
0,4,4,4,4,4,4,4,4,4,4,4,5,5,0,5,5,4,4,4,4,4,4,4,10,0
0,10,10,10,10,4,4,4,4,4,4,4,5,5,8,5,5,4,4,4,4,4,4,4,4,4
0,10,10,10,10,4,4,4,4,4,4,4,4,5,5,5,4,10,4,4,4,4,4,4,10,0
0,10,4,10,10,10,4,10,4,4,4,4,4,4,4,10,10,10,10,10,10,10,4,4,0,0
0,0,10,10,10,4,4,10,10,10,4,4,4,4,4,10,0,0,10,4,10,10,10,10,0,0
0,0,10,10,10,4,10,10,10,10,10,4,4,30,30,0,17,15,0,0,10,10,10,10,0,0
0,0,0,10,10,10,10,10,10,10,10,4,10,30,30,0,0,0,17,0,0,0,4,10,0,0
0,0,27,10,10,10,10,10,10,10,10,10,16,16,31,0,17,17,0,0,0,0,0,17,0,0
0,0,10,10,10,10,10,10,10,10,10,0,15,0,15,31,0,15,17,0,0,0,0,0,0,0
0,0,10,4,10,4,10,10,10,10,10,0,0,0,0,0,0,0,17,0,0,17,17,17,17,0
0,10,10,10,10,10,10,10,10,10,0,0,0,0,0,0,0,0,17,0,0,17,0,0,0,0
0,10,10,10,10,10,10,10,10,0,0,0,0,0,0,0,0,0,0,0,0,0,0,0,0,0
0,16,15,10,10,10,4,0,0,15,0,0,0,17,0,0,0,0,0,0,0,0,0,17,0,0
0,16,16,15,16,16,0,0,0,15,0,0,17,0,27,0,0,15,0,0,0,0,0,15,0,0
0,0,16,16,16,16,0,0,0,0,0,0,0,0,16,16,16,16,16,16,0,0,0,0,0,0
0,16,16,16,16,16,0,0,0,0,0,0,0,16,16,16,16,16,16,16,0,0,0,0,0,0
0,0,32,32,0,0,0,0,0,0,0,0,0,16,16,15,16,15,16,16,0,0,0,0,0,0
0,0,0,0,0,0,0,0,0,0,0,0,0,0,0,26,0,26,0,0,0,0,0,0,0,0
endlayer

layer
0,0,0,0,0,0,0,0,16,0,0,0,0,0,0,0,0,0,0,0,0,0,0,0,0,0
0,16,0,0,0,16,16,30,16,16,16,16,0,0,0,0,0,0,0,0,0,0,0,0,0,0
0,0,16,0,16,16,16,16,16,16,16,16,32,32,0,0,0,0,0,0,0,0,0,0,0,0
0,16,0,0,0,0,0,16,16,16,16,16,32,32,0,0,16,16,0,0,0,10,0,0,0,0
0,15,16,0,0,0,27,16,16,16,16,15,32,32,0,16,16,10,10,10,10,10,10,0,0,0
16,16,16,0,0,15,0,0,16,16,16,32,32,32,16,15,10,10,10,10,10,10,10,10,0,0
16,0,0,0,0,0,0,0,32,32,32,17,32,17,16,10,4,10,10,10,10,10,10,10,0,0
0,0,0,0,0,0,0,0,32,32,32,32,32,10,10,10,10,10,10,10,10,10,10,10,0,0
0,0,0,0,0,31,0,0,32,32,27,0,10,10,10,10,10,10,10,10,4,4,4,10,10,0
0,0,0,0,0,17,30,0,32,32,32,10,10,10,10,10,10,10,10,10,4,4,4,10,0,0
0,0,16,17,17,0,30,31,31,31,15,15,15,15,15,4,4,10,10,4,4,4,4,10,0,0
0,0,16,15,16,0,0,0,30,15,15,15,15,37,0,24,4,4,4,4,4,4,4,10,0,0
0,0,27,17,17,0,0,4,25,15,15,15,15,15,15,10,4,4,4,4,4,4,4,10,0,0
0,0,0,0,0,0,10,4,13,0,0,15,15,15,15,15,4,4,4,4,4,4,4,10,0,0
0,0,0,0,0,10,10,4,38,15,15,15,15,15,15,15,31,4,4,4,4,4,4,0,0,0
0,0,0,0,10,10,10,10,15,15,37,15,15,15,15,15,15,15,15,4,4,4,4,10,0,0
0,0,27,10,4,10,10,31,15,15,15,15,15,15,15,15,15,15,15,4,4,4,4,10,0,0
0,0,10,10,10,10,10,15,15,15,15,15,15,15,15,15,15,15,15,15,4,4,4,4,0,0
0,0,10,10,10,10,15,15,15,15,15,15,15,15,15,15,15,15,15,15,4,4,4,4,0,0
0,0,10,10,10,10,15,15,15,15,15,15,15,15,15,15,15,15,15,15,4,4,4,10,0,0
0,15,10,10,10,15,15,15,15,15,15,15,15,15,15,15,15,15,15,15,4,4,4,4,10,0
0,0,10,10,15,15,15,15,15,15,15,15,15,15,15,15,15,15,15,15,4,4,4,4,0,0
0,0,10,10,15,15,15,15,15,15,15,15,15,15,15,15,15,15,15,4,10,4,4,4,0,0
0,0,10,10,10,15,15,15,15,15,15,15,15,15,15,15,15,15,15,4,10,10,4,4,0,0
0,10,10,10,10,15,15,15,15,15,15,15,15,15,15,15,15,15,15,4,10,10,10,10,0,0
0,10,10,10,10,15,15,15,15,15,15,15,15,15,15,15,15,15,4,4,4,10,10,10,0,0
16,16,16,16,0,30,15,15,15,15,15,15,15,15,36,15,15,15,30,4,4,4,10,4,4,4
0,16,16,16,16,30,30,15,15,15,15,15,15,15,15,15,15,0,31,31,4,4,4,4,0,0
0,16,15,16,16,0,30,0,15,15,15,15,15,15,15,0,0,0,0,0,0,0,10,10,0,0
0,16,16,16,17,30,31,0,0,16,15,15,15,15,30,0,0,0,0,15,0,0,0,0,0,0
0,0,16,16,16,31,0,0,0,16,16,15,31,30,0,0,0,15,16,0,0,0,0,17,0,0
0,0,32,32,32,0,0,0,0,16,16,30,16,16,0,0,0,16,16,16,0,0,15,17,0,0
0,32,27,32,32,16,16,0,0,0,16,16,16,0,0,0,0,0,16,0,0,0,0,0,0,0
0,32,32,32,32,16,16,16,0,0,0,0,15,0,15,0,0,15,0,0,0,0,0,0,0,0
0,32,32,15,16,15,16,16,0,0,0,0,0,0,0,0,0,0,0,0,0,0,0,0,0,0
0,0,0,16,16,16,16,16,0,0,0,0,0,0,0,0,0,0,0,0,0,0,0,0,0,0
0,16,16,16,16,16,16,16,16,16,16,0,0,0,0,0,0,0,0,0,0,16,16,16,16,0
0,16,15,16,16,16,15,16,16,15,16,16,0,0,0,0,0,0,0,0,0,16,16,16,16,16
0,16,16,15,16,16,0,16,16,15,16,16,0,0,27,0,0,15,0,0,0,16,16,15,16,16
0,16,16,16,16,16,0,16,16,16,16,16,0,0,0,0,16,16,16,16,0,16,16,16,16,16
0,0,16,16,16,16,0,0,16,16,16,16,0,0,16,16,16,16,16,16,0,16,16,16,16,0
0,0,32,32,0,0,0,0,0,0,0,0,0,0,16,26,16,15,16,16,0,0,0,0,0,0
0,0,0,0,0,0,0,0,0,0,0,0,0,0,0,26,0,35,26,0,0,0,0,0,0,0
endlayer

layer
0,0,0,0,0,16,0,0,0,0,0,0,0,0,0,0,0,0,0,0,0,0,0,0,0,0
0,0,0,0,0,16,16,16,16,16,0,0,0,0,0,0,0,0,0,0,0,0,0,0,0,0
0,0,0,0,32,16,16,16,16,16,16,16,0,0,0,0,0,0,0,0,0,0,0,0,0,0
0,0,0,0,32,32,16,16,16,16,16,16,32,0,16,16,16,16,0,0,0,0,0,0,0,0
0,35,16,0,32,32,27,16,16,16,16,15,32,16,16,16,16,16,16,0,0,0,0,0,0,0
16,16,0,0,32,15,32,32,16,16,16,32,32,16,16,15,16,16,16,16,0,17,0,0,0,0
0,0,0,0,0,32,32,32,32,0,0,0,0,16,16,16,15,16,16,16,32,0,0,0,0,0
0,0,0,0,0,0,0,0,0,32,32,0,0,0,16,16,16,16,16,0,0,0,0,0,0,0
0,0,0,0,0,0,0,0,0,32,27,32,17,0,17,16,16,16,0,0,10,10,10,0,0,0
0,0,0,0,0,0,0,0,0,32,32,0,0,0,0,0,0,0,0,0,10,10,10,0,0,0
0,0,0,16,0,0,0,31,31,31,15,15,15,0,15,15,30,0,0,10,10,10,10,0,0,0
0,0,16,16,16,0,0,0,30,15,0,15,0,15,15,0,30,10,10,10,10,4,10,0,0,0
0,0,27,16,0,0,0,15,0,24,15,15,0,0,15,25,4,10,10,10,10,10,10,0,0,0
0,0,0,0,0,0,0,15,15,0,15,15,0,0,15,30,4,10,10,10,10,10,10,0,0,0
0,32,32,32,32,0,0,15,15,15,15,0,0,0,0,15,31,10,10,10,4,10,10,0,0,0
32,32,32,32,32,0,0,0,43,0,15,0,0,0,0,31,15,15,4,4,10,10,10,0,0,0
32,32,27,32,15,0,0,15,15,15,15,40,0,0,0,40,39,0,15,10,10,10,10,0,0,0
32,32,32,32,32,0,0,15,0,0,0,0,0,0,0,0,0,0,0,15,10,10,10,10,0,0
16,16,16,16,32,0,15,15,0,0,0,0,0,0,0,0,0,0,0,15,4,10,10,4,0,0
35,16,16,16,0,0,15,15,0,0,0,0,0,0,0,0,0,0,0,15,10,10,4,0,0,0
35,15,16,16,0,15,40,44,40,41,0,0,0,0,0,0,0,0,0,15,10,4,4,10,0,0
26,16,16,16,15,15,40,0,40,42,0,0,0,0,0,0,0,0,15,15,4,4,10,10,0,0
0,16,16,0,15,15,40,45,40,0,0,0,0,0,0,0,0,0,15,15,0,10,10,10,0,0
0,0,0,0,0,15,0,0,0,0,0,0,0,0,0,0,0,0,15,15,0,0,10,4,0,0
0,0,0,0,16,15,0,0,0,0,0,0,0,0,0,0,0,15,30,15,0,0,0,0,0,0
0,0,0,0,16,15,0,0,0,0,0,0,0,0,0,0,0,15,30,31,4,16,16,17,0,0
0,16,16,16,16,16,15,0,0,0,0,0,0,0,0,0,15,15,0,0,4,10,17,15,31,31
16,16,16,16,16,16,30,15,15,0,0,0,15,0,0,15,15,0,0,0,4,31,31,31,16,0
16,16,15,16,16,16,30,16,15,15,15,15,15,15,15,0,0,0,0,0,16,16,16,16,16,0
16,16,16,16,16,0,0,0,0,0,15,15,15,15,0,0,0,16,16,15,16,16,16,16,16,0
32,16,16,16,16,0,0,0,0,0,16,15,16,0,0,0,16,15,16,16,16,16,16,16,16,0
0,32,32,32,32,0,0,0,0,0,16,16,16,16,16,16,16,16,16,16,16,16,15,16,16,0
0,32,27,32,32,0,0,0,0,0,16,16,16,16,16,16,16,16,16,16,16,16,16,16,16,0
0,32,32,32,32,16,16,0,0,0,16,16,15,16,16,16,16,15,16,16,0,16,16,16,0,0
0,32,32,15,16,15,16,0,0,0,16,16,16,16,16,16,16,16,16,16,0,0,0,0,0,0
0,0,0,0,16,16,16,16,16,0,16,16,16,16,16,16,16,16,16,0,0,0,0,0,0,0
0,0,0,0,16,16,16,16,16,16,16,16,0,0,0,16,16,16,16,0,0,0,16,16,16,16
0,0,15,16,16,16,15,16,16,15,16,16,0,0,0,16,16,16,16,16,0,16,16,16,16,16
0,0,16,15,16,16,16,16,16,15,16,16,0,0,27,16,16,15,16,16,0,16,16,15,16,16
0,0,16,16,0,16,16,16,16,16,16,16,0,0,0,16,16,16,16,16,0,16,16,16,16,16
0,0,0,0,0,0,0,16,16,16,16,0,0,0,0,16,16,16,16,16,0,0,16,16,16,0
0,0,0,0,0,0,0,0,0,0,0,0,0,0,16,16,16,15,16,0,0,0,0,0,0,0
0,0,0,0,0,0,0,0,0,0,0,0,0,0,0,0,26,26,16,0,0,0,0,0,0,0
endlayer

layer
0,0,0,0,0,0,0,0,0,0,0,0,0,0,0,0,0,0,0,0,0,0,0,0,0,0
0,0,0,0,0,16,16,16,16,0,0,0,0,0,0,0,0,0,0,0,0,0,0,0,0,0
0,0,0,0,0,16,16,16,16,16,16,16,0,0,0,0,0,0,0,0,0,0,0,0,0,0
0,0,0,0,32,32,16,16,16,16,16,16,0,0,16,16,16,16,0,0,0,0,0,0,0,0
0,0,0,0,32,32,27,16,16,16,16,15,32,16,16,16,16,16,16,0,0,0,0,0,0,0
0,0,0,0,32,15,32,32,16,16,16,32,0,16,16,16,16,16,16,16,0,0,0,0,0,0
0,0,0,0,0,32,32,32,32,0,0,0,0,16,16,16,15,16,16,16,0,0,0,0,0,0
0,0,0,0,0,0,0,0,0,0,32,0,0,0,16,16,16,16,16,0,0,0,0,0,0,0
0,0,0,0,0,0,0,0,0,32,32,32,0,0,16,16,16,16,0,0,0,0,0,0,0,0
0,0,0,0,0,0,0,0,0,0,32,0,0,0,0,0,0,0,0,0,0,0,0,0,0,0
0,16,16,0,0,0,0,0,0,0,15,15,15,0,15,15,0,0,0,0,0,0,0,0,0,0
0,16,16,0,0,0,0,0,0,15,0,15,0,15,15,0,30,0,0,0,0,15,0,0,0,0
0,16,27,0,0,0,0,0,15,0,23,15,0,0,15,0,30,0,0,0,0,0,0,0,0,0
16,16,16,0,0,0,0,0,15,0,15,15,0,0,15,13,15,0,0,0,0,0,0,0,0,0
16,16,16,32,0,0,0,0,15,15,15,0,0,0,15,38,15,0,0,0,31,0,0,0,0,0
32,32,32,32,32,0,0,0,0,0,15,0,0,0,46,30,15,15,31,31,0,0,0,0,0,0
32,32,27,32,15,0,0,15,15,15,15,40,0,0,0,40,0,0,15,0,0,0,0,0,0,0
32,32,32,32,32,0,0,15,0,0,0,0,0,0,0,0,0,0,0,15,0,0,0,0,0,0
16,16,16,16,32,0,15,15,0,0,0,0,0,0,0,0,0,0,0,15,31,0,0,31,0,0
0,16,16,16,0,0,15,15,0,0,0,0,0,0,0,0,0,0,0,15,0,0,30,0,0,0
35,15,16,16,0,15,40,47,41,0,0,0,0,0,0,0,0,0,0,15,0,31,30,17,0,0
0,16,16,16,15,15,40,0,40,42,0,0,0,0,0,0,0,0,15,31,31,31,17,0,0,0
0,16,16,0,15,15,40,45,40,0,0,0,0,0,0,0,0,0,15,0,0,0,0,0,0,0
0,0,0,0,0,15,0,0,0,0,0,0,0,0,0,0,0,0,15,0,0,0,0,15,0,0
0,0,0,0,0,15,48,0,0,0,0,0,0,0,0,0,0,15,0,0,0,0,0,0,16,0
0,16,0,0,16,15,0,0,0,0,0,0,0,0,0,0,0,15,0,31,31,16,16,16,16,0
16,16,0,0,16,16,15,0,0,0,0,0,0,0,0,0,15,0,0,0,30,16,16,15,16,16
16,16,16,0,16,16,16,15,15,15,0,0,15,0,0,15,15,0,0,0,31,31,16,16,16,16
16,16,15,16,0,16,16,16,0,0,15,15,15,15,15,0,0,0,0,0,16,16,16,16,16,0
16,0,16,16,0,0,0,0,0,0,0,16,0,0,0,0,0,16,16,15,0,16,16,16,16,0
0,0,0,0,0,0,0,0,0,0,16,16,16,0,16,16,16,15,16,16,16,16,16,16,16,0
0,0,32,32,0,0,0,0,0,0,0,16,16,16,16,16,16,16,16,16,16,16,15,16,16,0
0,32,16,16,16,0,0,0,0,0,16,16,16,16,16,16,16,16,16,16,16,16,16,16,16,0
0,0,16,16,16,16,0,0,0,0,16,16,15,16,16,16,16,15,16,16,0,16,16,16,0,0
0,16,16,15,16,16,16,0,0,0,16,16,16,16,16,16,16,16,16,16,0,0,0,0,0,0
0,16,16,16,16,16,16,16,16,16,16,16,16,16,16,16,16,16,16,16,0,0,0,0,0,0
0,16,16,16,16,16,16,16,16,16,16,16,0,32,32,32,32,16,16,16,0,0,0,0,0,0
0,0,15,16,16,16,15,16,16,15,16,16,32,32,32,32,32,16,16,16,0,0,0,16,16,0
0,0,16,16,16,16,16,16,16,16,16,16,0,32,27,32,32,15,16,16,0,0,16,15,16,0
0,0,0,16,0,16,16,16,16,16,16,16,32,32,32,32,32,16,16,16,0,0,0,16,0,0
0,0,0,0,0,0,0,0,0,0,0,0,0,32,32,32,32,16,16,16,0,0,0,0,0,0
0,0,0,0,0,0,0,0,0,0,0,0,0,0,0,0,16,16,16,0,0,0,0,0,0,0
0,0,0,0,0,0,0,0,0,0,0,0,0,0,0,0,0,16,0,0,0,0,0,0,0,0
endlayer

layer
0,0,0,0,0,0,0,0,0,0,0,0,0,0,0,0,0,0,0,0,0,0,0,0,0,0
0,0,0,0,0,16,16,0,16,0,0,0,0,0,0,0,0,0,0,0,0,0,0,0,0,0
0,0,0,0,0,16,16,16,16,0,16,16,16,0,0,0,0,0,0,0,0,0,0,0,0,0
0,0,0,0,0,32,16,16,16,16,16,16,16,16,16,16,16,0,0,0,0,0,0,0,0,0
0,0,0,0,0,32,27,32,0,16,16,15,16,16,16,16,16,16,0,0,0,0,0,0,0,0
0,0,0,0,0,15,32,32,0,16,16,16,16,16,16,16,16,16,16,0,0,0,0,0,0,0
0,0,0,16,16,30,0,0,0,16,16,16,16,16,16,16,15,16,16,0,0,0,0,0,0,0
0,0,16,16,16,16,0,0,0,0,0,0,0,0,16,16,16,16,16,0,0,0,0,0,0,0
0,0,0,16,16,0,0,0,0,0,0,0,0,0,16,16,16,16,16,0,0,0,0,0,0,0
0,0,0,0,0,0,0,0,0,0,0,0,0,0,0,0,0,0,0,0,0,0,0,0,0,0
0,16,16,0,0,0,0,0,0,0,0,0,15,15,15,0,0,0,0,0,0,0,0,0,0,0
0,16,16,0,0,0,0,0,0,15,15,15,15,51,15,15,0,0,0,0,0,15,0,0,0,0
0,16,27,0,0,0,0,0,0,15,0,15,49,15,15,15,0,0,0,0,0,0,0,0,0,0
0,16,16,0,0,0,0,0,0,15,22,15,0,15,25,0,15,0,0,0,0,0,0,0,0,0
16,16,16,0,0,0,0,0,0,15,15,48,0,15,15,0,15,0,0,0,0,0,0,0,0,0
0,0,32,0,0,0,0,0,0,15,51,15,0,0,0,15,15,15,0,0,0,0,0,0,0,0
16,32,27,32,15,0,0,0,0,15,15,40,52,0,50,40,0,0,15,0,0,0,0,0,0,0
16,16,32,32,0,0,0,0,15,0,0,49,0,0,0,49,0,0,0,15,0,0,0,0,0,0
16,16,0,0,0,0,0,15,15,0,0,0,0,0,0,0,0,0,0,15,0,0,0,0,0,0
0,16,0,0,0,0,0,15,0,0,0,0,0,0,0,0,0,0,0,15,0,0,0,0,0,0
16,15,16,0,0,0,15,0,0,0,0,0,0,0,0,0,0,0,15,15,0,0,0,0,0,0
0,16,16,0,0,15,40,54,42,42,0,0,0,0,0,0,0,0,15,31,31,0,0,0,0,0
0,0,0,0,0,15,40,40,40,0,0,0,0,0,0,0,0,0,15,0,0,0,0,0,0,0
0,0,0,0,0,15,0,0,0,0,0,0,0,0,0,0,0,15,0,0,0,0,0,15,0,0
0,0,0,0,0,15,0,0,0,0,0,0,0,0,0,0,0,15,0,0,0,0,16,16,16,16
0,0,0,0,0,16,15,15,0,0,0,0,0,0,0,0,15,0,0,0,0,16,16,16,16,16
0,16,0,0,0,16,15,15,15,15,15,0,53,0,0,0,15,0,0,0,16,16,16,15,16,0
16,16,16,0,0,0,16,0,0,0,15,15,15,15,15,15,0,16,16,16,16,16,16,16,16,16
16,16,16,16,0,0,0,0,0,0,0,0,0,0,0,0,16,16,16,16,16,16,16,16,16,16
16,16,16,0,0,0,0,0,0,0,0,0,0,0,0,16,16,16,16,15,16,16,16,16,0,0
0,0,0,0,0,0,0,0,0,0,0,0,0,0,16,16,16,16,16,16,16,16,16,16,0,0
0,0,32,0,0,0,0,0,0,0,0,0,0,16,16,16,16,16,16,16,16,16,15,16,0,0
0,16,16,16,16,0,0,0,0,0,0,16,16,16,16,16,16,16,16,16,16,0,16,16,0,0
0,16,16,16,16,16,0,0,0,0,0,16,15,16,15,16,16,15,16,16,0,0,0,0,0,0
0,16,16,15,16,16,16,0,0,0,0,0,16,16,16,16,16,16,0,0,0,0,0,0,0,0
0,16,16,16,16,16,0,16,16,16,16,16,0,0,0,0,0,0,0,0,0,0,0,0,0,0
0,16,16,16,16,16,16,16,16,16,16,16,0,32,32,32,32,0,0,0,0,0,0,0,0,0
0,0,15,0,16,16,15,16,16,15,16,16,32,32,32,32,32,16,16,0,0,0,0,16,0,0
0,0,0,16,16,16,16,16,16,16,16,16,32,32,27,32,32,15,16,0,0,0,16,16,16,0
0,0,0,0,16,0,0,16,16,16,16,16,32,32,32,32,32,16,0,0,0,0,0,16,0,0
0,0,0,0,0,0,0,0,0,0,0,0,32,32,32,32,32,0,0,0,0,0,0,0,0,0
0,0,0,0,0,0,0,0,0,0,0,0,0,0,0,0,0,0,0,0,0,0,0,0,0,0
0,0,0,0,0,0,0,0,0,0,0,0,0,0,0,0,0,0,0,0,0,0,0,0,0,0
endlayer

layer
0,0,0,0,0,0,0,0,0,0,0,0,0,0,0,0,0,0,0,0,0,0,0,0,0,0
0,0,0,0,0,0,16,16,0,0,0,0,0,0,0,0,0,0,0,0,0,0,0,0,0,0
0,0,0,0,0,0,0,16,0,0,16,16,16,0,0,0,0,0,0,0,0,0,0,0,0,0
0,0,0,0,0,0,30,0,0,16,16,16,16,16,0,0,0,0,0,0,0,0,0,0,0,0
0,0,0,0,0,16,30,16,0,16,16,15,16,16,0,16,0,0,0,0,0,0,0,0,0,0
0,0,16,16,16,15,16,0,0,16,16,16,16,16,16,16,16,0,0,0,0,0,0,0,0,0
0,0,16,16,16,16,30,16,0,16,16,16,16,0,0,16,15,16,0,0,0,0,0,0,0,0
0,16,16,16,16,30,16,0,0,0,0,0,0,0,0,16,16,16,0,0,0,0,0,0,0,0
0,16,16,16,16,30,16,0,0,0,0,0,0,0,0,0,0,0,0,0,0,0,0,0,0,0
0,0,16,16,16,16,0,0,0,0,0,0,0,0,0,0,0,0,0,0,0,0,0,0,0,0
0,32,32,32,0,0,0,0,0,0,0,0,0,15,15,0,0,0,0,0,0,0,0,0,0,0
0,32,32,32,32,0,0,0,0,0,15,15,15,55,15,0,0,0,0,0,0,15,0,0,0,0
0,32,27,32,32,0,0,0,0,15,0,15,15,15,0,15,0,0,0,0,0,0,0,0,0,0
32,32,32,32,32,0,0,0,0,15,0,15,15,24,0,0,15,0,0,0,0,0,16,0,0,0
0,32,32,32,32,0,0,0,0,15,21,15,15,15,15,15,0,0,0,0,0,0,0,0,0,0
0,0,32,0,0,0,0,0,0,15,55,15,15,15,0,15,15,15,0,0,0,0,0,0,0,0
16,16,32,32,15,0,0,0,0,15,15,40,40,40,40,40,0,0,15,0,0,0,0,0,0,0
16,16,32,0,0,0,0,0,15,0,0,0,0,49,0,0,0,0,0,15,0,0,0,0,0,0
16,16,0,0,0,0,0,0,15,0,0,0,0,0,0,0,0,0,0,15,0,0,0,0,0,0
0,16,0,0,0,0,0,15,48,0,0,0,0,0,0,0,0,0,0,15,0,0,0,0,0,0
16,16,16,0,0,0,15,0,0,0,0,0,0,0,0,0,0,0,15,0,0,0,0,0,0,0
0,16,0,0,0,0,15,0,42,56,0,0,0,0,0,0,0,0,15,0,0,0,0,0,0,0
0,0,0,0,0,0,15,54,40,42,0,0,0,0,0,0,0,0,15,0,0,0,0,0,0,0
0,0,0,0,0,0,15,40,0,0,0,0,0,0,0,0,0,15,0,0,0,0,0,15,0,0
0,0,0,0,0,0,15,0,0,0,0,0,0,0,0,0,0,15,0,0,0,0,16,16,16,0
0,0,0,0,0,0,16,15,0,0,0,0,0,0,0,0,15,0,0,0,0,16,16,16,16,16
0,0,0,0,0,16,16,16,15,15,15,0,0,0,0,15,0,0,0,0,0,16,16,16,16,0
0,0,0,0,0,0,16,0,0,0,0,15,15,15,15,0,0,16,16,16,16,16,16,16,16,0
0,0,0,0,0,0,0,0,0,0,0,0,0,0,0,0,16,16,16,16,16,16,16,16,0,0
0,0,32,0,0,0,0,0,0,0,0,0,0,0,0,16,16,16,16,15,16,16,0,0,0,0
0,0,0,0,0,0,0,0,0,0,0,0,0,0,16,16,16,16,16,16,16,16,16,0,0,0
0,0,16,0,0,0,0,0,0,0,0,0,0,16,16,16,16,16,16,16,16,16,16,16,0,0
0,16,16,16,0,0,0,0,0,0,0,0,16,16,16,16,16,16,16,0,0,0,16,0,0,0
0,0,16,16,16,0,16,0,0,0,0,16,16,16,16,16,16,16,16,0,0,0,0,0,0,0
16,16,16,15,16,16,16,16,0,0,0,0,16,0,16,16,16,16,0,0,0,0,0,0,0,0
0,16,16,16,16,16,16,16,16,0,0,0,0,0,0,0,0,0,0,0,0,0,0,0,0,0
16,30,16,30,31,16,16,0,16,16,16,0,0,0,0,0,0,0,0,0,0,0,0,0,0,0
0,16,15,16,16,16,16,16,16,15,16,0,0,0,32,32,0,16,0,0,0,0,0,0,0,0
0,0,16,16,16,16,16,0,16,16,16,0,0,32,27,32,16,16,16,0,0,0,0,0,0,0
0,0,16,16,16,16,16,0,0,0,0,0,0,32,32,32,0,16,0,0,0,0,0,0,0,0
0,0,0,16,16,16,0,0,0,0,0,0,0,0,0,0,0,0,0,0,0,0,0,0,0,0
0,0,0,0,0,0,0,0,0,0,0,0,0,0,0,0,0,0,0,0,0,0,0,0,0,0
0,0,0,0,0,0,0,0,0,0,0,0,0,0,0,0,0,0,0,0,0,0,0,0,0,0
endlayer

layer
0,0,0,0,0,0,0,0,0,0,0,0,0,0,0,0,0,0,0,0,0,0,0,0,0,0
0,0,0,0,0,0,0,0,0,0,0,0,0,0,0,0,0,0,0,0,0,0,0,0,0,0
0,0,0,0,0,16,16,30,16,0,0,0,0,0,0,0,0,0,0,0,0,0,0,0,0,0
0,0,0,0,16,16,16,16,16,0,16,16,0,0,0,0,0,0,0,0,0,0,0,0,0,0
0,0,0,0,16,16,16,16,16,0,16,15,16,0,0,0,0,0,0,0,0,0,0,0,0,0
0,0,16,16,16,15,16,16,16,0,0,16,0,0,0,0,16,0,0,0,0,0,0,0,0,0
0,0,16,16,16,16,30,16,16,0,0,0,0,0,0,16,16,16,0,0,0,0,0,0,0,0
0,0,16,16,16,16,16,30,16,0,0,0,0,0,0,0,16,0,0,0,0,0,0,0,0,0
0,0,16,16,16,16,16,16,0,0,0,0,0,0,0,0,0,0,0,0,0,0,0,0,0,0
0,0,16,16,16,30,0,0,0,0,0,0,0,0,0,0,0,0,0,16,16,16,0,0,0,0
0,32,32,32,16,30,16,0,0,0,0,0,0,0,0,0,0,0,0,16,16,16,0,0,0,0
0,32,32,32,32,16,0,0,0,0,0,15,15,15,15,0,0,0,0,16,16,15,0,0,0,0
32,32,27,32,32,0,0,0,0,0,15,0,0,23,0,15,0,0,0,16,16,16,0,0,0,0
32,32,32,32,32,16,0,0,0,15,15,0,0,0,0,15,0,0,0,16,16,16,16,0,0,0
32,32,32,32,16,16,16,0,0,15,15,57,0,0,15,15,0,0,0,0,0,0,0,0,0,0
0,0,0,0,0,16,0,16,0,15,15,0,0,0,0,15,15,0,0,0,0,0,0,0,0,0
0,0,0,0,15,0,0,16,0,15,40,40,40,40,40,40,0,15,0,0,0,0,0,0,0,0
0,0,0,0,0,0,0,0,0,15,0,0,0,0,0,0,0,0,15,0,0,0,0,0,0,0
16,0,16,0,0,0,0,0,15,0,0,0,0,0,0,0,0,0,0,15,0,0,0,0,0,0
16,16,16,16,0,0,0,15,0,0,0,0,0,0,0,0,0,0,0,15,0,0,0,0,0,0
0,0,0,0,0,0,15,0,0,0,0,0,0,0,0,0,0,0,15,0,0,0,0,0,0,0
0,0,0,0,0,0,15,0,42,42,0,0,0,0,0,0,0,0,15,0,0,0,16,16,16,16
0,0,0,0,0,0,15,31,31,42,0,0,0,0,0,0,0,15,0,0,0,16,16,16,16,16
0,0,0,0,0,0,15,0,54,42,0,0,0,0,0,0,0,15,0,0,0,16,16,15,16,16
0,0,0,0,0,0,0,15,40,40,0,0,0,0,0,0,0,15,0,0,0,16,16,16,16,0
0,0,0,0,0,0,0,15,15,40,0,0,0,0,0,0,15,0,0,0,0,16,16,16,16,0
0,0,0,0,0,0,0,0,15,15,15,15,15,15,15,15,0,0,0,0,0,16,16,16,16,0
0,0,0,0,0,0,0,0,0,0,0,0,0,0,0,0,0,0,0,0,0,16,16,16,16,0
0,0,32,0,0,0,0,0,0,0,0,0,0,0,0,0,16,16,16,16,16,0,0,16,0,0
0,0,32,32,0,0,0,0,0,0,0,0,0,0,0,16,16,16,16,15,16,0,0,0,0,0
0,16,16,16,0,0,0,0,0,0,0,0,0,0,0,0,16,16,16,16,0,0,0,0,0,0
35,31,16,16,16,0,0,0,0,0,0,0,0,0,0,0,0,16,16,16,0,0,0,0,0,0
16,16,16,16,16,0,0,0,0,0,0,0,0,0,16,16,16,16,16,0,0,0,0,0,0,0
16,16,16,16,16,0,0,0,0,0,0,0,0,0,0,16,0,0,0,0,0,0,0,0,0,0
16,16,16,16,16,16,0,0,0,0,0,0,0,0,0,0,0,0,0,0,0,0,0,0,0,0
16,16,16,16,16,31,16,0,0,0,0,0,0,0,0,0,0,0,0,0,0,0,0,0,0,0
16,16,16,16,16,16,0,0,0,16,0,0,0,0,0,0,0,0,0,0,0,0,0,0,0,0
16,16,15,16,16,16,16,0,16,16,16,0,0,0,32,0,0,0,0,0,0,0,0,0,0,0
35,30,16,30,16,16,16,0,0,16,0,0,0,32,32,32,0,0,0,0,0,0,0,0,0,0
16,0,16,16,16,16,16,0,0,0,0,0,0,0,32,0,0,0,0,0,0,0,0,0,0,0
0,0,0,16,16,16,0,0,0,0,0,0,0,0,0,0,0,0,0,0,0,0,0,0,0,0
0,0,0,0,0,0,0,0,0,0,0,0,0,0,0,0,0,0,0,0,0,0,0,0,0,0
0,0,0,0,0,0,0,0,0,0,0,0,0,0,0,0,0,0,0,0,0,0,0,0,0,0
endlayer

layer
0,0,0,0,0,0,16,0,0,0,0,0,0,0,0,0,0,0,0,0,0,0,0,0,0,0
0,0,0,0,0,16,16,16,16,16,0,0,0,0,0,0,0,0,0,0,0,0,0,0,0,0
0,0,0,0,0,16,16,16,16,16,0,0,0,0,0,0,0,0,0,0,0,0,0,0,0,0
0,0,0,0,16,30,16,16,16,16,0,16,0,0,0,0,0,0,0,0,0,0,0,0,0,0
0,0,0,0,16,30,16,16,16,0,16,16,16,0,0,0,0,0,0,0,0,0,0,0,0,0
0,0,16,16,16,15,16,16,16,0,0,16,0,0,0,0,0,0,0,0,0,0,0,0,0,0
0,16,16,16,16,16,16,16,16,0,0,0,0,0,0,0,0,0,0,0,0,0,0,0,0,0
0,16,16,16,16,16,16,16,31,16,0,0,0,0,0,0,0,0,0,0,0,0,0,0,0,0
0,0,16,16,16,16,16,16,16,31,16,0,0,0,0,0,0,0,0,0,0,0,0,0,0,0
0,0,16,16,16,16,16,16,0,16,0,0,0,0,0,0,0,0,0,16,16,16,0,0,0,0
0,0,0,16,16,16,16,16,0,0,0,0,0,0,0,0,0,0,0,16,16,16,0,0,0,0
0,0,32,16,16,16,16,16,0,0,0,15,15,15,15,0,0,0,0,16,16,15,35,0,0,0
0,32,27,32,16,16,16,0,0,0,15,0,0,0,0,15,0,0,0,16,16,16,35,0,0,0
0,32,32,16,16,16,16,16,0,15,0,0,0,0,0,15,0,0,0,0,16,16,16,0,0,0
0,0,30,16,16,30,16,16,0,15,0,0,0,0,15,0,0,0,0,0,0,0,0,0,0,0
0,0,0,30,30,16,16,16,16,15,0,0,0,0,0,15,15,0,0,0,0,0,0,0,0,0
0,0,0,0,15,16,16,16,16,15,40,40,40,40,40,40,0,15,0,0,0,0,0,0,0,0
0,16,16,16,0,0,0,0,0,15,0,0,0,0,0,0,0,0,15,0,0,0,0,0,0,0
16,16,16,16,16,0,0,0,15,0,0,0,0,0,0,0,0,0,0,15,0,0,0,0,0,0
16,16,16,16,16,0,0,15,0,0,0,0,0,0,42,0,0,0,0,15,0,0,0,0,0,0
0,16,16,16,0,0,15,0,0,0,0,0,0,42,42,42,0,0,15,0,0,0,0,0,0,0
0,0,0,0,0,0,15,0,0,56,0,0,0,0,42,0,0,0,15,0,0,16,16,16,16,0
0,0,0,0,0,0,15,0,15,31,0,0,0,0,0,0,0,15,0,0,0,16,16,16,16,16
0,0,0,0,0,0,15,0,0,42,42,0,0,0,0,0,0,15,0,0,0,16,16,15,16,16
0,0,0,0,0,0,0,15,0,0,42,0,0,0,0,0,0,15,0,0,0,16,16,16,16,16
0,0,0,0,0,0,0,15,0,58,40,0,0,0,0,0,15,0,0,0,0,0,16,16,16,0
0,0,0,0,0,0,0,0,15,15,15,15,15,15,15,15,0,0,0,0,0,0,16,16,16,0
0,0,0,0,0,0,0,0,0,0,0,0,0,0,0,0,0,0,0,0,0,0,0,16,0,0
16,0,32,0,0,0,0,0,0,0,0,0,0,0,0,0,0,0,0,16,0,0,0,0,0,0
16,16,16,0,0,0,0,0,0,0,0,0,0,0,0,0,0,16,16,16,16,0,0,0,0,0
16,16,16,16,0,0,0,0,0,0,0,0,0,0,0,0,0,16,16,16,0,0,0,0,0,0
16,16,16,16,16,0,0,0,0,0,0,0,0,0,0,0,0,0,0,0,0,0,0,0,0,0
0,16,16,16,0,0,0,0,0,0,0,0,0,0,0,0,0,0,0,0,0,0,0,0,0,0
35,16,16,16,16,16,16,0,0,0,0,0,0,0,0,0,0,0,0,0,0,0,0,0,0,0
16,16,16,16,16,16,16,16,0,0,0,0,0,0,0,0,0,0,0,0,0,0,0,0,0,0
16,16,16,16,16,16,16,16,0,0,0,0,0,0,0,0,0,0,0,0,0,0,0,0,0,0
35,16,16,16,16,16,16,16,0,0,0,0,0,0,0,0,0,0,0,0,0,0,0,0,0,0
35,31,15,31,31,16,16,0,0,0,0,0,0,0,0,0,0,0,0,0,0,0,0,0,0,0
16,16,16,16,16,16,16,0,0,0,0,0,0,0,0,0,0,0,0,0,0,0,0,0,0,0
16,16,16,16,30,16,16,0,0,0,0,0,0,0,0,0,0,0,0,0,0,0,0,0,0,0
16,16,0,16,16,16,0,0,0,0,0,0,0,0,0,0,0,0,0,0,0,0,0,0,0,0
0,0,0,0,0,0,0,0,0,0,0,0,0,0,0,0,0,0,0,0,0,0,0,0,0,0
0,0,0,0,0,0,0,0,0,0,0,0,0,0,0,0,0,0,0,0,0,0,0,0,0,0
endlayer

layer
0,0,0,0,0,0,0,0,0,0,0,0,0,0,0,0,0,0,0,0,0,0,0,0,0,0
0,0,0,0,16,16,16,16,16,16,0,0,0,0,0,0,0,0,0,0,0,0,0,0,0,0
0,0,0,16,16,16,16,16,16,16,0,0,0,0,0,0,0,0,0,0,0,0,0,0,0,0
0,0,0,16,16,16,16,16,16,16,0,0,0,0,0,0,0,0,0,0,0,0,0,0,0,0
0,0,0,16,16,16,16,16,16,0,0,0,0,0,0,0,0,0,0,0,0,0,0,0,0,0
0,0,0,0,16,15,31,31,16,0,0,0,0,0,0,0,0,0,0,0,0,0,0,0,0,0
0,0,0,16,30,30,16,16,16,16,16,0,0,0,0,0,0,0,0,0,0,0,0,0,0,0
0,0,16,16,30,16,30,16,16,16,16,16,0,0,0,0,0,0,0,0,0,0,0,0,0,0
0,0,0,16,16,16,16,16,16,16,16,16,0,0,0,0,0,0,0,0,0,0,0,0,0,0
0,0,0,16,16,16,16,16,16,16,16,16,0,0,0,0,0,0,0,0,0,0,0,0,0,0
0,0,16,16,16,16,16,16,16,16,16,0,0,0,0,0,0,0,0,0,0,16,0,0,0,0
0,16,16,16,16,16,16,16,0,0,0,0,0,0,0,0,0,0,0,0,16,15,35,35,0,0
16,30,16,16,16,16,30,16,0,0,15,15,15,15,15,0,0,0,0,0,0,16,35,0,0,0
0,16,30,16,16,30,16,16,0,15,0,0,49,59,15,0,0,0,0,0,0,0,0,0,0,0
0,0,0,16,16,30,16,16,0,15,0,0,0,0,15,0,0,0,31,31,31,15,0,0,0,0
0,0,0,16,30,16,16,16,0,15,0,0,0,0,0,15,15,31,31,31,30,0,0,0,0,0
0,0,0,0,15,16,16,0,0,15,40,40,40,40,40,40,0,15,31,30,0,0,0,0,0,0
0,16,31,30,0,0,0,0,0,15,0,0,0,0,0,0,0,0,15,15,0,0,0,0,0,0
16,16,16,16,16,0,0,0,15,0,0,0,0,0,0,0,0,0,0,15,0,0,0,0,0,0
16,16,16,16,16,0,0,15,0,0,0,0,0,0,56,0,0,0,0,15,0,0,0,0,0,0
16,16,16,16,16,0,15,0,0,0,30,0,0,56,42,56,0,0,15,0,0,0,0,0,0,0
0,16,16,16,0,0,15,0,0,0,30,0,0,0,56,0,0,0,15,0,0,0,0,0,0,0
0,0,0,0,0,0,15,0,0,15,31,0,0,0,0,0,0,15,35,35,0,0,16,16,0,0
0,0,0,0,0,0,15,0,0,0,56,0,0,0,0,0,0,15,35,35,0,0,16,15,16,0
0,0,0,0,0,0,0,15,0,0,42,0,0,0,0,0,0,15,35,35,26,0,0,16,0,0
0,0,0,0,0,0,0,15,0,0,58,40,0,0,0,0,15,0,0,26,0,0,0,0,0,0
0,0,0,0,0,0,0,0,15,15,15,15,15,15,15,15,0,0,0,0,0,0,0,0,0,0
0,0,0,0,0,0,0,0,0,0,0,0,0,0,0,0,0,0,0,0,0,0,0,0,0,0
16,0,0,0,0,0,0,0,0,0,0,0,0,0,0,0,0,0,0,0,0,0,0,0,0,0
16,16,16,0,0,0,0,0,0,0,0,0,0,0,0,0,0,0,0,0,0,0,0,0,0,0
16,16,16,16,0,0,0,0,0,0,0,0,0,0,0,0,0,0,0,0,0,0,0,0,0,0
16,16,16,16,0,0,0,0,0,0,0,0,0,0,0,0,0,0,0,0,0,0,0,0,0,0
0,16,16,0,0,0,0,0,0,0,0,0,0,0,0,0,0,0,0,0,0,0,0,0,0,0
0,16,16,16,16,16,16,0,0,0,0,0,0,0,0,0,0,0,0,0,0,0,0,0,0,0
0,16,16,16,16,16,16,16,0,0,0,0,0,0,0,0,0,0,0,0,0,0,0,0,0,0
16,16,16,16,16,16,16,16,0,0,0,0,0,0,0,0,0,0,0,0,0,0,0,0,0,0
0,16,16,16,16,31,31,16,0,0,0,0,0,0,0,0,0,0,0,0,0,0,0,0,0,0
16,16,15,31,16,16,16,0,0,0,0,0,0,0,0,0,0,0,0,0,0,0,0,0,0,0
16,30,16,30,31,16,16,0,0,0,0,0,0,0,0,0,0,0,0,0,0,0,0,0,0,0
16,30,16,16,16,16,16,0,0,0,0,0,0,0,0,0,0,0,0,0,0,0,0,0,0,0
0,16,16,16,16,16,16,0,0,0,0,0,0,0,0,0,0,0,0,0,0,0,0,0,0,0
0,0,0,16,16,16,0,0,0,0,0,0,0,0,0,0,0,0,0,0,0,0,0,0,0,0
0,0,0,0,0,0,0,0,0,0,0,0,0,0,0,0,0,0,0,0,0,0,0,0,0,0
endlayer

layer
0,0,0,0,0,0,0,0,0,0,0,0,0,0,0,0,0,0,0,0,0,0,0,0,0,0
0,0,0,0,16,16,16,0,0,16,0,0,0,0,0,0,0,0,0,0,0,0,0,0,0,0
0,0,0,16,16,16,16,16,0,16,0,0,0,0,0,0,0,0,0,0,0,0,0,0,0,0
0,0,0,16,16,16,16,16,16,16,0,0,0,0,0,0,0,0,0,0,0,0,0,0,0,0
0,0,0,16,16,16,16,16,31,31,16,0,0,0,0,0,0,0,0,0,0,0,0,0,0,0
0,0,0,16,16,15,31,31,31,16,0,0,0,0,0,0,0,0,0,0,0,0,0,0,0,0
0,0,16,16,16,30,16,16,16,16,16,0,0,0,0,0,0,0,0,0,0,0,0,0,0,0
0,0,16,16,16,30,16,16,16,16,16,0,0,0,0,0,0,0,0,0,0,0,0,0,0,0
0,0,16,16,16,16,16,16,16,16,16,16,0,0,0,0,0,0,0,0,0,0,0,0,0,0
0,0,0,16,16,16,16,16,16,16,16,0,0,0,0,0,0,0,0,0,0,0,0,0,0,0
16,16,16,0,16,16,16,16,16,16,0,0,0,0,0,0,0,0,0,0,0,16,0,0,0,0
16,16,16,16,16,16,16,16,16,0,0,0,0,0,0,0,0,0,0,0,16,16,35,0,0,0
16,16,16,16,16,16,16,16,16,0,15,15,15,15,0,0,0,0,0,0,0,16,0,0,0,0
16,16,16,16,16,30,16,16,16,15,40,40,40,40,15,0,0,31,31,31,31,0,0,0,0,0
16,16,16,16,16,16,16,16,0,15,40,40,40,40,15,0,0,30,0,0,60,15,0,0,0,0
0,0,0,16,16,16,16,16,0,15,40,40,40,40,40,15,31,30,0,0,31,15,0,0,0,0
0,0,31,31,15,16,16,0,0,15,40,40,40,40,40,40,40,41,0,30,0,0,0,0,0,0
0,16,16,16,0,0,0,0,0,15,40,40,40,40,40,40,40,40,54,30,0,0,0,0,0,0
16,31,16,16,16,0,0,0,15,0,0,0,40,40,40,40,40,40,40,15,26,0,0,0,0,0
16,16,16,16,16,0,0,15,0,0,0,0,40,40,40,40,40,40,40,15,0,0,0,0,0,0
16,16,16,16,16,0,15,61,0,0,15,0,40,40,40,40,40,40,15,26,0,0,0,0,0,0
0,16,16,16,0,0,15,0,0,0,0,0,40,40,40,40,40,40,15,0,0,0,0,0,0,0
0,0,0,0,0,0,15,31,31,15,0,0,40,40,40,40,40,15,0,35,0,0,0,16,0,0
0,0,0,0,0,0,15,0,0,0,0,0,40,40,40,40,40,15,31,26,26,0,16,16,16,0
0,0,0,0,0,0,0,15,0,0,42,42,40,40,40,40,40,15,35,35,26,0,0,16,0,0
0,0,0,0,0,35,35,15,0,0,0,58,40,40,40,40,15,0,0,26,26,0,0,0,0,0
0,0,0,0,0,35,15,35,15,15,15,15,15,15,15,15,0,0,0,0,0,0,0,0,0,0
0,0,0,0,0,26,0,0,0,0,0,0,15,15,0,0,0,0,0,0,0,0,0,0,0,0
16,16,0,0,0,0,0,0,0,0,0,0,0,0,0,0,0,0,0,0,0,0,0,0,0,0
16,31,16,0,0,0,0,0,0,0,0,0,0,0,0,0,0,0,0,0,0,0,0,0,0,0
0,16,16,16,0,0,0,0,0,0,0,0,0,0,0,0,0,0,0,0,0,0,0,0,0,0
0,16,16,16,0,0,0,0,0,0,0,0,0,0,0,0,0,0,0,0,0,0,0,0,0,0
0,16,16,0,0,0,0,0,0,0,0,0,0,0,0,0,0,0,0,0,0,0,0,0,0,0
0,16,16,0,16,16,16,0,0,0,0,0,0,0,0,0,0,0,0,0,0,0,0,0,0,0
0,16,16,16,16,16,16,16,0,0,0,0,0,0,0,0,0,0,0,0,0,0,0,0,0,0
0,16,16,16,16,16,16,16,16,0,0,0,0,0,0,0,0,0,0,0,0,0,0,0,0,0
0,16,16,16,16,16,16,16,16,0,0,0,0,0,0,0,0,0,0,0,0,0,0,0,0,0
0,16,15,31,31,31,16,16,16,0,0,0,0,0,0,0,0,0,0,0,0,0,0,0,0,0
16,16,16,16,31,16,16,16,0,0,0,0,0,0,0,0,0,0,0,0,0,0,0,0,0,0
16,16,16,16,16,31,31,16,0,0,0,0,0,0,0,0,0,0,0,0,0,0,0,0,0,0
0,16,16,16,16,16,16,0,0,0,0,0,0,0,0,0,0,0,0,0,0,0,0,0,0,0
0,16,0,16,16,16,0,0,0,0,0,0,0,0,0,0,0,0,0,0,0,0,0,0,0,0
0,0,0,0,0,0,0,0,0,0,0,0,0,0,0,0,0,0,0,0,0,0,0,0,0,0
endlayer

layer
0,0,0,0,0,0,0,0,0,0,0,0,0,0,0,0,0,0,0,0,0,0,0,0,0,0
0,0,0,0,16,16,0,0,0,0,0,0,0,0,0,0,0,0,0,0,0,0,0,0,0,0
0,0,0,16,16,16,16,16,16,16,16,0,0,0,0,0,0,0,0,0,0,0,0,0,0,0
0,0,0,16,16,16,16,16,16,16,16,16,0,0,0,0,0,0,0,0,0,0,0,0,0,0
0,0,0,16,16,16,16,16,16,16,16,16,0,0,0,0,0,0,0,0,0,0,0,0,0,0
0,0,0,16,16,15,16,16,31,31,16,16,0,0,0,0,0,0,0,0,0,0,0,0,0,0
0,0,16,16,16,16,16,16,16,16,16,0,0,0,0,0,0,0,0,0,0,0,0,0,0,0
0,0,16,16,16,16,16,16,16,16,16,16,0,0,0,0,0,0,0,0,0,0,0,0,0,0
0,0,16,16,16,16,30,16,16,16,16,0,0,0,0,0,0,0,0,0,0,0,0,0,0,0
0,0,0,16,16,16,30,16,16,16,16,0,0,0,0,0,0,0,26,26,35,0,0,0,0,0
0,16,0,16,16,16,16,16,16,16,0,0,0,0,0,0,0,0,26,26,35,35,0,0,0,0
16,16,16,16,16,16,16,16,16,0,0,0,0,0,0,0,0,0,0,26,35,35,0,0,0,0
16,16,16,16,16,16,16,16,16,0,15,15,15,15,0,0,0,0,0,0,0,0,0,0,0,0
16,16,16,16,16,16,16,16,16,15,30,0,0,0,15,0,0,31,31,15,15,0,0,0,0,0
16,16,16,30,16,16,16,0,0,15,15,0,0,0,15,0,0,30,0,0,60,15,0,0,0,0
31,31,0,30,16,16,16,0,0,15,0,0,0,0,0,15,15,30,0,0,15,15,0,0,0,0
16,16,16,0,15,0,0,0,0,15,0,0,0,0,0,0,0,0,0,30,0,0,0,0,0,0
16,16,16,30,30,0,0,0,0,15,42,42,42,0,0,0,0,0,0,30,35,0,0,0,0,0
16,16,16,30,30,0,0,0,15,0,0,0,42,0,0,0,0,0,0,15,26,0,0,0,0,0
16,16,16,16,0,0,0,15,0,0,0,0,42,0,0,0,0,0,0,15,26,26,0,0,0,0
16,16,16,0,0,0,15,0,0,0,0,0,42,0,0,0,0,62,15,0,0,0,0,0,0,0
0,0,0,0,0,0,15,0,0,0,0,0,42,0,0,0,0,63,15,0,0,0,0,0,0,0
0,0,0,0,0,0,15,0,0,0,0,0,42,0,0,0,0,15,0,0,0,0,0,0,0,0
0,0,0,0,35,35,15,0,0,0,0,0,42,0,0,0,0,15,26,26,26,0,0,0,0,0
0,0,0,35,35,31,31,15,0,0,0,42,42,0,0,0,64,15,0,0,0,0,0,0,0,0
0,0,35,35,31,0,35,0,15,0,0,0,0,0,0,0,15,0,0,0,0,0,0,0,0,0
0,0,0,0,0,35,35,35,0,15,15,30,30,30,30,15,0,0,0,0,0,0,0,0,0,0
0,16,16,0,0,26,35,35,0,0,0,15,30,30,15,0,0,0,0,0,0,0,0,0,0,0
0,16,16,16,0,0,35,0,26,26,0,0,30,30,0,0,0,0,0,0,0,0,0,0,0,0
0,0,16,16,0,0,0,0,0,0,0,0,30,30,0,0,0,0,0,0,0,0,0,0,0,0
0,0,16,16,0,0,0,0,0,0,0,0,30,30,0,0,0,0,0,0,0,0,0,0,0,0
0,16,16,0,0,0,0,0,0,0,0,0,0,0,0,0,0,0,0,0,0,0,0,0,0,0
0,16,0,0,0,0,0,0,0,0,0,0,0,0,0,0,0,0,0,0,0,0,0,0,0,0
0,0,16,0,0,0,0,0,0,0,0,0,0,0,0,0,0,0,0,0,0,0,0,0,0,0
0,35,16,0,0,16,16,16,0,0,0,0,0,0,0,0,0,0,0,0,0,0,0,0,0,0
0,0,16,0,16,16,16,16,16,0,0,0,0,0,0,0,0,0,0,0,0,0,0,0,0,0
0,0,16,0,16,16,16,16,16,0,0,0,0,0,0,0,0,0,0,0,0,0,0,0,0,0
0,16,15,16,16,16,31,31,16,0,0,0,0,0,0,0,0,0,0,0,0,0,0,0,0,0
0,16,16,16,16,31,31,16,16,0,0,0,0,0,0,0,0,0,0,0,0,0,0,0,0,0
0,16,16,16,16,16,16,16,16,0,0,0,0,0,0,0,0,0,0,0,0,0,0,0,0,0
0,0,16,16,16,16,16,16,16,0,0,0,0,0,0,0,0,0,0,0,0,0,0,0,0,0
0,16,16,0,16,16,16,16,0,0,0,0,0,0,0,0,0,0,0,0,0,0,0,0,0,0
0,0,0,0,0,0,0,0,0,0,0,0,0,0,0,0,0,0,0,0,0,0,0,0,0,0
endlayer

layer
0,0,0,0,0,0,0,0,0,0,0,0,0,0,0,0,0,0,0,0,0,0,0,0,0,0
0,0,0,0,0,0,0,0,0,0,0,0,0,0,0,0,0,0,0,0,0,0,0,0,0,0
0,0,0,0,0,16,0,0,16,16,0,0,0,0,0,0,0,0,0,0,0,0,0,0,0,0
0,0,0,0,16,16,16,16,16,16,16,0,0,0,0,0,0,0,0,0,0,0,0,0,0,0
0,0,0,0,0,16,16,16,16,16,16,16,0,0,0,0,0,0,0,0,0,0,0,0,0,0
0,0,0,16,16,15,16,16,16,16,16,16,0,0,0,0,0,0,0,0,0,0,0,0,0,0
0,0,16,16,16,16,16,16,16,16,16,16,0,0,0,0,0,0,0,0,0,0,0,0,0,0
0,0,0,16,16,16,16,16,16,16,16,0,0,0,0,0,0,0,0,0,0,0,0,0,0,0
0,0,0,16,16,16,16,16,16,16,0,0,0,0,0,0,0,35,35,35,35,35,35,0,0,0
0,0,0,16,16,16,16,16,16,16,0,0,0,0,0,0,0,35,35,35,35,35,35,0,0,0
0,0,0,0,16,16,16,16,16,0,0,0,0,0,0,26,26,0,35,35,35,35,35,0,0,0
0,16,0,16,16,16,16,16,0,0,0,0,0,0,0,0,35,35,35,35,30,35,35,0,0,0
16,16,16,16,16,16,16,16,0,0,15,15,15,15,0,0,35,35,35,35,30,35,35,0,0,0
16,16,16,16,16,16,16,16,0,15,30,0,0,0,15,0,35,35,15,15,15,35,35,35,0,0
16,16,16,16,16,16,16,0,0,15,0,0,0,0,15,0,0,15,0,15,60,15,35,35,0,0
16,16,16,16,16,16,16,0,0,15,0,0,0,0,0,15,15,15,0,0,15,15,0,0,0,0
16,16,16,16,15,0,0,0,0,15,0,0,0,0,0,0,0,0,0,15,0,0,0,0,0,0
16,16,16,16,0,0,0,0,0,15,0,0,0,0,0,0,0,0,0,15,0,35,0,0,0,0
16,16,16,16,16,0,0,0,15,0,0,0,0,0,0,0,0,0,0,15,26,26,0,26,0,0
16,16,30,16,30,16,0,15,0,0,0,0,0,0,0,0,0,0,0,15,31,31,26,26,26,0
16,16,16,0,16,0,15,0,0,0,0,0,0,0,0,0,0,0,15,26,26,26,26,26,0,0
0,0,0,0,0,0,15,0,0,0,0,0,0,0,0,0,0,0,15,26,0,26,0,0,0,0
0,0,0,0,0,0,15,0,0,0,0,0,0,0,0,0,0,15,0,0,0,0,0,0,0,0
0,0,0,0,0,35,15,0,0,0,0,0,0,0,0,0,0,15,0,0,0,0,0,0,0,0
0,0,0,0,35,35,0,15,0,0,0,0,0,0,0,0,0,15,0,0,0,0,0,0,0,0
0,0,35,35,35,35,35,35,15,0,0,0,0,0,0,0,15,0,0,0,0,0,0,0,0,0
0,0,35,31,35,35,35,35,0,15,15,30,0,0,30,15,0,0,0,0,0,0,0,0,0,0
0,16,35,35,35,26,26,0,0,0,0,30,0,0,30,26,26,0,0,0,0,0,0,0,0,0
0,0,16,0,0,0,0,26,26,26,0,30,0,0,30,26,26,0,0,0,0,0,0,0,0,0
0,0,16,16,0,0,0,0,26,26,0,30,0,0,30,0,26,0,0,0,0,0,0,0,0,0
0,0,16,26,0,0,0,0,0,0,0,30,54,54,30,0,0,0,0,0,0,0,0,0,0,0
0,0,35,0,0,0,0,0,0,0,0,0,30,30,0,0,0,0,0,0,0,0,0,0,0,0
0,0,35,0,0,0,0,0,0,0,0,0,30,30,0,0,0,0,0,0,0,0,0,0,0,0
0,0,35,0,0,0,0,0,0,0,0,0,0,0,0,0,0,0,0,0,0,0,0,0,0,0
0,0,0,0,0,16,16,16,0,0,0,0,0,0,0,0,0,0,0,0,0,0,0,0,0,0
0,0,0,0,16,16,16,16,16,0,0,0,0,0,0,0,0,0,0,0,0,0,0,0,0,0
0,16,16,0,16,16,16,16,16,16,0,0,0,0,0,0,0,0,0,0,0,0,0,0,0,0
0,16,15,16,16,16,16,16,16,16,0,0,0,0,0,0,0,0,0,0,0,0,0,0,0,0
0,0,16,0,16,16,16,16,16,16,0,0,0,0,0,0,0,0,0,0,0,0,0,0,0,0
16,16,0,16,16,16,16,16,16,0,0,0,0,0,0,0,0,0,0,0,0,0,0,0,0,0
0,16,16,0,16,16,16,16,0,0,0,0,0,0,0,0,0,0,0,0,0,0,0,0,0,0
0,0,0,0,0,16,16,0,0,0,0,0,0,0,0,0,0,0,0,0,0,0,0,0,0,0
0,0,0,0,0,0,0,0,0,0,0,0,0,0,0,0,0,0,0,0,0,0,0,0,0,0
endlayer

layer
0,0,0,0,0,0,0,0,0,0,0,0,0,0,0,0,0,0,0,0,0,0,0,0,0,0
0,0,0,0,0,0,0,0,0,0,0,0,0,0,0,0,0,0,0,0,0,0,0,0,0,0
0,0,0,0,0,0,0,0,0,0,0,0,0,0,0,0,0,0,0,0,0,0,0,0,0,0
0,0,0,0,16,16,16,0,16,16,0,0,0,0,0,0,0,0,0,0,0,0,0,0,0,0
0,0,0,16,16,16,16,16,16,16,16,0,0,0,0,0,0,0,0,0,0,0,0,0,0,0
0,0,0,16,16,16,16,16,16,16,16,16,0,0,0,0,0,0,0,0,0,0,0,0,0,0
0,0,0,16,16,16,16,16,16,16,16,0,0,0,0,0,0,0,0,0,0,0,0,0,0,0
0,0,0,0,16,16,16,16,16,16,0,0,0,0,0,0,0,0,35,0,0,0,0,0,0,0
0,0,0,0,16,16,16,16,16,0,0,0,26,26,0,0,0,0,35,35,26,35,35,0,0,0
0,0,0,0,16,16,16,16,16,0,0,0,26,26,0,0,0,0,35,35,30,35,35,0,0,0
0,0,0,0,16,16,16,16,0,0,26,26,26,0,26,35,35,0,0,35,30,35,35,0,0,0
0,0,0,0,16,16,16,0,0,0,0,0,0,26,26,35,15,26,35,35,35,35,35,0,0,0
0,16,16,16,16,16,16,0,0,0,15,15,15,15,0,35,35,35,35,35,26,35,0,35,0,0
16,16,16,16,16,16,16,16,0,15,0,0,49,0,15,0,35,35,15,15,15,35,35,35,0,0
16,16,16,16,30,16,16,0,0,15,0,0,0,0,15,0,35,15,59,15,60,15,35,35,0,0
16,16,16,16,30,16,16,0,0,65,0,0,0,0,0,15,15,15,0,15,15,15,26,26,0,0
16,16,16,16,15,31,31,0,0,15,0,0,0,0,0,0,0,0,0,15,0,0,0,0,0,0
16,16,16,16,16,16,16,0,0,15,0,0,0,0,0,0,0,0,0,15,0,26,26,0,0,0
16,16,16,16,16,16,16,0,15,0,0,0,0,0,0,0,0,0,0,15,26,26,26,26,0,0
16,16,16,16,16,16,16,15,0,0,0,0,0,0,0,0,0,0,0,15,26,26,15,26,26,0
16,16,16,16,16,16,15,0,0,0,0,0,0,0,0,0,0,0,15,26,26,26,26,26,26,0
0,16,16,16,16,16,15,0,0,0,0,0,0,0,0,0,0,0,15,0,26,26,26,26,0,0
0,0,0,0,0,0,15,0,0,0,0,0,0,0,0,0,0,15,0,0,0,0,0,0,0,0
0,0,0,0,0,0,15,0,0,0,0,0,0,0,0,0,0,65,0,0,0,0,0,0,0,0
0,0,0,0,35,35,0,15,0,0,0,0,0,0,0,0,0,15,0,0,0,0,0,0,0,0
0,0,0,0,35,35,35,35,15,0,0,0,0,0,0,0,15,0,0,0,0,0,0,0,0,0
0,0,15,35,35,35,35,35,0,15,15,30,0,0,30,15,0,0,0,0,0,0,0,0,0,0
0,0,35,35,0,26,0,0,0,0,0,30,0,59,30,26,26,26,0,0,0,0,0,0,0,0
0,0,0,0,0,0,0,26,26,26,0,30,0,0,30,26,26,26,0,0,0,0,0,0,0,0
0,0,16,0,0,0,0,0,26,31,31,30,0,0,30,26,26,26,0,0,0,0,0,0,0,0
0,0,0,0,0,0,0,26,26,26,26,30,0,0,30,0,0,26,0,0,0,0,0,0,0,0
0,0,35,0,0,0,0,0,0,0,0,30,0,0,30,0,0,0,0,0,0,0,0,0,0,0
0,0,26,0,0,0,0,0,0,26,0,30,54,54,30,0,0,0,0,0,0,0,0,0,0,0
0,0,0,0,0,0,0,0,26,26,26,0,30,30,0,0,0,0,0,0,0,0,0,0,0,0
0,0,0,0,0,0,0,0,0,0,0,0,15,15,0,0,0,0,0,0,0,0,0,0,0,0
0,16,16,16,0,0,16,16,0,0,0,0,0,0,0,0,0,0,0,0,0,0,0,0,0,0
0,16,16,16,16,16,16,16,16,0,0,0,0,0,0,0,0,0,0,0,0,0,0,0,0,0
0,0,16,16,16,16,16,16,16,16,0,0,0,0,0,0,0,0,0,0,0,0,0,0,0,0
0,16,16,16,16,16,16,16,16,0,0,0,0,0,0,0,0,0,0,0,0,0,0,0,0,0
0,16,16,16,16,16,16,16,0,0,0,0,0,0,0,0,0,0,0,0,0,0,0,0,0,0
0,0,16,0,0,16,16,0,0,0,0,0,0,0,0,0,0,0,0,0,0,0,0,0,0,0
0,0,0,0,0,0,0,0,0,0,0,0,0,0,0,0,0,0,0,0,0,0,0,0,0,0
0,0,0,0,0,0,0,0,0,0,0,0,0,0,0,0,0,0,0,0,0,0,0,0,0,0
endlayer

layer
0,0,0,0,0,0,0,0,0,0,0,0,0,0,0,0,0,0,0,0,0,0,0,0,0,0
0,0,0,0,0,0,0,0,0,0,0,0,0,0,0,0,0,0,0,0,0,0,0,0,0,0
0,0,0,0,0,0,0,0,0,0,0,0,0,0,0,0,0,0,0,0,0,0,0,0,0,0
0,0,0,0,0,16,0,0,0,0,0,0,0,0,0,0,0,0,0,0,0,0,0,0,0,0
0,0,0,0,16,16,16,0,16,16,0,0,0,0,0,0,0,0,0,0,0,0,0,0,0,0
0,0,0,16,16,16,16,16,16,16,16,0,0,0,0,0,0,0,0,0,0,0,0,0,0,0
0,0,0,0,16,16,16,0,16,16,0,0,0,0,0,0,0,0,0,0,0,0,0,0,0,0
0,0,0,0,0,16,16,0,0,26,0,0,26,26,0,0,0,26,26,0,0,0,0,0,0,0
0,0,0,0,0,16,16,16,0,0,0,26,26,26,26,0,0,0,26,35,26,0,0,0,0,0
0,0,0,0,0,16,16,16,35,0,0,26,26,26,26,26,0,26,26,35,26,35,0,0,0,0
0,0,0,0,0,0,16,26,35,0,26,26,26,26,26,35,35,26,26,35,26,35,35,0,0,0
0,0,0,0,0,0,0,26,35,0,15,15,0,26,26,0,26,30,35,26,26,35,35,0,0,0
0,0,0,16,16,16,0,0,35,15,0,0,15,15,0,0,35,35,35,26,26,35,35,35,0,0
0,0,16,16,16,16,16,0,50,15,0,0,0,0,15,0,35,35,35,15,15,35,35,35,35,0
16,16,16,16,16,16,16,0,50,15,0,0,0,0,15,0,0,35,15,15,60,15,15,35,35,0
16,16,16,16,16,16,16,0,50,15,0,0,0,0,0,15,15,15,0,15,15,15,15,26,0,0
16,16,16,16,15,16,16,0,50,15,0,0,0,0,0,0,0,0,0,15,0,0,0,0,0,0
0,16,16,16,16,16,16,16,50,15,0,0,0,0,0,0,0,0,0,15,0,0,0,0,0,0
0,16,16,16,16,16,16,16,15,0,0,0,0,0,0,0,0,0,0,15,0,26,26,26,26,26
16,16,16,16,16,16,16,15,0,0,0,0,0,0,0,0,0,0,0,15,0,26,26,15,26,26
0,16,16,16,16,16,15,0,0,0,0,0,0,0,0,0,0,0,15,52,0,26,26,26,26,0
0,0,16,0,16,0,15,0,0,0,0,0,0,0,0,0,0,0,15,52,0,0,26,0,0,0
0,0,0,0,0,0,15,0,0,0,0,0,0,0,0,0,0,15,40,52,0,0,0,0,0,0
0,0,0,0,0,0,15,0,0,0,0,0,0,0,0,0,0,15,40,52,0,0,0,0,0,0
0,0,35,0,35,35,47,15,0,0,0,0,0,0,0,0,0,15,40,52,0,0,0,0,0,0
0,35,35,0,35,35,35,35,15,0,0,0,0,0,0,0,15,40,40,52,0,0,0,0,0,0
0,35,15,35,35,35,35,35,50,15,15,15,30,30,15,15,40,40,40,52,0,0,0,0,0,0
0,0,35,35,35,26,26,26,0,0,0,0,30,30,0,0,26,26,0,0,0,0,0,0,0,0
0,0,35,35,0,0,26,26,0,0,0,30,0,0,30,26,26,26,0,0,0,0,0,0,0,0
0,0,0,0,0,0,26,26,26,26,0,30,0,0,30,26,26,26,0,0,0,0,0,0,0,0
0,0,0,0,0,0,26,26,26,26,26,30,0,0,30,0,26,26,0,0,0,0,0,0,0,0
0,0,0,0,0,0,26,0,26,26,26,30,0,0,30,0,0,0,0,0,0,0,0,0,0,0
0,0,0,0,0,0,0,0,26,31,26,30,0,0,30,0,0,0,0,0,0,0,0,0,0,0
0,0,0,0,0,0,0,0,26,26,26,30,54,54,30,0,0,0,0,0,0,0,0,0,0,0
0,0,0,0,0,0,0,0,0,0,0,15,15,15,15,0,0,0,0,0,0,0,0,0,0,0
0,0,16,0,0,0,0,0,0,0,0,0,0,0,0,0,0,0,0,0,0,0,0,0,0,0
0,16,16,16,0,0,16,16,0,0,0,0,0,0,0,0,0,0,0,0,0,0,0,0,0,0
0,0,16,16,16,16,16,16,16,0,0,0,0,0,0,0,0,0,0,0,0,0,0,0,0,0
0,0,16,16,16,16,16,16,0,0,0,0,0,0,0,0,0,0,0,0,0,0,0,0,0,0
0,0,16,0,0,16,16,0,0,0,0,0,0,0,0,0,0,0,0,0,0,0,0,0,0,0
0,0,0,0,0,0,0,0,0,0,0,0,0,0,0,0,0,0,0,0,0,0,0,0,0,0
0,0,0,0,0,0,0,0,0,0,0,0,0,0,0,0,0,0,0,0,0,0,0,0,0,0
0,0,0,0,0,0,0,0,0,0,0,0,0,0,0,0,0,0,0,0,0,0,0,0,0,0
endlayer

layer
0,0,0,0,0,0,0,0,0,0,0,0,0,0,0,0,0,0,0,0,0,0,0,0,0,0
0,0,0,0,0,0,0,0,0,0,0,0,0,0,0,0,0,0,0,0,0,0,0,0,0,0
0,0,0,0,0,0,0,0,0,0,0,0,0,0,0,0,0,0,0,0,0,0,0,0,0,0
0,0,0,0,0,0,0,0,0,0,0,0,0,0,0,0,0,0,0,0,0,0,0,0,0,0
0,0,0,0,0,16,0,0,0,0,0,0,0,0,0,0,0,0,0,0,0,0,0,0,0,0
0,0,0,0,16,16,16,0,16,16,26,0,0,0,0,0,0,0,0,0,0,0,0,0,0,0
0,0,0,0,0,16,0,0,26,26,26,26,0,0,0,0,0,0,0,0,0,0,0,0,0,0
0,0,0,0,0,0,0,0,26,26,0,35,35,26,0,0,0,26,0,0,0,0,0,0,0,0
0,0,0,0,0,0,16,0,35,35,35,35,30,26,26,26,0,26,26,26,0,0,0,0,0,0
0,0,0,0,0,0,16,26,35,35,35,26,26,26,26,26,35,26,26,35,26,0,0,0,0,0
0,0,0,0,0,0,0,26,35,35,15,15,15,26,26,35,35,26,26,35,26,26,0,0,0,0
0,0,0,0,0,0,0,26,35,15,0,0,30,0,26,26,35,35,26,0,26,26,35,26,0,0
0,0,0,0,16,0,0,0,0,15,0,0,15,0,26,26,0,35,26,26,26,26,35,26,26,0
0,0,0,16,16,16,0,0,66,67,0,0,67,67,67,67,67,67,67,66,15,15,35,35,35,26
0,0,16,16,16,16,16,0,66,40,0,0,0,0,0,66,66,67,40,15,0,60,15,26,26,26
16,16,16,16,16,16,16,16,66,40,0,0,0,0,0,0,0,40,47,15,15,15,15,0,0,0
0,0,16,16,16,16,16,16,66,40,0,0,0,0,0,0,0,0,47,66,0,0,0,0,0,0
0,0,16,16,16,16,16,16,66,40,0,0,0,0,0,0,0,0,47,66,0,0,0,0,26,0
0,0,16,16,16,16,16,0,66,47,0,0,0,0,0,0,0,0,47,66,0,26,26,26,26,0
0,16,16,16,16,16,0,66,66,47,0,0,0,0,0,0,0,0,47,66,0,26,26,26,26,26
0,0,16,0,16,0,66,47,67,47,0,0,0,0,0,0,0,0,40,66,0,0,26,26,26,26
0,0,0,0,35,0,66,47,67,47,0,0,0,0,0,0,0,0,40,66,0,0,0,0,0,0
0,0,0,0,0,0,66,47,67,47,0,0,0,0,0,0,0,0,40,66,0,0,0,0,0,0
0,0,0,0,0,0,66,47,67,47,0,0,0,0,0,0,0,0,40,66,0,0,0,0,0,0
0,0,26,0,0,0,35,66,66,47,0,0,0,0,0,0,0,40,67,66,0,0,0,0,0,0
0,35,35,35,0,0,0,0,66,47,0,0,0,0,0,0,40,40,67,66,0,0,0,0,0,0
0,35,35,35,0,0,0,0,66,67,67,67,67,67,67,67,67,67,67,66,0,0,0,0,0,0
35,35,35,35,0,0,0,0,0,0,0,0,0,0,0,0,0,0,0,0,0,0,0,0,0,0
0,0,0,0,0,26,26,26,0,0,0,0,30,30,0,0,26,0,0,0,0,0,0,0,0,0
0,0,0,0,0,26,26,31,26,0,0,0,30,30,0,0,26,35,26,0,0,0,0,0,0,0
0,0,0,0,0,0,26,26,26,0,0,30,0,0,30,26,26,26,26,0,0,0,0,0,0,0
0,0,0,0,0,0,26,26,26,26,26,30,0,0,30,0,26,26,0,0,0,0,0,0,0,0
0,0,0,0,0,0,0,26,26,26,26,30,0,0,30,0,0,0,0,0,0,0,0,0,0,0
0,0,0,0,0,0,0,0,26,26,26,30,0,0,30,0,0,0,0,0,0,0,0,0,0,0
0,0,0,0,0,0,0,0,0,0,0,15,0,8,15,0,0,0,0,0,0,0,0,0,0,0
0,0,0,0,0,0,0,0,0,0,0,0,15,15,0,0,0,0,0,0,0,0,0,0,0,0
0,0,16,0,0,0,0,0,0,0,0,0,0,0,0,0,0,0,0,0,0,0,0,0,0,0
0,16,16,16,0,0,16,16,0,0,0,0,0,0,0,0,0,0,0,0,0,0,0,0,0,0
0,0,16,0,0,16,16,0,0,0,0,0,0,0,0,0,0,0,0,0,0,0,0,0,0,0
0,0,0,0,0,0,0,0,0,0,0,0,0,0,0,0,0,0,0,0,0,0,0,0,0,0
0,0,0,0,0,0,0,0,0,0,0,0,0,0,0,0,0,0,0,0,0,0,0,0,0,0
0,0,0,0,0,0,0,0,0,0,0,0,0,0,0,0,0,0,0,0,0,0,0,0,0,0
0,0,0,0,0,0,0,0,0,0,0,0,0,0,0,0,0,0,0,0,0,0,0,0,0,0
endlayer

layer
0,0,0,0,0,0,0,0,0,0,0,0,0,0,0,0,0,0,0,0,0,0,0,0,0,0
0,0,0,0,0,0,0,0,0,0,0,0,0,0,0,0,0,0,0,0,0,0,0,0,0,0
0,0,0,0,0,0,0,0,0,0,0,0,0,0,0,0,0,0,0,0,0,0,0,0,0,0
0,0,0,0,0,0,0,0,0,0,0,0,0,0,0,0,0,0,0,0,0,0,0,0,0,0
0,0,0,0,0,0,0,0,0,0,0,0,0,0,0,0,0,0,0,0,0,0,0,0,0,0
0,0,0,0,0,16,0,0,0,0,0,0,0,0,0,0,0,0,0,0,0,0,0,0,0,0
0,0,0,0,0,0,0,0,0,26,26,26,0,26,0,0,0,0,0,0,0,0,0,0,0,0
0,0,0,0,0,0,0,0,26,26,26,35,26,26,0,0,0,26,0,0,0,0,0,0,0,0
0,0,0,0,0,0,35,35,35,35,30,35,35,26,26,26,26,26,0,0,0,0,0,0,0,0
0,0,0,0,0,0,35,35,35,35,15,15,26,26,26,35,35,35,26,26,0,0,0,0,0,0
0,0,0,0,0,0,35,35,35,15,68,0,15,26,26,35,30,35,35,0,0,0,0,0,0,0
0,0,0,0,0,0,0,0,35,15,0,0,15,26,30,31,35,35,0,0,26,0,0,0,0,0
0,0,0,0,0,0,0,0,0,15,0,0,30,31,31,26,26,0,0,0,0,0,26,26,0,0
0,0,0,0,16,0,0,0,0,0,67,47,40,40,40,40,67,66,0,0,15,15,26,26,26,0
0,0,0,16,16,16,0,0,0,0,66,47,0,0,0,0,47,66,0,15,0,60,15,26,0,0
0,0,0,16,16,16,16,0,0,0,66,47,0,0,0,0,47,66,0,0,15,15,15,0,0,0
0,0,16,16,16,16,16,16,0,0,66,47,0,0,0,0,47,66,0,0,0,0,0,0,0,0
0,0,0,16,16,16,16,0,0,0,66,47,0,0,0,0,47,66,0,0,0,0,26,26,0,0
0,0,0,0,16,0,0,0,0,0,66,47,0,0,0,0,47,66,0,0,0,0,26,26,26,0
0,0,16,0,16,0,0,0,0,0,66,47,0,0,0,0,47,66,0,0,0,0,26,26,26,0
0,0,0,0,0,0,0,0,0,0,66,47,0,0,0,0,47,66,0,0,0,0,26,26,26,0
0,0,0,0,0,0,0,0,0,0,66,47,0,0,0,0,47,66,0,0,0,0,0,0,26,0
0,0,0,0,0,0,0,0,0,0,66,47,0,0,0,0,47,66,0,0,0,0,0,0,0,0
0,0,0,0,0,0,0,0,0,0,66,47,0,0,0,0,47,66,0,0,0,0,0,0,0,0
0,0,0,0,0,0,0,0,0,0,66,47,0,0,0,0,67,66,0,0,0,0,0,0,0,0
0,0,26,0,0,0,0,0,0,0,66,47,0,0,0,0,67,66,0,0,0,0,0,0,0,0
26,35,35,0,0,0,0,0,0,0,66,67,67,67,67,67,67,66,0,0,0,0,0,0,0,0
0,35,0,0,0,0,0,0,0,0,0,0,0,0,0,0,0,0,0,0,0,0,0,0,0,0
0,0,0,0,0,0,0,26,26,26,26,0,0,0,0,0,0,0,0,0,0,0,0,0,0,0
0,0,0,0,0,0,26,26,26,26,0,0,0,0,0,0,26,0,0,0,0,0,0,0,0,0
0,0,0,0,0,0,26,26,26,0,0,0,30,30,0,26,26,26,0,0,0,0,0,0,0,0
0,0,0,0,0,0,0,0,26,26,26,0,30,30,0,0,26,0,0,0,0,0,0,0,0,0
0,0,0,0,0,0,0,0,26,26,26,30,0,0,30,0,0,0,0,0,0,0,0,0,0,0
0,0,0,0,0,0,0,0,26,0,0,15,0,0,15,0,0,0,0,0,0,0,0,0,0,0
0,0,0,0,0,0,0,0,0,0,0,15,0,8,15,0,0,0,0,0,0,0,0,0,0,0
0,0,0,0,0,0,0,0,0,0,0,0,15,15,0,0,0,0,0,0,0,0,0,0,0,0
0,0,0,0,0,0,0,0,0,0,0,0,0,0,0,0,0,0,0,0,0,0,0,0,0,0
0,0,16,0,0,0,0,0,0,0,0,0,0,0,0,0,0,0,0,0,0,0,0,0,0,0
0,0,0,0,0,0,0,0,0,0,0,0,0,0,0,0,0,0,0,0,0,0,0,0,0,0
0,0,0,0,0,0,0,0,0,0,0,0,0,0,0,0,0,0,0,0,0,0,0,0,0,0
0,0,0,0,0,0,0,0,0,0,0,0,0,0,0,0,0,0,0,0,0,0,0,0,0,0
0,0,0,0,0,0,0,0,0,0,0,0,0,0,0,0,0,0,0,0,0,0,0,0,0,0
0,0,0,0,0,0,0,0,0,0,0,0,0,0,0,0,0,0,0,0,0,0,0,0,0,0
endlayer

layer
0,0,0,0,0,0,0,0,0,0,0,0,0,0,0,0,0,0,0,0,0,0,0,0,0,0
0,0,0,0,0,0,0,0,0,0,0,0,0,0,0,0,0,0,0,0,0,0,0,0,0,0
0,0,0,0,0,0,0,0,0,0,0,0,0,0,0,0,0,0,0,0,0,0,0,0,0,0
0,0,0,0,0,0,0,0,0,0,0,0,0,0,0,0,0,0,0,0,0,0,0,0,0,0
0,0,0,0,0,0,0,0,0,0,0,0,0,0,0,0,0,0,0,0,0,0,0,0,0,0
0,0,0,0,0,0,0,0,0,0,0,0,0,0,0,0,0,0,0,0,0,0,0,0,0,0
0,0,0,0,0,0,0,0,0,0,0,0,0,0,0,0,0,0,0,0,0,0,0,0,0,0
0,0,0,0,0,0,0,0,0,0,0,35,0,0,0,0,0,0,0,0,0,0,0,0,0,0
0,0,0,0,0,0,0,0,40,40,40,40,40,40,40,0,0,26,0,0,0,0,0,0,0,0
0,0,0,0,0,0,35,0,40,40,15,15,40,40,40,0,26,26,0,0,0,0,0,0,0,0
0,0,0,0,0,0,0,0,40,15,68,0,15,40,40,26,26,26,0,0,0,0,0,0,0,0
0,0,0,0,0,0,0,0,40,15,0,0,15,40,40,35,26,0,0,0,0,0,0,0,0,0
0,0,0,0,0,0,0,0,40,40,15,15,40,40,40,26,26,0,0,40,40,40,40,40,0,0
0,0,0,0,0,0,0,0,40,40,40,40,67,40,40,66,0,0,0,40,15,15,40,40,0,0
0,0,0,0,16,0,0,0,40,40,40,40,67,47,47,66,0,0,0,40,15,60,15,40,0,0
0,0,0,0,16,0,0,0,0,0,0,0,66,47,47,66,0,0,0,40,40,15,15,40,0,0
0,0,0,16,16,16,16,0,0,0,0,0,66,47,47,66,0,0,0,40,40,40,40,40,0,0
0,0,0,0,16,0,0,0,0,0,0,0,66,47,47,66,0,0,0,0,0,0,0,0,0,0
0,0,0,0,0,0,0,0,0,0,0,0,66,47,47,66,0,0,0,0,0,0,0,35,35,0
0,0,0,0,0,0,0,0,0,0,0,0,66,47,47,66,0,0,0,0,0,0,35,35,35,0
0,0,0,0,0,0,0,0,0,0,0,0,66,47,47,66,0,0,0,0,0,0,26,26,26,0
0,0,0,0,0,0,0,0,0,0,0,0,66,47,47,66,0,0,0,0,0,0,0,26,0,0
0,0,0,0,0,0,0,0,0,0,0,0,66,47,47,66,0,0,0,0,0,0,0,0,0,0
0,0,0,0,0,0,0,0,0,0,0,0,66,47,47,66,0,0,0,0,0,0,0,0,0,0
0,0,0,0,0,0,0,0,0,0,0,0,66,47,47,66,0,0,0,0,0,0,0,0,0,0
0,0,0,0,0,0,0,0,0,0,0,0,66,47,47,66,0,0,0,0,0,0,0,0,0,0
0,0,0,0,0,0,0,0,0,0,0,0,66,67,67,66,0,0,0,0,0,0,0,0,0,0
0,0,0,0,0,0,0,0,0,0,0,0,0,0,0,0,0,0,0,0,0,0,0,0,0,0
0,0,0,0,0,0,0,0,0,0,0,0,0,0,0,0,0,0,0,0,0,0,0,0,0,0
0,0,0,0,0,0,0,0,0,26,0,0,0,0,0,0,0,0,0,0,0,0,0,0,0,0
0,0,0,0,0,0,0,0,0,0,0,0,0,0,0,0,0,0,0,0,0,0,0,0,0,0
0,0,0,0,0,0,0,0,0,0,0,0,0,0,0,0,0,0,0,0,0,0,0,0,0,0
0,0,0,0,0,0,0,0,0,0,40,40,30,30,40,40,40,0,0,0,0,0,0,0,0,0
0,0,0,0,0,0,0,0,0,0,40,15,0,0,15,40,40,0,0,0,0,0,0,0,0,0
0,0,0,0,0,0,0,0,0,0,40,15,0,8,15,40,40,0,0,0,0,0,0,0,0,0
0,0,0,0,0,0,0,0,0,0,40,40,15,15,40,40,40,0,0,0,0,0,0,0,0,0
0,0,0,0,0,0,0,0,0,0,40,40,40,40,40,40,40,0,0,0,0,0,0,0,0,0
0,0,0,0,0,0,0,0,0,0,40,40,40,40,40,40,40,0,0,0,0,0,0,0,0,0
0,0,0,0,0,0,0,0,0,0,0,0,0,0,0,0,0,0,0,0,0,0,0,0,0,0
0,0,0,0,0,0,0,0,0,0,0,0,0,0,0,0,0,0,0,0,0,0,0,0,0,0
0,0,0,0,0,0,0,0,0,0,0,0,0,0,0,0,0,0,0,0,0,0,0,0,0,0
0,0,0,0,0,0,0,0,0,0,0,0,0,0,0,0,0,0,0,0,0,0,0,0,0,0
0,0,0,0,0,0,0,0,0,0,0,0,0,0,0,0,0,0,0,0,0,0,0,0,0,0
endlayer

layer
0,0,0,0,0,0,0,0,0,0,0,0,0,0,0,0,0,0,0,0,0,0,0,0,0,0
0,0,0,0,0,0,0,0,0,0,0,0,0,0,0,0,0,0,0,0,0,0,0,0,0,0
0,0,0,0,0,0,0,0,0,0,0,0,0,0,0,0,0,0,0,0,0,0,0,0,0,0
0,0,0,0,0,0,0,0,0,0,0,0,0,0,0,0,0,0,0,0,0,0,0,0,0,0
0,0,0,0,0,0,0,0,0,0,0,0,0,0,0,0,0,0,0,0,0,0,0,0,0,0
0,0,0,0,0,0,0,0,0,0,0,0,0,0,0,0,0,0,0,0,0,0,0,0,0,0
0,0,0,0,0,0,0,0,0,0,0,0,0,0,0,0,0,0,0,0,0,0,0,0,0,0
0,0,0,0,0,0,0,0,0,0,0,0,0,0,0,0,0,0,0,0,0,0,0,0,0,0
0,0,0,0,0,0,0,0,40,40,40,40,40,40,40,0,0,0,0,0,0,0,0,0,0,0
0,0,0,0,0,0,0,0,40,0,0,0,0,0,40,0,0,0,0,0,0,0,0,0,0,0
0,0,0,0,0,0,0,0,40,0,0,0,0,0,40,0,0,0,0,0,0,0,0,0,0,0
0,0,0,0,0,0,0,0,40,0,0,0,0,0,40,26,0,0,0,0,0,0,0,0,0,0
0,0,0,0,0,0,0,0,40,0,0,0,0,0,40,26,0,0,0,40,42,42,42,40,0,0
0,0,0,0,0,0,0,0,40,0,0,0,0,0,40,0,0,0,0,42,0,0,0,42,0,0
0,0,0,0,0,0,0,0,40,40,40,40,40,71,40,0,0,0,0,42,0,0,0,42,0,0
0,0,0,0,0,0,0,0,0,0,0,0,0,0,0,0,0,0,0,42,0,0,0,42,0,0
0,0,0,0,16,0,0,0,0,0,0,0,0,0,0,0,0,0,0,40,42,42,42,40,0,0
0,0,0,0,0,0,0,0,0,0,0,0,0,0,0,0,0,0,0,0,0,0,0,0,0,0
0,0,0,0,0,0,0,0,0,0,0,0,0,0,0,0,0,0,0,0,0,0,0,0,0,0
0,0,0,0,0,0,0,0,0,0,0,0,0,0,0,0,0,0,0,0,0,0,0,0,0,0
0,0,0,0,0,0,0,0,0,0,0,0,0,0,0,0,0,0,0,0,0,0,0,0,0,0
0,0,0,0,0,0,0,0,0,0,0,0,0,0,0,0,0,0,0,0,0,0,0,0,0,0
0,0,0,0,0,0,0,0,0,0,0,0,0,0,0,0,0,0,0,0,0,0,0,0,0,0
0,0,0,0,0,0,0,0,0,0,0,0,0,0,0,0,0,0,0,0,0,0,0,0,0,0
0,0,0,0,0,0,0,0,0,0,0,0,0,0,0,0,0,0,0,0,0,0,0,0,0,0
0,0,0,0,0,0,0,0,0,0,0,0,0,0,0,0,0,0,0,0,0,0,0,0,0,0
0,0,0,0,0,0,0,0,0,0,0,0,0,0,0,0,0,0,0,0,0,0,0,0,0,0
0,0,0,0,0,0,0,0,0,0,0,0,0,0,0,0,0,0,0,0,0,0,0,0,0,0
0,0,0,0,0,0,0,0,0,0,0,0,0,0,0,0,0,0,0,0,0,0,0,0,0,0
0,0,0,0,0,0,0,0,0,0,0,0,0,0,0,0,0,0,0,0,0,0,0,0,0,0
0,0,0,0,0,0,0,0,0,0,0,0,0,0,0,0,0,0,0,0,0,0,0,0,0,0
0,0,0,0,0,0,0,0,0,0,0,0,0,0,0,0,0,0,0,0,0,0,0,0,0,0
0,0,0,0,0,0,0,0,0,0,40,40,40,40,40,40,40,0,0,0,0,0,0,0,0,0
0,0,0,0,0,0,0,0,0,0,40,0,0,0,0,0,40,0,0,0,0,0,0,0,0,0
0,0,0,0,0,0,0,0,0,0,40,0,0,0,0,0,40,0,0,0,0,0,0,0,0,0
0,0,0,0,0,0,0,0,0,0,40,0,0,0,0,69,40,0,0,0,0,0,0,0,0,0
0,0,0,0,0,0,0,0,0,0,40,64,0,0,0,70,40,0,0,0,0,0,0,0,0,0
0,0,0,0,0,0,0,0,0,0,40,40,40,40,40,40,40,0,0,0,0,0,0,0,0,0
0,0,0,0,0,0,0,0,0,0,0,0,0,0,0,0,0,0,0,0,0,0,0,0,0,0
0,0,0,0,0,0,0,0,0,0,0,0,0,0,0,0,0,0,0,0,0,0,0,0,0,0
0,0,0,0,0,0,0,0,0,0,0,0,0,0,0,0,0,0,0,0,0,0,0,0,0,0
0,0,0,0,0,0,0,0,0,0,0,0,0,0,0,0,0,0,0,0,0,0,0,0,0,0
0,0,0,0,0,0,0,0,0,0,0,0,0,0,0,0,0,0,0,0,0,0,0,0,0,0
endlayer

layer
0,0,0,0,0,0,0,0,0,0,0,0,0,0,0,0,0,0,0,0,0,0,0,0,0,0
0,0,0,0,0,0,0,0,0,0,0,0,0,0,0,0,0,0,0,0,0,0,0,0,0,0
0,0,0,0,0,0,0,0,0,0,0,0,0,0,0,0,0,0,0,0,0,0,0,0,0,0
0,0,0,0,0,0,0,0,0,0,0,0,0,0,0,0,0,0,0,0,0,0,0,0,0,0
0,0,0,0,0,0,0,0,0,0,0,0,0,0,0,0,0,0,0,0,0,0,0,0,0,0
0,0,0,0,0,0,0,0,0,0,0,0,0,0,0,0,0,0,0,0,0,0,0,0,0,0
0,0,0,0,0,0,0,0,0,0,0,0,0,0,0,0,0,0,0,0,0,0,0,0,0,0
0,0,0,0,0,0,0,0,0,0,0,0,0,0,0,0,0,0,0,0,0,0,0,0,0,0
0,0,0,0,0,0,0,0,40,65,40,65,40,65,40,0,0,0,0,0,0,0,0,0,0,0
0,0,0,0,0,0,0,0,72,0,0,0,0,0,72,0,0,0,0,0,0,0,0,0,0,0
0,0,0,0,0,0,0,0,0,0,0,0,0,0,0,0,0,0,0,0,0,0,0,0,0,0
0,0,0,0,0,0,0,0,0,0,0,0,0,0,0,0,0,0,0,0,0,0,0,0,0,0
0,0,0,0,0,0,0,0,54,0,0,0,0,0,54,0,0,0,0,40,0,0,0,40,0,0
0,0,0,0,0,0,0,0,40,0,0,0,0,0,40,0,0,0,0,0,0,0,0,0,0,0
0,0,0,0,0,0,0,0,40,65,40,65,40,73,40,0,0,0,0,0,0,0,0,0,0,0
0,0,0,0,0,0,0,0,0,0,0,0,0,0,0,0,0,0,0,0,0,0,0,0,0,0
0,0,0,0,0,0,0,0,0,0,0,0,0,0,0,0,0,0,0,40,0,0,0,40,0,0
0,0,0,0,0,0,0,0,0,0,0,0,0,0,0,0,0,0,0,0,0,0,0,0,0,0
0,0,0,0,0,0,0,0,0,0,0,0,0,0,0,0,0,0,0,0,0,0,0,0,0,0
0,0,0,0,0,0,0,0,0,0,0,0,0,0,0,0,0,0,0,0,0,0,0,0,0,0
0,0,0,0,0,0,0,0,0,0,0,0,0,0,0,0,0,0,0,0,0,0,0,0,0,0
0,0,0,0,0,0,0,0,0,0,0,0,0,0,0,0,0,0,0,0,0,0,0,0,0,0
0,0,0,0,0,0,0,0,0,0,0,0,0,0,0,0,0,0,0,0,0,0,0,0,0,0
0,0,0,0,0,0,0,0,0,0,0,0,0,0,0,0,0,0,0,0,0,0,0,0,0,0
0,0,0,0,0,0,0,0,0,0,0,0,0,0,0,0,0,0,0,0,0,0,0,0,0,0
0,0,0,0,0,0,0,0,0,0,0,0,0,0,0,0,0,0,0,0,0,0,0,0,0,0
0,0,0,0,0,0,0,0,0,0,0,0,0,0,0,0,0,0,0,0,0,0,0,0,0,0
0,0,0,0,0,0,0,0,0,0,0,0,0,0,0,0,0,0,0,0,0,0,0,0,0,0
0,0,0,0,0,0,0,0,0,0,0,0,0,0,0,0,0,0,0,0,0,0,0,0,0,0
0,0,0,0,0,0,0,0,0,0,0,0,0,0,0,0,0,0,0,0,0,0,0,0,0,0
0,0,0,0,0,0,0,0,0,0,0,0,0,0,0,0,0,0,0,0,0,0,0,0,0,0
0,0,0,0,0,0,0,0,0,0,0,0,0,0,0,0,0,0,0,0,0,0,0,0,0,0
0,0,0,0,0,0,0,0,0,0,40,40,40,65,40,40,40,0,0,0,0,0,0,0,0,0
0,0,0,0,0,0,0,0,0,0,40,0,0,0,0,0,40,0,0,0,0,0,0,0,0,0
0,0,0,0,0,0,0,0,0,0,65,0,0,0,0,0,65,0,0,0,0,0,0,0,0,0
0,0,0,0,0,0,0,0,0,0,65,0,0,0,0,0,65,0,0,0,0,0,0,0,0,0
0,0,0,0,0,0,0,0,0,0,40,0,0,0,0,0,40,0,0,0,0,0,0,0,0,0
0,0,0,0,0,0,0,0,0,0,40,40,65,65,65,40,40,0,0,0,0,0,0,0,0,0
0,0,0,0,0,0,0,0,0,0,0,0,0,0,0,0,0,0,0,0,0,0,0,0,0,0
0,0,0,0,0,0,0,0,0,0,0,0,0,0,0,0,0,0,0,0,0,0,0,0,0,0
0,0,0,0,0,0,0,0,0,0,0,0,0,0,0,0,0,0,0,0,0,0,0,0,0,0
0,0,0,0,0,0,0,0,0,0,0,0,0,0,0,0,0,0,0,0,0,0,0,0,0,0
0,0,0,0,0,0,0,0,0,0,0,0,0,0,0,0,0,0,0,0,0,0,0,0,0,0
endlayer

layer
0,0,0,0,0,0,0,0,0,0,0,0,0,0,0,0,0,0,0,0,0,0,0,0,0,0
0,0,0,0,0,0,0,0,0,0,0,0,0,0,0,0,0,0,0,0,0,0,0,0,0,0
0,0,0,0,0,0,0,0,0,0,0,0,0,0,0,0,0,0,0,0,0,0,0,0,0,0
0,0,0,0,0,0,0,0,0,0,0,0,0,0,0,0,0,0,0,0,0,0,0,0,0,0
0,0,0,0,0,0,0,0,0,0,0,0,0,0,0,0,0,0,0,0,0,0,0,0,0,0
0,0,0,0,0,0,0,0,0,0,0,0,0,0,0,0,0,0,0,0,0,0,0,0,0,0
0,0,0,0,0,0,0,0,0,0,0,0,0,0,0,0,0,0,0,0,0,0,0,0,0,0
0,0,0,0,0,0,0,47,47,47,47,47,47,47,47,47,0,0,0,0,0,0,0,0,0,0
0,0,0,0,0,0,0,47,40,40,40,40,40,40,40,47,0,0,0,0,0,0,0,0,0,0
0,0,0,0,0,0,0,47,40,0,0,0,0,0,40,47,0,0,0,0,0,0,0,0,0,0
0,0,0,0,0,0,0,47,40,0,0,0,0,0,40,47,0,0,0,0,0,0,0,0,0,0
0,0,0,0,0,0,0,47,40,0,0,0,0,0,40,47,0,0,0,0,0,0,0,0,0,0
0,0,0,0,0,0,0,47,40,0,0,0,0,0,40,47,0,0,0,40,0,0,0,40,0,0
0,0,0,0,0,0,0,47,40,0,0,0,0,53,40,47,0,0,0,0,0,0,0,0,0,0
0,0,0,0,0,0,0,47,40,40,40,40,40,40,40,47,0,0,0,0,0,0,0,0,0,0
0,0,0,0,0,0,0,47,47,47,47,47,47,47,47,47,0,0,0,0,0,0,0,0,0,0
0,0,0,0,0,0,0,0,0,0,0,0,0,0,0,0,0,0,0,40,0,0,0,40,0,0
0,0,0,0,0,0,0,0,0,0,0,0,0,0,0,0,0,0,0,0,0,0,0,0,0,0
0,0,0,0,0,0,0,0,0,0,0,0,0,0,0,0,0,0,0,0,0,0,0,0,0,0
0,0,0,0,0,0,0,0,0,0,0,0,0,0,0,0,0,0,0,0,0,0,0,0,0,0
0,0,0,0,0,0,0,0,0,0,0,0,0,0,0,0,0,0,0,0,0,0,0,0,0,0
0,0,0,0,0,0,0,0,0,0,0,0,0,0,0,0,0,0,0,0,0,0,0,0,0,0
0,0,0,0,0,0,0,0,0,0,0,0,0,0,0,0,0,0,0,0,0,0,0,0,0,0
0,0,0,0,0,0,0,0,0,0,0,0,0,0,0,0,0,0,0,0,0,0,0,0,0,0
0,0,0,0,0,0,0,0,0,0,0,0,0,0,0,0,0,0,0,0,0,0,0,0,0,0
0,0,0,0,0,0,0,0,0,0,0,0,0,0,0,0,0,0,0,0,0,0,0,0,0,0
0,0,0,0,0,0,0,0,0,0,0,0,0,0,0,0,0,0,0,0,0,0,0,0,0,0
0,0,0,0,0,0,0,0,0,0,0,0,0,0,0,0,0,0,0,0,0,0,0,0,0,0
0,0,0,0,0,0,0,0,0,0,0,0,0,0,0,0,0,0,0,0,0,0,0,0,0,0
0,0,0,0,0,0,0,0,0,0,0,0,0,0,0,0,0,0,0,0,0,0,0,0,0,0
0,0,0,0,0,0,0,0,0,0,0,0,0,0,0,0,0,0,0,0,0,0,0,0,0,0
0,0,0,0,0,0,0,0,0,40,74,74,74,74,74,74,74,40,0,0,0,0,0,0,0,0
0,0,0,0,0,0,0,0,0,50,40,40,40,40,40,40,40,52,0,0,0,0,0,0,0,0
0,0,0,0,0,0,0,0,0,50,40,0,0,0,0,0,40,52,0,0,0,0,0,0,0,0
0,0,0,0,0,0,0,0,0,50,40,0,0,0,0,0,40,52,0,0,0,0,0,0,0,0
0,0,0,0,0,0,0,0,0,50,40,0,0,0,0,0,40,52,0,0,0,0,0,0,0,0
0,0,0,0,0,0,0,0,0,50,40,0,0,0,0,0,40,52,0,0,0,0,0,0,0,0
0,0,0,0,0,0,0,0,0,50,40,40,40,40,40,40,40,52,0,0,0,0,0,0,0,0
0,0,0,0,0,0,0,0,0,40,75,75,75,75,75,75,75,40,0,0,0,0,0,0,0,0
0,0,0,0,0,0,0,0,0,0,0,0,0,0,0,0,0,0,0,0,0,0,0,0,0,0
0,0,0,0,0,0,0,0,0,0,0,0,0,0,0,0,0,0,0,0,0,0,0,0,0,0
0,0,0,0,0,0,0,0,0,0,0,0,0,0,0,0,0,0,0,0,0,0,0,0,0,0
0,0,0,0,0,0,0,0,0,0,0,0,0,0,0,0,0,0,0,0,0,0,0,0,0,0
endlayer

layer
0,0,0,0,0,0,0,0,0,0,0,0,0,0,0,0,0,0,0,0,0,0,0,0,0,0
0,0,0,0,0,0,0,0,0,0,0,0,0,0,0,0,0,0,0,0,0,0,0,0,0,0
0,0,0,0,0,0,0,0,0,0,0,0,0,0,0,0,0,0,0,0,0,0,0,0,0,0
0,0,0,0,0,0,0,0,0,0,0,0,0,0,0,0,0,0,0,0,0,0,0,0,0,0
0,0,0,0,0,0,0,0,0,0,0,0,0,0,0,0,0,0,0,0,0,0,0,0,0,0
0,0,0,0,0,0,0,0,0,0,0,0,0,0,0,0,0,0,0,0,0,0,0,0,0,0
0,0,0,0,0,0,0,0,0,0,0,0,0,0,0,0,0,0,0,0,0,0,0,0,0,0
0,0,0,0,0,0,0,0,0,0,0,0,0,0,0,0,0,0,0,0,0,0,0,0,0,0
0,0,0,0,0,0,0,0,40,40,40,40,40,40,40,0,0,0,0,0,0,0,0,0,0,0
0,0,0,0,0,0,0,0,40,0,0,0,0,0,40,0,0,0,0,0,0,0,0,0,0,0
0,0,0,0,0,0,0,0,40,0,0,0,0,0,40,0,0,0,0,0,0,0,0,0,0,0
0,0,0,0,0,0,0,0,40,0,0,0,0,0,40,0,0,0,66,66,66,66,66,66,66,0
0,0,0,0,0,0,0,0,40,0,0,0,0,0,40,0,0,0,66,40,40,40,40,40,66,0
0,0,0,0,0,0,0,0,40,0,0,0,0,0,40,0,0,0,66,40,0,0,0,40,66,0
0,0,0,0,0,0,0,0,40,40,40,40,40,40,40,0,0,0,66,40,0,0,0,40,66,0
0,0,0,0,0,0,0,0,0,0,0,0,0,0,0,0,0,0,66,40,0,0,0,40,66,0
0,0,0,0,0,0,0,0,0,0,0,0,0,0,0,0,0,0,66,40,40,40,40,40,66,0
0,0,0,0,0,0,0,0,0,0,0,0,0,0,0,0,0,0,66,66,66,66,66,66,66,0
0,0,0,0,0,0,0,0,0,0,0,0,0,0,0,0,0,0,0,0,0,0,0,0,0,0
0,0,0,0,0,0,0,0,0,0,0,0,0,0,0,0,0,0,0,0,0,0,0,0,0,0
0,0,0,0,0,0,0,0,0,0,0,0,0,0,0,0,0,0,0,0,0,0,0,0,0,0
0,0,0,0,0,0,0,0,0,0,0,0,0,0,0,0,0,0,0,0,0,0,0,0,0,0
0,0,0,0,0,0,0,0,0,0,0,0,0,0,0,0,0,0,0,0,0,0,0,0,0,0
0,0,0,0,0,0,0,0,0,0,0,0,0,0,0,0,0,0,0,0,0,0,0,0,0,0
0,0,0,0,0,0,0,0,0,0,0,0,0,0,0,0,0,0,0,0,0,0,0,0,0,0
0,0,0,0,0,0,0,0,0,0,0,0,0,0,0,0,0,0,0,0,0,0,0,0,0,0
0,0,0,0,0,0,0,0,0,0,0,0,0,0,0,0,0,0,0,0,0,0,0,0,0,0
0,0,0,0,0,0,0,0,0,0,0,0,0,0,0,0,0,0,0,0,0,0,0,0,0,0
0,0,0,0,0,0,0,0,0,0,0,0,0,0,0,0,0,0,0,0,0,0,0,0,0,0
0,0,0,0,0,0,0,0,0,0,0,0,0,0,0,0,0,0,0,0,0,0,0,0,0,0
0,0,0,0,0,0,0,0,0,0,0,0,0,0,0,0,0,0,0,0,0,0,0,0,0,0
0,0,0,0,0,0,0,0,0,66,66,66,66,66,66,66,66,66,0,0,0,0,0,0,0,0
0,0,0,0,0,0,0,0,0,40,67,40,40,40,40,40,67,40,0,0,0,0,0,0,0,0
0,0,0,0,0,0,0,0,0,40,67,0,0,0,0,0,67,40,0,0,0,0,0,0,0,0
0,0,0,0,0,0,0,0,0,40,67,0,0,0,0,0,67,40,0,0,0,0,0,0,0,0
0,0,0,0,0,0,0,0,0,40,67,0,0,0,0,0,67,40,0,0,0,0,0,0,0,0
0,0,0,0,0,0,0,0,0,40,67,0,0,0,0,0,67,40,0,0,0,0,0,0,0,0
0,0,0,0,0,0,0,0,0,40,67,40,40,40,40,40,67,40,0,0,0,0,0,0,0,0
0,0,0,0,0,0,0,0,0,66,66,66,66,66,66,66,66,66,0,0,0,0,0,0,0,0
0,0,0,0,0,0,0,0,0,0,0,0,0,0,0,0,0,0,0,0,0,0,0,0,0,0
0,0,0,0,0,0,0,0,0,0,0,0,0,0,0,0,0,0,0,0,0,0,0,0,0,0
0,0,0,0,0,0,0,0,0,0,0,0,0,0,0,0,0,0,0,0,0,0,0,0,0,0
0,0,0,0,0,0,0,0,0,0,0,0,0,0,0,0,0,0,0,0,0,0,0,0,0,0
endlayer

layer
0,0,0,0,0,0,0,0,0,0,0,0,0,0,0,0,0,0,0,0,0,0,0,0,0,0
0,0,0,0,0,0,0,0,0,0,0,0,0,0,0,0,0,0,0,0,0,0,0,0,0,0
0,0,0,0,0,0,0,0,0,0,0,0,0,0,0,0,0,0,0,0,0,0,0,0,0,0
0,0,0,0,0,0,0,0,0,0,0,0,0,0,0,0,0,0,0,0,0,0,0,0,0,0
0,0,0,0,0,0,0,0,0,0,0,0,0,0,0,0,0,0,0,0,0,0,0,0,0,0
0,0,0,0,0,0,0,0,0,0,0,0,0,0,0,0,0,0,0,0,0,0,0,0,0,0
0,0,0,0,0,0,0,0,0,0,0,0,0,0,0,0,0,0,0,0,0,0,0,0,0,0
0,0,0,0,0,0,0,0,0,0,0,0,0,0,0,0,0,0,0,0,0,0,0,0,0,0
0,0,0,0,0,0,0,0,0,0,0,0,0,0,0,0,0,0,0,0,0,0,0,0,0,0
0,0,0,0,0,0,0,0,0,40,40,40,40,40,0,0,0,0,0,0,0,0,0,0,0,0
0,0,0,0,0,0,0,0,0,40,0,0,0,40,0,0,0,0,0,0,0,0,0,0,0,0
0,0,0,0,0,0,0,0,0,40,0,0,0,40,0,0,0,0,0,0,0,0,0,0,0,0
0,0,0,0,0,0,0,0,0,40,0,0,0,40,0,0,0,0,0,0,0,0,0,0,0,0
0,0,0,0,0,0,0,0,0,40,40,40,40,40,0,0,0,0,0,0,40,40,40,0,0,0
0,0,0,0,0,0,0,0,0,0,0,0,0,0,0,0,0,0,0,0,40,0,40,0,0,0
0,0,0,0,0,0,0,0,0,0,0,0,0,0,0,0,0,0,0,0,40,40,40,0,0,0
0,0,0,0,0,0,0,0,0,0,0,0,0,0,0,0,0,0,0,0,0,0,0,0,0,0
0,0,0,0,0,0,0,0,0,0,0,0,0,0,0,0,0,0,0,0,0,0,0,0,0,0
0,0,0,0,0,0,0,0,0,0,0,0,0,0,0,0,0,0,0,0,0,0,0,0,0,0
0,0,0,0,0,0,0,0,0,0,0,0,0,0,0,0,0,0,0,0,0,0,0,0,0,0
0,0,0,0,0,0,0,0,0,0,0,0,0,0,0,0,0,0,0,0,0,0,0,0,0,0
0,0,0,0,0,0,0,0,0,0,0,0,0,0,0,0,0,0,0,0,0,0,0,0,0,0
0,0,0,0,0,0,0,0,0,0,0,0,0,0,0,0,0,0,0,0,0,0,0,0,0,0
0,0,0,0,0,0,0,0,0,0,0,0,0,0,0,0,0,0,0,0,0,0,0,0,0,0
0,0,0,0,0,0,0,0,0,0,0,0,0,0,0,0,0,0,0,0,0,0,0,0,0,0
0,0,0,0,0,0,0,0,0,0,0,0,0,0,0,0,0,0,0,0,0,0,0,0,0,0
0,0,0,0,0,0,0,0,0,0,0,0,0,0,0,0,0,0,0,0,0,0,0,0,0,0
0,0,0,0,0,0,0,0,0,0,0,0,0,0,0,0,0,0,0,0,0,0,0,0,0,0
0,0,0,0,0,0,0,0,0,0,0,0,0,0,0,0,0,0,0,0,0,0,0,0,0,0
0,0,0,0,0,0,0,0,0,0,0,0,0,0,0,0,0,0,0,0,0,0,0,0,0,0
0,0,0,0,0,0,0,0,0,0,0,0,0,0,0,0,0,0,0,0,0,0,0,0,0,0
0,0,0,0,0,0,0,0,0,0,0,0,0,0,0,0,0,0,0,0,0,0,0,0,0,0
0,0,0,0,0,0,0,0,0,0,0,0,0,0,0,0,0,0,0,0,0,0,0,0,0,0
0,0,0,0,0,0,0,0,0,66,66,66,66,66,66,66,66,66,0,0,0,0,0,0,0,0
0,0,0,0,0,0,0,0,0,40,40,47,47,47,47,47,40,40,0,0,0,0,0,0,0,0
0,0,0,0,0,0,0,0,0,40,40,47,47,47,47,47,40,40,0,0,0,0,0,0,0,0
0,0,0,0,0,0,0,0,0,66,66,66,66,66,66,66,66,66,0,0,0,0,0,0,0,0
0,0,0,0,0,0,0,0,0,0,0,0,0,0,0,0,0,0,0,0,0,0,0,0,0,0
0,0,0,0,0,0,0,0,0,0,0,0,0,0,0,0,0,0,0,0,0,0,0,0,0,0
0,0,0,0,0,0,0,0,0,0,0,0,0,0,0,0,0,0,0,0,0,0,0,0,0,0
0,0,0,0,0,0,0,0,0,0,0,0,0,0,0,0,0,0,0,0,0,0,0,0,0,0
0,0,0,0,0,0,0,0,0,0,0,0,0,0,0,0,0,0,0,0,0,0,0,0,0,0
0,0,0,0,0,0,0,0,0,0,0,0,0,0,0,0,0,0,0,0,0,0,0,0,0,0
endlayer

layer
0,0,0,0,0,0,0,0,0,0,0,0,0,0,0,0,0,0,0,0,0,0,0,0,0,0
0,0,0,0,0,0,0,0,0,0,0,0,0,0,0,0,0,0,0,0,0,0,0,0,0,0
0,0,0,0,0,0,0,0,0,0,0,0,0,0,0,0,0,0,0,0,0,0,0,0,0,0
0,0,0,0,0,0,0,0,0,0,0,0,0,0,0,0,0,0,0,0,0,0,0,0,0,0
0,0,0,0,0,0,0,0,0,0,0,0,0,0,0,0,0,0,0,0,0,0,0,0,0,0
0,0,0,0,0,0,0,0,0,0,0,0,0,0,0,0,0,0,0,0,0,0,0,0,0,0
0,0,0,0,0,0,0,0,0,0,0,0,0,0,0,0,0,0,0,0,0,0,0,0,0,0
0,0,0,0,0,0,0,0,0,0,0,0,0,0,0,0,0,0,0,0,0,0,0,0,0,0
0,0,0,0,0,0,0,0,0,0,0,0,0,0,0,0,0,0,0,0,0,0,0,0,0,0
0,0,0,0,0,0,0,0,0,0,0,0,0,0,0,0,0,0,0,0,0,0,0,0,0,0
0,0,0,0,0,0,0,0,0,0,40,40,40,0,0,0,0,0,0,0,0,0,0,0,0,0
0,0,0,0,0,0,0,0,0,0,40,40,40,0,0,0,0,0,0,0,0,0,0,0,0,0
0,0,0,0,0,0,0,0,0,0,40,40,40,0,0,0,0,0,0,0,0,0,0,0,0,0
0,0,0,0,0,0,0,0,0,0,0,0,0,0,0,0,0,0,0,0,0,0,0,0,0,0
0,0,0,0,0,0,0,0,0,0,0,0,0,0,0,0,0,0,0,0,0,40,0,0,0,0
0,0,0,0,0,0,0,0,0,0,0,0,0,0,0,0,0,0,0,0,0,0,0,0,0,0
0,0,0,0,0,0,0,0,0,0,0,0,0,0,0,0,0,0,0,0,0,0,0,0,0,0
0,0,0,0,0,0,0,0,0,0,0,0,0,0,0,0,0,0,0,0,0,0,0,0,0,0
0,0,0,0,0,0,0,0,0,0,0,0,0,0,0,0,0,0,0,0,0,0,0,0,0,0
0,0,0,0,0,0,0,0,0,0,0,0,0,0,0,0,0,0,0,0,0,0,0,0,0,0
0,0,0,0,0,0,0,0,0,0,0,0,0,0,0,0,0,0,0,0,0,0,0,0,0,0
0,0,0,0,0,0,0,0,0,0,0,0,0,0,0,0,0,0,0,0,0,0,0,0,0,0
0,0,0,0,0,0,0,0,0,0,0,0,0,0,0,0,0,0,0,0,0,0,0,0,0,0
0,0,0,0,0,0,0,0,0,0,0,0,0,0,0,0,0,0,0,0,0,0,0,0,0,0
0,0,0,0,0,0,0,0,0,0,0,0,0,0,0,0,0,0,0,0,0,0,0,0,0,0
0,0,0,0,0,0,0,0,0,0,0,0,0,0,0,0,0,0,0,0,0,0,0,0,0,0
0,0,0,0,0,0,0,0,0,0,0,0,0,0,0,0,0,0,0,0,0,0,0,0,0,0
0,0,0,0,0,0,0,0,0,0,0,0,0,0,0,0,0,0,0,0,0,0,0,0,0,0
0,0,0,0,0,0,0,0,0,0,0,0,0,0,0,0,0,0,0,0,0,0,0,0,0,0
0,0,0,0,0,0,0,0,0,0,0,0,0,0,0,0,0,0,0,0,0,0,0,0,0,0
0,0,0,0,0,0,0,0,0,0,0,0,0,0,0,0,0,0,0,0,0,0,0,0,0,0
0,0,0,0,0,0,0,0,0,0,0,0,0,0,0,0,0,0,0,0,0,0,0,0,0,0
0,0,0,0,0,0,0,0,0,0,0,0,0,0,0,0,0,0,0,0,0,0,0,0,0,0
0,0,0,0,0,0,0,0,0,0,0,0,0,0,0,0,0,0,0,0,0,0,0,0,0,0
0,0,0,0,0,0,0,0,0,0,0,0,0,0,0,0,0,0,0,0,0,0,0,0,0,0
0,0,0,0,0,0,0,0,0,0,0,0,0,0,0,0,0,0,0,0,0,0,0,0,0,0
0,0,0,0,0,0,0,0,0,0,0,0,0,0,0,0,0,0,0,0,0,0,0,0,0,0
0,0,0,0,0,0,0,0,0,0,0,0,0,0,0,0,0,0,0,0,0,0,0,0,0,0
0,0,0,0,0,0,0,0,0,0,0,0,0,0,0,0,0,0,0,0,0,0,0,0,0,0
0,0,0,0,0,0,0,0,0,0,0,0,0,0,0,0,0,0,0,0,0,0,0,0,0,0
0,0,0,0,0,0,0,0,0,0,0,0,0,0,0,0,0,0,0,0,0,0,0,0,0,0
0,0,0,0,0,0,0,0,0,0,0,0,0,0,0,0,0,0,0,0,0,0,0,0,0,0
0,0,0,0,0,0,0,0,0,0,0,0,0,0,0,0,0,0,0,0,0,0,0,0,0,0
endlayer

layer
0,0,0,0,0,0,0,0,0,0,0,0,0,0,0,0,0,0,0,0,0,0,0,0,0,0
0,0,0,0,0,0,0,0,0,0,0,0,0,0,0,0,0,0,0,0,0,0,0,0,0,0
0,0,0,0,0,0,0,0,0,0,0,0,0,0,0,0,0,0,0,0,0,0,0,0,0,0
0,0,0,0,0,0,0,0,0,0,0,0,0,0,0,0,0,0,0,0,0,0,0,0,0,0
0,0,0,0,0,0,0,0,0,0,0,0,0,0,0,0,0,0,0,0,0,0,0,0,0,0
0,0,0,0,0,0,0,0,0,0,0,0,0,0,0,0,0,0,0,0,0,0,0,0,0,0
0,0,0,0,0,0,0,0,0,0,0,0,0,0,0,0,0,0,0,0,0,0,0,0,0,0
0,0,0,0,0,0,0,0,0,0,0,0,0,0,0,0,0,0,0,0,0,0,0,0,0,0
0,0,0,0,0,0,0,0,0,0,0,0,0,0,0,0,0,0,0,0,0,0,0,0,0,0
0,0,0,0,0,0,0,0,0,0,0,0,0,0,0,0,0,0,0,0,0,0,0,0,0,0
0,0,0,0,0,0,0,0,0,0,0,0,0,0,0,0,0,0,0,0,0,0,0,0,0,0
0,0,0,0,0,0,0,0,0,0,0,40,0,0,0,0,0,0,0,0,0,0,0,0,0,0
0,0,0,0,0,0,0,0,0,0,0,0,0,0,0,0,0,0,0,0,0,0,0,0,0,0
0,0,0,0,0,0,0,0,0,0,0,0,0,0,0,0,0,0,0,0,0,0,0,0,0,0
0,0,0,0,0,0,0,0,0,0,0,0,0,0,0,0,0,0,0,0,0,0,0,0,0,0
0,0,0,0,0,0,0,0,0,0,0,0,0,0,0,0,0,0,0,0,0,0,0,0,0,0
0,0,0,0,0,0,0,0,0,0,0,0,0,0,0,0,0,0,0,0,0,0,0,0,0,0
0,0,0,0,0,0,0,0,0,0,0,0,0,0,0,0,0,0,0,0,0,0,0,0,0,0
0,0,0,0,0,0,0,0,0,0,0,0,0,0,0,0,0,0,0,0,0,0,0,0,0,0
0,0,0,0,0,0,0,0,0,0,0,0,0,0,0,0,0,0,0,0,0,0,0,0,0,0
0,0,0,0,0,0,0,0,0,0,0,0,0,0,0,0,0,0,0,0,0,0,0,0,0,0
0,0,0,0,0,0,0,0,0,0,0,0,0,0,0,0,0,0,0,0,0,0,0,0,0,0
0,0,0,0,0,0,0,0,0,0,0,0,0,0,0,0,0,0,0,0,0,0,0,0,0,0
0,0,0,0,0,0,0,0,0,0,0,0,0,0,0,0,0,0,0,0,0,0,0,0,0,0
0,0,0,0,0,0,0,0,0,0,0,0,0,0,0,0,0,0,0,0,0,0,0,0,0,0
0,0,0,0,0,0,0,0,0,0,0,0,0,0,0,0,0,0,0,0,0,0,0,0,0,0
0,0,0,0,0,0,0,0,0,0,0,0,0,0,0,0,0,0,0,0,0,0,0,0,0,0
0,0,0,0,0,0,0,0,0,0,0,0,0,0,0,0,0,0,0,0,0,0,0,0,0,0
0,0,0,0,0,0,0,0,0,0,0,0,0,0,0,0,0,0,0,0,0,0,0,0,0,0
0,0,0,0,0,0,0,0,0,0,0,0,0,0,0,0,0,0,0,0,0,0,0,0,0,0
0,0,0,0,0,0,0,0,0,0,0,0,0,0,0,0,0,0,0,0,0,0,0,0,0,0
0,0,0,0,0,0,0,0,0,0,0,0,0,0,0,0,0,0,0,0,0,0,0,0,0,0
0,0,0,0,0,0,0,0,0,0,0,0,0,0,0,0,0,0,0,0,0,0,0,0,0,0
0,0,0,0,0,0,0,0,0,0,0,0,0,0,0,0,0,0,0,0,0,0,0,0,0,0
0,0,0,0,0,0,0,0,0,0,0,0,0,0,0,0,0,0,0,0,0,0,0,0,0,0
0,0,0,0,0,0,0,0,0,0,0,0,0,0,0,0,0,0,0,0,0,0,0,0,0,0
0,0,0,0,0,0,0,0,0,0,0,0,0,0,0,0,0,0,0,0,0,0,0,0,0,0
0,0,0,0,0,0,0,0,0,0,0,0,0,0,0,0,0,0,0,0,0,0,0,0,0,0
0,0,0,0,0,0,0,0,0,0,0,0,0,0,0,0,0,0,0,0,0,0,0,0,0,0
0,0,0,0,0,0,0,0,0,0,0,0,0,0,0,0,0,0,0,0,0,0,0,0,0,0
0,0,0,0,0,0,0,0,0,0,0,0,0,0,0,0,0,0,0,0,0,0,0,0,0,0
0,0,0,0,0,0,0,0,0,0,0,0,0,0,0,0,0,0,0,0,0,0,0,0,0,0
0,0,0,0,0,0,0,0,0,0,0,0,0,0,0,0,0,0,0,0,0,0,0,0,0,0
endlayer

