# Converted from schematic
# THIS TEMPLATE USES DEFAULTS!  Please edit for corrections.
# If you need help, consult template_rules.txt

weight=1
embed_into_distance=5
acceptable_target_blocks=stone,grass,dirt,sand,gravel
dimensions=20,13,12
allowable_overhang=0
max_leveling=2
leveling_buffer=1
preserve_water=0
preserve_lava=0
preserve_plants=0


rule1=0,100,stone
rule2=0,100,coal_ore
rule3=1,100,gravel
rule4=0,100,dirt
rule5=0,100,water-8
rule6=0,100,water-9
rule7=0,100,water-2
rule8=0,100,water-1
rule9=0,100,water-3
rule10=0,100,water
rule11=0,100,web
rule12=0,100,grass
rule13=0,100,stonebrick-2
rule14=0,100,stonebrick
rule15=1,100,tallgrass-1
rule16=1,100,iron_door-3
rule17=0,100,stonebrick-1
rule18=0,100,stone_brick_stairs-1
rule19=1,100,stone_pressure_plate
rule20=0,100,bookshelf
rule21=1,100,iron_door-8
rule22=0,100,stone_slab-5
rule23=0,100,stone_brick_stairs-2
rule24=0,100,stone_brick_stairs-4
rule25=0,100,stone_brick_stairs
rule26=2,100,torch-4
rule27=0,100,stone_slab-13
rule28=0,100,glass_pane
rule29=0,100,stone_brick_stairs-3
rule30=0,100,cauldron
rule31=0,100,double_wooden_slab
rule32=0,100,wooden_slab-8
rule33=0,100,brewing_stand
rule34=2,100,torch-3
rule35=0,100,iron_bars
rule36=0,100,chest-4
# warding rune placeholder
rule37=0,100,MobSpawner:Zombie


layer
1,1,1,1,1,3,3,3,3,1,1,1
1,1,1,1,1,3,3,3,3,1,2,2
1,1,1,1,0,0,0,0,1,1,2,2
1,1,1,1,1,1,1,0,1,1,1,1
1,1,1,1,1,1,1,1,1,1,1,1
1,1,1,1,1,1,1,1,1,1,1,1
3,3,1,1,1,1,1,1,1,1,1,1
3,3,3,1,1,1,1,1,1,1,1,1
3,3,3,3,1,1,1,1,1,1,1,1
3,3,3,3,3,1,1,1,1,1,1,1
1,3,3,3,1,1,1,1,1,1,1,1
1,1,1,1,1,1,1,1,1,1,1,1
1,1,1,1,1,1,1,1,1,1,1,1
endlayer

layer
1,1,1,1,1,1,3,1,1,4,4,4
1,1,1,1,1,1,4,4,4,4,2,2
1,1,0,0,0,4,4,4,4,4,2,2
1,1,1,1,1,1,4,0,1,1,1,1
1,1,1,1,1,1,1,0,1,1,1,1
1,1,0,1,1,1,1,1,1,1,1,1
3,3,1,1,1,1,1,1,1,1,1,1
3,3,0,1,1,1,1,1,1,1,1,1
3,3,0,3,3,1,1,1,1,1,1,1
3,3,0,1,1,1,9,7,1,1,1,1
1,3,0,3,1,1,1,8,6,5,6,5
1,1,1,1,1,1,1,1,1,1,1,1
1,1,1,1,1,1,1,1,1,1,1,1
endlayer

layer
4,1,1,1,1,1,4,4,4,4,4,4
1,4,1,1,1,4,4,4,4,4,4,2
1,0,0,0,0,4,4,4,4,4,4,2
1,0,0,0,0,0,0,0,4,1,1,1
4,0,0,0,0,0,0,0,1,1,1,1
1,0,0,0,0,0,0,0,1,1,1,1
4,0,0,1,1,1,1,1,1,1,1,1
4,4,0,1,1,1,1,1,1,1,1,1
4,4,0,1,1,1,1,1,1,1,1,1
4,1,0,1,1,0,0,0,1,1,1,1
1,4,0,1,1,1,1,0,8,10,8,10
1,1,1,1,1,1,1,1,1,1,1,1
1,1,1,1,1,1,1,1,1,1,1,1
endlayer

layer
12,4,4,4,12,4,4,4,4,4,4,4
12,4,4,4,4,4,4,4,4,4,4,5
4,4,4,4,4,4,4,4,4,4,4,4
4,4,4,4,4,4,4,4,4,4,4,4
4,4,4,4,4,4,4,4,4,4,4,4
4,4,4,4,4,4,4,4,4,4,4,4
4,4,4,4,4,4,4,4,4,4,4,4
4,4,4,4,4,4,4,4,4,4,4,4
4,4,4,4,13,11,0,0,11,4,4,4
4,4,1,1,0,0,0,0,11,4,4,4
4,4,1,1,1,4,4,4,4,4,4,5
4,4,4,4,4,4,4,4,4,4,4,4
4,4,4,4,4,4,4,4,4,4,4,4
endlayer

layer
10,10,10,10,10,10,10,10,10,10,10,10
10,12,12,12,12,12,12,12,12,12,12,10
10,12,14,1,1,1,1,1,1,14,12,10
10,12,14,1,1,1,1,1,1,1,12,10
10,12,1,1,1,1,1,1,1,1,12,10
10,12,1,1,1,1,1,1,1,1,12,10
10,12,1,1,1,1,1,1,1,1,12,10
10,12,1,1,13,1,1,1,1,1,12,10
10,12,14,1,0,1,1,1,1,1,12,10
10,12,1,1,0,0,13,1,1,1,12,10
10,12,14,1,1,13,1,1,1,14,12,10
10,4,12,12,12,12,12,12,12,12,12,10
10,10,10,10,10,10,10,10,10,10,10,10
endlayer

layer
0,0,0,0,0,0,0,0,0,0,0,0
0,0,0,0,0,0,15,15,0,0,0,0
0,0,0,14,14,14,14,14,14,0,0,0
0,0,14,1,0,20,11,14,14,14,0,0
0,0,14,1,20,20,0,0,18,14,0,0
0,0,17,1,0,0,0,0,0,14,0,0
0,0,14,1,0,0,0,0,19,16,0,0
0,0,14,1,0,0,0,0,0,14,0,0
0,0,14,13,0,20,0,0,0,14,15,0
0,0,14,1,0,20,0,0,11,17,0,0
0,0,0,14,17,14,14,14,14,0,0,0
0,0,0,0,0,0,0,0,0,0,0,0
0,0,0,0,0,0,0,0,0,0,0,0
endlayer

layer
0,0,0,0,0,0,0,0,0,0,0,0
0,0,0,0,0,0,0,0,0,0,0,0
0,0,0,14,14,14,14,14,14,0,0,0
0,0,14,1,0,20,14,23,0,14,0,0
0,0,14,1,20,20,24,0,0,14,0,0
0,0,14,1,0,0,0,0,0,14,0,0
0,0,14,1,0,0,0,0,0,21,0,0
0,0,14,13,0,0,0,0,0,14,0,0
0,0,14,13,0,20,0,0,0,22,0,0
0,0,14,1,0,20,0,0,0,14,0,0
0,0,0,14,14,14,14,14,14,0,0,0
0,0,0,0,0,0,0,0,0,0,0,0
0,0,0,0,0,0,0,0,0,0,0,0
endlayer

layer
0,0,0,0,0,0,0,0,0,0,0,0
0,0,0,0,0,0,0,0,0,0,0,0
0,0,0,14,14,14,14,14,14,0,0,0
0,0,14,1,20,20,0,0,0,14,0,0
0,0,14,1,20,20,25,0,0,14,0,0
0,0,14,1,0,0,0,0,0,22,0,0
0,0,14,1,26,0,0,0,0,13,0,0
0,0,14,1,0,0,0,0,0,14,0,0
0,0,14,1,20,20,0,0,0,14,0,0
0,0,14,1,20,20,0,0,0,14,0,0
0,0,0,14,14,14,14,14,14,0,0,0
0,0,0,0,0,0,0,0,0,0,0,0
0,0,0,0,0,0,0,0,0,0,0,0
endlayer

layer
0,0,0,0,0,0,0,0,0,0,0,0
0,0,0,0,0,0,0,0,0,0,0,0
0,0,0,14,14,14,28,14,14,0,0,0
0,0,14,14,14,14,0,0,0,14,0,0
0,0,14,14,14,14,0,14,27,14,0,0
0,0,14,14,14,14,25,14,14,14,0,0
0,0,14,14,14,14,14,14,14,14,0,0
0,0,14,14,14,14,14,14,14,27,0,0
0,0,14,14,14,14,14,14,14,14,0,0
0,0,14,13,14,14,17,14,14,14,0,0
0,0,0,14,14,14,14,14,14,0,0,0
0,0,0,0,0,0,0,0,0,0,0,0
0,0,0,0,0,0,0,0,0,0,0,0
endlayer

layer
0,0,0,0,0,0,0,0,0,0,0,0
0,0,0,0,0,0,0,0,0,0,0,0
0,0,0,14,14,14,14,14,14,0,0,0
0,0,17,11,0,0,0,0,0,14,0,0
0,0,14,30,0,0,0,0,0,14,0,0
0,0,14,31,0,0,0,0,0,14,0,0
0,0,14,32,0,0,0,29,14,14,0,0
0,0,14,32,0,0,0,0,0,14,0,0
0,0,14,32,0,0,0,0,0,13,0,0
0,0,14,31,11,0,0,0,0,14,0,0
0,0,0,14,14,14,14,14,14,0,0,0
0,0,0,0,0,0,0,0,0,0,0,0
0,0,0,0,0,0,0,0,0,0,0,0
endlayer

layer
0,0,0,0,0,0,0,0,0,0,0,0
0,0,0,0,0,0,0,0,0,0,0,0
0,0,0,14,14,14,14,14,14,0,0,0
0,0,14,0,0,0,0,0,0,14,0,0
0,0,14,0,0,0,0,0,0,14,0,0
0,0,14,33,0,0,0,0,18,14,0,0
0,0,14,0,0,0,0,0,22,14,0,0
0,0,13,0,0,0,0,0,0,14,0,0
0,0,14,0,0,0,0,0,0,14,0,0
0,0,17,20,0,0,0,0,0,14,0,0
0,0,0,14,14,14,14,14,14,0,0,0
0,0,0,0,0,0,0,0,0,0,0,0
0,0,0,0,0,0,0,0,0,0,0,0
endlayer

layer
0,0,0,0,0,0,0,0,0,0,0,0
0,0,0,0,0,0,0,0,0,0,0,0
0,0,0,14,14,14,14,14,14,0,0,0
0,0,14,0,0,0,0,0,0,14,0,0
0,0,14,0,0,0,0,0,18,14,0,0
0,0,28,0,0,0,0,0,0,14,0,0
0,0,28,0,0,0,0,0,0,17,0,0
0,0,28,0,0,0,0,0,0,14,0,0
0,0,14,26,0,0,0,0,34,14,0,0
0,0,14,20,0,0,0,0,11,14,0,0
0,0,0,14,14,14,14,14,14,0,0,0
0,0,0,0,0,0,0,0,0,0,0,0
0,0,0,0,0,0,0,0,0,0,0,0
endlayer

layer
0,0,0,0,0,0,0,0,0,0,0,0
0,0,0,0,0,0,0,0,0,0,0,0
0,0,14,14,14,14,14,14,14,14,0,0
0,0,14,14,14,14,14,23,22,14,0,0
0,0,14,14,14,14,14,14,0,14,0,0
0,0,14,14,14,14,13,14,0,14,0,0
0,0,14,14,14,14,14,27,0,14,0,0
0,0,14,14,14,14,14,14,14,14,0,0
0,0,14,14,14,14,14,14,14,14,0,0
0,0,14,14,14,14,14,14,14,14,0,0
0,0,13,14,14,14,14,14,14,14,0,0
0,0,0,0,0,0,0,0,0,0,0,0
0,0,0,0,0,0,0,0,0,0,0,0
endlayer

layer
0,0,0,0,0,0,0,0,0,0,0,0
0,0,0,0,0,0,0,0,0,0,0,0
0,0,35,35,35,14,14,14,14,0,0,0
0,0,35,0,14,0,0,0,0,14,0,0
0,0,35,0,14,0,0,0,0,14,0,0
0,0,35,0,14,0,0,0,0,14,0,0
0,0,35,0,14,0,0,0,0,14,0,0
0,0,35,0,14,0,0,36,36,14,0,0
0,0,35,0,0,14,14,14,14,35,0,0
0,0,35,0,0,0,0,0,0,35,0,0
0,0,35,35,35,35,35,35,35,35,0,0
0,0,0,0,0,0,0,0,0,0,0,0
0,0,0,0,0,0,0,0,0,0,0,0
endlayer

layer
0,0,0,0,0,0,0,0,0,0,0,0
0,0,0,0,0,0,0,0,0,0,0,0
0,0,0,0,0,14,22,27,17,0,0,0
0,0,0,0,14,0,0,0,0,14,0,0
0,0,0,0,22,0,0,0,0,14,0,0
0,0,0,0,13,0,0,0,0,22,0,0
0,0,0,0,22,0,0,0,0,13,0,0
0,0,0,0,14,0,0,0,0,14,0,0
0,0,0,0,0,14,13,14,14,0,0,0
0,0,0,0,0,0,0,0,0,0,0,0
0,0,0,0,0,0,0,0,0,0,0,0
0,0,0,0,0,0,0,0,0,0,0,0
0,0,0,0,0,0,0,0,0,0,0,0
endlayer

layer
0,0,0,0,0,0,0,0,0,0,0,0
0,0,0,0,0,0,0,0,0,0,0,0
0,0,0,0,0,14,14,14,14,0,0,0
0,0,0,0,14,0,0,0,0,14,0,0
0,0,0,0,14,0,0,0,0,14,0,0
0,0,0,0,14,0,0,0,0,14,0,0
0,0,0,0,27,0,0,0,0,13,0,0
0,0,0,0,14,0,0,0,0,14,0,0
0,0,0,0,0,14,27,0,14,0,0,0
0,0,0,0,0,0,0,0,0,0,0,0
0,0,0,0,0,0,0,0,0,0,0,0
0,0,0,0,0,0,0,0,0,0,0,0
0,0,0,0,0,0,0,0,0,0,0,0
endlayer

layer
0,0,0,0,0,0,0,0,0,0,0,0
0,0,0,0,0,0,0,0,0,0,0,0
0,0,0,0,0,14,14,14,14,0,0,0
0,0,0,0,14,0,0,0,0,14,0,0
0,0,0,0,14,0,0,0,0,27,0,0
0,0,0,0,14,0,0,0,0,14,0,0
0,0,0,0,14,0,0,0,0,14,0,0
0,0,0,0,13,0,0,0,0,14,0,0
0,0,0,0,0,14,14,14,14,0,0,0
0,0,0,0,0,0,0,0,0,0,0,0
0,0,0,0,0,0,0,0,0,0,0,0
0,0,0,0,0,0,0,0,0,0,0,0
0,0,0,0,0,0,0,0,0,0,0,0
endlayer

layer
0,0,0,0,0,0,0,0,0,0,0,0
0,0,0,0,0,0,0,0,0,0,0,0
0,0,0,0,22,25,25,25,25,22,0,0
0,0,0,0,29,27,27,27,27,23,0,0
0,0,0,0,29,27,0,0,0,23,0,0
0,0,0,0,29,27,0,0,27,23,0,0
0,0,0,0,29,27,0,0,27,23,0,0
0,0,0,0,29,27,27,27,27,23,0,0
0,0,0,0,22,18,18,18,18,22,0,0
0,0,0,0,0,0,0,0,0,0,0,0
0,0,0,0,0,0,0,0,0,0,0,0
0,0,0,0,0,0,0,0,0,0,0,0
0,0,0,0,0,0,0,0,0,0,0,0
endlayer

layer
0,0,0,0,0,0,0,0,0,0,0,0
0,0,0,0,0,0,0,0,0,0,0,0
0,0,0,0,0,0,0,0,0,0,0,0
0,0,0,0,0,22,25,25,22,0,0,0
0,0,0,0,0,29,27,27,23,0,0,0
0,0,0,0,0,29,37,0,23,0,0,0
0,0,0,0,0,29,27,27,23,0,0,0
0,0,0,0,0,22,18,18,22,0,0,0
0,0,0,0,0,0,0,0,0,0,0,0
0,0,0,0,0,0,0,0,0,0,0,0
0,0,0,0,0,0,0,0,0,0,0,0
0,0,0,0,0,0,0,0,0,0,0,0
0,0,0,0,0,0,0,0,0,0,0,0
endlayer

layer
0,0,0,0,0,0,0,0,0,0,0,0
0,0,0,0,0,0,0,0,0,0,0,0
0,0,0,0,0,0,0,0,0,0,0,0
0,0,0,0,0,0,0,0,0,0,0,0
0,0,0,0,0,0,0,0,0,0,0,0
0,0,0,0,0,0,22,22,0,0,0,0
0,0,0,0,0,0,0,0,0,0,0,0
0,0,0,0,0,0,0,0,0,0,0,0
0,0,0,0,0,0,0,0,0,0,0,0
0,0,0,0,0,0,0,0,0,0,0,0
0,0,0,0,0,0,0,0,0,0,0,0
0,0,0,0,0,0,0,0,0,0,0,0
0,0,0,0,0,0,0,0,0,0,0,0
endlayer

