# Converted from schematic
# THIS TEMPLATE USES DEFAULTS!  Please edit for corrections.
# If you need help, consult template_rules.txt
biomesToSpawnIn=mesa,mesa (bryce),mesa plateau, mesa plateau f m, mesa plateau m
weight=10
embed_into_distance=1
unacceptable_target_blocks=flowing_water,water,flowing_lava,lava,Natura:Cloud
dimensions=8,12,17
allowable_overhang=0
max_leveling=2
leveling_buffer=1
preserve_water=0
preserve_lava=0
preserve_plants=0

rule1=0,100,sand-1
rule2=0,100,stained_hardened_clay-4
rule3=0,100,wooden_slab
rule4=0,100,double_wooden_slab
rule5=0,100,stained_hardened_clay-1
rule6=0,100,wooden_door-1
rule7=0,100,wooden_door-9
rule8=0,100,wooden_door-8
rule9=0,100,fence
rule10=2,100,torch-4
rule11=2,100,torch-3
rule12=0,100,preserveBlock


layer
12,12,2,2,2,2,12,12,12,12,12,12,12,12,12,12,12
12,2,12,12,2,12,12,12,12,12,12,12,12,12,12,12,12
2,12,12,12,12,12,12,2,2,2,12,12,12,12,12,12,12
2,12,12,12,12,2,2,2,2,2,2,12,12,12,12,12,12
2,12,12,12,2,2,2,2,2,2,2,2,12,12,12,12,12
2,12,12,2,2,2,2,2,2,2,2,2,12,12,12,12,12
2,12,12,2,2,2,2,2,2,2,2,2,12,12,12,12,12
2,12,12,2,2,2,2,2,2,2,2,12,12,12,12,12,12
2,12,12,12,2,2,2,2,2,2,12,12,12,12,12,12,12
2,12,12,12,2,2,2,2,12,12,12,12,12,12,12,12,12
12,2,12,12,12,12,12,12,12,12,12,12,12,12,12,12,12
12,12,2,2,2,12,12,12,12,12,12,12,12,12,12,12,12
endlayer

layer
0,0,2,2,2,2,2,2,2,2,0,0,0,0,0,0,0
0,2,2,2,2,2,2,2,2,2,2,0,0,0,0,0,0
2,2,2,2,2,2,2,2,2,2,1,2,0,0,0,0,0
2,2,2,2,2,2,2,2,2,2,2,2,2,2,2,2,2
2,2,2,2,2,2,2,2,2,2,2,2,2,2,4,3,3
2,2,2,2,2,2,2,2,2,2,2,2,2,2,4,3,3
2,2,2,2,2,2,2,2,2,2,2,2,2,2,4,3,3
2,2,2,2,2,2,2,2,2,2,2,2,2,2,4,3,3
2,2,2,2,2,2,2,2,2,2,2,2,2,2,2,2,2
2,2,2,2,2,2,2,2,2,2,1,2,0,0,0,0,0
0,2,2,2,2,2,2,2,2,2,2,0,0,0,0,0,0
0,0,2,2,2,2,2,2,2,2,0,0,0,0,0,0,0
endlayer

layer
0,0,0,0,0,0,0,0,0,0,0,0,0,0,0,0,0
0,0,0,0,0,0,0,0,0,0,0,0,0,0,0,0,0
0,0,0,0,2,2,2,0,0,0,0,0,0,0,0,0,0
0,0,0,2,2,2,2,2,0,0,0,0,0,0,0,0,0
0,0,2,2,2,2,2,2,2,5,2,0,0,0,0,0,0
0,2,2,2,2,2,2,2,2,2,3,0,0,0,0,0,0
0,2,2,2,2,2,2,2,2,2,3,0,0,0,0,0,0
0,0,2,2,2,2,2,2,2,5,2,0,0,0,0,0,0
0,0,0,2,2,2,2,2,0,0,0,0,0,0,0,0,0
0,0,0,0,2,2,2,0,0,0,0,0,0,0,0,0,0
0,0,0,0,0,0,0,0,0,0,0,0,0,0,0,0,0
0,0,0,0,0,0,0,0,0,0,0,0,0,0,0,0,0
endlayer

layer
0,0,0,0,0,0,0,0,0,0,0,0,0,0,0,0,0
0,0,0,0,0,0,0,0,0,0,0,0,0,0,0,0,0
0,0,0,0,2,2,2,0,0,0,0,0,0,0,0,0,0
0,0,0,2,0,0,0,2,0,0,0,0,0,0,0,0,0
0,0,2,0,0,0,0,0,2,5,0,0,0,0,0,0,0
0,2,0,0,0,0,0,0,0,6,0,0,0,0,0,0,0
0,2,0,0,0,0,0,0,0,6,0,0,0,0,0,0,0
0,0,2,0,0,0,0,0,2,5,0,0,0,0,0,0,0
0,0,0,2,0,0,0,2,0,0,0,0,0,0,0,0,0
0,0,0,0,2,2,2,0,0,0,0,0,0,0,0,0,0
0,0,0,0,0,0,0,0,0,0,0,0,0,0,0,0,0
0,0,0,0,0,0,0,0,0,0,0,0,0,0,0,0,0
endlayer

layer
0,0,0,0,0,0,0,0,0,0,0,0,0,0,0,0,0
0,0,0,0,0,0,0,0,0,0,0,0,0,0,0,0,0
0,0,0,0,2,9,2,0,0,0,0,0,0,0,0,0,0
0,0,0,2,0,0,0,2,0,0,0,0,0,0,0,0,0
0,0,2,0,0,0,0,0,2,5,0,0,0,0,0,0,0
0,2,10,0,0,0,0,0,0,7,0,0,0,0,0,0,0
0,2,0,0,0,0,0,0,0,8,0,0,0,0,0,0,0
0,0,2,0,0,0,0,0,2,5,0,0,0,0,0,0,0
0,0,0,2,0,0,0,2,0,0,0,0,0,0,0,0,0
0,0,0,0,2,9,2,0,0,0,0,0,0,0,0,0,0
0,0,0,0,0,0,0,0,0,0,0,0,0,0,0,0,0
0,0,0,0,0,0,0,0,0,0,0,0,0,0,0,0,0
endlayer

layer
0,0,0,0,0,0,0,0,0,0,0,0,0,0,0,0,0
0,0,0,0,0,0,0,0,0,0,0,0,0,0,0,0,0
0,0,0,0,2,2,2,0,0,0,0,0,0,0,0,0,0
0,0,0,2,0,0,0,2,0,0,0,0,0,0,0,0,0
0,0,2,0,0,0,0,0,2,5,0,0,0,0,0,0,0
0,2,0,0,0,0,0,0,11,2,0,0,0,0,0,0,0
0,2,0,0,0,0,0,0,0,2,0,0,0,0,0,0,0
0,0,2,0,0,0,0,0,2,5,0,0,0,0,0,0,0
0,0,0,2,0,0,0,2,0,0,0,0,0,0,0,0,0
0,0,0,0,2,2,2,0,0,0,0,0,0,0,0,0,0
0,0,0,0,0,0,0,0,0,0,0,0,0,0,0,0,0
0,0,0,0,0,0,0,0,0,0,0,0,0,0,0,0,0
endlayer

layer
0,0,0,0,0,0,0,0,0,0,0,0,0,0,0,0,0
0,0,0,0,0,0,0,0,0,0,0,0,0,0,0,0,0
0,0,0,0,2,2,2,0,0,0,0,0,0,0,0,0,0
0,0,0,2,2,2,2,2,0,0,0,0,0,0,0,0,0
0,0,2,2,2,2,2,2,2,5,0,0,0,0,0,0,0
0,2,2,2,2,2,2,2,2,5,0,0,0,0,0,0,0
0,2,2,2,2,2,2,2,2,5,0,0,0,0,0,0,0
0,0,2,2,2,2,2,2,2,5,0,0,0,0,0,0,0
0,0,0,2,2,2,2,2,0,0,0,0,0,0,0,0,0
0,0,0,0,2,2,2,0,0,0,0,0,0,0,0,0,0
0,0,0,0,0,0,0,0,0,0,0,0,0,0,0,0,0
0,0,0,0,0,0,0,0,0,0,0,0,0,0,0,0,0
endlayer

layer
0,0,0,0,0,0,0,0,0,0,0,0,0,0,0,0,0
0,0,0,0,0,0,0,0,0,0,0,0,0,0,0,0,0
0,0,0,0,3,3,3,0,0,0,0,0,0,0,0,0,0
0,0,0,3,0,0,0,3,0,0,0,0,0,0,0,0,0
0,0,3,0,0,0,0,0,3,3,0,0,0,0,0,0,0
0,3,0,0,0,0,0,0,0,3,0,0,0,0,0,0,0
0,3,0,0,0,0,0,0,0,3,0,0,0,0,0,0,0
0,0,3,0,0,0,0,0,3,3,0,0,0,0,0,0,0
0,0,0,3,0,0,0,3,0,0,0,0,0,0,0,0,0
0,0,0,0,3,3,3,0,0,0,0,0,0,0,0,0,0
0,0,0,0,0,0,0,0,0,0,0,0,0,0,0,0,0
0,0,0,0,0,0,0,0,0,0,0,0,0,0,0,0,0
endlayer

