# Converted from schematic
# THIS TEMPLATE USES DEFAULTS!  Please edit for corrections.
# If you need help, consult template_rules.txt
biomesToSpawnIn=mesa,mesa (bryce),mesa plateau, mesa plateau f m, mesa plateau m
weight=20
embed_into_distance=1
unacceptable_target_blocks=flowing_water,water,flowing_lava,lava,Natura:Cloud
dimensions=8,10,9
allowable_overhang=0
max_leveling=2
leveling_buffer=1
preserve_water=0
preserve_lava=0
preserve_plants=1


rule1=0,100,sand-1
rule2=0,100,stained_hardened_clay-1
rule3=0,100,wooden_slab
rule4=0,100,fence
rule5=0,100,wooden_slab-8


layer
2,2,2,2,2,2,2,2,1
2,2,2,2,2,2,2,2,1
2,2,2,2,2,2,2,2,0
2,2,2,2,2,0,0,0,0
2,2,2,2,2,0,0,0,0
2,2,2,2,0,0,0,0,0
2,2,2,2,2,2,2,2,2
2,2,2,2,2,2,2,0,2
2,2,2,2,2,2,2,2,2
2,2,2,2,2,2,2,2,2
endlayer

layer
2,2,2,2,2,2,2,2,2
3,2,2,2,0,0,0,0,2
3,2,2,2,0,0,0,0,2
2,2,2,2,0,0,0,0,0
2,0,0,0,0,0,0,0,0
2,0,0,0,0,0,0,0,0
0,0,0,0,0,0,0,0,2
2,0,0,0,0,0,0,0,2
2,0,0,0,0,0,0,0,2
2,2,2,2,2,2,2,2,2
endlayer

layer
2,2,2,2,2,4,2,2,2
0,0,3,2,0,0,0,0,2
0,0,3,2,0,0,0,0,0
2,2,2,2,0,0,0,0,0
2,0,0,0,0,0,0,0,0
2,0,0,0,0,0,0,0,0
0,0,0,0,0,0,0,0,0
2,0,0,0,0,0,0,0,4
0,0,0,0,0,0,0,0,2
0,0,0,2,2,2,4,2,2
endlayer

layer
2,2,2,2,2,0,0,0,2
0,0,0,0,0,0,0,0,0
0,0,0,0,0,0,0,0,0
2,2,2,2,0,0,0,0,0
2,2,2,0,0,0,0,0,0
2,5,5,5,0,0,0,0,0
0,5,5,5,5,5,0,0,0
2,5,5,5,5,5,5,5,0
2,0,5,5,5,5,5,5,2
0,0,0,2,2,2,2,2,2
endlayer

layer
2,2,2,0,0,0,0,0,0
0,0,0,0,0,0,0,0,0
0,0,0,0,0,0,0,0,0
2,0,0,0,0,0,0,0,0
2,0,0,0,0,0,0,0,0
2,2,2,2,0,0,0,0,0
0,0,0,0,0,0,0,0,0
2,0,0,0,0,0,0,0,0
2,0,0,0,0,0,0,0,0
0,0,2,2,2,0,2,2,2
endlayer

layer
0,0,0,0,0,0,0,0,0
0,0,0,0,0,0,0,0,0
0,0,0,0,0,0,0,0,0
0,0,0,0,0,0,0,0,0
0,0,0,0,0,0,0,0,0
2,2,4,2,0,0,0,0,0
2,0,0,0,0,0,0,0,0
2,0,0,0,0,0,0,0,2
2,0,0,0,0,0,0,0,2
2,2,4,2,2,0,4,2,2
endlayer

layer
0,0,0,0,0,0,0,0,0
0,0,0,0,0,0,0,0,0
0,0,0,0,0,0,0,0,0
0,0,0,0,0,0,0,0,0
0,0,0,0,0,0,0,0,0
2,2,2,0,0,0,0,0,0
2,5,5,5,5,5,5,0,0
2,5,5,5,5,5,5,5,2
2,5,5,5,5,5,5,5,2
2,2,0,2,0,0,2,2,2
endlayer

layer
0,0,0,0,0,0,0,0,0
0,0,0,0,0,0,0,0,0
0,0,0,0,0,0,0,0,0
0,0,0,0,0,0,0,0,0
0,0,0,0,0,0,0,0,0
3,3,3,3,0,0,0,0,0
3,0,0,0,0,0,0,0,3
3,0,0,0,0,0,0,0,3
3,0,0,0,0,0,0,0,3
3,3,3,3,0,0,3,3,3
endlayer

