# Converted from schematic
# THIS TEMPLATE USES DEFAULTS!  Please edit for corrections.
# If you need help, consult template_rules.txt
biomesToSpawnIn=mesa,mesa (bryce),mesa plateau, mesa plateau f m, mesa plateau m
weight=20
embed_into_distance=1
unacceptable_target_blocks=flowing_water,water,flowing_lava,lava,Natura:Cloud
dimensions=10,14,8
allowable_overhang=0
max_leveling=2
leveling_buffer=1
preserve_water=0
preserve_lava=0
preserve_plants=1


rule1=0,100,preserveBlock
rule2=0,100,planks
rule3=0,100,stained_hardened_clay-12
rule4=0,100,stained_hardened_clay-1
rule5=0,100,wooden_slab
rule6=0,100,planks
rule7=0,100,fence
rule8=0,100,wooden_slab
rule9=0,100,wooden_slab-8


layer
1,1,1,1,1,1,1,1
0,0,0,0,0,1,1,1
0,0,0,0,0,0,1,1
0,0,0,0,0,0,1,1
0,0,0,0,0,0,1,1
2,2,0,2,2,2,1,1
2,2,0,2,2,2,1,1
2,2,2,2,2,2,1,1
2,2,2,2,2,2,1,1
2,2,2,2,2,2,1,1
2,2,2,2,2,2,1,1
2,2,2,2,2,2,1,1
2,2,2,2,2,2,1,1
1,1,1,1,1,1,1,1
endlayer

layer
0,0,0,0,0,0,0,0
0,0,0,0,0,0,3,0
0,0,0,0,0,0,0,0
0,0,0,0,0,0,0,0
0,0,0,0,0,0,0,0
0,0,0,0,0,0,0,0
4,0,0,0,0,0,4,0
4,0,0,0,0,0,4,0
4,0,0,0,0,0,4,0
4,0,0,0,0,0,4,0
4,0,0,0,0,5,4,0
4,0,0,0,0,6,4,0
4,4,4,4,4,6,4,0
3,4,4,4,4,4,3,0
endlayer

layer
0,0,0,0,0,0,0,0
0,0,0,0,0,4,3,0
0,0,0,0,0,0,0,0
0,0,0,0,0,0,0,0
0,0,0,0,0,0,0,0
0,0,0,0,0,0,0,0
4,0,0,0,0,0,0,0
0,0,0,0,0,0,0,0
0,0,0,0,0,0,4,0
0,0,0,0,0,0,0,0
4,0,0,0,0,0,4,0
0,0,0,0,0,0,7,0
4,4,4,4,6,5,4,0
3,4,4,4,0,4,3,0
endlayer

layer
0,0,0,0,0,0,0,0
0,0,0,0,0,4,3,0
0,0,0,0,0,0,4,0
0,0,0,0,0,0,0,8
0,0,0,0,0,0,0,0
0,0,0,0,0,0,4,8
4,0,0,0,0,0,4,0
4,0,0,0,0,0,4,8
4,0,0,0,0,0,4,0
4,0,0,0,0,0,4,8
4,0,0,0,0,0,4,0
4,0,0,0,0,0,4,8
4,4,6,5,0,0,4,0
3,4,4,4,0,4,3,0
endlayer

layer
0,0,0,0,0,0,0,0
0,0,0,0,0,3,3,0
0,0,0,0,0,9,3,0
0,0,0,0,0,0,0,0
0,0,0,0,0,0,0,0
0,0,0,0,0,0,0,0
0,0,0,0,0,0,0,0
0,0,0,0,0,0,0,0
3,9,0,0,0,9,3,0
3,9,9,9,9,9,3,0
3,9,9,9,9,9,3,0
3,9,9,9,9,9,3,0
3,5,0,0,0,0,3,0
3,3,3,3,0,3,3,0
endlayer

layer
0,0,0,0,0,0,0,0
0,0,0,0,0,0,0,0
0,0,0,0,0,0,0,0
0,0,0,0,0,0,0,0
0,0,0,0,0,0,0,0
0,0,0,0,0,0,0,0
0,0,0,0,0,0,0,0
0,0,0,0,0,0,0,0
4,0,0,0,0,0,4,0
4,0,0,0,0,0,4,0
0,0,0,0,0,0,4,0
4,0,0,0,0,0,4,0
4,0,0,0,0,0,4,0
3,4,0,4,0,4,3,0
endlayer

layer
0,0,0,0,0,0,0,0
0,0,0,0,0,0,0,0
0,0,0,0,0,0,0,0
0,0,0,0,0,0,0,0
0,0,0,0,0,0,0,0
0,0,0,0,0,0,0,0
0,0,0,0,0,0,0,0
0,0,0,0,0,0,0,0
4,0,0,0,0,0,4,0
0,0,0,0,0,0,0,0
0,0,0,0,0,0,4,0
0,0,0,0,0,0,0,0
4,0,0,0,0,0,4,0
3,4,7,4,0,4,3,0
endlayer

layer
0,0,0,0,0,0,0,0
0,0,0,0,0,0,0,0
0,0,0,0,0,0,0,0
0,0,0,0,0,0,0,0
0,0,0,0,0,0,0,0
0,0,0,0,0,0,0,0
0,0,0,0,0,0,0,0
0,0,0,0,0,0,0,0
4,0,0,0,0,0,4,0
4,0,0,0,0,0,4,8
0,0,0,0,0,0,4,0
4,0,0,0,0,0,0,8
4,0,0,0,0,0,0,0
3,4,4,0,0,0,0,0
endlayer

layer
0,0,0,0,0,0,0,0
0,0,0,0,0,0,0,0
0,0,0,0,0,0,0,0
0,0,0,0,0,0,0,0
0,0,0,0,0,0,0,0
0,0,0,0,0,0,0,0
0,0,0,0,0,0,0,0
0,0,3,0,0,3,0,0
3,9,9,9,9,9,3,0
3,0,0,9,0,0,3,0
0,0,0,0,0,0,0,0
3,9,0,0,0,0,0,0
3,9,9,0,0,0,0,0
3,3,0,0,0,0,0,0
endlayer

layer
0,0,0,0,0,0,0,0
0,0,0,0,0,0,0,0
0,0,0,0,0,0,0,0
0,0,0,0,0,0,0,0
0,0,0,0,0,0,0,0
0,0,0,0,0,0,0,0
0,0,0,0,0,0,0,0
3,5,0,3,0,5,3,0
5,0,0,0,0,0,5,0
0,0,0,0,0,0,0,0
0,0,0,0,0,0,0,0
0,0,0,0,0,0,0,0
5,0,0,0,0,0,0,0
3,0,0,0,0,0,0,0
endlayer

